2018-04-17 22:16:07,788 ERROR exception 1841 Internal Server Error: /accounts/login/
Traceback (most recent call last):
  File "/home/adrian/skyfolk/venv/lib/python3.5/site-packages/urllib3/connection.py", line 141, in _new_conn
    (self.host, self.port), self.timeout, **extra_kw)
  File "/home/adrian/skyfolk/venv/lib/python3.5/site-packages/urllib3/util/connection.py", line 83, in create_connection
    raise err
  File "/home/adrian/skyfolk/venv/lib/python3.5/site-packages/urllib3/util/connection.py", line 73, in create_connection
    sock.connect(sa)
ConnectionRefusedError: [Errno 111] Connection refused

During handling of the above exception, another exception occurred:

Traceback (most recent call last):
  File "/home/adrian/skyfolk/venv/lib/python3.5/site-packages/elasticsearch/connection/http_urllib3.py", line 95, in perform_request
    response = self.pool.urlopen(method, url, body, retries=False, headers=self.headers, **kw)
  File "/home/adrian/skyfolk/venv/lib/python3.5/site-packages/urllib3/connectionpool.py", line 639, in urlopen
    _stacktrace=sys.exc_info()[2])
  File "/home/adrian/skyfolk/venv/lib/python3.5/site-packages/urllib3/util/retry.py", line 333, in increment
    raise six.reraise(type(error), error, _stacktrace)
  File "/home/adrian/skyfolk/venv/lib/python3.5/site-packages/urllib3/packages/six.py", line 686, in reraise
    raise value
  File "/home/adrian/skyfolk/venv/lib/python3.5/site-packages/urllib3/connectionpool.py", line 601, in urlopen
    chunked=chunked)
  File "/home/adrian/skyfolk/venv/lib/python3.5/site-packages/urllib3/connectionpool.py", line 357, in _make_request
    conn.request(method, url, **httplib_request_kw)
  File "/usr/lib/python3.5/http/client.py", line 1106, in request
    self._send_request(method, url, body, headers)
  File "/usr/lib/python3.5/http/client.py", line 1151, in _send_request
    self.endheaders(body)
  File "/usr/lib/python3.5/http/client.py", line 1102, in endheaders
    self._send_output(message_body)
  File "/usr/lib/python3.5/http/client.py", line 934, in _send_output
    self.send(msg)
  File "/usr/lib/python3.5/http/client.py", line 877, in send
    self.connect()
  File "/home/adrian/skyfolk/venv/lib/python3.5/site-packages/urllib3/connection.py", line 166, in connect
    conn = self._new_conn()
  File "/home/adrian/skyfolk/venv/lib/python3.5/site-packages/urllib3/connection.py", line 150, in _new_conn
    self, "Failed to establish a new connection: %s" % e)
urllib3.exceptions.NewConnectionError: <urllib3.connection.HTTPConnection object at 0x7f719da867f0>: Failed to establish a new connection: [Errno 111] Connection refused

During handling of the above exception, another exception occurred:

Traceback (most recent call last):
  File "/home/adrian/skyfolk/venv/lib/python3.5/site-packages/django/core/handlers/exception.py", line 41, in inner
    response = get_response(request)
  File "/home/adrian/skyfolk/venv/lib/python3.5/site-packages/django/core/handlers/base.py", line 249, in _legacy_get_response
    response = self._get_response(request)
  File "/home/adrian/skyfolk/venv/lib/python3.5/site-packages/django/core/handlers/base.py", line 187, in _get_response
    response = self.process_exception_by_middleware(e, request)
  File "/home/adrian/skyfolk/venv/lib/python3.5/site-packages/channels/handler.py", line 243, in process_exception_by_middleware
    return super(AsgiHandler, self).process_exception_by_middleware(exception, request)
  File "/home/adrian/skyfolk/venv/lib/python3.5/site-packages/django/core/handlers/base.py", line 185, in _get_response
    response = wrapped_callback(request, *callback_args, **callback_kwargs)
  File "/home/adrian/skyfolk/venv/lib/python3.5/site-packages/django/views/generic/base.py", line 68, in view
    return self.dispatch(request, *args, **kwargs)
  File "/home/adrian/skyfolk/venv/lib/python3.5/site-packages/django/utils/decorators.py", line 67, in _wrapper
    return bound_func(*args, **kwargs)
  File "/home/adrian/skyfolk/venv/lib/python3.5/site-packages/django/views/decorators/debug.py", line 76, in sensitive_post_parameters_wrapper
    return view(request, *args, **kwargs)
  File "/home/adrian/skyfolk/venv/lib/python3.5/site-packages/django/utils/decorators.py", line 63, in bound_func
    return func.__get__(self, type(self))(*args2, **kwargs2)
  File "/home/adrian/skyfolk/venv/lib/python3.5/site-packages/allauth/account/views.py", line 137, in dispatch
    return super(LoginView, self).dispatch(request, *args, **kwargs)
  File "/home/adrian/skyfolk/venv/lib/python3.5/site-packages/allauth/account/views.py", line 80, in dispatch
    **kwargs)
  File "/home/adrian/skyfolk/venv/lib/python3.5/site-packages/django/views/generic/base.py", line 88, in dispatch
    return handler(request, *args, **kwargs)
  File "/home/adrian/skyfolk/venv/lib/python3.5/site-packages/allauth/account/views.py", line 103, in post
    response = self.form_valid(form)
  File "/home/adrian/skyfolk/venv/lib/python3.5/site-packages/allauth/account/views.py", line 150, in form_valid
    return form.login(self.request, redirect_url=success_url)
  File "/home/adrian/skyfolk/user_profile/forms.py", line 72, in login
    return super(CustomLoginForm, self).login(request=request, redirect_url=redirect_url)
  File "/home/adrian/skyfolk/venv/lib/python3.5/site-packages/allauth/account/forms.py", line 197, in login
    redirect_url=redirect_url)
  File "/home/adrian/skyfolk/venv/lib/python3.5/site-packages/allauth/account/utils.py", line 150, in perform_login
    adapter.login(request, user)
  File "/home/adrian/skyfolk/venv/lib/python3.5/site-packages/allauth/account/adapter.py", line 385, in login
    django_login(request, user)
  File "/home/adrian/skyfolk/venv/lib/python3.5/site-packages/django/contrib/auth/__init__.py", line 161, in login
    user_logged_in.send(sender=user.__class__, request=request, user=user)
  File "/home/adrian/skyfolk/venv/lib/python3.5/site-packages/django/dispatch/dispatcher.py", line 193, in send
    for receiver in self._live_receivers(sender)
  File "/home/adrian/skyfolk/venv/lib/python3.5/site-packages/django/dispatch/dispatcher.py", line 193, in <listcomp>
    for receiver in self._live_receivers(sender)
  File "/home/adrian/skyfolk/venv/lib/python3.5/site-packages/django/contrib/auth/models.py", line 25, in update_last_login
    user.save(update_fields=['last_login'])
  File "/home/adrian/skyfolk/venv/lib/python3.5/site-packages/django/contrib/auth/base_user.py", line 80, in save
    super(AbstractBaseUser, self).save(*args, **kwargs)
  File "/home/adrian/skyfolk/venv/lib/python3.5/site-packages/django/db/models/base.py", line 808, in save
    force_update=force_update, update_fields=update_fields)
  File "/home/adrian/skyfolk/venv/lib/python3.5/site-packages/django/db/models/base.py", line 848, in save_base
    update_fields=update_fields, raw=raw, using=using,
  File "/home/adrian/skyfolk/venv/lib/python3.5/site-packages/django/dispatch/dispatcher.py", line 193, in send
    for receiver in self._live_receivers(sender)
  File "/home/adrian/skyfolk/venv/lib/python3.5/site-packages/django/dispatch/dispatcher.py", line 193, in <listcomp>
    for receiver in self._live_receivers(sender)
  File "/home/adrian/skyfolk/user_profile/signals.py", line 136, in save_user_profile
    instance.profile.save()
  File "/home/adrian/skyfolk/venv/lib/python3.5/site-packages/django/db/models/base.py", line 808, in save
    force_update=force_update, update_fields=update_fields)
  File "/home/adrian/skyfolk/venv/lib/python3.5/site-packages/django/db/models/base.py", line 848, in save_base
    update_fields=update_fields, raw=raw, using=using,
  File "/home/adrian/skyfolk/venv/lib/python3.5/site-packages/django/dispatch/dispatcher.py", line 193, in send
    for receiver in self._live_receivers(sender)
  File "/home/adrian/skyfolk/venv/lib/python3.5/site-packages/django/dispatch/dispatcher.py", line 193, in <listcomp>
    for receiver in self._live_receivers(sender)
  File "/home/adrian/skyfolk/venv/lib/python3.5/site-packages/haystack/signals.py", line 52, in handle_save
    index.update_object(instance, using=using)
  File "/home/adrian/skyfolk/venv/lib/python3.5/site-packages/haystack/indexes.py", line 284, in update_object
    backend.update(self, [instance])
  File "/home/adrian/skyfolk/venv/lib/python3.5/site-packages/haystack/backends/elasticsearch_backend.py", line 190, in update
    bulk(self.conn, prepped_docs, index=self.index_name, doc_type='modelresult')
  File "/home/adrian/skyfolk/venv/lib/python3.5/site-packages/elasticsearch/helpers/__init__.py", line 190, in bulk
    for ok, item in streaming_bulk(client, actions, **kwargs):
  File "/home/adrian/skyfolk/venv/lib/python3.5/site-packages/elasticsearch/helpers/__init__.py", line 162, in streaming_bulk
    for result in _process_bulk_chunk(client, bulk_actions, raise_on_exception, raise_on_error, **kwargs):
  File "/home/adrian/skyfolk/venv/lib/python3.5/site-packages/elasticsearch/helpers/__init__.py", line 91, in _process_bulk_chunk
    raise e
  File "/home/adrian/skyfolk/venv/lib/python3.5/site-packages/elasticsearch/helpers/__init__.py", line 87, in _process_bulk_chunk
    resp = client.bulk('\n'.join(bulk_actions) + '\n', **kwargs)
  File "/home/adrian/skyfolk/venv/lib/python3.5/site-packages/elasticsearch/client/utils.py", line 69, in _wrapped
    return func(*args, params=params, **kwargs)
  File "/home/adrian/skyfolk/venv/lib/python3.5/site-packages/elasticsearch/client/__init__.py", line 785, in bulk
    doc_type, '_bulk'), params=params, body=self._bulk_body(body))
  File "/home/adrian/skyfolk/venv/lib/python3.5/site-packages/elasticsearch/transport.py", line 327, in perform_request
    status, headers, data = connection.perform_request(method, url, params, body, ignore=ignore, timeout=timeout)
  File "/home/adrian/skyfolk/venv/lib/python3.5/site-packages/elasticsearch/connection/http_urllib3.py", line 106, in perform_request
    raise ConnectionError('N/A', str(e), e)
elasticsearch.exceptions.ConnectionError: ConnectionError(<urllib3.connection.HTTPConnection object at 0x7f719da867f0>: Failed to establish a new connection: [Errno 111] Connection refused) caused by: NewConnectionError(<urllib3.connection.HTTPConnection object at 0x7f719da867f0>: Failed to establish a new connection: [Errno 111] Connection refused)
2018-04-17 22:21:05,510 ERROR exception 2930 Internal Server Error: /config/invitations/send-invite/
Traceback (most recent call last):
  File "/home/adrian/skyfolk/venv/lib/python3.5/site-packages/django/core/handlers/exception.py", line 41, in inner
    response = get_response(request)
  File "/home/adrian/skyfolk/venv/lib/python3.5/site-packages/django/core/handlers/base.py", line 249, in _legacy_get_response
    response = self._get_response(request)
  File "/home/adrian/skyfolk/venv/lib/python3.5/site-packages/django/core/handlers/base.py", line 187, in _get_response
    response = self.process_exception_by_middleware(e, request)
  File "/home/adrian/skyfolk/venv/lib/python3.5/site-packages/channels/handler.py", line 243, in process_exception_by_middleware
    return super(AsgiHandler, self).process_exception_by_middleware(exception, request)
  File "/home/adrian/skyfolk/venv/lib/python3.5/site-packages/django/core/handlers/base.py", line 185, in _get_response
    response = wrapped_callback(request, *callback_args, **callback_kwargs)
  File "/home/adrian/skyfolk/venv/lib/python3.5/site-packages/django/views/generic/base.py", line 68, in view
    return self.dispatch(request, *args, **kwargs)
  File "/home/adrian/skyfolk/venv/lib/python3.5/site-packages/django/utils/decorators.py", line 67, in _wrapper
    return bound_func(*args, **kwargs)
  File "/home/adrian/skyfolk/venv/lib/python3.5/site-packages/django/contrib/auth/decorators.py", line 23, in _wrapped_view
    return view_func(request, *args, **kwargs)
  File "/home/adrian/skyfolk/venv/lib/python3.5/site-packages/django/utils/decorators.py", line 63, in bound_func
    return func.__get__(self, type(self))(*args2, **kwargs2)
  File "/home/adrian/skyfolk/venv/lib/python3.5/site-packages/django/contrib/auth/decorators.py", line 22, in _wrapped_view
    if test_func(request.user):
AttributeError: 'SendInvite' object has no attribute 'user'
2018-04-25 18:03:22,236 ERROR exception 2061 Internal Server Error: /accounts/login/
Traceback (most recent call last):
  File "/home/adrian/skyfolk/venv/lib/python3.5/site-packages/django/core/handlers/exception.py", line 41, in inner
    response = get_response(request)
  File "/home/adrian/skyfolk/venv/lib/python3.5/site-packages/django/core/handlers/base.py", line 249, in _legacy_get_response
    response = self._get_response(request)
  File "/home/adrian/skyfolk/venv/lib/python3.5/site-packages/django/core/handlers/base.py", line 187, in _get_response
    response = self.process_exception_by_middleware(e, request)
  File "/home/adrian/skyfolk/venv/lib/python3.5/site-packages/channels/handler.py", line 243, in process_exception_by_middleware
    return super(AsgiHandler, self).process_exception_by_middleware(exception, request)
  File "/home/adrian/skyfolk/venv/lib/python3.5/site-packages/django/core/handlers/base.py", line 185, in _get_response
    response = wrapped_callback(request, *callback_args, **callback_kwargs)
  File "/home/adrian/skyfolk/venv/lib/python3.5/site-packages/django/views/generic/base.py", line 68, in view
    return self.dispatch(request, *args, **kwargs)
  File "/home/adrian/skyfolk/venv/lib/python3.5/site-packages/django/utils/decorators.py", line 67, in _wrapper
    return bound_func(*args, **kwargs)
  File "/home/adrian/skyfolk/venv/lib/python3.5/site-packages/django/views/decorators/debug.py", line 76, in sensitive_post_parameters_wrapper
    return view(request, *args, **kwargs)
  File "/home/adrian/skyfolk/venv/lib/python3.5/site-packages/django/utils/decorators.py", line 63, in bound_func
    return func.__get__(self, type(self))(*args2, **kwargs2)
  File "/home/adrian/skyfolk/venv/lib/python3.5/site-packages/allauth/account/views.py", line 137, in dispatch
    return super(LoginView, self).dispatch(request, *args, **kwargs)
  File "/home/adrian/skyfolk/venv/lib/python3.5/site-packages/allauth/account/views.py", line 80, in dispatch
    **kwargs)
  File "/home/adrian/skyfolk/venv/lib/python3.5/site-packages/django/views/generic/base.py", line 88, in dispatch
    return handler(request, *args, **kwargs)
  File "/home/adrian/skyfolk/venv/lib/python3.5/site-packages/allauth/account/views.py", line 103, in post
    response = self.form_valid(form)
  File "/home/adrian/skyfolk/venv/lib/python3.5/site-packages/allauth/account/views.py", line 150, in form_valid
    return form.login(self.request, redirect_url=success_url)
  File "/home/adrian/skyfolk/user_profile/forms.py", line 33, in login
    user_profile = NodeProfile.nodes.get(user_id=self.user.id)
  File "/home/adrian/skyfolk/venv/lib/python3.5/site-packages/neomodel/match.py", line 510, in get
    raise MultipleNodesReturned(repr(kwargs))
neomodel.exceptions.MultipleNodesReturned: {'user_id': 1}
2018-04-25 18:04:45,436 ERROR exception 2061 Internal Server Error: /accounts/login/
Traceback (most recent call last):
  File "/home/adrian/skyfolk/venv/lib/python3.5/site-packages/django/core/handlers/exception.py", line 41, in inner
    response = get_response(request)
  File "/home/adrian/skyfolk/venv/lib/python3.5/site-packages/django/core/handlers/base.py", line 249, in _legacy_get_response
    response = self._get_response(request)
  File "/home/adrian/skyfolk/venv/lib/python3.5/site-packages/django/core/handlers/base.py", line 187, in _get_response
    response = self.process_exception_by_middleware(e, request)
  File "/home/adrian/skyfolk/venv/lib/python3.5/site-packages/channels/handler.py", line 243, in process_exception_by_middleware
    return super(AsgiHandler, self).process_exception_by_middleware(exception, request)
  File "/home/adrian/skyfolk/venv/lib/python3.5/site-packages/django/core/handlers/base.py", line 185, in _get_response
    response = wrapped_callback(request, *callback_args, **callback_kwargs)
  File "/home/adrian/skyfolk/venv/lib/python3.5/site-packages/django/views/generic/base.py", line 68, in view
    return self.dispatch(request, *args, **kwargs)
  File "/home/adrian/skyfolk/venv/lib/python3.5/site-packages/django/utils/decorators.py", line 67, in _wrapper
    return bound_func(*args, **kwargs)
  File "/home/adrian/skyfolk/venv/lib/python3.5/site-packages/django/views/decorators/debug.py", line 76, in sensitive_post_parameters_wrapper
    return view(request, *args, **kwargs)
  File "/home/adrian/skyfolk/venv/lib/python3.5/site-packages/django/utils/decorators.py", line 63, in bound_func
    return func.__get__(self, type(self))(*args2, **kwargs2)
  File "/home/adrian/skyfolk/venv/lib/python3.5/site-packages/allauth/account/views.py", line 137, in dispatch
    return super(LoginView, self).dispatch(request, *args, **kwargs)
  File "/home/adrian/skyfolk/venv/lib/python3.5/site-packages/allauth/account/views.py", line 80, in dispatch
    **kwargs)
  File "/home/adrian/skyfolk/venv/lib/python3.5/site-packages/django/views/generic/base.py", line 88, in dispatch
    return handler(request, *args, **kwargs)
  File "/home/adrian/skyfolk/venv/lib/python3.5/site-packages/allauth/account/views.py", line 103, in post
    response = self.form_valid(form)
  File "/home/adrian/skyfolk/venv/lib/python3.5/site-packages/allauth/account/views.py", line 150, in form_valid
    return form.login(self.request, redirect_url=success_url)
  File "/home/adrian/skyfolk/user_profile/forms.py", line 69, in login
    fail_silently=False,
  File "/home/adrian/skyfolk/venv/lib/python3.5/site-packages/django/core/mail/__init__.py", line 62, in send_mail
    return mail.send()
  File "/home/adrian/skyfolk/venv/lib/python3.5/site-packages/django/core/mail/message.py", line 348, in send
    return self.get_connection(fail_silently).send_messages([self])
  File "/home/adrian/skyfolk/venv/lib/python3.5/site-packages/django/core/mail/backends/smtp.py", line 104, in send_messages
    new_conn_created = self.open()
  File "/home/adrian/skyfolk/venv/lib/python3.5/site-packages/django/core/mail/backends/smtp.py", line 64, in open
    self.connection = self.connection_class(self.host, self.port, **connection_params)
  File "/usr/lib/python3.5/smtplib.py", line 251, in __init__
    (code, msg) = self.connect(host, port)
  File "/usr/lib/python3.5/smtplib.py", line 335, in connect
    self.sock = self._get_socket(host, port, self.timeout)
  File "/usr/lib/python3.5/smtplib.py", line 306, in _get_socket
    self.source_address)
  File "/usr/lib/python3.5/socket.py", line 711, in create_connection
    raise err
  File "/usr/lib/python3.5/socket.py", line 702, in create_connection
    sock.connect(sa)
ConnectionRefusedError: [Errno 111] Connection refused
2018-04-25 18:04:49,266 ERROR exception 2061 Internal Server Error: /accounts/login/
Traceback (most recent call last):
  File "/home/adrian/skyfolk/venv/lib/python3.5/site-packages/django/core/handlers/exception.py", line 41, in inner
    response = get_response(request)
  File "/home/adrian/skyfolk/venv/lib/python3.5/site-packages/django/core/handlers/base.py", line 249, in _legacy_get_response
    response = self._get_response(request)
  File "/home/adrian/skyfolk/venv/lib/python3.5/site-packages/django/core/handlers/base.py", line 187, in _get_response
    response = self.process_exception_by_middleware(e, request)
  File "/home/adrian/skyfolk/venv/lib/python3.5/site-packages/channels/handler.py", line 243, in process_exception_by_middleware
    return super(AsgiHandler, self).process_exception_by_middleware(exception, request)
  File "/home/adrian/skyfolk/venv/lib/python3.5/site-packages/django/core/handlers/base.py", line 185, in _get_response
    response = wrapped_callback(request, *callback_args, **callback_kwargs)
  File "/home/adrian/skyfolk/venv/lib/python3.5/site-packages/django/views/generic/base.py", line 68, in view
    return self.dispatch(request, *args, **kwargs)
  File "/home/adrian/skyfolk/venv/lib/python3.5/site-packages/django/utils/decorators.py", line 67, in _wrapper
    return bound_func(*args, **kwargs)
  File "/home/adrian/skyfolk/venv/lib/python3.5/site-packages/django/views/decorators/debug.py", line 76, in sensitive_post_parameters_wrapper
    return view(request, *args, **kwargs)
  File "/home/adrian/skyfolk/venv/lib/python3.5/site-packages/django/utils/decorators.py", line 63, in bound_func
    return func.__get__(self, type(self))(*args2, **kwargs2)
  File "/home/adrian/skyfolk/venv/lib/python3.5/site-packages/allauth/account/views.py", line 137, in dispatch
    return super(LoginView, self).dispatch(request, *args, **kwargs)
  File "/home/adrian/skyfolk/venv/lib/python3.5/site-packages/allauth/account/views.py", line 80, in dispatch
    **kwargs)
  File "/home/adrian/skyfolk/venv/lib/python3.5/site-packages/django/views/generic/base.py", line 88, in dispatch
    return handler(request, *args, **kwargs)
  File "/home/adrian/skyfolk/venv/lib/python3.5/site-packages/allauth/account/views.py", line 103, in post
    response = self.form_valid(form)
  File "/home/adrian/skyfolk/venv/lib/python3.5/site-packages/allauth/account/views.py", line 150, in form_valid
    return form.login(self.request, redirect_url=success_url)
  File "/home/adrian/skyfolk/user_profile/forms.py", line 69, in login
    fail_silently=False,
  File "/home/adrian/skyfolk/venv/lib/python3.5/site-packages/django/core/mail/__init__.py", line 62, in send_mail
    return mail.send()
  File "/home/adrian/skyfolk/venv/lib/python3.5/site-packages/django/core/mail/message.py", line 348, in send
    return self.get_connection(fail_silently).send_messages([self])
  File "/home/adrian/skyfolk/venv/lib/python3.5/site-packages/django/core/mail/backends/smtp.py", line 104, in send_messages
    new_conn_created = self.open()
  File "/home/adrian/skyfolk/venv/lib/python3.5/site-packages/django/core/mail/backends/smtp.py", line 64, in open
    self.connection = self.connection_class(self.host, self.port, **connection_params)
  File "/usr/lib/python3.5/smtplib.py", line 251, in __init__
    (code, msg) = self.connect(host, port)
  File "/usr/lib/python3.5/smtplib.py", line 335, in connect
    self.sock = self._get_socket(host, port, self.timeout)
  File "/usr/lib/python3.5/smtplib.py", line 306, in _get_socket
    self.source_address)
  File "/usr/lib/python3.5/socket.py", line 711, in create_connection
    raise err
  File "/usr/lib/python3.5/socket.py", line 702, in create_connection
    sock.connect(sa)
ConnectionRefusedError: [Errno 111] Connection refused
2018-04-25 18:05:54,447 ERROR exception 2415 Internal Server Error: /accounts/login/
Traceback (most recent call last):
  File "/home/adrian/skyfolk/venv/lib/python3.5/site-packages/django/core/handlers/exception.py", line 41, in inner
    response = get_response(request)
  File "/home/adrian/skyfolk/venv/lib/python3.5/site-packages/django/core/handlers/base.py", line 249, in _legacy_get_response
    response = self._get_response(request)
  File "/home/adrian/skyfolk/venv/lib/python3.5/site-packages/django/core/handlers/base.py", line 187, in _get_response
    response = self.process_exception_by_middleware(e, request)
  File "/home/adrian/skyfolk/venv/lib/python3.5/site-packages/channels/handler.py", line 243, in process_exception_by_middleware
    return super(AsgiHandler, self).process_exception_by_middleware(exception, request)
  File "/home/adrian/skyfolk/venv/lib/python3.5/site-packages/django/core/handlers/base.py", line 185, in _get_response
    response = wrapped_callback(request, *callback_args, **callback_kwargs)
  File "/home/adrian/skyfolk/venv/lib/python3.5/site-packages/django/views/generic/base.py", line 68, in view
    return self.dispatch(request, *args, **kwargs)
  File "/home/adrian/skyfolk/venv/lib/python3.5/site-packages/django/utils/decorators.py", line 67, in _wrapper
    return bound_func(*args, **kwargs)
  File "/home/adrian/skyfolk/venv/lib/python3.5/site-packages/django/views/decorators/debug.py", line 76, in sensitive_post_parameters_wrapper
    return view(request, *args, **kwargs)
  File "/home/adrian/skyfolk/venv/lib/python3.5/site-packages/django/utils/decorators.py", line 63, in bound_func
    return func.__get__(self, type(self))(*args2, **kwargs2)
  File "/home/adrian/skyfolk/venv/lib/python3.5/site-packages/allauth/account/views.py", line 137, in dispatch
    return super(LoginView, self).dispatch(request, *args, **kwargs)
  File "/home/adrian/skyfolk/venv/lib/python3.5/site-packages/allauth/account/views.py", line 80, in dispatch
    **kwargs)
  File "/home/adrian/skyfolk/venv/lib/python3.5/site-packages/django/views/generic/base.py", line 88, in dispatch
    return handler(request, *args, **kwargs)
  File "/home/adrian/skyfolk/venv/lib/python3.5/site-packages/allauth/account/views.py", line 103, in post
    response = self.form_valid(form)
  File "/home/adrian/skyfolk/venv/lib/python3.5/site-packages/allauth/account/views.py", line 150, in form_valid
    return form.login(self.request, redirect_url=success_url)
  File "/home/adrian/skyfolk/user_profile/forms.py", line 69, in login
    fail_silently=False,
  File "/home/adrian/skyfolk/venv/lib/python3.5/site-packages/django/core/mail/__init__.py", line 62, in send_mail
    return mail.send()
  File "/home/adrian/skyfolk/venv/lib/python3.5/site-packages/django/core/mail/message.py", line 348, in send
    return self.get_connection(fail_silently).send_messages([self])
  File "/home/adrian/skyfolk/venv/lib/python3.5/site-packages/django/core/mail/backends/smtp.py", line 104, in send_messages
    new_conn_created = self.open()
  File "/home/adrian/skyfolk/venv/lib/python3.5/site-packages/django/core/mail/backends/smtp.py", line 64, in open
    self.connection = self.connection_class(self.host, self.port, **connection_params)
  File "/usr/lib/python3.5/smtplib.py", line 251, in __init__
    (code, msg) = self.connect(host, port)
  File "/usr/lib/python3.5/smtplib.py", line 335, in connect
    self.sock = self._get_socket(host, port, self.timeout)
  File "/usr/lib/python3.5/smtplib.py", line 306, in _get_socket
    self.source_address)
  File "/usr/lib/python3.5/socket.py", line 711, in create_connection
    raise err
  File "/usr/lib/python3.5/socket.py", line 702, in create_connection
    sock.connect(sa)
ConnectionRefusedError: [Errno 111] Connection refused
2018-04-25 18:06:14,617 ERROR exception 2547 Internal Server Error: /accounts/login/
Traceback (most recent call last):
  File "/home/adrian/skyfolk/venv/lib/python3.5/site-packages/django/core/handlers/exception.py", line 41, in inner
    response = get_response(request)
  File "/home/adrian/skyfolk/venv/lib/python3.5/site-packages/django/core/handlers/base.py", line 249, in _legacy_get_response
    response = self._get_response(request)
  File "/home/adrian/skyfolk/venv/lib/python3.5/site-packages/django/core/handlers/base.py", line 187, in _get_response
    response = self.process_exception_by_middleware(e, request)
  File "/home/adrian/skyfolk/venv/lib/python3.5/site-packages/channels/handler.py", line 243, in process_exception_by_middleware
    return super(AsgiHandler, self).process_exception_by_middleware(exception, request)
  File "/home/adrian/skyfolk/venv/lib/python3.5/site-packages/django/core/handlers/base.py", line 185, in _get_response
    response = wrapped_callback(request, *callback_args, **callback_kwargs)
  File "/home/adrian/skyfolk/venv/lib/python3.5/site-packages/django/views/generic/base.py", line 68, in view
    return self.dispatch(request, *args, **kwargs)
  File "/home/adrian/skyfolk/venv/lib/python3.5/site-packages/django/utils/decorators.py", line 67, in _wrapper
    return bound_func(*args, **kwargs)
  File "/home/adrian/skyfolk/venv/lib/python3.5/site-packages/django/views/decorators/debug.py", line 76, in sensitive_post_parameters_wrapper
    return view(request, *args, **kwargs)
  File "/home/adrian/skyfolk/venv/lib/python3.5/site-packages/django/utils/decorators.py", line 63, in bound_func
    return func.__get__(self, type(self))(*args2, **kwargs2)
  File "/home/adrian/skyfolk/venv/lib/python3.5/site-packages/allauth/account/views.py", line 137, in dispatch
    return super(LoginView, self).dispatch(request, *args, **kwargs)
  File "/home/adrian/skyfolk/venv/lib/python3.5/site-packages/allauth/account/views.py", line 80, in dispatch
    **kwargs)
  File "/home/adrian/skyfolk/venv/lib/python3.5/site-packages/django/views/generic/base.py", line 88, in dispatch
    return handler(request, *args, **kwargs)
  File "/home/adrian/skyfolk/venv/lib/python3.5/site-packages/allauth/account/views.py", line 103, in post
    response = self.form_valid(form)
  File "/home/adrian/skyfolk/venv/lib/python3.5/site-packages/allauth/account/views.py", line 150, in form_valid
    return form.login(self.request, redirect_url=success_url)
  File "/home/adrian/skyfolk/user_profile/forms.py", line 69, in login
    fail_silently=False,
  File "/home/adrian/skyfolk/venv/lib/python3.5/site-packages/django/core/mail/__init__.py", line 62, in send_mail
    return mail.send()
  File "/home/adrian/skyfolk/venv/lib/python3.5/site-packages/django/core/mail/message.py", line 348, in send
    return self.get_connection(fail_silently).send_messages([self])
  File "/home/adrian/skyfolk/venv/lib/python3.5/site-packages/django/core/mail/backends/smtp.py", line 104, in send_messages
    new_conn_created = self.open()
  File "/home/adrian/skyfolk/venv/lib/python3.5/site-packages/django/core/mail/backends/smtp.py", line 64, in open
    self.connection = self.connection_class(self.host, self.port, **connection_params)
  File "/usr/lib/python3.5/smtplib.py", line 251, in __init__
    (code, msg) = self.connect(host, port)
  File "/usr/lib/python3.5/smtplib.py", line 335, in connect
    self.sock = self._get_socket(host, port, self.timeout)
  File "/usr/lib/python3.5/smtplib.py", line 306, in _get_socket
    self.source_address)
  File "/usr/lib/python3.5/socket.py", line 711, in create_connection
    raise err
  File "/usr/lib/python3.5/socket.py", line 702, in create_connection
    sock.connect(sa)
ConnectionRefusedError: [Errno 111] Connection refused
2018-04-25 18:06:45,634 ERROR exception 2630 Internal Server Error: /accounts/signup/
Traceback (most recent call last):
  File "/home/adrian/skyfolk/venv/lib/python3.5/site-packages/django/core/handlers/exception.py", line 41, in inner
    response = get_response(request)
  File "/home/adrian/skyfolk/venv/lib/python3.5/site-packages/django/core/handlers/base.py", line 249, in _legacy_get_response
    response = self._get_response(request)
  File "/home/adrian/skyfolk/venv/lib/python3.5/site-packages/django/core/handlers/base.py", line 187, in _get_response
    response = self.process_exception_by_middleware(e, request)
  File "/home/adrian/skyfolk/venv/lib/python3.5/site-packages/channels/handler.py", line 243, in process_exception_by_middleware
    return super(AsgiHandler, self).process_exception_by_middleware(exception, request)
  File "/home/adrian/skyfolk/venv/lib/python3.5/site-packages/django/core/handlers/base.py", line 185, in _get_response
    response = wrapped_callback(request, *callback_args, **callback_kwargs)
  File "/home/adrian/skyfolk/venv/lib/python3.5/site-packages/django/views/generic/base.py", line 68, in view
    return self.dispatch(request, *args, **kwargs)
  File "/home/adrian/skyfolk/venv/lib/python3.5/site-packages/django/utils/decorators.py", line 67, in _wrapper
    return bound_func(*args, **kwargs)
  File "/home/adrian/skyfolk/venv/lib/python3.5/site-packages/django/views/decorators/debug.py", line 76, in sensitive_post_parameters_wrapper
    return view(request, *args, **kwargs)
  File "/home/adrian/skyfolk/venv/lib/python3.5/site-packages/django/utils/decorators.py", line 63, in bound_func
    return func.__get__(self, type(self))(*args2, **kwargs2)
  File "/home/adrian/skyfolk/venv/lib/python3.5/site-packages/allauth/account/views.py", line 214, in dispatch
    return super(SignupView, self).dispatch(request, *args, **kwargs)
  File "/home/adrian/skyfolk/venv/lib/python3.5/site-packages/allauth/account/views.py", line 80, in dispatch
    **kwargs)
  File "/home/adrian/skyfolk/venv/lib/python3.5/site-packages/allauth/account/views.py", line 192, in dispatch
    **kwargs)
  File "/home/adrian/skyfolk/venv/lib/python3.5/site-packages/django/views/generic/base.py", line 88, in dispatch
    return handler(request, *args, **kwargs)
  File "/home/adrian/skyfolk/venv/lib/python3.5/site-packages/allauth/account/views.py", line 103, in post
    response = self.form_valid(form)
  File "/home/adrian/skyfolk/venv/lib/python3.5/site-packages/allauth/account/views.py", line 235, in form_valid
    self.get_success_url())
  File "/home/adrian/skyfolk/venv/lib/python3.5/site-packages/allauth/account/utils.py", line 183, in complete_signup
    signal_kwargs=signal_kwargs)
  File "/home/adrian/skyfolk/venv/lib/python3.5/site-packages/allauth/account/utils.py", line 143, in perform_login
    send_email_confirmation(request, user, signup=signup)
  File "/home/adrian/skyfolk/venv/lib/python3.5/site-packages/allauth/account/utils.py", line 314, in send_email_confirmation
    signup=signup)
  File "/home/adrian/skyfolk/venv/lib/python3.5/site-packages/allauth/account/models.py", line 60, in send_confirmation
    confirmation.send(request, signup=signup)
  File "/home/adrian/skyfolk/venv/lib/python3.5/site-packages/allauth/account/models.py", line 166, in send
    get_adapter(request).send_confirmation_mail(request, self, signup)
  File "/home/adrian/skyfolk/venv/lib/python3.5/site-packages/allauth/account/adapter.py", line 444, in send_confirmation_mail
    ctx)
  File "/home/adrian/skyfolk/venv/lib/python3.5/site-packages/allauth/account/adapter.py", line 137, in send_mail
    msg.send()
  File "/home/adrian/skyfolk/venv/lib/python3.5/site-packages/django/core/mail/message.py", line 348, in send
    return self.get_connection(fail_silently).send_messages([self])
  File "/home/adrian/skyfolk/venv/lib/python3.5/site-packages/django/core/mail/backends/smtp.py", line 104, in send_messages
    new_conn_created = self.open()
  File "/home/adrian/skyfolk/venv/lib/python3.5/site-packages/django/core/mail/backends/smtp.py", line 64, in open
    self.connection = self.connection_class(self.host, self.port, **connection_params)
  File "/usr/lib/python3.5/smtplib.py", line 251, in __init__
    (code, msg) = self.connect(host, port)
  File "/usr/lib/python3.5/smtplib.py", line 335, in connect
    self.sock = self._get_socket(host, port, self.timeout)
  File "/usr/lib/python3.5/smtplib.py", line 306, in _get_socket
    self.source_address)
  File "/usr/lib/python3.5/socket.py", line 711, in create_connection
    raise err
  File "/usr/lib/python3.5/socket.py", line 702, in create_connection
    sock.connect(sa)
ConnectionRefusedError: [Errno 111] Connection refused
2018-04-25 18:07:25,507 ERROR exception 2630 Internal Server Error: /accounts/login/
Traceback (most recent call last):
  File "/home/adrian/skyfolk/venv/lib/python3.5/site-packages/django/core/handlers/exception.py", line 41, in inner
    response = get_response(request)
  File "/home/adrian/skyfolk/venv/lib/python3.5/site-packages/django/core/handlers/base.py", line 249, in _legacy_get_response
    response = self._get_response(request)
  File "/home/adrian/skyfolk/venv/lib/python3.5/site-packages/django/core/handlers/base.py", line 187, in _get_response
    response = self.process_exception_by_middleware(e, request)
  File "/home/adrian/skyfolk/venv/lib/python3.5/site-packages/channels/handler.py", line 243, in process_exception_by_middleware
    return super(AsgiHandler, self).process_exception_by_middleware(exception, request)
  File "/home/adrian/skyfolk/venv/lib/python3.5/site-packages/django/core/handlers/base.py", line 185, in _get_response
    response = wrapped_callback(request, *callback_args, **callback_kwargs)
  File "/home/adrian/skyfolk/venv/lib/python3.5/site-packages/django/views/generic/base.py", line 68, in view
    return self.dispatch(request, *args, **kwargs)
  File "/home/adrian/skyfolk/venv/lib/python3.5/site-packages/django/utils/decorators.py", line 67, in _wrapper
    return bound_func(*args, **kwargs)
  File "/home/adrian/skyfolk/venv/lib/python3.5/site-packages/django/views/decorators/debug.py", line 76, in sensitive_post_parameters_wrapper
    return view(request, *args, **kwargs)
  File "/home/adrian/skyfolk/venv/lib/python3.5/site-packages/django/utils/decorators.py", line 63, in bound_func
    return func.__get__(self, type(self))(*args2, **kwargs2)
  File "/home/adrian/skyfolk/venv/lib/python3.5/site-packages/allauth/account/views.py", line 137, in dispatch
    return super(LoginView, self).dispatch(request, *args, **kwargs)
  File "/home/adrian/skyfolk/venv/lib/python3.5/site-packages/allauth/account/views.py", line 80, in dispatch
    **kwargs)
  File "/home/adrian/skyfolk/venv/lib/python3.5/site-packages/django/views/generic/base.py", line 88, in dispatch
    return handler(request, *args, **kwargs)
  File "/home/adrian/skyfolk/venv/lib/python3.5/site-packages/allauth/account/views.py", line 103, in post
    response = self.form_valid(form)
  File "/home/adrian/skyfolk/venv/lib/python3.5/site-packages/allauth/account/views.py", line 150, in form_valid
    return form.login(self.request, redirect_url=success_url)
  File "/home/adrian/skyfolk/user_profile/forms.py", line 69, in login
    fail_silently=False,
  File "/home/adrian/skyfolk/venv/lib/python3.5/site-packages/django/core/mail/__init__.py", line 62, in send_mail
    return mail.send()
  File "/home/adrian/skyfolk/venv/lib/python3.5/site-packages/django/core/mail/message.py", line 348, in send
    return self.get_connection(fail_silently).send_messages([self])
  File "/home/adrian/skyfolk/venv/lib/python3.5/site-packages/django/core/mail/backends/smtp.py", line 104, in send_messages
    new_conn_created = self.open()
  File "/home/adrian/skyfolk/venv/lib/python3.5/site-packages/django/core/mail/backends/smtp.py", line 64, in open
    self.connection = self.connection_class(self.host, self.port, **connection_params)
  File "/usr/lib/python3.5/smtplib.py", line 251, in __init__
    (code, msg) = self.connect(host, port)
  File "/usr/lib/python3.5/smtplib.py", line 335, in connect
    self.sock = self._get_socket(host, port, self.timeout)
  File "/usr/lib/python3.5/smtplib.py", line 306, in _get_socket
    self.source_address)
  File "/usr/lib/python3.5/socket.py", line 711, in create_connection
    raise err
  File "/usr/lib/python3.5/socket.py", line 702, in create_connection
    sock.connect(sa)
ConnectionRefusedError: [Errno 111] Connection refused
2018-04-25 18:10:53,736 ERROR exception 6452 Internal Server Error: /accounts/login/
Traceback (most recent call last):
  File "/home/adrian/skyfolk/venv/lib/python3.5/site-packages/django/core/handlers/exception.py", line 41, in inner
    response = get_response(request)
  File "/home/adrian/skyfolk/venv/lib/python3.5/site-packages/django/core/handlers/base.py", line 249, in _legacy_get_response
    response = self._get_response(request)
  File "/home/adrian/skyfolk/venv/lib/python3.5/site-packages/django/core/handlers/base.py", line 187, in _get_response
    response = self.process_exception_by_middleware(e, request)
  File "/home/adrian/skyfolk/venv/lib/python3.5/site-packages/channels/handler.py", line 243, in process_exception_by_middleware
    return super(AsgiHandler, self).process_exception_by_middleware(exception, request)
  File "/home/adrian/skyfolk/venv/lib/python3.5/site-packages/django/core/handlers/base.py", line 185, in _get_response
    response = wrapped_callback(request, *callback_args, **callback_kwargs)
  File "/home/adrian/skyfolk/venv/lib/python3.5/site-packages/django/views/generic/base.py", line 68, in view
    return self.dispatch(request, *args, **kwargs)
  File "/home/adrian/skyfolk/venv/lib/python3.5/site-packages/django/utils/decorators.py", line 67, in _wrapper
    return bound_func(*args, **kwargs)
  File "/home/adrian/skyfolk/venv/lib/python3.5/site-packages/django/views/decorators/debug.py", line 76, in sensitive_post_parameters_wrapper
    return view(request, *args, **kwargs)
  File "/home/adrian/skyfolk/venv/lib/python3.5/site-packages/django/utils/decorators.py", line 63, in bound_func
    return func.__get__(self, type(self))(*args2, **kwargs2)
  File "/home/adrian/skyfolk/venv/lib/python3.5/site-packages/allauth/account/views.py", line 137, in dispatch
    return super(LoginView, self).dispatch(request, *args, **kwargs)
  File "/home/adrian/skyfolk/venv/lib/python3.5/site-packages/allauth/account/views.py", line 80, in dispatch
    **kwargs)
  File "/home/adrian/skyfolk/venv/lib/python3.5/site-packages/django/views/generic/base.py", line 88, in dispatch
    return handler(request, *args, **kwargs)
  File "/home/adrian/skyfolk/venv/lib/python3.5/site-packages/allauth/account/views.py", line 103, in post
    response = self.form_valid(form)
  File "/home/adrian/skyfolk/venv/lib/python3.5/site-packages/allauth/account/views.py", line 150, in form_valid
    return form.login(self.request, redirect_url=success_url)
  File "/home/adrian/skyfolk/user_profile/forms.py", line 69, in login
    fail_silently=False,
  File "/home/adrian/skyfolk/venv/lib/python3.5/site-packages/django/core/mail/__init__.py", line 62, in send_mail
    return mail.send()
  File "/home/adrian/skyfolk/venv/lib/python3.5/site-packages/django/core/mail/message.py", line 348, in send
    return self.get_connection(fail_silently).send_messages([self])
  File "/home/adrian/skyfolk/venv/lib/python3.5/site-packages/django/core/mail/backends/smtp.py", line 104, in send_messages
    new_conn_created = self.open()
  File "/home/adrian/skyfolk/venv/lib/python3.5/site-packages/django/core/mail/backends/smtp.py", line 69, in open
    self.connection.starttls(keyfile=self.ssl_keyfile, certfile=self.ssl_certfile)
  File "/usr/lib/python3.5/smtplib.py", line 751, in starttls
    "STARTTLS extension not supported by server.")
smtplib.SMTPNotSupportedError: STARTTLS extension not supported by server.
2018-04-25 18:16:21,385 ERROR exception 7286 Internal Server Error: /
Traceback (most recent call last):
  File "/home/adrian/skyfolk/venv/lib/python3.5/site-packages/django/core/handlers/exception.py", line 41, in inner
    response = get_response(request)
  File "/home/adrian/skyfolk/venv/lib/python3.5/site-packages/django/core/handlers/base.py", line 249, in _legacy_get_response
    response = self._get_response(request)
  File "/home/adrian/skyfolk/venv/lib/python3.5/site-packages/django/core/handlers/base.py", line 217, in _get_response
    response = self.process_exception_by_middleware(e, request)
  File "/home/adrian/skyfolk/venv/lib/python3.5/site-packages/channels/handler.py", line 243, in process_exception_by_middleware
    return super(AsgiHandler, self).process_exception_by_middleware(exception, request)
  File "/home/adrian/skyfolk/venv/lib/python3.5/site-packages/django/core/handlers/base.py", line 215, in _get_response
    response = response.render()
  File "/home/adrian/skyfolk/venv/lib/python3.5/site-packages/django/template/response.py", line 107, in render
    self.content = self.rendered_content
  File "/home/adrian/skyfolk/venv/lib/python3.5/site-packages/django/template/response.py", line 84, in rendered_content
    content = template.render(context, self._request)
  File "/home/adrian/skyfolk/venv/lib/python3.5/site-packages/django/template/backends/django.py", line 66, in render
    return self.template.render(context)
  File "/home/adrian/skyfolk/venv/lib/python3.5/site-packages/django/template/base.py", line 207, in render
    return self._render(context)
  File "/home/adrian/skyfolk/venv/lib/python3.5/site-packages/django/template/base.py", line 199, in _render
    return self.nodelist.render(context)
  File "/home/adrian/skyfolk/venv/lib/python3.5/site-packages/django/template/base.py", line 990, in render
    bit = node.render_annotated(context)
  File "/home/adrian/skyfolk/venv/lib/python3.5/site-packages/django/template/base.py", line 957, in render_annotated
    return self.render(context)
  File "/home/adrian/skyfolk/venv/lib/python3.5/site-packages/django/template/loader_tags.py", line 177, in render
    return compiled_parent._render(context)
  File "/home/adrian/skyfolk/venv/lib/python3.5/site-packages/django/template/base.py", line 199, in _render
    return self.nodelist.render(context)
  File "/home/adrian/skyfolk/venv/lib/python3.5/site-packages/django/template/base.py", line 990, in render
    bit = node.render_annotated(context)
  File "/home/adrian/skyfolk/venv/lib/python3.5/site-packages/django/template/base.py", line 957, in render_annotated
    return self.render(context)
  File "/home/adrian/skyfolk/venv/lib/python3.5/site-packages/compressor/templatetags/compress.py", line 131, in render
    return self.render_compressed(context, self.kind, self.mode, forced=forced)
  File "/home/adrian/skyfolk/venv/lib/python3.5/site-packages/compressor/templatetags/compress.py", line 103, in render_compressed
    cache_key, cache_content = self.render_cached(compressor, kind, mode)
  File "/home/adrian/skyfolk/venv/lib/python3.5/site-packages/compressor/templatetags/compress.py", line 82, in render_cached
    cache_key = get_templatetag_cachekey(compressor, mode, kind)
  File "/home/adrian/skyfolk/venv/lib/python3.5/site-packages/compressor/cache.py", line 97, in get_templatetag_cachekey
    "templatetag.%s.%s.%s" % (compressor.cachekey, mode, kind))
  File "/home/adrian/skyfolk/venv/lib/python3.5/site-packages/django/utils/functional.py", line 35, in __get__
    res = instance.__dict__[self.name] = self.func(instance)
  File "/home/adrian/skyfolk/venv/lib/python3.5/site-packages/compressor/base.py", line 177, in cachekey
    [self.content] + self.mtimes).encode(self.charset), 12)
  File "/home/adrian/skyfolk/venv/lib/python3.5/site-packages/django/utils/functional.py", line 35, in __get__
    res = instance.__dict__[self.name] = self.func(instance)
  File "/home/adrian/skyfolk/venv/lib/python3.5/site-packages/compressor/base.py", line 171, in mtimes
    for kind, value, basename, elem in self.split_contents()
  File "/home/adrian/skyfolk/venv/lib/python3.5/site-packages/compressor/css.py", line 20, in split_contents
    basename = self.get_basename(elem_attribs['href'])
  File "/home/adrian/skyfolk/venv/lib/python3.5/site-packages/compressor/base.py", line 85, in get_basename
    "compressed" % (url, base_url))
compressor.exceptions.UncompressableFileError: 'https://d32rim3h420riw.cloudfront.net/css/style.css' isn't accessible via COMPRESS_URL ('https://d32rim3h420riw.cloudfront.net/static/') and can't be compressed
2018-04-25 18:16:22,371 ERROR exception 7286 Internal Server Error: /
Traceback (most recent call last):
  File "/home/adrian/skyfolk/venv/lib/python3.5/site-packages/django/core/handlers/exception.py", line 41, in inner
    response = get_response(request)
  File "/home/adrian/skyfolk/venv/lib/python3.5/site-packages/django/core/handlers/base.py", line 249, in _legacy_get_response
    response = self._get_response(request)
  File "/home/adrian/skyfolk/venv/lib/python3.5/site-packages/django/core/handlers/base.py", line 217, in _get_response
    response = self.process_exception_by_middleware(e, request)
  File "/home/adrian/skyfolk/venv/lib/python3.5/site-packages/channels/handler.py", line 243, in process_exception_by_middleware
    return super(AsgiHandler, self).process_exception_by_middleware(exception, request)
  File "/home/adrian/skyfolk/venv/lib/python3.5/site-packages/django/core/handlers/base.py", line 215, in _get_response
    response = response.render()
  File "/home/adrian/skyfolk/venv/lib/python3.5/site-packages/django/template/response.py", line 107, in render
    self.content = self.rendered_content
  File "/home/adrian/skyfolk/venv/lib/python3.5/site-packages/django/template/response.py", line 84, in rendered_content
    content = template.render(context, self._request)
  File "/home/adrian/skyfolk/venv/lib/python3.5/site-packages/django/template/backends/django.py", line 66, in render
    return self.template.render(context)
  File "/home/adrian/skyfolk/venv/lib/python3.5/site-packages/django/template/base.py", line 207, in render
    return self._render(context)
  File "/home/adrian/skyfolk/venv/lib/python3.5/site-packages/django/template/base.py", line 199, in _render
    return self.nodelist.render(context)
  File "/home/adrian/skyfolk/venv/lib/python3.5/site-packages/django/template/base.py", line 990, in render
    bit = node.render_annotated(context)
  File "/home/adrian/skyfolk/venv/lib/python3.5/site-packages/django/template/base.py", line 957, in render_annotated
    return self.render(context)
  File "/home/adrian/skyfolk/venv/lib/python3.5/site-packages/django/template/loader_tags.py", line 177, in render
    return compiled_parent._render(context)
  File "/home/adrian/skyfolk/venv/lib/python3.5/site-packages/django/template/base.py", line 199, in _render
    return self.nodelist.render(context)
  File "/home/adrian/skyfolk/venv/lib/python3.5/site-packages/django/template/base.py", line 990, in render
    bit = node.render_annotated(context)
  File "/home/adrian/skyfolk/venv/lib/python3.5/site-packages/django/template/base.py", line 957, in render_annotated
    return self.render(context)
  File "/home/adrian/skyfolk/venv/lib/python3.5/site-packages/compressor/templatetags/compress.py", line 131, in render
    return self.render_compressed(context, self.kind, self.mode, forced=forced)
  File "/home/adrian/skyfolk/venv/lib/python3.5/site-packages/compressor/templatetags/compress.py", line 103, in render_compressed
    cache_key, cache_content = self.render_cached(compressor, kind, mode)
  File "/home/adrian/skyfolk/venv/lib/python3.5/site-packages/compressor/templatetags/compress.py", line 82, in render_cached
    cache_key = get_templatetag_cachekey(compressor, mode, kind)
  File "/home/adrian/skyfolk/venv/lib/python3.5/site-packages/compressor/cache.py", line 97, in get_templatetag_cachekey
    "templatetag.%s.%s.%s" % (compressor.cachekey, mode, kind))
  File "/home/adrian/skyfolk/venv/lib/python3.5/site-packages/django/utils/functional.py", line 35, in __get__
    res = instance.__dict__[self.name] = self.func(instance)
  File "/home/adrian/skyfolk/venv/lib/python3.5/site-packages/compressor/base.py", line 177, in cachekey
    [self.content] + self.mtimes).encode(self.charset), 12)
  File "/home/adrian/skyfolk/venv/lib/python3.5/site-packages/django/utils/functional.py", line 35, in __get__
    res = instance.__dict__[self.name] = self.func(instance)
  File "/home/adrian/skyfolk/venv/lib/python3.5/site-packages/compressor/base.py", line 171, in mtimes
    for kind, value, basename, elem in self.split_contents()
  File "/home/adrian/skyfolk/venv/lib/python3.5/site-packages/compressor/css.py", line 20, in split_contents
    basename = self.get_basename(elem_attribs['href'])
  File "/home/adrian/skyfolk/venv/lib/python3.5/site-packages/compressor/base.py", line 85, in get_basename
    "compressed" % (url, base_url))
compressor.exceptions.UncompressableFileError: 'https://d32rim3h420riw.cloudfront.net/css/style.css' isn't accessible via COMPRESS_URL ('https://d32rim3h420riw.cloudfront.net/static/') and can't be compressed
2018-04-25 22:54:30,956 ERROR exception 6014 Internal Server Error: /accounts/signup/
Traceback (most recent call last):
  File "/home/adrian/skyfolk/venv/lib/python3.5/site-packages/django/core/handlers/exception.py", line 41, in inner
    response = get_response(request)
  File "/home/adrian/skyfolk/venv/lib/python3.5/site-packages/django/core/handlers/base.py", line 249, in _legacy_get_response
    response = self._get_response(request)
  File "/home/adrian/skyfolk/venv/lib/python3.5/site-packages/django/core/handlers/base.py", line 217, in _get_response
    response = self.process_exception_by_middleware(e, request)
  File "/home/adrian/skyfolk/venv/lib/python3.5/site-packages/channels/handler.py", line 243, in process_exception_by_middleware
    return super(AsgiHandler, self).process_exception_by_middleware(exception, request)
  File "/home/adrian/skyfolk/venv/lib/python3.5/site-packages/django/core/handlers/base.py", line 215, in _get_response
    response = response.render()
  File "/home/adrian/skyfolk/venv/lib/python3.5/site-packages/django/template/response.py", line 107, in render
    self.content = self.rendered_content
  File "/home/adrian/skyfolk/venv/lib/python3.5/site-packages/django/template/response.py", line 82, in rendered_content
    template = self.resolve_template(self.template_name)
  File "/home/adrian/skyfolk/venv/lib/python3.5/site-packages/django/template/response.py", line 66, in resolve_template
    return get_template(template, using=self.using)
  File "/home/adrian/skyfolk/venv/lib/python3.5/site-packages/django/template/loader.py", line 21, in get_template
    return engine.get_template(template_name)
  File "/home/adrian/skyfolk/venv/lib/python3.5/site-packages/django/template/backends/django.py", line 39, in get_template
    return Template(self.engine.get_template(template_name), self)
  File "/home/adrian/skyfolk/venv/lib/python3.5/site-packages/django/template/engine.py", line 162, in get_template
    template, origin = self.find_template(template_name)
  File "/home/adrian/skyfolk/venv/lib/python3.5/site-packages/django/template/engine.py", line 136, in find_template
    name, template_dirs=dirs, skip=skip,
  File "/home/adrian/skyfolk/venv/lib/python3.5/site-packages/django/template/loaders/base.py", line 44, in get_template
    contents, origin, origin.template_name, self.engine,
  File "/home/adrian/skyfolk/venv/lib/python3.5/site-packages/django/template/base.py", line 191, in __init__
    self.nodelist = self.compile_nodelist()
  File "/home/adrian/skyfolk/venv/lib/python3.5/site-packages/django/template/base.py", line 230, in compile_nodelist
    return parser.parse()
  File "/home/adrian/skyfolk/venv/lib/python3.5/site-packages/django/template/base.py", line 516, in parse
    self.extend_nodelist(nodelist, compiled_result, token)
  File "/home/adrian/skyfolk/venv/lib/python3.5/site-packages/django/template/base.py", line 534, in extend_nodelist
    token, '%r must be the first tag in the template.' % node,
django.template.exceptions.TemplateSyntaxError: <ExtendsNode: extends "account/base.html"> must be the first tag in the template.
2018-05-01 22:07:17,220 ERROR exception 5622 Internal Server Error: /accounts/signup/
Traceback (most recent call last):
  File "/home/adrian/skyfolk/venv/lib/python3.5/site-packages/django/core/handlers/exception.py", line 41, in inner
    response = get_response(request)
  File "/home/adrian/skyfolk/venv/lib/python3.5/site-packages/django/core/handlers/base.py", line 249, in _legacy_get_response
    response = self._get_response(request)
  File "/home/adrian/skyfolk/venv/lib/python3.5/site-packages/django/core/handlers/base.py", line 187, in _get_response
    response = self.process_exception_by_middleware(e, request)
  File "/home/adrian/skyfolk/venv/lib/python3.5/site-packages/channels/handler.py", line 243, in process_exception_by_middleware
    return super(AsgiHandler, self).process_exception_by_middleware(exception, request)
  File "/home/adrian/skyfolk/venv/lib/python3.5/site-packages/django/core/handlers/base.py", line 185, in _get_response
    response = wrapped_callback(request, *callback_args, **callback_kwargs)
  File "/home/adrian/skyfolk/venv/lib/python3.5/site-packages/django/views/generic/base.py", line 68, in view
    return self.dispatch(request, *args, **kwargs)
  File "/home/adrian/skyfolk/venv/lib/python3.5/site-packages/django/utils/decorators.py", line 67, in _wrapper
    return bound_func(*args, **kwargs)
  File "/home/adrian/skyfolk/venv/lib/python3.5/site-packages/django/views/decorators/debug.py", line 76, in sensitive_post_parameters_wrapper
    return view(request, *args, **kwargs)
  File "/home/adrian/skyfolk/venv/lib/python3.5/site-packages/django/utils/decorators.py", line 63, in bound_func
    return func.__get__(self, type(self))(*args2, **kwargs2)
  File "/home/adrian/skyfolk/user_profile/views.py", line 1640, in dispatch
    return super(CustomSignupView, self).dispatch(request, *args, **kwargs)
  File "/home/adrian/skyfolk/venv/lib/python3.5/site-packages/allauth/account/views.py", line 80, in dispatch
    **kwargs)
  File "/home/adrian/skyfolk/venv/lib/python3.5/site-packages/allauth/account/views.py", line 192, in dispatch
    **kwargs)
  File "/home/adrian/skyfolk/venv/lib/python3.5/site-packages/formtools/wizard/views.py", line 248, in dispatch
    response = super(WizardView, self).dispatch(request, *args, **kwargs)
  File "/home/adrian/skyfolk/venv/lib/python3.5/site-packages/django/views/generic/base.py", line 88, in dispatch
    return handler(request, *args, **kwargs)
  File "/home/adrian/skyfolk/venv/lib/python3.5/site-packages/formtools/wizard/views.py", line 309, in post
    return self.render_done(form, **kwargs)
  File "/home/adrian/skyfolk/venv/lib/python3.5/site-packages/formtools/wizard/views.py", line 365, in render_done
    done_response = self.done(final_forms.values(), form_dict=final_forms, **kwargs)
  File "/home/adrian/skyfolk/user_profile/views.py", line 1673, in done
    self.get_success_url())
  File "/home/adrian/skyfolk/venv/lib/python3.5/site-packages/allauth/account/utils.py", line 183, in complete_signup
    signal_kwargs=signal_kwargs)
  File "/home/adrian/skyfolk/venv/lib/python3.5/site-packages/allauth/account/utils.py", line 150, in perform_login
    adapter.login(request, user)
  File "/home/adrian/skyfolk/venv/lib/python3.5/site-packages/allauth/account/adapter.py", line 385, in login
    django_login(request, user)
  File "/home/adrian/skyfolk/venv/lib/python3.5/site-packages/django/contrib/auth/__init__.py", line 161, in login
    user_logged_in.send(sender=user.__class__, request=request, user=user)
  File "/home/adrian/skyfolk/venv/lib/python3.5/site-packages/django/dispatch/dispatcher.py", line 193, in send
    for receiver in self._live_receivers(sender)
  File "/home/adrian/skyfolk/venv/lib/python3.5/site-packages/django/dispatch/dispatcher.py", line 193, in <listcomp>
    for receiver in self._live_receivers(sender)
  File "/home/adrian/skyfolk/user_profile/signals.py", line 172, in handle_login
    user_node = NodeProfile.nodes.get(user_id=user.id)
  File "/home/adrian/skyfolk/venv/lib/python3.5/site-packages/neomodel/match.py", line 510, in get
    raise MultipleNodesReturned(repr(kwargs))
neomodel.exceptions.MultipleNodesReturned: {'user_id': 3}
2018-05-01 22:16:53,306 ERROR exception 5622 Internal Server Error: /accounts/google/login/
Traceback (most recent call last):
  File "/home/adrian/skyfolk/venv/lib/python3.5/site-packages/django/core/handlers/exception.py", line 41, in inner
    response = get_response(request)
  File "/home/adrian/skyfolk/venv/lib/python3.5/site-packages/django/core/handlers/base.py", line 249, in _legacy_get_response
    response = self._get_response(request)
  File "/home/adrian/skyfolk/venv/lib/python3.5/site-packages/django/core/handlers/base.py", line 187, in _get_response
    response = self.process_exception_by_middleware(e, request)
  File "/home/adrian/skyfolk/venv/lib/python3.5/site-packages/channels/handler.py", line 243, in process_exception_by_middleware
    return super(AsgiHandler, self).process_exception_by_middleware(exception, request)
  File "/home/adrian/skyfolk/venv/lib/python3.5/site-packages/django/core/handlers/base.py", line 185, in _get_response
    response = wrapped_callback(request, *callback_args, **callback_kwargs)
  File "/home/adrian/skyfolk/venv/lib/python3.5/site-packages/allauth/socialaccount/providers/oauth2/views.py", line 73, in view
    return self.dispatch(request, *args, **kwargs)
  File "/home/adrian/skyfolk/venv/lib/python3.5/site-packages/allauth/socialaccount/providers/oauth2/views.py", line 96, in dispatch
    app = provider.get_app(self.request)
  File "/home/adrian/skyfolk/venv/lib/python3.5/site-packages/allauth/socialaccount/providers/base.py", line 52, in get_app
    return SocialApp.objects.get_current(self.id, request)
  File "/home/adrian/skyfolk/venv/lib/python3.5/site-packages/allauth/socialaccount/models.py", line 34, in get_current
    provider=provider)
  File "/home/adrian/skyfolk/venv/lib/python3.5/site-packages/django/db/models/manager.py", line 85, in manager_method
    return getattr(self.get_queryset(), name)(*args, **kwargs)
  File "/home/adrian/skyfolk/venv/lib/python3.5/site-packages/django/db/models/query.py", line 380, in get
    self.model._meta.object_name
allauth.socialaccount.models.DoesNotExist: SocialApp matching query does not exist.
