2018-07-10 16:34:33,320 ERROR exception 16874 Internal Server Error: /publication/add_like/
Traceback (most recent call last):
  File "/home/adrian/skyfolk/venv/lib/python3.6/site-packages/django/core/handlers/exception.py", line 41, in inner
    response = get_response(request)
  File "/home/adrian/skyfolk/venv/lib/python3.6/site-packages/django/core/handlers/base.py", line 249, in _legacy_get_response
    response = self._get_response(request)
  File "/home/adrian/skyfolk/venv/lib/python3.6/site-packages/django/core/handlers/base.py", line 187, in _get_response
    response = self.process_exception_by_middleware(e, request)
  File "/home/adrian/skyfolk/venv/lib/python3.6/site-packages/channels/handler.py", line 243, in process_exception_by_middleware
    return super(AsgiHandler, self).process_exception_by_middleware(exception, request)
  File "/home/adrian/skyfolk/venv/lib/python3.6/site-packages/django/core/handlers/base.py", line 185, in _get_response
    response = wrapped_callback(request, *callback_args, **callback_kwargs)
  File "/home/adrian/skyfolk/venv/lib/python3.6/site-packages/django/contrib/auth/decorators.py", line 23, in _wrapped_view
    return view_func(request, *args, **kwargs)
  File "/usr/lib/python3.6/contextlib.py", line 52, in inner
    return func(*args, **kwds)
  File "/home/adrian/skyfolk/publications/views.py", line 438, in add_like
    publication.user_give_me_like.add(user)
  File "/home/adrian/skyfolk/venv/lib/python3.6/site-packages/django/db/models/fields/related_descriptors.py", line 934, in add
    self._add_items(self.source_field_name, self.target_field_name, *objs)
  File "/home/adrian/skyfolk/venv/lib/python3.6/site-packages/django/db/models/fields/related_descriptors.py", line 1112, in _add_items
    model=self.model, pk_set=new_ids, using=db,
  File "/home/adrian/skyfolk/venv/lib/python3.6/site-packages/django/dispatch/dispatcher.py", line 193, in send
    for receiver in self._live_receivers(sender)
  File "/home/adrian/skyfolk/venv/lib/python3.6/site-packages/django/dispatch/dispatcher.py", line 193, in <listcomp>
    for receiver in self._live_receivers(sender)
  File "/home/adrian/skyfolk/publications/signals.py", line 32, in publication_received_like
    if total_likes >= 100:
TypeError: '>=' not supported between instances of 'dict' and 'int'
2018-07-10 16:34:50,411 ERROR exception 16993 Internal Server Error: /publication/add_like/
Traceback (most recent call last):
  File "/home/adrian/skyfolk/venv/lib/python3.6/site-packages/django/core/handlers/exception.py", line 41, in inner
    response = get_response(request)
  File "/home/adrian/skyfolk/venv/lib/python3.6/site-packages/django/core/handlers/base.py", line 249, in _legacy_get_response
    response = self._get_response(request)
  File "/home/adrian/skyfolk/venv/lib/python3.6/site-packages/django/core/handlers/base.py", line 187, in _get_response
    response = self.process_exception_by_middleware(e, request)
  File "/home/adrian/skyfolk/venv/lib/python3.6/site-packages/channels/handler.py", line 243, in process_exception_by_middleware
    return super(AsgiHandler, self).process_exception_by_middleware(exception, request)
  File "/home/adrian/skyfolk/venv/lib/python3.6/site-packages/django/core/handlers/base.py", line 185, in _get_response
    response = wrapped_callback(request, *callback_args, **callback_kwargs)
  File "/home/adrian/skyfolk/venv/lib/python3.6/site-packages/django/contrib/auth/decorators.py", line 23, in _wrapped_view
    return view_func(request, *args, **kwargs)
  File "/usr/lib/python3.6/contextlib.py", line 52, in inner
    return func(*args, **kwds)
  File "/home/adrian/skyfolk/publications/views.py", line 438, in add_like
    publication.user_give_me_like.add(user)
  File "/home/adrian/skyfolk/venv/lib/python3.6/site-packages/django/db/models/fields/related_descriptors.py", line 934, in add
    self._add_items(self.source_field_name, self.target_field_name, *objs)
  File "/home/adrian/skyfolk/venv/lib/python3.6/site-packages/django/db/models/fields/related_descriptors.py", line 1112, in _add_items
    model=self.model, pk_set=new_ids, using=db,
  File "/home/adrian/skyfolk/venv/lib/python3.6/site-packages/django/dispatch/dispatcher.py", line 193, in send
    for receiver in self._live_receivers(sender)
  File "/home/adrian/skyfolk/venv/lib/python3.6/site-packages/django/dispatch/dispatcher.py", line 193, in <listcomp>
    for receiver in self._live_receivers(sender)
  File "/home/adrian/skyfolk/publications/signals.py", line 32, in publication_received_like
    if qs.total_likes >= 100:
AttributeError: 'dict' object has no attribute 'total_likes'
2018-07-10 16:36:17,365 ERROR exception 17539 Internal Server Error: /publication/add_like/
Traceback (most recent call last):
  File "/home/adrian/skyfolk/venv/lib/python3.6/site-packages/django/core/handlers/exception.py", line 41, in inner
    response = get_response(request)
  File "/home/adrian/skyfolk/venv/lib/python3.6/site-packages/django/core/handlers/base.py", line 249, in _legacy_get_response
    response = self._get_response(request)
  File "/home/adrian/skyfolk/venv/lib/python3.6/site-packages/django/core/handlers/base.py", line 187, in _get_response
    response = self.process_exception_by_middleware(e, request)
  File "/home/adrian/skyfolk/venv/lib/python3.6/site-packages/channels/handler.py", line 243, in process_exception_by_middleware
    return super(AsgiHandler, self).process_exception_by_middleware(exception, request)
  File "/home/adrian/skyfolk/venv/lib/python3.6/site-packages/django/core/handlers/base.py", line 185, in _get_response
    response = wrapped_callback(request, *callback_args, **callback_kwargs)
  File "/home/adrian/skyfolk/venv/lib/python3.6/site-packages/django/contrib/auth/decorators.py", line 23, in _wrapped_view
    return view_func(request, *args, **kwargs)
  File "/usr/lib/python3.6/contextlib.py", line 52, in inner
    return func(*args, **kwds)
  File "/home/adrian/skyfolk/publications/views.py", line 438, in add_like
    publication.user_give_me_like.add(user)
  File "/home/adrian/skyfolk/venv/lib/python3.6/site-packages/django/db/models/fields/related_descriptors.py", line 934, in add
    self._add_items(self.source_field_name, self.target_field_name, *objs)
  File "/home/adrian/skyfolk/venv/lib/python3.6/site-packages/django/db/models/fields/related_descriptors.py", line 1112, in _add_items
    model=self.model, pk_set=new_ids, using=db,
  File "/home/adrian/skyfolk/venv/lib/python3.6/site-packages/django/dispatch/dispatcher.py", line 193, in send
    for receiver in self._live_receivers(sender)
  File "/home/adrian/skyfolk/venv/lib/python3.6/site-packages/django/dispatch/dispatcher.py", line 193, in <listcomp>
    for receiver in self._live_receivers(sender)
  File "/home/adrian/skyfolk/publications/signals.py", line 30, in publication_received_like
    When(~Q(user_give_me_like=instance.author_id), then=Value(1)), default=0), output_field=IntegerField()))
  File "/home/adrian/skyfolk/venv/lib/python3.6/site-packages/django/db/models/aggregates.py", line 69, in __init__
    expression, distinct='DISTINCT ' if distinct else '', output_field=IntegerField(), **extra)
TypeError: __init__() got multiple values for keyword argument 'output_field'
2018-07-10 16:37:50,270 ERROR exception 18497 Internal Server Error: /publication/add_like/
Traceback (most recent call last):
  File "/home/adrian/skyfolk/venv/lib/python3.6/site-packages/django/core/handlers/exception.py", line 41, in inner
    response = get_response(request)
  File "/home/adrian/skyfolk/venv/lib/python3.6/site-packages/django/core/handlers/base.py", line 249, in _legacy_get_response
    response = self._get_response(request)
  File "/home/adrian/skyfolk/venv/lib/python3.6/site-packages/django/core/handlers/base.py", line 187, in _get_response
    response = self.process_exception_by_middleware(e, request)
  File "/home/adrian/skyfolk/venv/lib/python3.6/site-packages/channels/handler.py", line 243, in process_exception_by_middleware
    return super(AsgiHandler, self).process_exception_by_middleware(exception, request)
  File "/home/adrian/skyfolk/venv/lib/python3.6/site-packages/django/core/handlers/base.py", line 185, in _get_response
    response = wrapped_callback(request, *callback_args, **callback_kwargs)
  File "/home/adrian/skyfolk/venv/lib/python3.6/site-packages/django/contrib/auth/decorators.py", line 23, in _wrapped_view
    return view_func(request, *args, **kwargs)
  File "/usr/lib/python3.6/contextlib.py", line 52, in inner
    return func(*args, **kwds)
  File "/home/adrian/skyfolk/publications/views.py", line 438, in add_like
    publication.user_give_me_like.add(user)
  File "/home/adrian/skyfolk/venv/lib/python3.6/site-packages/django/db/models/fields/related_descriptors.py", line 934, in add
    self._add_items(self.source_field_name, self.target_field_name, *objs)
  File "/home/adrian/skyfolk/venv/lib/python3.6/site-packages/django/db/models/fields/related_descriptors.py", line 1112, in _add_items
    model=self.model, pk_set=new_ids, using=db,
  File "/home/adrian/skyfolk/venv/lib/python3.6/site-packages/django/dispatch/dispatcher.py", line 193, in send
    for receiver in self._live_receivers(sender)
  File "/home/adrian/skyfolk/venv/lib/python3.6/site-packages/django/dispatch/dispatcher.py", line 193, in <listcomp>
    for receiver in self._live_receivers(sender)
  File "/home/adrian/skyfolk/publications/signals.py", line 30, in publication_received_like
    When(~Q(user_give_me_like=instance.author_id), then=Value(1)), default=0), output_field=IntegerField()))
  File "/home/adrian/skyfolk/venv/lib/python3.6/site-packages/django/db/models/aggregates.py", line 69, in __init__
    expression, distinct='DISTINCT ' if distinct else '', output_field=IntegerField(), **extra)
TypeError: __init__() got multiple values for keyword argument 'output_field'
2018-07-10 16:39:13,184 ERROR exception 19079 Internal Server Error: /publication/add_like/
Traceback (most recent call last):
  File "/home/adrian/skyfolk/venv/lib/python3.6/site-packages/django/core/handlers/exception.py", line 41, in inner
    response = get_response(request)
  File "/home/adrian/skyfolk/venv/lib/python3.6/site-packages/django/core/handlers/base.py", line 249, in _legacy_get_response
    response = self._get_response(request)
  File "/home/adrian/skyfolk/venv/lib/python3.6/site-packages/django/core/handlers/base.py", line 187, in _get_response
    response = self.process_exception_by_middleware(e, request)
  File "/home/adrian/skyfolk/venv/lib/python3.6/site-packages/channels/handler.py", line 243, in process_exception_by_middleware
    return super(AsgiHandler, self).process_exception_by_middleware(exception, request)
  File "/home/adrian/skyfolk/venv/lib/python3.6/site-packages/django/core/handlers/base.py", line 185, in _get_response
    response = wrapped_callback(request, *callback_args, **callback_kwargs)
  File "/home/adrian/skyfolk/venv/lib/python3.6/site-packages/django/contrib/auth/decorators.py", line 23, in _wrapped_view
    return view_func(request, *args, **kwargs)
  File "/usr/lib/python3.6/contextlib.py", line 52, in inner
    return func(*args, **kwds)
  File "/home/adrian/skyfolk/publications/views.py", line 438, in add_like
    publication.user_give_me_like.add(user)
  File "/home/adrian/skyfolk/venv/lib/python3.6/site-packages/django/db/models/fields/related_descriptors.py", line 934, in add
    self._add_items(self.source_field_name, self.target_field_name, *objs)
  File "/home/adrian/skyfolk/venv/lib/python3.6/site-packages/django/db/models/fields/related_descriptors.py", line 1112, in _add_items
    model=self.model, pk_set=new_ids, using=db,
  File "/home/adrian/skyfolk/venv/lib/python3.6/site-packages/django/dispatch/dispatcher.py", line 193, in send
    for receiver in self._live_receivers(sender)
  File "/home/adrian/skyfolk/venv/lib/python3.6/site-packages/django/dispatch/dispatcher.py", line 193, in <listcomp>
    for receiver in self._live_receivers(sender)
  File "/home/adrian/skyfolk/publications/signals.py", line 32, in publication_received_like
    print(qs)
  File "/home/adrian/skyfolk/venv/lib/python3.6/site-packages/django/db/models/query.py", line 226, in __repr__
    data = list(self[:REPR_OUTPUT_SIZE + 1])
  File "/home/adrian/skyfolk/venv/lib/python3.6/site-packages/django/db/models/query.py", line 250, in __iter__
    self._fetch_all()
  File "/home/adrian/skyfolk/venv/lib/python3.6/site-packages/django/db/models/query.py", line 1118, in _fetch_all
    self._result_cache = list(self._iterable_class(self))
  File "/home/adrian/skyfolk/venv/lib/python3.6/site-packages/django/db/models/query.py", line 69, in __iter__
    setattr(obj, attr_name, row[col_pos])
AttributeError: can't set attribute
2018-07-10 16:39:14,342 ERROR exception 19079 Internal Server Error: /publication/add_like/
Traceback (most recent call last):
  File "/home/adrian/skyfolk/venv/lib/python3.6/site-packages/django/core/handlers/exception.py", line 41, in inner
    response = get_response(request)
  File "/home/adrian/skyfolk/venv/lib/python3.6/site-packages/django/core/handlers/base.py", line 249, in _legacy_get_response
    response = self._get_response(request)
  File "/home/adrian/skyfolk/venv/lib/python3.6/site-packages/django/core/handlers/base.py", line 187, in _get_response
    response = self.process_exception_by_middleware(e, request)
  File "/home/adrian/skyfolk/venv/lib/python3.6/site-packages/channels/handler.py", line 243, in process_exception_by_middleware
    return super(AsgiHandler, self).process_exception_by_middleware(exception, request)
  File "/home/adrian/skyfolk/venv/lib/python3.6/site-packages/django/core/handlers/base.py", line 185, in _get_response
    response = wrapped_callback(request, *callback_args, **callback_kwargs)
  File "/home/adrian/skyfolk/venv/lib/python3.6/site-packages/django/contrib/auth/decorators.py", line 23, in _wrapped_view
    return view_func(request, *args, **kwargs)
  File "/usr/lib/python3.6/contextlib.py", line 52, in inner
    return func(*args, **kwds)
  File "/home/adrian/skyfolk/publications/views.py", line 438, in add_like
    publication.user_give_me_like.add(user)
  File "/home/adrian/skyfolk/venv/lib/python3.6/site-packages/django/db/models/fields/related_descriptors.py", line 934, in add
    self._add_items(self.source_field_name, self.target_field_name, *objs)
  File "/home/adrian/skyfolk/venv/lib/python3.6/site-packages/django/db/models/fields/related_descriptors.py", line 1112, in _add_items
    model=self.model, pk_set=new_ids, using=db,
  File "/home/adrian/skyfolk/venv/lib/python3.6/site-packages/django/dispatch/dispatcher.py", line 193, in send
    for receiver in self._live_receivers(sender)
  File "/home/adrian/skyfolk/venv/lib/python3.6/site-packages/django/dispatch/dispatcher.py", line 193, in <listcomp>
    for receiver in self._live_receivers(sender)
  File "/home/adrian/skyfolk/publications/signals.py", line 32, in publication_received_like
    print(qs)
  File "/home/adrian/skyfolk/venv/lib/python3.6/site-packages/django/db/models/query.py", line 226, in __repr__
    data = list(self[:REPR_OUTPUT_SIZE + 1])
  File "/home/adrian/skyfolk/venv/lib/python3.6/site-packages/django/db/models/query.py", line 250, in __iter__
    self._fetch_all()
  File "/home/adrian/skyfolk/venv/lib/python3.6/site-packages/django/db/models/query.py", line 1118, in _fetch_all
    self._result_cache = list(self._iterable_class(self))
  File "/home/adrian/skyfolk/venv/lib/python3.6/site-packages/django/db/models/query.py", line 69, in __iter__
    setattr(obj, attr_name, row[col_pos])
AttributeError: can't set attribute
2018-07-10 16:40:48,080 ERROR exception 19589 Internal Server Error: /publication/add_like/
Traceback (most recent call last):
  File "/home/adrian/skyfolk/venv/lib/python3.6/site-packages/django/core/handlers/exception.py", line 41, in inner
    response = get_response(request)
  File "/home/adrian/skyfolk/venv/lib/python3.6/site-packages/django/core/handlers/base.py", line 249, in _legacy_get_response
    response = self._get_response(request)
  File "/home/adrian/skyfolk/venv/lib/python3.6/site-packages/django/core/handlers/base.py", line 187, in _get_response
    response = self.process_exception_by_middleware(e, request)
  File "/home/adrian/skyfolk/venv/lib/python3.6/site-packages/channels/handler.py", line 243, in process_exception_by_middleware
    return super(AsgiHandler, self).process_exception_by_middleware(exception, request)
  File "/home/adrian/skyfolk/venv/lib/python3.6/site-packages/django/core/handlers/base.py", line 185, in _get_response
    response = wrapped_callback(request, *callback_args, **callback_kwargs)
  File "/home/adrian/skyfolk/venv/lib/python3.6/site-packages/django/contrib/auth/decorators.py", line 23, in _wrapped_view
    return view_func(request, *args, **kwargs)
  File "/usr/lib/python3.6/contextlib.py", line 52, in inner
    return func(*args, **kwds)
  File "/home/adrian/skyfolk/publications/views.py", line 438, in add_like
    publication.user_give_me_like.add(user)
  File "/home/adrian/skyfolk/venv/lib/python3.6/site-packages/django/db/models/fields/related_descriptors.py", line 934, in add
    self._add_items(self.source_field_name, self.target_field_name, *objs)
  File "/home/adrian/skyfolk/venv/lib/python3.6/site-packages/django/db/models/fields/related_descriptors.py", line 1112, in _add_items
    model=self.model, pk_set=new_ids, using=db,
  File "/home/adrian/skyfolk/venv/lib/python3.6/site-packages/django/dispatch/dispatcher.py", line 193, in send
    for receiver in self._live_receivers(sender)
  File "/home/adrian/skyfolk/venv/lib/python3.6/site-packages/django/dispatch/dispatcher.py", line 193, in <listcomp>
    for receiver in self._live_receivers(sender)
  File "/home/adrian/skyfolk/publications/signals.py", line 32, in publication_received_like
    if qs['total_likes'] >= 100:
  File "/home/adrian/skyfolk/venv/lib/python3.6/site-packages/django/db/models/query.py", line 265, in __getitem__
    raise TypeError
TypeError
2018-07-10 16:41:11,893 ERROR exception 19746 Internal Server Error: /publication/add_like/
Traceback (most recent call last):
  File "/home/adrian/skyfolk/venv/lib/python3.6/site-packages/django/core/handlers/exception.py", line 41, in inner
    response = get_response(request)
  File "/home/adrian/skyfolk/venv/lib/python3.6/site-packages/django/core/handlers/base.py", line 249, in _legacy_get_response
    response = self._get_response(request)
  File "/home/adrian/skyfolk/venv/lib/python3.6/site-packages/django/core/handlers/base.py", line 187, in _get_response
    response = self.process_exception_by_middleware(e, request)
  File "/home/adrian/skyfolk/venv/lib/python3.6/site-packages/channels/handler.py", line 243, in process_exception_by_middleware
    return super(AsgiHandler, self).process_exception_by_middleware(exception, request)
  File "/home/adrian/skyfolk/venv/lib/python3.6/site-packages/django/core/handlers/base.py", line 185, in _get_response
    response = wrapped_callback(request, *callback_args, **callback_kwargs)
  File "/home/adrian/skyfolk/venv/lib/python3.6/site-packages/django/contrib/auth/decorators.py", line 23, in _wrapped_view
    return view_func(request, *args, **kwargs)
  File "/usr/lib/python3.6/contextlib.py", line 52, in inner
    return func(*args, **kwds)
  File "/home/adrian/skyfolk/publications/views.py", line 438, in add_like
    publication.user_give_me_like.add(user)
  File "/home/adrian/skyfolk/venv/lib/python3.6/site-packages/django/db/models/fields/related_descriptors.py", line 934, in add
    self._add_items(self.source_field_name, self.target_field_name, *objs)
  File "/home/adrian/skyfolk/venv/lib/python3.6/site-packages/django/db/models/fields/related_descriptors.py", line 1112, in _add_items
    model=self.model, pk_set=new_ids, using=db,
  File "/home/adrian/skyfolk/venv/lib/python3.6/site-packages/django/dispatch/dispatcher.py", line 193, in send
    for receiver in self._live_receivers(sender)
  File "/home/adrian/skyfolk/venv/lib/python3.6/site-packages/django/dispatch/dispatcher.py", line 193, in <listcomp>
    for receiver in self._live_receivers(sender)
  File "/home/adrian/skyfolk/publications/signals.py", line 32, in publication_received_like
    if qs['total_likes'] >= 100:
  File "/home/adrian/skyfolk/venv/lib/python3.6/site-packages/django/db/models/query.py", line 265, in __getitem__
    raise TypeError
TypeError
2018-07-10 16:41:15,557 ERROR exception 19746 Internal Server Error: /publication/add_like/
Traceback (most recent call last):
  File "/home/adrian/skyfolk/venv/lib/python3.6/site-packages/django/core/handlers/exception.py", line 41, in inner
    response = get_response(request)
  File "/home/adrian/skyfolk/venv/lib/python3.6/site-packages/django/core/handlers/base.py", line 249, in _legacy_get_response
    response = self._get_response(request)
  File "/home/adrian/skyfolk/venv/lib/python3.6/site-packages/django/core/handlers/base.py", line 187, in _get_response
    response = self.process_exception_by_middleware(e, request)
  File "/home/adrian/skyfolk/venv/lib/python3.6/site-packages/channels/handler.py", line 243, in process_exception_by_middleware
    return super(AsgiHandler, self).process_exception_by_middleware(exception, request)
  File "/home/adrian/skyfolk/venv/lib/python3.6/site-packages/django/core/handlers/base.py", line 185, in _get_response
    response = wrapped_callback(request, *callback_args, **callback_kwargs)
  File "/home/adrian/skyfolk/venv/lib/python3.6/site-packages/django/contrib/auth/decorators.py", line 23, in _wrapped_view
    return view_func(request, *args, **kwargs)
  File "/usr/lib/python3.6/contextlib.py", line 52, in inner
    return func(*args, **kwds)
  File "/home/adrian/skyfolk/publications/views.py", line 438, in add_like
    publication.user_give_me_like.add(user)
  File "/home/adrian/skyfolk/venv/lib/python3.6/site-packages/django/db/models/fields/related_descriptors.py", line 934, in add
    self._add_items(self.source_field_name, self.target_field_name, *objs)
  File "/home/adrian/skyfolk/venv/lib/python3.6/site-packages/django/db/models/fields/related_descriptors.py", line 1112, in _add_items
    model=self.model, pk_set=new_ids, using=db,
  File "/home/adrian/skyfolk/venv/lib/python3.6/site-packages/django/dispatch/dispatcher.py", line 193, in send
    for receiver in self._live_receivers(sender)
  File "/home/adrian/skyfolk/venv/lib/python3.6/site-packages/django/dispatch/dispatcher.py", line 193, in <listcomp>
    for receiver in self._live_receivers(sender)
  File "/home/adrian/skyfolk/publications/signals.py", line 32, in publication_received_like
    if qs['total_likes'] >= 100:
  File "/home/adrian/skyfolk/venv/lib/python3.6/site-packages/django/db/models/query.py", line 265, in __getitem__
    raise TypeError
TypeError
2018-07-10 16:41:16,319 ERROR exception 19746 Internal Server Error: /publication/add_like/
Traceback (most recent call last):
  File "/home/adrian/skyfolk/venv/lib/python3.6/site-packages/django/core/handlers/exception.py", line 41, in inner
    response = get_response(request)
  File "/home/adrian/skyfolk/venv/lib/python3.6/site-packages/django/core/handlers/base.py", line 249, in _legacy_get_response
    response = self._get_response(request)
  File "/home/adrian/skyfolk/venv/lib/python3.6/site-packages/django/core/handlers/base.py", line 187, in _get_response
    response = self.process_exception_by_middleware(e, request)
  File "/home/adrian/skyfolk/venv/lib/python3.6/site-packages/channels/handler.py", line 243, in process_exception_by_middleware
    return super(AsgiHandler, self).process_exception_by_middleware(exception, request)
  File "/home/adrian/skyfolk/venv/lib/python3.6/site-packages/django/core/handlers/base.py", line 185, in _get_response
    response = wrapped_callback(request, *callback_args, **callback_kwargs)
  File "/home/adrian/skyfolk/venv/lib/python3.6/site-packages/django/contrib/auth/decorators.py", line 23, in _wrapped_view
    return view_func(request, *args, **kwargs)
  File "/usr/lib/python3.6/contextlib.py", line 52, in inner
    return func(*args, **kwds)
  File "/home/adrian/skyfolk/publications/views.py", line 438, in add_like
    publication.user_give_me_like.add(user)
  File "/home/adrian/skyfolk/venv/lib/python3.6/site-packages/django/db/models/fields/related_descriptors.py", line 934, in add
    self._add_items(self.source_field_name, self.target_field_name, *objs)
  File "/home/adrian/skyfolk/venv/lib/python3.6/site-packages/django/db/models/fields/related_descriptors.py", line 1112, in _add_items
    model=self.model, pk_set=new_ids, using=db,
  File "/home/adrian/skyfolk/venv/lib/python3.6/site-packages/django/dispatch/dispatcher.py", line 193, in send
    for receiver in self._live_receivers(sender)
  File "/home/adrian/skyfolk/venv/lib/python3.6/site-packages/django/dispatch/dispatcher.py", line 193, in <listcomp>
    for receiver in self._live_receivers(sender)
  File "/home/adrian/skyfolk/publications/signals.py", line 32, in publication_received_like
    if qs['total_likes'] >= 100:
  File "/home/adrian/skyfolk/venv/lib/python3.6/site-packages/django/db/models/query.py", line 265, in __getitem__
    raise TypeError
TypeError
2018-07-10 16:42:07,646 ERROR exception 20091 Internal Server Error: /publication/add_like/
Traceback (most recent call last):
  File "/home/adrian/skyfolk/venv/lib/python3.6/site-packages/django/core/handlers/exception.py", line 41, in inner
    response = get_response(request)
  File "/home/adrian/skyfolk/venv/lib/python3.6/site-packages/django/core/handlers/base.py", line 249, in _legacy_get_response
    response = self._get_response(request)
  File "/home/adrian/skyfolk/venv/lib/python3.6/site-packages/django/core/handlers/base.py", line 187, in _get_response
    response = self.process_exception_by_middleware(e, request)
  File "/home/adrian/skyfolk/venv/lib/python3.6/site-packages/channels/handler.py", line 243, in process_exception_by_middleware
    return super(AsgiHandler, self).process_exception_by_middleware(exception, request)
  File "/home/adrian/skyfolk/venv/lib/python3.6/site-packages/django/core/handlers/base.py", line 185, in _get_response
    response = wrapped_callback(request, *callback_args, **callback_kwargs)
  File "/home/adrian/skyfolk/venv/lib/python3.6/site-packages/django/contrib/auth/decorators.py", line 23, in _wrapped_view
    return view_func(request, *args, **kwargs)
  File "/usr/lib/python3.6/contextlib.py", line 52, in inner
    return func(*args, **kwds)
  File "/home/adrian/skyfolk/publications/views.py", line 438, in add_like
    publication.user_give_me_like.add(user)
  File "/home/adrian/skyfolk/venv/lib/python3.6/site-packages/django/db/models/fields/related_descriptors.py", line 934, in add
    self._add_items(self.source_field_name, self.target_field_name, *objs)
  File "/home/adrian/skyfolk/venv/lib/python3.6/site-packages/django/db/models/fields/related_descriptors.py", line 1112, in _add_items
    model=self.model, pk_set=new_ids, using=db,
  File "/home/adrian/skyfolk/venv/lib/python3.6/site-packages/django/dispatch/dispatcher.py", line 193, in send
    for receiver in self._live_receivers(sender)
  File "/home/adrian/skyfolk/venv/lib/python3.6/site-packages/django/dispatch/dispatcher.py", line 193, in <listcomp>
    for receiver in self._live_receivers(sender)
  File "/home/adrian/skyfolk/publications/signals.py", line 32, in publication_received_like
    if qs['total_likes'] >= 100:
  File "/home/adrian/skyfolk/venv/lib/python3.6/site-packages/django/db/models/query.py", line 265, in __getitem__
    raise TypeError
TypeError
2018-07-10 16:42:18,849 ERROR exception 20208 Internal Server Error: /publication/add_like/
Traceback (most recent call last):
  File "/home/adrian/skyfolk/venv/lib/python3.6/site-packages/django/core/handlers/exception.py", line 41, in inner
    response = get_response(request)
  File "/home/adrian/skyfolk/venv/lib/python3.6/site-packages/django/core/handlers/base.py", line 249, in _legacy_get_response
    response = self._get_response(request)
  File "/home/adrian/skyfolk/venv/lib/python3.6/site-packages/django/core/handlers/base.py", line 187, in _get_response
    response = self.process_exception_by_middleware(e, request)
  File "/home/adrian/skyfolk/venv/lib/python3.6/site-packages/channels/handler.py", line 243, in process_exception_by_middleware
    return super(AsgiHandler, self).process_exception_by_middleware(exception, request)
  File "/home/adrian/skyfolk/venv/lib/python3.6/site-packages/django/core/handlers/base.py", line 185, in _get_response
    response = wrapped_callback(request, *callback_args, **callback_kwargs)
  File "/home/adrian/skyfolk/venv/lib/python3.6/site-packages/django/contrib/auth/decorators.py", line 23, in _wrapped_view
    return view_func(request, *args, **kwargs)
  File "/usr/lib/python3.6/contextlib.py", line 52, in inner
    return func(*args, **kwds)
  File "/home/adrian/skyfolk/publications/views.py", line 438, in add_like
    publication.user_give_me_like.add(user)
  File "/home/adrian/skyfolk/venv/lib/python3.6/site-packages/django/db/models/fields/related_descriptors.py", line 934, in add
    self._add_items(self.source_field_name, self.target_field_name, *objs)
  File "/home/adrian/skyfolk/venv/lib/python3.6/site-packages/django/db/models/fields/related_descriptors.py", line 1112, in _add_items
    model=self.model, pk_set=new_ids, using=db,
  File "/home/adrian/skyfolk/venv/lib/python3.6/site-packages/django/dispatch/dispatcher.py", line 193, in send
    for receiver in self._live_receivers(sender)
  File "/home/adrian/skyfolk/venv/lib/python3.6/site-packages/django/dispatch/dispatcher.py", line 193, in <listcomp>
    for receiver in self._live_receivers(sender)
  File "/home/adrian/skyfolk/publications/signals.py", line 32, in publication_received_like
    if qs['total_likes'] >= 100:
  File "/home/adrian/skyfolk/venv/lib/python3.6/site-packages/django/db/models/query.py", line 265, in __getitem__
    raise TypeError
TypeError
2018-07-10 16:42:20,710 ERROR exception 20208 Internal Server Error: /publication/add_like/
Traceback (most recent call last):
  File "/home/adrian/skyfolk/venv/lib/python3.6/site-packages/django/core/handlers/exception.py", line 41, in inner
    response = get_response(request)
  File "/home/adrian/skyfolk/venv/lib/python3.6/site-packages/django/core/handlers/base.py", line 249, in _legacy_get_response
    response = self._get_response(request)
  File "/home/adrian/skyfolk/venv/lib/python3.6/site-packages/django/core/handlers/base.py", line 187, in _get_response
    response = self.process_exception_by_middleware(e, request)
  File "/home/adrian/skyfolk/venv/lib/python3.6/site-packages/channels/handler.py", line 243, in process_exception_by_middleware
    return super(AsgiHandler, self).process_exception_by_middleware(exception, request)
  File "/home/adrian/skyfolk/venv/lib/python3.6/site-packages/django/core/handlers/base.py", line 185, in _get_response
    response = wrapped_callback(request, *callback_args, **callback_kwargs)
  File "/home/adrian/skyfolk/venv/lib/python3.6/site-packages/django/contrib/auth/decorators.py", line 23, in _wrapped_view
    return view_func(request, *args, **kwargs)
  File "/usr/lib/python3.6/contextlib.py", line 52, in inner
    return func(*args, **kwds)
  File "/home/adrian/skyfolk/publications/views.py", line 438, in add_like
    publication.user_give_me_like.add(user)
  File "/home/adrian/skyfolk/venv/lib/python3.6/site-packages/django/db/models/fields/related_descriptors.py", line 934, in add
    self._add_items(self.source_field_name, self.target_field_name, *objs)
  File "/home/adrian/skyfolk/venv/lib/python3.6/site-packages/django/db/models/fields/related_descriptors.py", line 1112, in _add_items
    model=self.model, pk_set=new_ids, using=db,
  File "/home/adrian/skyfolk/venv/lib/python3.6/site-packages/django/dispatch/dispatcher.py", line 193, in send
    for receiver in self._live_receivers(sender)
  File "/home/adrian/skyfolk/venv/lib/python3.6/site-packages/django/dispatch/dispatcher.py", line 193, in <listcomp>
    for receiver in self._live_receivers(sender)
  File "/home/adrian/skyfolk/publications/signals.py", line 32, in publication_received_like
    if qs['total_likes'] >= 100:
  File "/home/adrian/skyfolk/venv/lib/python3.6/site-packages/django/db/models/query.py", line 265, in __getitem__
    raise TypeError
TypeError
2018-07-10 16:43:59,745 ERROR exception 20613 Internal Server Error: /publication/add_like/
Traceback (most recent call last):
  File "/home/adrian/skyfolk/venv/lib/python3.6/site-packages/django/core/handlers/exception.py", line 41, in inner
    response = get_response(request)
  File "/home/adrian/skyfolk/venv/lib/python3.6/site-packages/django/core/handlers/base.py", line 249, in _legacy_get_response
    response = self._get_response(request)
  File "/home/adrian/skyfolk/venv/lib/python3.6/site-packages/django/core/handlers/base.py", line 187, in _get_response
    response = self.process_exception_by_middleware(e, request)
  File "/home/adrian/skyfolk/venv/lib/python3.6/site-packages/channels/handler.py", line 243, in process_exception_by_middleware
    return super(AsgiHandler, self).process_exception_by_middleware(exception, request)
  File "/home/adrian/skyfolk/venv/lib/python3.6/site-packages/django/core/handlers/base.py", line 185, in _get_response
    response = wrapped_callback(request, *callback_args, **callback_kwargs)
  File "/home/adrian/skyfolk/venv/lib/python3.6/site-packages/django/contrib/auth/decorators.py", line 23, in _wrapped_view
    return view_func(request, *args, **kwargs)
  File "/usr/lib/python3.6/contextlib.py", line 52, in inner
    return func(*args, **kwds)
  File "/home/adrian/skyfolk/publications/views.py", line 438, in add_like
    publication.user_give_me_like.add(user)
  File "/home/adrian/skyfolk/venv/lib/python3.6/site-packages/django/db/models/fields/related_descriptors.py", line 934, in add
    self._add_items(self.source_field_name, self.target_field_name, *objs)
  File "/home/adrian/skyfolk/venv/lib/python3.6/site-packages/django/db/models/fields/related_descriptors.py", line 1112, in _add_items
    model=self.model, pk_set=new_ids, using=db,
  File "/home/adrian/skyfolk/venv/lib/python3.6/site-packages/django/dispatch/dispatcher.py", line 193, in send
    for receiver in self._live_receivers(sender)
  File "/home/adrian/skyfolk/venv/lib/python3.6/site-packages/django/dispatch/dispatcher.py", line 193, in <listcomp>
    for receiver in self._live_receivers(sender)
  File "/home/adrian/skyfolk/publications/signals.py", line 32, in publication_received_like
    if qs['total_likes'] >= 100:
  File "/home/adrian/skyfolk/venv/lib/python3.6/site-packages/django/db/models/query.py", line 265, in __getitem__
    raise TypeError
TypeError
2018-07-10 16:44:29,039 ERROR exception 20852 Internal Server Error: /publication/add_like/
Traceback (most recent call last):
  File "/home/adrian/skyfolk/venv/lib/python3.6/site-packages/django/core/handlers/exception.py", line 41, in inner
    response = get_response(request)
  File "/home/adrian/skyfolk/venv/lib/python3.6/site-packages/django/core/handlers/base.py", line 249, in _legacy_get_response
    response = self._get_response(request)
  File "/home/adrian/skyfolk/venv/lib/python3.6/site-packages/django/core/handlers/base.py", line 187, in _get_response
    response = self.process_exception_by_middleware(e, request)
  File "/home/adrian/skyfolk/venv/lib/python3.6/site-packages/channels/handler.py", line 243, in process_exception_by_middleware
    return super(AsgiHandler, self).process_exception_by_middleware(exception, request)
  File "/home/adrian/skyfolk/venv/lib/python3.6/site-packages/django/core/handlers/base.py", line 185, in _get_response
    response = wrapped_callback(request, *callback_args, **callback_kwargs)
  File "/home/adrian/skyfolk/venv/lib/python3.6/site-packages/django/contrib/auth/decorators.py", line 23, in _wrapped_view
    return view_func(request, *args, **kwargs)
  File "/usr/lib/python3.6/contextlib.py", line 52, in inner
    return func(*args, **kwds)
  File "/home/adrian/skyfolk/publications/views.py", line 438, in add_like
    publication.user_give_me_like.add(user)
  File "/home/adrian/skyfolk/venv/lib/python3.6/site-packages/django/db/models/fields/related_descriptors.py", line 934, in add
    self._add_items(self.source_field_name, self.target_field_name, *objs)
  File "/home/adrian/skyfolk/venv/lib/python3.6/site-packages/django/db/models/fields/related_descriptors.py", line 1112, in _add_items
    model=self.model, pk_set=new_ids, using=db,
  File "/home/adrian/skyfolk/venv/lib/python3.6/site-packages/django/dispatch/dispatcher.py", line 193, in send
    for receiver in self._live_receivers(sender)
  File "/home/adrian/skyfolk/venv/lib/python3.6/site-packages/django/dispatch/dispatcher.py", line 193, in <listcomp>
    for receiver in self._live_receivers(sender)
  File "/home/adrian/skyfolk/publications/signals.py", line 31, in publication_received_like
    print(qs.likes)
AttributeError: 'TreeQuerySet' object has no attribute 'likes'
2018-07-10 16:45:08,841 ERROR exception 21035 Internal Server Error: /publication/add_like/
Traceback (most recent call last):
  File "/home/adrian/skyfolk/venv/lib/python3.6/site-packages/django/core/handlers/exception.py", line 41, in inner
    response = get_response(request)
  File "/home/adrian/skyfolk/venv/lib/python3.6/site-packages/django/core/handlers/base.py", line 249, in _legacy_get_response
    response = self._get_response(request)
  File "/home/adrian/skyfolk/venv/lib/python3.6/site-packages/django/core/handlers/base.py", line 187, in _get_response
    response = self.process_exception_by_middleware(e, request)
  File "/home/adrian/skyfolk/venv/lib/python3.6/site-packages/channels/handler.py", line 243, in process_exception_by_middleware
    return super(AsgiHandler, self).process_exception_by_middleware(exception, request)
  File "/home/adrian/skyfolk/venv/lib/python3.6/site-packages/django/core/handlers/base.py", line 185, in _get_response
    response = wrapped_callback(request, *callback_args, **callback_kwargs)
  File "/home/adrian/skyfolk/venv/lib/python3.6/site-packages/django/contrib/auth/decorators.py", line 23, in _wrapped_view
    return view_func(request, *args, **kwargs)
  File "/usr/lib/python3.6/contextlib.py", line 52, in inner
    return func(*args, **kwds)
  File "/home/adrian/skyfolk/publications/views.py", line 438, in add_like
    publication.user_give_me_like.add(user)
  File "/home/adrian/skyfolk/venv/lib/python3.6/site-packages/django/db/models/fields/related_descriptors.py", line 934, in add
    self._add_items(self.source_field_name, self.target_field_name, *objs)
  File "/home/adrian/skyfolk/venv/lib/python3.6/site-packages/django/db/models/fields/related_descriptors.py", line 1112, in _add_items
    model=self.model, pk_set=new_ids, using=db,
  File "/home/adrian/skyfolk/venv/lib/python3.6/site-packages/django/dispatch/dispatcher.py", line 193, in send
    for receiver in self._live_receivers(sender)
  File "/home/adrian/skyfolk/venv/lib/python3.6/site-packages/django/dispatch/dispatcher.py", line 193, in <listcomp>
    for receiver in self._live_receivers(sender)
  File "/home/adrian/skyfolk/publications/signals.py", line 31, in publication_received_like
    print(qs.likes)
AttributeError: 'TreeQuerySet' object has no attribute 'likes'
2018-07-10 16:45:18,749 ERROR exception 21168 Internal Server Error: /publication/add_like/
Traceback (most recent call last):
  File "/home/adrian/skyfolk/venv/lib/python3.6/site-packages/django/core/handlers/exception.py", line 41, in inner
    response = get_response(request)
  File "/home/adrian/skyfolk/venv/lib/python3.6/site-packages/django/core/handlers/base.py", line 249, in _legacy_get_response
    response = self._get_response(request)
  File "/home/adrian/skyfolk/venv/lib/python3.6/site-packages/django/core/handlers/base.py", line 187, in _get_response
    response = self.process_exception_by_middleware(e, request)
  File "/home/adrian/skyfolk/venv/lib/python3.6/site-packages/channels/handler.py", line 243, in process_exception_by_middleware
    return super(AsgiHandler, self).process_exception_by_middleware(exception, request)
  File "/home/adrian/skyfolk/venv/lib/python3.6/site-packages/django/core/handlers/base.py", line 185, in _get_response
    response = wrapped_callback(request, *callback_args, **callback_kwargs)
  File "/home/adrian/skyfolk/venv/lib/python3.6/site-packages/django/contrib/auth/decorators.py", line 23, in _wrapped_view
    return view_func(request, *args, **kwargs)
  File "/usr/lib/python3.6/contextlib.py", line 52, in inner
    return func(*args, **kwds)
  File "/home/adrian/skyfolk/publications/views.py", line 438, in add_like
    publication.user_give_me_like.add(user)
  File "/home/adrian/skyfolk/venv/lib/python3.6/site-packages/django/db/models/fields/related_descriptors.py", line 934, in add
    self._add_items(self.source_field_name, self.target_field_name, *objs)
  File "/home/adrian/skyfolk/venv/lib/python3.6/site-packages/django/db/models/fields/related_descriptors.py", line 1112, in _add_items
    model=self.model, pk_set=new_ids, using=db,
  File "/home/adrian/skyfolk/venv/lib/python3.6/site-packages/django/dispatch/dispatcher.py", line 193, in send
    for receiver in self._live_receivers(sender)
  File "/home/adrian/skyfolk/venv/lib/python3.6/site-packages/django/dispatch/dispatcher.py", line 193, in <listcomp>
    for receiver in self._live_receivers(sender)
  File "/home/adrian/skyfolk/publications/signals.py", line 32, in publication_received_like
    if qs.likes >= 100:
AttributeError: 'TreeQuerySet' object has no attribute 'likes'
2018-07-10 16:46:46,959 ERROR exception 21617 Internal Server Error: /publication/add_like/
Traceback (most recent call last):
  File "/home/adrian/skyfolk/venv/lib/python3.6/site-packages/django/core/handlers/exception.py", line 41, in inner
    response = get_response(request)
  File "/home/adrian/skyfolk/venv/lib/python3.6/site-packages/django/core/handlers/base.py", line 249, in _legacy_get_response
    response = self._get_response(request)
  File "/home/adrian/skyfolk/venv/lib/python3.6/site-packages/django/core/handlers/base.py", line 187, in _get_response
    response = self.process_exception_by_middleware(e, request)
  File "/home/adrian/skyfolk/venv/lib/python3.6/site-packages/channels/handler.py", line 243, in process_exception_by_middleware
    return super(AsgiHandler, self).process_exception_by_middleware(exception, request)
  File "/home/adrian/skyfolk/venv/lib/python3.6/site-packages/django/core/handlers/base.py", line 185, in _get_response
    response = wrapped_callback(request, *callback_args, **callback_kwargs)
  File "/home/adrian/skyfolk/venv/lib/python3.6/site-packages/django/contrib/auth/decorators.py", line 23, in _wrapped_view
    return view_func(request, *args, **kwargs)
  File "/usr/lib/python3.6/contextlib.py", line 52, in inner
    return func(*args, **kwds)
  File "/home/adrian/skyfolk/publications/views.py", line 438, in add_like
    publication.user_give_me_like.add(user)
  File "/home/adrian/skyfolk/venv/lib/python3.6/site-packages/django/db/models/fields/related_descriptors.py", line 934, in add
    self._add_items(self.source_field_name, self.target_field_name, *objs)
  File "/home/adrian/skyfolk/venv/lib/python3.6/site-packages/django/db/models/fields/related_descriptors.py", line 1112, in _add_items
    model=self.model, pk_set=new_ids, using=db,
  File "/home/adrian/skyfolk/venv/lib/python3.6/site-packages/django/dispatch/dispatcher.py", line 193, in send
    for receiver in self._live_receivers(sender)
  File "/home/adrian/skyfolk/venv/lib/python3.6/site-packages/django/dispatch/dispatcher.py", line 193, in <listcomp>
    for receiver in self._live_receivers(sender)
  File "/home/adrian/skyfolk/publications/signals.py", line 32, in publication_received_like
    if qs.likes >= 100:
AttributeError: 'TreeQuerySet' object has no attribute 'likes'
2018-07-10 16:47:05,433 ERROR exception 21738 Internal Server Error: /publication/add_like/
Traceback (most recent call last):
  File "/home/adrian/skyfolk/venv/lib/python3.6/site-packages/django/core/handlers/exception.py", line 41, in inner
    response = get_response(request)
  File "/home/adrian/skyfolk/venv/lib/python3.6/site-packages/django/core/handlers/base.py", line 249, in _legacy_get_response
    response = self._get_response(request)
  File "/home/adrian/skyfolk/venv/lib/python3.6/site-packages/django/core/handlers/base.py", line 187, in _get_response
    response = self.process_exception_by_middleware(e, request)
  File "/home/adrian/skyfolk/venv/lib/python3.6/site-packages/channels/handler.py", line 243, in process_exception_by_middleware
    return super(AsgiHandler, self).process_exception_by_middleware(exception, request)
  File "/home/adrian/skyfolk/venv/lib/python3.6/site-packages/django/core/handlers/base.py", line 185, in _get_response
    response = wrapped_callback(request, *callback_args, **callback_kwargs)
  File "/home/adrian/skyfolk/venv/lib/python3.6/site-packages/django/contrib/auth/decorators.py", line 23, in _wrapped_view
    return view_func(request, *args, **kwargs)
  File "/usr/lib/python3.6/contextlib.py", line 52, in inner
    return func(*args, **kwds)
  File "/home/adrian/skyfolk/publications/views.py", line 438, in add_like
    publication.user_give_me_like.add(user)
  File "/home/adrian/skyfolk/venv/lib/python3.6/site-packages/django/db/models/fields/related_descriptors.py", line 934, in add
    self._add_items(self.source_field_name, self.target_field_name, *objs)
  File "/home/adrian/skyfolk/venv/lib/python3.6/site-packages/django/db/models/fields/related_descriptors.py", line 1112, in _add_items
    model=self.model, pk_set=new_ids, using=db,
  File "/home/adrian/skyfolk/venv/lib/python3.6/site-packages/django/dispatch/dispatcher.py", line 193, in send
    for receiver in self._live_receivers(sender)
  File "/home/adrian/skyfolk/venv/lib/python3.6/site-packages/django/dispatch/dispatcher.py", line 193, in <listcomp>
    for receiver in self._live_receivers(sender)
  File "/home/adrian/skyfolk/publications/signals.py", line 32, in publication_received_like
    if qs.likes >= 100:
AttributeError: 'dict' object has no attribute 'likes'
2018-07-10 16:47:10,058 ERROR exception 21738 Internal Server Error: /publication/add_like/
Traceback (most recent call last):
  File "/home/adrian/skyfolk/venv/lib/python3.6/site-packages/django/core/handlers/exception.py", line 41, in inner
    response = get_response(request)
  File "/home/adrian/skyfolk/venv/lib/python3.6/site-packages/django/core/handlers/base.py", line 249, in _legacy_get_response
    response = self._get_response(request)
  File "/home/adrian/skyfolk/venv/lib/python3.6/site-packages/django/core/handlers/base.py", line 187, in _get_response
    response = self.process_exception_by_middleware(e, request)
  File "/home/adrian/skyfolk/venv/lib/python3.6/site-packages/channels/handler.py", line 243, in process_exception_by_middleware
    return super(AsgiHandler, self).process_exception_by_middleware(exception, request)
  File "/home/adrian/skyfolk/venv/lib/python3.6/site-packages/django/core/handlers/base.py", line 185, in _get_response
    response = wrapped_callback(request, *callback_args, **callback_kwargs)
  File "/home/adrian/skyfolk/venv/lib/python3.6/site-packages/django/contrib/auth/decorators.py", line 23, in _wrapped_view
    return view_func(request, *args, **kwargs)
  File "/usr/lib/python3.6/contextlib.py", line 52, in inner
    return func(*args, **kwds)
  File "/home/adrian/skyfolk/publications/views.py", line 438, in add_like
    publication.user_give_me_like.add(user)
  File "/home/adrian/skyfolk/venv/lib/python3.6/site-packages/django/db/models/fields/related_descriptors.py", line 934, in add
    self._add_items(self.source_field_name, self.target_field_name, *objs)
  File "/home/adrian/skyfolk/venv/lib/python3.6/site-packages/django/db/models/fields/related_descriptors.py", line 1112, in _add_items
    model=self.model, pk_set=new_ids, using=db,
  File "/home/adrian/skyfolk/venv/lib/python3.6/site-packages/django/dispatch/dispatcher.py", line 193, in send
    for receiver in self._live_receivers(sender)
  File "/home/adrian/skyfolk/venv/lib/python3.6/site-packages/django/dispatch/dispatcher.py", line 193, in <listcomp>
    for receiver in self._live_receivers(sender)
  File "/home/adrian/skyfolk/publications/signals.py", line 32, in publication_received_like
    if qs.likes >= 100:
AttributeError: 'dict' object has no attribute 'likes'
2018-07-10 16:47:25,500 ERROR exception 21903 Internal Server Error: /publication/add_like/
Traceback (most recent call last):
  File "/home/adrian/skyfolk/venv/lib/python3.6/site-packages/django/core/handlers/exception.py", line 41, in inner
    response = get_response(request)
  File "/home/adrian/skyfolk/venv/lib/python3.6/site-packages/django/core/handlers/base.py", line 249, in _legacy_get_response
    response = self._get_response(request)
  File "/home/adrian/skyfolk/venv/lib/python3.6/site-packages/django/core/handlers/base.py", line 187, in _get_response
    response = self.process_exception_by_middleware(e, request)
  File "/home/adrian/skyfolk/venv/lib/python3.6/site-packages/channels/handler.py", line 243, in process_exception_by_middleware
    return super(AsgiHandler, self).process_exception_by_middleware(exception, request)
  File "/home/adrian/skyfolk/venv/lib/python3.6/site-packages/django/core/handlers/base.py", line 185, in _get_response
    response = wrapped_callback(request, *callback_args, **callback_kwargs)
  File "/home/adrian/skyfolk/venv/lib/python3.6/site-packages/django/contrib/auth/decorators.py", line 23, in _wrapped_view
    return view_func(request, *args, **kwargs)
  File "/usr/lib/python3.6/contextlib.py", line 52, in inner
    return func(*args, **kwds)
  File "/home/adrian/skyfolk/publications/views.py", line 438, in add_like
    publication.user_give_me_like.add(user)
  File "/home/adrian/skyfolk/venv/lib/python3.6/site-packages/django/db/models/fields/related_descriptors.py", line 934, in add
    self._add_items(self.source_field_name, self.target_field_name, *objs)
  File "/home/adrian/skyfolk/venv/lib/python3.6/site-packages/django/db/models/fields/related_descriptors.py", line 1112, in _add_items
    model=self.model, pk_set=new_ids, using=db,
  File "/home/adrian/skyfolk/venv/lib/python3.6/site-packages/django/dispatch/dispatcher.py", line 193, in send
    for receiver in self._live_receivers(sender)
  File "/home/adrian/skyfolk/venv/lib/python3.6/site-packages/django/dispatch/dispatcher.py", line 193, in <listcomp>
    for receiver in self._live_receivers(sender)
  File "/home/adrian/skyfolk/publications/signals.py", line 32, in publication_received_like
    if qs.likes >= 100:
AttributeError: 'dict' object has no attribute 'likes'
2018-07-10 16:47:31,210 ERROR exception 21903 Internal Server Error: /publication/add_like/
Traceback (most recent call last):
  File "/home/adrian/skyfolk/venv/lib/python3.6/site-packages/django/core/handlers/exception.py", line 41, in inner
    response = get_response(request)
  File "/home/adrian/skyfolk/venv/lib/python3.6/site-packages/django/core/handlers/base.py", line 249, in _legacy_get_response
    response = self._get_response(request)
  File "/home/adrian/skyfolk/venv/lib/python3.6/site-packages/django/core/handlers/base.py", line 187, in _get_response
    response = self.process_exception_by_middleware(e, request)
  File "/home/adrian/skyfolk/venv/lib/python3.6/site-packages/channels/handler.py", line 243, in process_exception_by_middleware
    return super(AsgiHandler, self).process_exception_by_middleware(exception, request)
  File "/home/adrian/skyfolk/venv/lib/python3.6/site-packages/django/core/handlers/base.py", line 185, in _get_response
    response = wrapped_callback(request, *callback_args, **callback_kwargs)
  File "/home/adrian/skyfolk/venv/lib/python3.6/site-packages/django/contrib/auth/decorators.py", line 23, in _wrapped_view
    return view_func(request, *args, **kwargs)
  File "/usr/lib/python3.6/contextlib.py", line 52, in inner
    return func(*args, **kwds)
  File "/home/adrian/skyfolk/publications/views.py", line 438, in add_like
    publication.user_give_me_like.add(user)
  File "/home/adrian/skyfolk/venv/lib/python3.6/site-packages/django/db/models/fields/related_descriptors.py", line 934, in add
    self._add_items(self.source_field_name, self.target_field_name, *objs)
  File "/home/adrian/skyfolk/venv/lib/python3.6/site-packages/django/db/models/fields/related_descriptors.py", line 1112, in _add_items
    model=self.model, pk_set=new_ids, using=db,
  File "/home/adrian/skyfolk/venv/lib/python3.6/site-packages/django/dispatch/dispatcher.py", line 193, in send
    for receiver in self._live_receivers(sender)
  File "/home/adrian/skyfolk/venv/lib/python3.6/site-packages/django/dispatch/dispatcher.py", line 193, in <listcomp>
    for receiver in self._live_receivers(sender)
  File "/home/adrian/skyfolk/publications/signals.py", line 32, in publication_received_like
    if qs.likes >= 100:
AttributeError: 'dict' object has no attribute 'likes'
2018-07-10 16:47:37,877 ERROR exception 21903 Internal Server Error: /publication/add_like/
Traceback (most recent call last):
  File "/home/adrian/skyfolk/venv/lib/python3.6/site-packages/django/core/handlers/exception.py", line 41, in inner
    response = get_response(request)
  File "/home/adrian/skyfolk/venv/lib/python3.6/site-packages/django/core/handlers/base.py", line 249, in _legacy_get_response
    response = self._get_response(request)
  File "/home/adrian/skyfolk/venv/lib/python3.6/site-packages/django/core/handlers/base.py", line 187, in _get_response
    response = self.process_exception_by_middleware(e, request)
  File "/home/adrian/skyfolk/venv/lib/python3.6/site-packages/channels/handler.py", line 243, in process_exception_by_middleware
    return super(AsgiHandler, self).process_exception_by_middleware(exception, request)
  File "/home/adrian/skyfolk/venv/lib/python3.6/site-packages/django/core/handlers/base.py", line 185, in _get_response
    response = wrapped_callback(request, *callback_args, **callback_kwargs)
  File "/home/adrian/skyfolk/venv/lib/python3.6/site-packages/django/contrib/auth/decorators.py", line 23, in _wrapped_view
    return view_func(request, *args, **kwargs)
  File "/usr/lib/python3.6/contextlib.py", line 52, in inner
    return func(*args, **kwds)
  File "/home/adrian/skyfolk/publications/views.py", line 438, in add_like
    publication.user_give_me_like.add(user)
  File "/home/adrian/skyfolk/venv/lib/python3.6/site-packages/django/db/models/fields/related_descriptors.py", line 934, in add
    self._add_items(self.source_field_name, self.target_field_name, *objs)
  File "/home/adrian/skyfolk/venv/lib/python3.6/site-packages/django/db/models/fields/related_descriptors.py", line 1112, in _add_items
    model=self.model, pk_set=new_ids, using=db,
  File "/home/adrian/skyfolk/venv/lib/python3.6/site-packages/django/dispatch/dispatcher.py", line 193, in send
    for receiver in self._live_receivers(sender)
  File "/home/adrian/skyfolk/venv/lib/python3.6/site-packages/django/dispatch/dispatcher.py", line 193, in <listcomp>
    for receiver in self._live_receivers(sender)
  File "/home/adrian/skyfolk/publications/signals.py", line 32, in publication_received_like
    if qs.likes >= 100:
AttributeError: 'dict' object has no attribute 'likes'
2018-07-10 16:47:39,279 ERROR exception 21903 Internal Server Error: /publication/add_like/
Traceback (most recent call last):
  File "/home/adrian/skyfolk/venv/lib/python3.6/site-packages/django/core/handlers/exception.py", line 41, in inner
    response = get_response(request)
  File "/home/adrian/skyfolk/venv/lib/python3.6/site-packages/django/core/handlers/base.py", line 249, in _legacy_get_response
    response = self._get_response(request)
  File "/home/adrian/skyfolk/venv/lib/python3.6/site-packages/django/core/handlers/base.py", line 187, in _get_response
    response = self.process_exception_by_middleware(e, request)
  File "/home/adrian/skyfolk/venv/lib/python3.6/site-packages/channels/handler.py", line 243, in process_exception_by_middleware
    return super(AsgiHandler, self).process_exception_by_middleware(exception, request)
  File "/home/adrian/skyfolk/venv/lib/python3.6/site-packages/django/core/handlers/base.py", line 185, in _get_response
    response = wrapped_callback(request, *callback_args, **callback_kwargs)
  File "/home/adrian/skyfolk/venv/lib/python3.6/site-packages/django/contrib/auth/decorators.py", line 23, in _wrapped_view
    return view_func(request, *args, **kwargs)
  File "/usr/lib/python3.6/contextlib.py", line 52, in inner
    return func(*args, **kwds)
  File "/home/adrian/skyfolk/publications/views.py", line 438, in add_like
    publication.user_give_me_like.add(user)
  File "/home/adrian/skyfolk/venv/lib/python3.6/site-packages/django/db/models/fields/related_descriptors.py", line 934, in add
    self._add_items(self.source_field_name, self.target_field_name, *objs)
  File "/home/adrian/skyfolk/venv/lib/python3.6/site-packages/django/db/models/fields/related_descriptors.py", line 1112, in _add_items
    model=self.model, pk_set=new_ids, using=db,
  File "/home/adrian/skyfolk/venv/lib/python3.6/site-packages/django/dispatch/dispatcher.py", line 193, in send
    for receiver in self._live_receivers(sender)
  File "/home/adrian/skyfolk/venv/lib/python3.6/site-packages/django/dispatch/dispatcher.py", line 193, in <listcomp>
    for receiver in self._live_receivers(sender)
  File "/home/adrian/skyfolk/publications/signals.py", line 32, in publication_received_like
    if qs.likes >= 100:
AttributeError: 'dict' object has no attribute 'likes'
2018-07-10 16:47:39,875 ERROR exception 21903 Internal Server Error: /publication/add_like/
Traceback (most recent call last):
  File "/home/adrian/skyfolk/venv/lib/python3.6/site-packages/django/core/handlers/exception.py", line 41, in inner
    response = get_response(request)
  File "/home/adrian/skyfolk/venv/lib/python3.6/site-packages/django/core/handlers/base.py", line 249, in _legacy_get_response
    response = self._get_response(request)
  File "/home/adrian/skyfolk/venv/lib/python3.6/site-packages/django/core/handlers/base.py", line 187, in _get_response
    response = self.process_exception_by_middleware(e, request)
  File "/home/adrian/skyfolk/venv/lib/python3.6/site-packages/channels/handler.py", line 243, in process_exception_by_middleware
    return super(AsgiHandler, self).process_exception_by_middleware(exception, request)
  File "/home/adrian/skyfolk/venv/lib/python3.6/site-packages/django/core/handlers/base.py", line 185, in _get_response
    response = wrapped_callback(request, *callback_args, **callback_kwargs)
  File "/home/adrian/skyfolk/venv/lib/python3.6/site-packages/django/contrib/auth/decorators.py", line 23, in _wrapped_view
    return view_func(request, *args, **kwargs)
  File "/usr/lib/python3.6/contextlib.py", line 52, in inner
    return func(*args, **kwds)
  File "/home/adrian/skyfolk/publications/views.py", line 438, in add_like
    publication.user_give_me_like.add(user)
  File "/home/adrian/skyfolk/venv/lib/python3.6/site-packages/django/db/models/fields/related_descriptors.py", line 934, in add
    self._add_items(self.source_field_name, self.target_field_name, *objs)
  File "/home/adrian/skyfolk/venv/lib/python3.6/site-packages/django/db/models/fields/related_descriptors.py", line 1112, in _add_items
    model=self.model, pk_set=new_ids, using=db,
  File "/home/adrian/skyfolk/venv/lib/python3.6/site-packages/django/dispatch/dispatcher.py", line 193, in send
    for receiver in self._live_receivers(sender)
  File "/home/adrian/skyfolk/venv/lib/python3.6/site-packages/django/dispatch/dispatcher.py", line 193, in <listcomp>
    for receiver in self._live_receivers(sender)
  File "/home/adrian/skyfolk/publications/signals.py", line 32, in publication_received_like
    if qs.likes >= 100:
AttributeError: 'dict' object has no attribute 'likes'
