2018-06-09 23:13:55,706 ERROR exception 24606 Internal Server Error: /awards/user/26/
Traceback (most recent call last):
  File "/home/adrian/skyfolk/venv/lib/python3.6/site-packages/django/core/handlers/exception.py", line 41, in inner
    response = get_response(request)
  File "/home/adrian/skyfolk/venv/lib/python3.6/site-packages/django/core/handlers/base.py", line 249, in _legacy_get_response
    response = self._get_response(request)
  File "/home/adrian/skyfolk/venv/lib/python3.6/site-packages/django/core/handlers/base.py", line 187, in _get_response
    response = self.process_exception_by_middleware(e, request)
  File "/home/adrian/skyfolk/venv/lib/python3.6/site-packages/channels/handler.py", line 243, in process_exception_by_middleware
    return super(AsgiHandler, self).process_exception_by_middleware(exception, request)
  File "/home/adrian/skyfolk/venv/lib/python3.6/site-packages/django/core/handlers/base.py", line 185, in _get_response
    response = wrapped_callback(request, *callback_args, **callback_kwargs)
  File "/home/adrian/skyfolk/venv/lib/python3.6/site-packages/django/contrib/auth/decorators.py", line 23, in _wrapped_view
    return view_func(request, *args, **kwargs)
  File "/home/adrian/skyfolk/venv/lib/python3.6/site-packages/django/views/decorators/csrf.py", line 58, in wrapped_view
    return view_func(*args, **kwargs)
  File "/home/adrian/skyfolk/venv/lib/python3.6/site-packages/django/views/generic/base.py", line 68, in view
    return self.dispatch(request, *args, **kwargs)
  File "/home/adrian/skyfolk/venv/lib/python3.6/site-packages/rest_framework/views.py", line 489, in dispatch
    response = self.handle_exception(exc)
  File "/home/adrian/skyfolk/venv/lib/python3.6/site-packages/rest_framework/views.py", line 449, in handle_exception
    self.raise_uncaught_exception(exc)
  File "/home/adrian/skyfolk/venv/lib/python3.6/site-packages/rest_framework/views.py", line 486, in dispatch
    response = handler(request, *args, **kwargs)
  File "/home/adrian/skyfolk/awards/views.py", line 44, in get
    q = Badge.objects.filter(users__id__in=profile.user_id).annotate(total_points=Sum('points'))
  File "/home/adrian/skyfolk/venv/lib/python3.6/site-packages/django/db/models/manager.py", line 85, in manager_method
    return getattr(self.get_queryset(), name)(*args, **kwargs)
  File "/home/adrian/skyfolk/venv/lib/python3.6/site-packages/django/db/models/query.py", line 784, in filter
    return self._filter_or_exclude(False, *args, **kwargs)
  File "/home/adrian/skyfolk/venv/lib/python3.6/site-packages/django/db/models/query.py", line 802, in _filter_or_exclude
    clone.query.add_q(Q(*args, **kwargs))
  File "/home/adrian/skyfolk/venv/lib/python3.6/site-packages/django/db/models/sql/query.py", line 1250, in add_q
    clause, _ = self._add_q(q_object, self.used_aliases)
  File "/home/adrian/skyfolk/venv/lib/python3.6/site-packages/django/db/models/sql/query.py", line 1276, in _add_q
    allow_joins=allow_joins, split_subq=split_subq,
  File "/home/adrian/skyfolk/venv/lib/python3.6/site-packages/django/db/models/sql/query.py", line 1210, in build_filter
    condition = self.build_lookup(lookups, col, value)
  File "/home/adrian/skyfolk/venv/lib/python3.6/site-packages/django/db/models/sql/query.py", line 1104, in build_lookup
    return final_lookup(lhs, rhs)
  File "/home/adrian/skyfolk/venv/lib/python3.6/site-packages/django/db/models/lookups.py", line 24, in __init__
    self.rhs = self.get_prep_lookup()
  File "/home/adrian/skyfolk/venv/lib/python3.6/site-packages/django/db/models/lookups.py", line 213, in get_prep_lookup
    for rhs_value in self.rhs:
TypeError: 'int' object is not iterable
2018-06-09 23:15:17,507 ERROR exception 25030 Internal Server Error: /awards/user/26/
Traceback (most recent call last):
  File "/home/adrian/skyfolk/venv/lib/python3.6/site-packages/django/core/handlers/exception.py", line 41, in inner
    response = get_response(request)
  File "/home/adrian/skyfolk/venv/lib/python3.6/site-packages/django/core/handlers/base.py", line 249, in _legacy_get_response
    response = self._get_response(request)
  File "/home/adrian/skyfolk/venv/lib/python3.6/site-packages/django/core/handlers/base.py", line 187, in _get_response
    response = self.process_exception_by_middleware(e, request)
  File "/home/adrian/skyfolk/venv/lib/python3.6/site-packages/channels/handler.py", line 243, in process_exception_by_middleware
    return super(AsgiHandler, self).process_exception_by_middleware(exception, request)
  File "/home/adrian/skyfolk/venv/lib/python3.6/site-packages/django/core/handlers/base.py", line 185, in _get_response
    response = wrapped_callback(request, *callback_args, **callback_kwargs)
  File "/home/adrian/skyfolk/venv/lib/python3.6/site-packages/django/contrib/auth/decorators.py", line 23, in _wrapped_view
    return view_func(request, *args, **kwargs)
  File "/home/adrian/skyfolk/venv/lib/python3.6/site-packages/django/views/decorators/csrf.py", line 58, in wrapped_view
    return view_func(*args, **kwargs)
  File "/home/adrian/skyfolk/venv/lib/python3.6/site-packages/django/views/generic/base.py", line 68, in view
    return self.dispatch(request, *args, **kwargs)
  File "/home/adrian/skyfolk/venv/lib/python3.6/site-packages/rest_framework/views.py", line 489, in dispatch
    response = self.handle_exception(exc)
  File "/home/adrian/skyfolk/venv/lib/python3.6/site-packages/rest_framework/views.py", line 449, in handle_exception
    self.raise_uncaught_exception(exc)
  File "/home/adrian/skyfolk/venv/lib/python3.6/site-packages/rest_framework/views.py", line 486, in dispatch
    response = handler(request, *args, **kwargs)
  File "/home/adrian/skyfolk/awards/views.py", line 44, in get
    q = Badge.objects.filter(users__in=profile.user_id).annotate(total_points=Sum('points'))
  File "/home/adrian/skyfolk/venv/lib/python3.6/site-packages/django/db/models/manager.py", line 85, in manager_method
    return getattr(self.get_queryset(), name)(*args, **kwargs)
  File "/home/adrian/skyfolk/venv/lib/python3.6/site-packages/django/db/models/query.py", line 784, in filter
    return self._filter_or_exclude(False, *args, **kwargs)
  File "/home/adrian/skyfolk/venv/lib/python3.6/site-packages/django/db/models/query.py", line 802, in _filter_or_exclude
    clone.query.add_q(Q(*args, **kwargs))
  File "/home/adrian/skyfolk/venv/lib/python3.6/site-packages/django/db/models/sql/query.py", line 1250, in add_q
    clause, _ = self._add_q(q_object, self.used_aliases)
  File "/home/adrian/skyfolk/venv/lib/python3.6/site-packages/django/db/models/sql/query.py", line 1276, in _add_q
    allow_joins=allow_joins, split_subq=split_subq,
  File "/home/adrian/skyfolk/venv/lib/python3.6/site-packages/django/db/models/sql/query.py", line 1206, in build_filter
    condition = lookup_class(lhs, value)
  File "/home/adrian/skyfolk/venv/lib/python3.6/site-packages/django/db/models/lookups.py", line 24, in __init__
    self.rhs = self.get_prep_lookup()
  File "/home/adrian/skyfolk/venv/lib/python3.6/site-packages/django/db/models/fields/related_lookups.py", line 47, in get_prep_lookup
    self.rhs = [get_normalized_value(val, self.lhs)[0] for val in self.rhs]
TypeError: 'int' object is not iterable
2018-06-09 23:15:19,308 ERROR exception 25030 Internal Server Error: /awards/user/26/
Traceback (most recent call last):
  File "/home/adrian/skyfolk/venv/lib/python3.6/site-packages/django/core/handlers/exception.py", line 41, in inner
    response = get_response(request)
  File "/home/adrian/skyfolk/venv/lib/python3.6/site-packages/django/core/handlers/base.py", line 249, in _legacy_get_response
    response = self._get_response(request)
  File "/home/adrian/skyfolk/venv/lib/python3.6/site-packages/django/core/handlers/base.py", line 187, in _get_response
    response = self.process_exception_by_middleware(e, request)
  File "/home/adrian/skyfolk/venv/lib/python3.6/site-packages/channels/handler.py", line 243, in process_exception_by_middleware
    return super(AsgiHandler, self).process_exception_by_middleware(exception, request)
  File "/home/adrian/skyfolk/venv/lib/python3.6/site-packages/django/core/handlers/base.py", line 185, in _get_response
    response = wrapped_callback(request, *callback_args, **callback_kwargs)
  File "/home/adrian/skyfolk/venv/lib/python3.6/site-packages/django/contrib/auth/decorators.py", line 23, in _wrapped_view
    return view_func(request, *args, **kwargs)
  File "/home/adrian/skyfolk/venv/lib/python3.6/site-packages/django/views/decorators/csrf.py", line 58, in wrapped_view
    return view_func(*args, **kwargs)
  File "/home/adrian/skyfolk/venv/lib/python3.6/site-packages/django/views/generic/base.py", line 68, in view
    return self.dispatch(request, *args, **kwargs)
  File "/home/adrian/skyfolk/venv/lib/python3.6/site-packages/rest_framework/views.py", line 489, in dispatch
    response = self.handle_exception(exc)
  File "/home/adrian/skyfolk/venv/lib/python3.6/site-packages/rest_framework/views.py", line 449, in handle_exception
    self.raise_uncaught_exception(exc)
  File "/home/adrian/skyfolk/venv/lib/python3.6/site-packages/rest_framework/views.py", line 486, in dispatch
    response = handler(request, *args, **kwargs)
  File "/home/adrian/skyfolk/awards/views.py", line 44, in get
    q = Badge.objects.filter(users__in=profile.user_id).annotate(total_points=Sum('points'))
  File "/home/adrian/skyfolk/venv/lib/python3.6/site-packages/django/db/models/manager.py", line 85, in manager_method
    return getattr(self.get_queryset(), name)(*args, **kwargs)
  File "/home/adrian/skyfolk/venv/lib/python3.6/site-packages/django/db/models/query.py", line 784, in filter
    return self._filter_or_exclude(False, *args, **kwargs)
  File "/home/adrian/skyfolk/venv/lib/python3.6/site-packages/django/db/models/query.py", line 802, in _filter_or_exclude
    clone.query.add_q(Q(*args, **kwargs))
  File "/home/adrian/skyfolk/venv/lib/python3.6/site-packages/django/db/models/sql/query.py", line 1250, in add_q
    clause, _ = self._add_q(q_object, self.used_aliases)
  File "/home/adrian/skyfolk/venv/lib/python3.6/site-packages/django/db/models/sql/query.py", line 1276, in _add_q
    allow_joins=allow_joins, split_subq=split_subq,
  File "/home/adrian/skyfolk/venv/lib/python3.6/site-packages/django/db/models/sql/query.py", line 1206, in build_filter
    condition = lookup_class(lhs, value)
  File "/home/adrian/skyfolk/venv/lib/python3.6/site-packages/django/db/models/lookups.py", line 24, in __init__
    self.rhs = self.get_prep_lookup()
  File "/home/adrian/skyfolk/venv/lib/python3.6/site-packages/django/db/models/fields/related_lookups.py", line 47, in get_prep_lookup
    self.rhs = [get_normalized_value(val, self.lhs)[0] for val in self.rhs]
TypeError: 'int' object is not iterable
2018-06-09 23:15:45,135 ERROR exception 25324 Internal Server Error: /awards/user/26/
Traceback (most recent call last):
  File "/home/adrian/skyfolk/venv/lib/python3.6/site-packages/django/core/handlers/exception.py", line 41, in inner
    response = get_response(request)
  File "/home/adrian/skyfolk/venv/lib/python3.6/site-packages/django/core/handlers/base.py", line 249, in _legacy_get_response
    response = self._get_response(request)
  File "/home/adrian/skyfolk/venv/lib/python3.6/site-packages/django/core/handlers/base.py", line 187, in _get_response
    response = self.process_exception_by_middleware(e, request)
  File "/home/adrian/skyfolk/venv/lib/python3.6/site-packages/channels/handler.py", line 243, in process_exception_by_middleware
    return super(AsgiHandler, self).process_exception_by_middleware(exception, request)
  File "/home/adrian/skyfolk/venv/lib/python3.6/site-packages/django/core/handlers/base.py", line 185, in _get_response
    response = wrapped_callback(request, *callback_args, **callback_kwargs)
  File "/home/adrian/skyfolk/venv/lib/python3.6/site-packages/django/contrib/auth/decorators.py", line 23, in _wrapped_view
    return view_func(request, *args, **kwargs)
  File "/home/adrian/skyfolk/venv/lib/python3.6/site-packages/django/views/decorators/csrf.py", line 58, in wrapped_view
    return view_func(*args, **kwargs)
  File "/home/adrian/skyfolk/venv/lib/python3.6/site-packages/django/views/generic/base.py", line 68, in view
    return self.dispatch(request, *args, **kwargs)
  File "/home/adrian/skyfolk/venv/lib/python3.6/site-packages/rest_framework/views.py", line 489, in dispatch
    response = self.handle_exception(exc)
  File "/home/adrian/skyfolk/venv/lib/python3.6/site-packages/rest_framework/views.py", line 449, in handle_exception
    self.raise_uncaught_exception(exc)
  File "/home/adrian/skyfolk/venv/lib/python3.6/site-packages/rest_framework/views.py", line 486, in dispatch
    response = handler(request, *args, **kwargs)
  File "/home/adrian/skyfolk/awards/views.py", line 44, in get
    q = Badge.objects.filter(users__in=profile.user).annotate(total_points=Sum('points'))
  File "/home/adrian/skyfolk/venv/lib/python3.6/site-packages/django/db/models/manager.py", line 85, in manager_method
    return getattr(self.get_queryset(), name)(*args, **kwargs)
  File "/home/adrian/skyfolk/venv/lib/python3.6/site-packages/django/db/models/query.py", line 784, in filter
    return self._filter_or_exclude(False, *args, **kwargs)
  File "/home/adrian/skyfolk/venv/lib/python3.6/site-packages/django/db/models/query.py", line 802, in _filter_or_exclude
    clone.query.add_q(Q(*args, **kwargs))
  File "/home/adrian/skyfolk/venv/lib/python3.6/site-packages/django/db/models/sql/query.py", line 1250, in add_q
    clause, _ = self._add_q(q_object, self.used_aliases)
  File "/home/adrian/skyfolk/venv/lib/python3.6/site-packages/django/db/models/sql/query.py", line 1276, in _add_q
    allow_joins=allow_joins, split_subq=split_subq,
  File "/home/adrian/skyfolk/venv/lib/python3.6/site-packages/django/db/models/sql/query.py", line 1206, in build_filter
    condition = lookup_class(lhs, value)
  File "/home/adrian/skyfolk/venv/lib/python3.6/site-packages/django/db/models/lookups.py", line 24, in __init__
    self.rhs = self.get_prep_lookup()
  File "/home/adrian/skyfolk/venv/lib/python3.6/site-packages/django/db/models/fields/related_lookups.py", line 47, in get_prep_lookup
    self.rhs = [get_normalized_value(val, self.lhs)[0] for val in self.rhs]
TypeError: 'User' object is not iterable
2018-06-09 23:15:46,625 ERROR exception 25324 Internal Server Error: /awards/user/26/
Traceback (most recent call last):
  File "/home/adrian/skyfolk/venv/lib/python3.6/site-packages/django/core/handlers/exception.py", line 41, in inner
    response = get_response(request)
  File "/home/adrian/skyfolk/venv/lib/python3.6/site-packages/django/core/handlers/base.py", line 249, in _legacy_get_response
    response = self._get_response(request)
  File "/home/adrian/skyfolk/venv/lib/python3.6/site-packages/django/core/handlers/base.py", line 187, in _get_response
    response = self.process_exception_by_middleware(e, request)
  File "/home/adrian/skyfolk/venv/lib/python3.6/site-packages/channels/handler.py", line 243, in process_exception_by_middleware
    return super(AsgiHandler, self).process_exception_by_middleware(exception, request)
  File "/home/adrian/skyfolk/venv/lib/python3.6/site-packages/django/core/handlers/base.py", line 185, in _get_response
    response = wrapped_callback(request, *callback_args, **callback_kwargs)
  File "/home/adrian/skyfolk/venv/lib/python3.6/site-packages/django/contrib/auth/decorators.py", line 23, in _wrapped_view
    return view_func(request, *args, **kwargs)
  File "/home/adrian/skyfolk/venv/lib/python3.6/site-packages/django/views/decorators/csrf.py", line 58, in wrapped_view
    return view_func(*args, **kwargs)
  File "/home/adrian/skyfolk/venv/lib/python3.6/site-packages/django/views/generic/base.py", line 68, in view
    return self.dispatch(request, *args, **kwargs)
  File "/home/adrian/skyfolk/venv/lib/python3.6/site-packages/rest_framework/views.py", line 489, in dispatch
    response = self.handle_exception(exc)
  File "/home/adrian/skyfolk/venv/lib/python3.6/site-packages/rest_framework/views.py", line 449, in handle_exception
    self.raise_uncaught_exception(exc)
  File "/home/adrian/skyfolk/venv/lib/python3.6/site-packages/rest_framework/views.py", line 486, in dispatch
    response = handler(request, *args, **kwargs)
  File "/home/adrian/skyfolk/awards/views.py", line 44, in get
    q = Badge.objects.filter(users__in=profile.user).annotate(total_points=Sum('points'))
  File "/home/adrian/skyfolk/venv/lib/python3.6/site-packages/django/db/models/manager.py", line 85, in manager_method
    return getattr(self.get_queryset(), name)(*args, **kwargs)
  File "/home/adrian/skyfolk/venv/lib/python3.6/site-packages/django/db/models/query.py", line 784, in filter
    return self._filter_or_exclude(False, *args, **kwargs)
  File "/home/adrian/skyfolk/venv/lib/python3.6/site-packages/django/db/models/query.py", line 802, in _filter_or_exclude
    clone.query.add_q(Q(*args, **kwargs))
  File "/home/adrian/skyfolk/venv/lib/python3.6/site-packages/django/db/models/sql/query.py", line 1250, in add_q
    clause, _ = self._add_q(q_object, self.used_aliases)
  File "/home/adrian/skyfolk/venv/lib/python3.6/site-packages/django/db/models/sql/query.py", line 1276, in _add_q
    allow_joins=allow_joins, split_subq=split_subq,
  File "/home/adrian/skyfolk/venv/lib/python3.6/site-packages/django/db/models/sql/query.py", line 1206, in build_filter
    condition = lookup_class(lhs, value)
  File "/home/adrian/skyfolk/venv/lib/python3.6/site-packages/django/db/models/lookups.py", line 24, in __init__
    self.rhs = self.get_prep_lookup()
  File "/home/adrian/skyfolk/venv/lib/python3.6/site-packages/django/db/models/fields/related_lookups.py", line 47, in get_prep_lookup
    self.rhs = [get_normalized_value(val, self.lhs)[0] for val in self.rhs]
TypeError: 'User' object is not iterable
2018-06-09 23:16:01,286 ERROR exception 25477 Internal Server Error: /awards/user/26/
Traceback (most recent call last):
  File "/home/adrian/skyfolk/venv/lib/python3.6/site-packages/django/core/handlers/exception.py", line 41, in inner
    response = get_response(request)
  File "/home/adrian/skyfolk/venv/lib/python3.6/site-packages/django/core/handlers/base.py", line 249, in _legacy_get_response
    response = self._get_response(request)
  File "/home/adrian/skyfolk/venv/lib/python3.6/site-packages/django/core/handlers/base.py", line 187, in _get_response
    response = self.process_exception_by_middleware(e, request)
  File "/home/adrian/skyfolk/venv/lib/python3.6/site-packages/channels/handler.py", line 243, in process_exception_by_middleware
    return super(AsgiHandler, self).process_exception_by_middleware(exception, request)
  File "/home/adrian/skyfolk/venv/lib/python3.6/site-packages/django/core/handlers/base.py", line 185, in _get_response
    response = wrapped_callback(request, *callback_args, **callback_kwargs)
  File "/home/adrian/skyfolk/venv/lib/python3.6/site-packages/django/contrib/auth/decorators.py", line 23, in _wrapped_view
    return view_func(request, *args, **kwargs)
  File "/home/adrian/skyfolk/venv/lib/python3.6/site-packages/django/views/decorators/csrf.py", line 58, in wrapped_view
    return view_func(*args, **kwargs)
  File "/home/adrian/skyfolk/venv/lib/python3.6/site-packages/django/views/generic/base.py", line 68, in view
    return self.dispatch(request, *args, **kwargs)
  File "/home/adrian/skyfolk/venv/lib/python3.6/site-packages/rest_framework/views.py", line 489, in dispatch
    response = self.handle_exception(exc)
  File "/home/adrian/skyfolk/venv/lib/python3.6/site-packages/rest_framework/views.py", line 449, in handle_exception
    self.raise_uncaught_exception(exc)
  File "/home/adrian/skyfolk/venv/lib/python3.6/site-packages/rest_framework/views.py", line 486, in dispatch
    response = handler(request, *args, **kwargs)
  File "/home/adrian/skyfolk/awards/views.py", line 44, in get
    q = Badge.objects.filter(users__id=profile.user_id).annotate(total_points=Sum('points'))
  File "/home/adrian/skyfolk/venv/lib/python3.6/site-packages/django/db/models/manager.py", line 85, in manager_method
    return getattr(self.get_queryset(), name)(*args, **kwargs)
  File "/home/adrian/skyfolk/venv/lib/python3.6/site-packages/django/db/models/query.py", line 784, in filter
    return self._filter_or_exclude(False, *args, **kwargs)
  File "/home/adrian/skyfolk/venv/lib/python3.6/site-packages/django/db/models/query.py", line 802, in _filter_or_exclude
    clone.query.add_q(Q(*args, **kwargs))
  File "/home/adrian/skyfolk/venv/lib/python3.6/site-packages/django/db/models/sql/query.py", line 1250, in add_q
    clause, _ = self._add_q(q_object, self.used_aliases)
  File "/home/adrian/skyfolk/venv/lib/python3.6/site-packages/django/db/models/sql/query.py", line 1276, in _add_q
    allow_joins=allow_joins, split_subq=split_subq,
  File "/home/adrian/skyfolk/venv/lib/python3.6/site-packages/django/db/models/sql/query.py", line 1210, in build_filter
    condition = self.build_lookup(lookups, col, value)
  File "/home/adrian/skyfolk/venv/lib/python3.6/site-packages/django/db/models/sql/query.py", line 1104, in build_lookup
    return final_lookup(lhs, rhs)
  File "/home/adrian/skyfolk/venv/lib/python3.6/site-packages/django/db/models/lookups.py", line 24, in __init__
    self.rhs = self.get_prep_lookup()
  File "/home/adrian/skyfolk/venv/lib/python3.6/site-packages/django/db/models/lookups.py", line 74, in get_prep_lookup
    return self.lhs.output_field.get_prep_value(self.rhs)
  File "/home/adrian/skyfolk/venv/lib/python3.6/site-packages/django/db/models/fields/__init__.py", line 966, in get_prep_value
    return int(value)
TypeError: int() argument must be a string, a bytes-like object or a number, not 'User'
2018-06-09 23:16:03,326 ERROR exception 25477 Internal Server Error: /awards/user/26/
Traceback (most recent call last):
  File "/home/adrian/skyfolk/venv/lib/python3.6/site-packages/django/core/handlers/exception.py", line 41, in inner
    response = get_response(request)
  File "/home/adrian/skyfolk/venv/lib/python3.6/site-packages/django/core/handlers/base.py", line 249, in _legacy_get_response
    response = self._get_response(request)
  File "/home/adrian/skyfolk/venv/lib/python3.6/site-packages/django/core/handlers/base.py", line 187, in _get_response
    response = self.process_exception_by_middleware(e, request)
  File "/home/adrian/skyfolk/venv/lib/python3.6/site-packages/channels/handler.py", line 243, in process_exception_by_middleware
    return super(AsgiHandler, self).process_exception_by_middleware(exception, request)
  File "/home/adrian/skyfolk/venv/lib/python3.6/site-packages/django/core/handlers/base.py", line 185, in _get_response
    response = wrapped_callback(request, *callback_args, **callback_kwargs)
  File "/home/adrian/skyfolk/venv/lib/python3.6/site-packages/django/contrib/auth/decorators.py", line 23, in _wrapped_view
    return view_func(request, *args, **kwargs)
  File "/home/adrian/skyfolk/venv/lib/python3.6/site-packages/django/views/decorators/csrf.py", line 58, in wrapped_view
    return view_func(*args, **kwargs)
  File "/home/adrian/skyfolk/venv/lib/python3.6/site-packages/django/views/generic/base.py", line 68, in view
    return self.dispatch(request, *args, **kwargs)
  File "/home/adrian/skyfolk/venv/lib/python3.6/site-packages/rest_framework/views.py", line 489, in dispatch
    response = self.handle_exception(exc)
  File "/home/adrian/skyfolk/venv/lib/python3.6/site-packages/rest_framework/views.py", line 449, in handle_exception
    self.raise_uncaught_exception(exc)
  File "/home/adrian/skyfolk/venv/lib/python3.6/site-packages/rest_framework/views.py", line 486, in dispatch
    response = handler(request, *args, **kwargs)
  File "/home/adrian/skyfolk/awards/views.py", line 44, in get
    q = Badge.objects.filter(users__id=profile.user_id).annotate(total_points=Sum('points'))
  File "/home/adrian/skyfolk/venv/lib/python3.6/site-packages/django/db/models/manager.py", line 85, in manager_method
    return getattr(self.get_queryset(), name)(*args, **kwargs)
  File "/home/adrian/skyfolk/venv/lib/python3.6/site-packages/django/db/models/query.py", line 784, in filter
    return self._filter_or_exclude(False, *args, **kwargs)
  File "/home/adrian/skyfolk/venv/lib/python3.6/site-packages/django/db/models/query.py", line 802, in _filter_or_exclude
    clone.query.add_q(Q(*args, **kwargs))
  File "/home/adrian/skyfolk/venv/lib/python3.6/site-packages/django/db/models/sql/query.py", line 1250, in add_q
    clause, _ = self._add_q(q_object, self.used_aliases)
  File "/home/adrian/skyfolk/venv/lib/python3.6/site-packages/django/db/models/sql/query.py", line 1276, in _add_q
    allow_joins=allow_joins, split_subq=split_subq,
  File "/home/adrian/skyfolk/venv/lib/python3.6/site-packages/django/db/models/sql/query.py", line 1210, in build_filter
    condition = self.build_lookup(lookups, col, value)
  File "/home/adrian/skyfolk/venv/lib/python3.6/site-packages/django/db/models/sql/query.py", line 1104, in build_lookup
    return final_lookup(lhs, rhs)
  File "/home/adrian/skyfolk/venv/lib/python3.6/site-packages/django/db/models/lookups.py", line 24, in __init__
    self.rhs = self.get_prep_lookup()
  File "/home/adrian/skyfolk/venv/lib/python3.6/site-packages/django/db/models/lookups.py", line 74, in get_prep_lookup
    return self.lhs.output_field.get_prep_value(self.rhs)
  File "/home/adrian/skyfolk/venv/lib/python3.6/site-packages/django/db/models/fields/__init__.py", line 966, in get_prep_value
    return int(value)
TypeError: int() argument must be a string, a bytes-like object or a number, not 'User'
2018-06-09 23:17:18,336 ERROR exception 25907 Internal Server Error: /awards/user/26/
Traceback (most recent call last):
  File "/home/adrian/skyfolk/venv/lib/python3.6/site-packages/django/core/handlers/exception.py", line 41, in inner
    response = get_response(request)
  File "/home/adrian/skyfolk/venv/lib/python3.6/site-packages/django/core/handlers/base.py", line 249, in _legacy_get_response
    response = self._get_response(request)
  File "/home/adrian/skyfolk/venv/lib/python3.6/site-packages/django/core/handlers/base.py", line 187, in _get_response
    response = self.process_exception_by_middleware(e, request)
  File "/home/adrian/skyfolk/venv/lib/python3.6/site-packages/channels/handler.py", line 243, in process_exception_by_middleware
    return super(AsgiHandler, self).process_exception_by_middleware(exception, request)
  File "/home/adrian/skyfolk/venv/lib/python3.6/site-packages/django/core/handlers/base.py", line 185, in _get_response
    response = wrapped_callback(request, *callback_args, **callback_kwargs)
  File "/home/adrian/skyfolk/venv/lib/python3.6/site-packages/django/contrib/auth/decorators.py", line 23, in _wrapped_view
    return view_func(request, *args, **kwargs)
  File "/home/adrian/skyfolk/venv/lib/python3.6/site-packages/django/views/decorators/csrf.py", line 58, in wrapped_view
    return view_func(*args, **kwargs)
  File "/home/adrian/skyfolk/venv/lib/python3.6/site-packages/django/views/generic/base.py", line 68, in view
    return self.dispatch(request, *args, **kwargs)
  File "/home/adrian/skyfolk/venv/lib/python3.6/site-packages/rest_framework/views.py", line 489, in dispatch
    response = self.handle_exception(exc)
  File "/home/adrian/skyfolk/venv/lib/python3.6/site-packages/rest_framework/views.py", line 449, in handle_exception
    self.raise_uncaught_exception(exc)
  File "/home/adrian/skyfolk/venv/lib/python3.6/site-packages/rest_framework/views.py", line 486, in dispatch
    response = handler(request, *args, **kwargs)
  File "/home/adrian/skyfolk/awards/views.py", line 45, in get
    return Response({'awards': awards, 'user_id': user_id, 'total_points': q.total_points})
AttributeError: 'QuerySet' object has no attribute 'total_points'
2018-06-09 23:17:34,119 ERROR exception 26110 Internal Server Error: /awards/user/26/
Traceback (most recent call last):
  File "/home/adrian/skyfolk/venv/lib/python3.6/site-packages/django/core/handlers/exception.py", line 41, in inner
    response = get_response(request)
  File "/home/adrian/skyfolk/venv/lib/python3.6/site-packages/django/core/handlers/base.py", line 249, in _legacy_get_response
    response = self._get_response(request)
  File "/home/adrian/skyfolk/venv/lib/python3.6/site-packages/django/core/handlers/base.py", line 187, in _get_response
    response = self.process_exception_by_middleware(e, request)
  File "/home/adrian/skyfolk/venv/lib/python3.6/site-packages/channels/handler.py", line 243, in process_exception_by_middleware
    return super(AsgiHandler, self).process_exception_by_middleware(exception, request)
  File "/home/adrian/skyfolk/venv/lib/python3.6/site-packages/django/core/handlers/base.py", line 185, in _get_response
    response = wrapped_callback(request, *callback_args, **callback_kwargs)
  File "/home/adrian/skyfolk/venv/lib/python3.6/site-packages/django/contrib/auth/decorators.py", line 23, in _wrapped_view
    return view_func(request, *args, **kwargs)
  File "/home/adrian/skyfolk/venv/lib/python3.6/site-packages/django/views/decorators/csrf.py", line 58, in wrapped_view
    return view_func(*args, **kwargs)
  File "/home/adrian/skyfolk/venv/lib/python3.6/site-packages/django/views/generic/base.py", line 68, in view
    return self.dispatch(request, *args, **kwargs)
  File "/home/adrian/skyfolk/venv/lib/python3.6/site-packages/rest_framework/views.py", line 489, in dispatch
    response = self.handle_exception(exc)
  File "/home/adrian/skyfolk/venv/lib/python3.6/site-packages/rest_framework/views.py", line 449, in handle_exception
    self.raise_uncaught_exception(exc)
  File "/home/adrian/skyfolk/venv/lib/python3.6/site-packages/rest_framework/views.py", line 486, in dispatch
    response = handler(request, *args, **kwargs)
  File "/home/adrian/skyfolk/awards/views.py", line 46, in get
    return Response({'awards': awards, 'user_id': user_id, 'total_points': q.total_points})
AttributeError: 'QuerySet' object has no attribute 'total_points'
2018-06-09 23:21:28,003 ERROR exception 27293 Internal Server Error: /awards/user/26/
Traceback (most recent call last):
  File "/home/adrian/skyfolk/venv/lib/python3.6/site-packages/django/core/handlers/exception.py", line 41, in inner
    response = get_response(request)
  File "/home/adrian/skyfolk/venv/lib/python3.6/site-packages/django/core/handlers/base.py", line 249, in _legacy_get_response
    response = self._get_response(request)
  File "/home/adrian/skyfolk/venv/lib/python3.6/site-packages/django/core/handlers/base.py", line 187, in _get_response
    response = self.process_exception_by_middleware(e, request)
  File "/home/adrian/skyfolk/venv/lib/python3.6/site-packages/channels/handler.py", line 243, in process_exception_by_middleware
    return super(AsgiHandler, self).process_exception_by_middleware(exception, request)
  File "/home/adrian/skyfolk/venv/lib/python3.6/site-packages/django/core/handlers/base.py", line 185, in _get_response
    response = wrapped_callback(request, *callback_args, **callback_kwargs)
  File "/home/adrian/skyfolk/venv/lib/python3.6/site-packages/django/contrib/auth/decorators.py", line 23, in _wrapped_view
    return view_func(request, *args, **kwargs)
  File "/home/adrian/skyfolk/venv/lib/python3.6/site-packages/django/views/decorators/csrf.py", line 58, in wrapped_view
    return view_func(*args, **kwargs)
  File "/home/adrian/skyfolk/venv/lib/python3.6/site-packages/django/views/generic/base.py", line 68, in view
    return self.dispatch(request, *args, **kwargs)
  File "/home/adrian/skyfolk/venv/lib/python3.6/site-packages/rest_framework/views.py", line 489, in dispatch
    response = self.handle_exception(exc)
  File "/home/adrian/skyfolk/venv/lib/python3.6/site-packages/rest_framework/views.py", line 449, in handle_exception
    self.raise_uncaught_exception(exc)
  File "/home/adrian/skyfolk/venv/lib/python3.6/site-packages/rest_framework/views.py", line 486, in dispatch
    response = handler(request, *args, **kwargs)
  File "/home/adrian/skyfolk/awards/views.py", line 46, in get
    return Response({'awards': awards, 'user_id': user_id, 'total_points': q.points__sum})
AttributeError: 'dict' object has no attribute 'points__sum'
2018-06-09 23:21:28,888 ERROR exception 27293 Internal Server Error: /awards/user/26/
Traceback (most recent call last):
  File "/home/adrian/skyfolk/venv/lib/python3.6/site-packages/django/core/handlers/exception.py", line 41, in inner
    response = get_response(request)
  File "/home/adrian/skyfolk/venv/lib/python3.6/site-packages/django/core/handlers/base.py", line 249, in _legacy_get_response
    response = self._get_response(request)
  File "/home/adrian/skyfolk/venv/lib/python3.6/site-packages/django/core/handlers/base.py", line 187, in _get_response
    response = self.process_exception_by_middleware(e, request)
  File "/home/adrian/skyfolk/venv/lib/python3.6/site-packages/channels/handler.py", line 243, in process_exception_by_middleware
    return super(AsgiHandler, self).process_exception_by_middleware(exception, request)
  File "/home/adrian/skyfolk/venv/lib/python3.6/site-packages/django/core/handlers/base.py", line 185, in _get_response
    response = wrapped_callback(request, *callback_args, **callback_kwargs)
  File "/home/adrian/skyfolk/venv/lib/python3.6/site-packages/django/contrib/auth/decorators.py", line 23, in _wrapped_view
    return view_func(request, *args, **kwargs)
  File "/home/adrian/skyfolk/venv/lib/python3.6/site-packages/django/views/decorators/csrf.py", line 58, in wrapped_view
    return view_func(*args, **kwargs)
  File "/home/adrian/skyfolk/venv/lib/python3.6/site-packages/django/views/generic/base.py", line 68, in view
    return self.dispatch(request, *args, **kwargs)
  File "/home/adrian/skyfolk/venv/lib/python3.6/site-packages/rest_framework/views.py", line 489, in dispatch
    response = self.handle_exception(exc)
  File "/home/adrian/skyfolk/venv/lib/python3.6/site-packages/rest_framework/views.py", line 449, in handle_exception
    self.raise_uncaught_exception(exc)
  File "/home/adrian/skyfolk/venv/lib/python3.6/site-packages/rest_framework/views.py", line 486, in dispatch
    response = handler(request, *args, **kwargs)
  File "/home/adrian/skyfolk/awards/views.py", line 46, in get
    return Response({'awards': awards, 'user_id': user_id, 'total_points': q.points__sum})
AttributeError: 'dict' object has no attribute 'points__sum'
2018-06-09 23:21:55,664 ERROR exception 27688 Internal Server Error: /awards/user/26/
Traceback (most recent call last):
  File "/home/adrian/skyfolk/venv/lib/python3.6/site-packages/django/core/handlers/exception.py", line 41, in inner
    response = get_response(request)
  File "/home/adrian/skyfolk/venv/lib/python3.6/site-packages/django/core/handlers/base.py", line 249, in _legacy_get_response
    response = self._get_response(request)
  File "/home/adrian/skyfolk/venv/lib/python3.6/site-packages/django/core/handlers/base.py", line 187, in _get_response
    response = self.process_exception_by_middleware(e, request)
  File "/home/adrian/skyfolk/venv/lib/python3.6/site-packages/channels/handler.py", line 243, in process_exception_by_middleware
    return super(AsgiHandler, self).process_exception_by_middleware(exception, request)
  File "/home/adrian/skyfolk/venv/lib/python3.6/site-packages/django/core/handlers/base.py", line 185, in _get_response
    response = wrapped_callback(request, *callback_args, **callback_kwargs)
  File "/home/adrian/skyfolk/venv/lib/python3.6/site-packages/django/contrib/auth/decorators.py", line 23, in _wrapped_view
    return view_func(request, *args, **kwargs)
  File "/home/adrian/skyfolk/venv/lib/python3.6/site-packages/django/views/decorators/csrf.py", line 58, in wrapped_view
    return view_func(*args, **kwargs)
  File "/home/adrian/skyfolk/venv/lib/python3.6/site-packages/django/views/generic/base.py", line 68, in view
    return self.dispatch(request, *args, **kwargs)
  File "/home/adrian/skyfolk/venv/lib/python3.6/site-packages/rest_framework/views.py", line 489, in dispatch
    response = self.handle_exception(exc)
  File "/home/adrian/skyfolk/venv/lib/python3.6/site-packages/rest_framework/views.py", line 449, in handle_exception
    self.raise_uncaught_exception(exc)
  File "/home/adrian/skyfolk/venv/lib/python3.6/site-packages/rest_framework/views.py", line 486, in dispatch
    response = handler(request, *args, **kwargs)
  File "/home/adrian/skyfolk/awards/views.py", line 46, in get
    return Response({'awards': awards, 'user_id': user_id, 'total_points': q.total_points})
AttributeError: 'dict' object has no attribute 'total_points'
2018-06-09 23:21:58,797 ERROR exception 27688 Internal Server Error: /awards/user/26/
Traceback (most recent call last):
  File "/home/adrian/skyfolk/venv/lib/python3.6/site-packages/django/core/handlers/exception.py", line 41, in inner
    response = get_response(request)
  File "/home/adrian/skyfolk/venv/lib/python3.6/site-packages/django/core/handlers/base.py", line 249, in _legacy_get_response
    response = self._get_response(request)
  File "/home/adrian/skyfolk/venv/lib/python3.6/site-packages/django/core/handlers/base.py", line 187, in _get_response
    response = self.process_exception_by_middleware(e, request)
  File "/home/adrian/skyfolk/venv/lib/python3.6/site-packages/channels/handler.py", line 243, in process_exception_by_middleware
    return super(AsgiHandler, self).process_exception_by_middleware(exception, request)
  File "/home/adrian/skyfolk/venv/lib/python3.6/site-packages/django/core/handlers/base.py", line 185, in _get_response
    response = wrapped_callback(request, *callback_args, **callback_kwargs)
  File "/home/adrian/skyfolk/venv/lib/python3.6/site-packages/django/contrib/auth/decorators.py", line 23, in _wrapped_view
    return view_func(request, *args, **kwargs)
  File "/home/adrian/skyfolk/venv/lib/python3.6/site-packages/django/views/decorators/csrf.py", line 58, in wrapped_view
    return view_func(*args, **kwargs)
  File "/home/adrian/skyfolk/venv/lib/python3.6/site-packages/django/views/generic/base.py", line 68, in view
    return self.dispatch(request, *args, **kwargs)
  File "/home/adrian/skyfolk/venv/lib/python3.6/site-packages/rest_framework/views.py", line 489, in dispatch
    response = self.handle_exception(exc)
  File "/home/adrian/skyfolk/venv/lib/python3.6/site-packages/rest_framework/views.py", line 449, in handle_exception
    self.raise_uncaught_exception(exc)
  File "/home/adrian/skyfolk/venv/lib/python3.6/site-packages/rest_framework/views.py", line 486, in dispatch
    response = handler(request, *args, **kwargs)
  File "/home/adrian/skyfolk/awards/views.py", line 46, in get
    return Response({'awards': awards, 'user_id': user_id, 'total_points': q.total_points})
AttributeError: 'dict' object has no attribute 'total_points'
2018-06-09 23:22:23,761 ERROR exception 28050 Internal Server Error: /awards/user/26/
Traceback (most recent call last):
  File "/home/adrian/skyfolk/venv/lib/python3.6/site-packages/django/core/handlers/exception.py", line 41, in inner
    response = get_response(request)
  File "/home/adrian/skyfolk/venv/lib/python3.6/site-packages/django/core/handlers/base.py", line 249, in _legacy_get_response
    response = self._get_response(request)
  File "/home/adrian/skyfolk/venv/lib/python3.6/site-packages/django/core/handlers/base.py", line 187, in _get_response
    response = self.process_exception_by_middleware(e, request)
  File "/home/adrian/skyfolk/venv/lib/python3.6/site-packages/channels/handler.py", line 243, in process_exception_by_middleware
    return super(AsgiHandler, self).process_exception_by_middleware(exception, request)
  File "/home/adrian/skyfolk/venv/lib/python3.6/site-packages/django/core/handlers/base.py", line 185, in _get_response
    response = wrapped_callback(request, *callback_args, **callback_kwargs)
  File "/home/adrian/skyfolk/venv/lib/python3.6/site-packages/django/contrib/auth/decorators.py", line 23, in _wrapped_view
    return view_func(request, *args, **kwargs)
  File "/home/adrian/skyfolk/venv/lib/python3.6/site-packages/django/views/decorators/csrf.py", line 58, in wrapped_view
    return view_func(*args, **kwargs)
  File "/home/adrian/skyfolk/venv/lib/python3.6/site-packages/django/views/generic/base.py", line 68, in view
    return self.dispatch(request, *args, **kwargs)
  File "/home/adrian/skyfolk/venv/lib/python3.6/site-packages/rest_framework/views.py", line 489, in dispatch
    response = self.handle_exception(exc)
  File "/home/adrian/skyfolk/venv/lib/python3.6/site-packages/rest_framework/views.py", line 449, in handle_exception
    self.raise_uncaught_exception(exc)
  File "/home/adrian/skyfolk/venv/lib/python3.6/site-packages/rest_framework/views.py", line 486, in dispatch
    response = handler(request, *args, **kwargs)
  File "/home/adrian/skyfolk/awards/views.py", line 46, in get
    return Response({'awards': awards, 'user_id': user_id, 'total_points': q.points__sum})
AttributeError: 'dict' object has no attribute 'points__sum'
2018-06-09 23:22:50,310 ERROR exception 28333 Internal Server Error: /awards/user/26/
Traceback (most recent call last):
  File "/home/adrian/skyfolk/venv/lib/python3.6/site-packages/django/core/handlers/exception.py", line 41, in inner
    response = get_response(request)
  File "/home/adrian/skyfolk/venv/lib/python3.6/site-packages/django/core/handlers/base.py", line 249, in _legacy_get_response
    response = self._get_response(request)
  File "/home/adrian/skyfolk/venv/lib/python3.6/site-packages/django/core/handlers/base.py", line 187, in _get_response
    response = self.process_exception_by_middleware(e, request)
  File "/home/adrian/skyfolk/venv/lib/python3.6/site-packages/channels/handler.py", line 243, in process_exception_by_middleware
    return super(AsgiHandler, self).process_exception_by_middleware(exception, request)
  File "/home/adrian/skyfolk/venv/lib/python3.6/site-packages/django/core/handlers/base.py", line 185, in _get_response
    response = wrapped_callback(request, *callback_args, **callback_kwargs)
  File "/home/adrian/skyfolk/venv/lib/python3.6/site-packages/django/contrib/auth/decorators.py", line 23, in _wrapped_view
    return view_func(request, *args, **kwargs)
  File "/home/adrian/skyfolk/venv/lib/python3.6/site-packages/django/views/decorators/csrf.py", line 58, in wrapped_view
    return view_func(*args, **kwargs)
  File "/home/adrian/skyfolk/venv/lib/python3.6/site-packages/django/views/generic/base.py", line 68, in view
    return self.dispatch(request, *args, **kwargs)
  File "/home/adrian/skyfolk/venv/lib/python3.6/site-packages/rest_framework/views.py", line 489, in dispatch
    response = self.handle_exception(exc)
  File "/home/adrian/skyfolk/venv/lib/python3.6/site-packages/rest_framework/views.py", line 449, in handle_exception
    self.raise_uncaught_exception(exc)
  File "/home/adrian/skyfolk/venv/lib/python3.6/site-packages/rest_framework/views.py", line 486, in dispatch
    response = handler(request, *args, **kwargs)
  File "/home/adrian/skyfolk/awards/views.py", line 46, in get
    return Response({'awards': awards, 'user_id': user_id, 'total_points': q.points__sum})
AttributeError: 'dict' object has no attribute 'points__sum'
2018-06-11 17:40:45,335 ERROR exception 25434 Internal Server Error: /submit_video/
Traceback (most recent call last):
  File "/home/adrian/skyfolk/venv/lib/python3.6/site-packages/django/core/handlers/exception.py", line 41, in inner
    response = get_response(request)
  File "/home/adrian/skyfolk/venv/lib/python3.6/site-packages/django/core/handlers/base.py", line 249, in _legacy_get_response
    response = self._get_response(request)
  File "/home/adrian/skyfolk/venv/lib/python3.6/site-packages/django/core/handlers/base.py", line 187, in _get_response
    response = self.process_exception_by_middleware(e, request)
  File "/home/adrian/skyfolk/venv/lib/python3.6/site-packages/channels/handler.py", line 243, in process_exception_by_middleware
    return super(AsgiHandler, self).process_exception_by_middleware(exception, request)
  File "/home/adrian/skyfolk/venv/lib/python3.6/site-packages/django/core/handlers/base.py", line 185, in _get_response
    response = wrapped_callback(request, *callback_args, **callback_kwargs)
  File "/home/adrian/skyfolk/venv/lib/python3.6/site-packages/django/views/decorators/http.py", line 40, in inner
    return func(request, *args, **kwargs)
  File "/home/adrian/skyfolk/venv/lib/python3.6/site-packages/django/contrib/auth/decorators.py", line 23, in _wrapped_view
    return view_func(request, *args, **kwargs)
  File "/home/adrian/skyfolk/photologue/views.py", line 215, in upload_video
    obj.save()
  File "/home/adrian/skyfolk/photologue/models.py", line 692, in save
    super(Video, self).save(*args, **kwargs)
  File "/home/adrian/skyfolk/venv/lib/python3.6/site-packages/django/db/models/base.py", line 808, in save
    force_update=force_update, update_fields=update_fields)
  File "/home/adrian/skyfolk/venv/lib/python3.6/site-packages/django/db/models/base.py", line 848, in save_base
    update_fields=update_fields, raw=raw, using=using,
  File "/home/adrian/skyfolk/venv/lib/python3.6/site-packages/django/dispatch/dispatcher.py", line 193, in send
    for receiver in self._live_receivers(sender)
  File "/home/adrian/skyfolk/venv/lib/python3.6/site-packages/django/dispatch/dispatcher.py", line 193, in <listcomp>
    for receiver in self._live_receivers(sender)
  File "/home/adrian/skyfolk/photologue/models.py", line 1096, in generate_video_thumb
    print(instance.video.url)
  File "/home/adrian/skyfolk/venv/lib/python3.6/site-packages/django/db/models/fields/files.py", line 69, in url
    self._require_file()
  File "/home/adrian/skyfolk/venv/lib/python3.6/site-packages/django/db/models/fields/files.py", line 46, in _require_file
    raise ValueError("The '%s' attribute has no file associated with it." % self.field.name)
ValueError: The 'video' attribute has no file associated with it.
2018-06-11 17:49:02,416 ERROR exception 28975 Internal Server Error: /multimedia/adrian/
Traceback (most recent call last):
  File "/home/adrian/skyfolk/venv/lib/python3.6/site-packages/django/template/base.py", line 882, in _resolve_lookup
    current = current[bit]
TypeError: 'FieldFile' object is not subscriptable

During handling of the above exception, another exception occurred:

Traceback (most recent call last):
  File "/home/adrian/skyfolk/venv/lib/python3.6/site-packages/django/core/handlers/exception.py", line 41, in inner
    response = get_response(request)
  File "/home/adrian/skyfolk/venv/lib/python3.6/site-packages/django/core/handlers/base.py", line 249, in _legacy_get_response
    response = self._get_response(request)
  File "/home/adrian/skyfolk/venv/lib/python3.6/site-packages/django/core/handlers/base.py", line 217, in _get_response
    response = self.process_exception_by_middleware(e, request)
  File "/home/adrian/skyfolk/venv/lib/python3.6/site-packages/channels/handler.py", line 243, in process_exception_by_middleware
    return super(AsgiHandler, self).process_exception_by_middleware(exception, request)
  File "/home/adrian/skyfolk/venv/lib/python3.6/site-packages/django/core/handlers/base.py", line 215, in _get_response
    response = response.render()
  File "/home/adrian/skyfolk/venv/lib/python3.6/site-packages/django/template/response.py", line 107, in render
    self.content = self.rendered_content
  File "/home/adrian/skyfolk/venv/lib/python3.6/site-packages/django/template/response.py", line 84, in rendered_content
    content = template.render(context, self._request)
  File "/home/adrian/skyfolk/venv/lib/python3.6/site-packages/django/template/backends/django.py", line 66, in render
    return self.template.render(context)
  File "/home/adrian/skyfolk/venv/lib/python3.6/site-packages/django/template/base.py", line 207, in render
    return self._render(context)
  File "/home/adrian/skyfolk/venv/lib/python3.6/site-packages/django/template/base.py", line 199, in _render
    return self.nodelist.render(context)
  File "/home/adrian/skyfolk/venv/lib/python3.6/site-packages/django/template/base.py", line 990, in render
    bit = node.render_annotated(context)
  File "/home/adrian/skyfolk/venv/lib/python3.6/site-packages/django/template/base.py", line 957, in render_annotated
    return self.render(context)
  File "/home/adrian/skyfolk/venv/lib/python3.6/site-packages/django/template/loader_tags.py", line 177, in render
    return compiled_parent._render(context)
  File "/home/adrian/skyfolk/venv/lib/python3.6/site-packages/django/template/base.py", line 199, in _render
    return self.nodelist.render(context)
  File "/home/adrian/skyfolk/venv/lib/python3.6/site-packages/django/template/base.py", line 990, in render
    bit = node.render_annotated(context)
  File "/home/adrian/skyfolk/venv/lib/python3.6/site-packages/django/template/base.py", line 957, in render_annotated
    return self.render(context)
  File "/home/adrian/skyfolk/venv/lib/python3.6/site-packages/django/template/loader_tags.py", line 72, in render
    result = block.nodelist.render(context)
  File "/home/adrian/skyfolk/venv/lib/python3.6/site-packages/django/template/base.py", line 990, in render
    bit = node.render_annotated(context)
  File "/home/adrian/skyfolk/venv/lib/python3.6/site-packages/django/template/base.py", line 957, in render_annotated
    return self.render(context)
  File "/home/adrian/skyfolk/venv/lib/python3.6/site-packages/django/template/defaulttags.py", line 322, in render
    return nodelist.render(context)
  File "/home/adrian/skyfolk/venv/lib/python3.6/site-packages/django/template/base.py", line 990, in render
    bit = node.render_annotated(context)
  File "/home/adrian/skyfolk/venv/lib/python3.6/site-packages/django/template/base.py", line 957, in render_annotated
    return self.render(context)
  File "/home/adrian/skyfolk/venv/lib/python3.6/site-packages/django/template/loader_tags.py", line 216, in render
    return template.render(context)
  File "/home/adrian/skyfolk/venv/lib/python3.6/site-packages/django/template/base.py", line 209, in render
    return self._render(context)
  File "/home/adrian/skyfolk/venv/lib/python3.6/site-packages/django/template/base.py", line 199, in _render
    return self.nodelist.render(context)
  File "/home/adrian/skyfolk/venv/lib/python3.6/site-packages/django/template/base.py", line 990, in render
    bit = node.render_annotated(context)
  File "/home/adrian/skyfolk/venv/lib/python3.6/site-packages/django/template/base.py", line 957, in render_annotated
    return self.render(context)
  File "/home/adrian/skyfolk/venv/lib/python3.6/site-packages/django/template/defaulttags.py", line 216, in render
    nodelist.append(node.render_annotated(context))
  File "/home/adrian/skyfolk/venv/lib/python3.6/site-packages/django/template/base.py", line 957, in render_annotated
    return self.render(context)
  File "/home/adrian/skyfolk/venv/lib/python3.6/site-packages/django/template/defaulttags.py", line 322, in render
    return nodelist.render(context)
  File "/home/adrian/skyfolk/venv/lib/python3.6/site-packages/django/template/base.py", line 990, in render
    bit = node.render_annotated(context)
  File "/home/adrian/skyfolk/venv/lib/python3.6/site-packages/django/template/base.py", line 957, in render_annotated
    return self.render(context)
  File "/home/adrian/skyfolk/venv/lib/python3.6/site-packages/django/template/defaulttags.py", line 322, in render
    return nodelist.render(context)
  File "/home/adrian/skyfolk/venv/lib/python3.6/site-packages/django/template/base.py", line 990, in render
    bit = node.render_annotated(context)
  File "/home/adrian/skyfolk/venv/lib/python3.6/site-packages/django/template/base.py", line 957, in render_annotated
    return self.render(context)
  File "/home/adrian/skyfolk/venv/lib/python3.6/site-packages/django/template/base.py", line 1040, in render
    output = self.filter_expression.resolve(context)
  File "/home/adrian/skyfolk/venv/lib/python3.6/site-packages/django/template/base.py", line 708, in resolve
    obj = self.var.resolve(context)
  File "/home/adrian/skyfolk/venv/lib/python3.6/site-packages/django/template/base.py", line 849, in resolve
    value = self._resolve_lookup(context)
  File "/home/adrian/skyfolk/venv/lib/python3.6/site-packages/django/template/base.py", line 890, in _resolve_lookup
    current = getattr(current, bit)
  File "/home/adrian/skyfolk/venv/lib/python3.6/site-packages/django/db/models/fields/files.py", line 69, in url
    self._require_file()
  File "/home/adrian/skyfolk/venv/lib/python3.6/site-packages/django/db/models/fields/files.py", line 46, in _require_file
    raise ValueError("The '%s' attribute has no file associated with it." % self.field.name)
ValueError: The 'video' attribute has no file associated with it.
2018-06-11 17:49:04,896 ERROR exception 28975 Internal Server Error: /multimedia/adrian/
Traceback (most recent call last):
  File "/home/adrian/skyfolk/venv/lib/python3.6/site-packages/django/template/base.py", line 882, in _resolve_lookup
    current = current[bit]
TypeError: 'FieldFile' object is not subscriptable

During handling of the above exception, another exception occurred:

Traceback (most recent call last):
  File "/home/adrian/skyfolk/venv/lib/python3.6/site-packages/django/core/handlers/exception.py", line 41, in inner
    response = get_response(request)
  File "/home/adrian/skyfolk/venv/lib/python3.6/site-packages/django/core/handlers/base.py", line 249, in _legacy_get_response
    response = self._get_response(request)
  File "/home/adrian/skyfolk/venv/lib/python3.6/site-packages/django/core/handlers/base.py", line 217, in _get_response
    response = self.process_exception_by_middleware(e, request)
  File "/home/adrian/skyfolk/venv/lib/python3.6/site-packages/channels/handler.py", line 243, in process_exception_by_middleware
    return super(AsgiHandler, self).process_exception_by_middleware(exception, request)
  File "/home/adrian/skyfolk/venv/lib/python3.6/site-packages/django/core/handlers/base.py", line 215, in _get_response
    response = response.render()
  File "/home/adrian/skyfolk/venv/lib/python3.6/site-packages/django/template/response.py", line 107, in render
    self.content = self.rendered_content
  File "/home/adrian/skyfolk/venv/lib/python3.6/site-packages/django/template/response.py", line 84, in rendered_content
    content = template.render(context, self._request)
  File "/home/adrian/skyfolk/venv/lib/python3.6/site-packages/django/template/backends/django.py", line 66, in render
    return self.template.render(context)
  File "/home/adrian/skyfolk/venv/lib/python3.6/site-packages/django/template/base.py", line 207, in render
    return self._render(context)
  File "/home/adrian/skyfolk/venv/lib/python3.6/site-packages/django/template/base.py", line 199, in _render
    return self.nodelist.render(context)
  File "/home/adrian/skyfolk/venv/lib/python3.6/site-packages/django/template/base.py", line 990, in render
    bit = node.render_annotated(context)
  File "/home/adrian/skyfolk/venv/lib/python3.6/site-packages/django/template/base.py", line 957, in render_annotated
    return self.render(context)
  File "/home/adrian/skyfolk/venv/lib/python3.6/site-packages/django/template/loader_tags.py", line 177, in render
    return compiled_parent._render(context)
  File "/home/adrian/skyfolk/venv/lib/python3.6/site-packages/django/template/base.py", line 199, in _render
    return self.nodelist.render(context)
  File "/home/adrian/skyfolk/venv/lib/python3.6/site-packages/django/template/base.py", line 990, in render
    bit = node.render_annotated(context)
  File "/home/adrian/skyfolk/venv/lib/python3.6/site-packages/django/template/base.py", line 957, in render_annotated
    return self.render(context)
  File "/home/adrian/skyfolk/venv/lib/python3.6/site-packages/django/template/loader_tags.py", line 72, in render
    result = block.nodelist.render(context)
  File "/home/adrian/skyfolk/venv/lib/python3.6/site-packages/django/template/base.py", line 990, in render
    bit = node.render_annotated(context)
  File "/home/adrian/skyfolk/venv/lib/python3.6/site-packages/django/template/base.py", line 957, in render_annotated
    return self.render(context)
  File "/home/adrian/skyfolk/venv/lib/python3.6/site-packages/django/template/defaulttags.py", line 322, in render
    return nodelist.render(context)
  File "/home/adrian/skyfolk/venv/lib/python3.6/site-packages/django/template/base.py", line 990, in render
    bit = node.render_annotated(context)
  File "/home/adrian/skyfolk/venv/lib/python3.6/site-packages/django/template/base.py", line 957, in render_annotated
    return self.render(context)
  File "/home/adrian/skyfolk/venv/lib/python3.6/site-packages/django/template/loader_tags.py", line 216, in render
    return template.render(context)
  File "/home/adrian/skyfolk/venv/lib/python3.6/site-packages/django/template/base.py", line 209, in render
    return self._render(context)
  File "/home/adrian/skyfolk/venv/lib/python3.6/site-packages/django/template/base.py", line 199, in _render
    return self.nodelist.render(context)
  File "/home/adrian/skyfolk/venv/lib/python3.6/site-packages/django/template/base.py", line 990, in render
    bit = node.render_annotated(context)
  File "/home/adrian/skyfolk/venv/lib/python3.6/site-packages/django/template/base.py", line 957, in render_annotated
    return self.render(context)
  File "/home/adrian/skyfolk/venv/lib/python3.6/site-packages/django/template/defaulttags.py", line 216, in render
    nodelist.append(node.render_annotated(context))
  File "/home/adrian/skyfolk/venv/lib/python3.6/site-packages/django/template/base.py", line 957, in render_annotated
    return self.render(context)
  File "/home/adrian/skyfolk/venv/lib/python3.6/site-packages/django/template/defaulttags.py", line 322, in render
    return nodelist.render(context)
  File "/home/adrian/skyfolk/venv/lib/python3.6/site-packages/django/template/base.py", line 990, in render
    bit = node.render_annotated(context)
  File "/home/adrian/skyfolk/venv/lib/python3.6/site-packages/django/template/base.py", line 957, in render_annotated
    return self.render(context)
  File "/home/adrian/skyfolk/venv/lib/python3.6/site-packages/django/template/defaulttags.py", line 322, in render
    return nodelist.render(context)
  File "/home/adrian/skyfolk/venv/lib/python3.6/site-packages/django/template/base.py", line 990, in render
    bit = node.render_annotated(context)
  File "/home/adrian/skyfolk/venv/lib/python3.6/site-packages/django/template/base.py", line 957, in render_annotated
    return self.render(context)
  File "/home/adrian/skyfolk/venv/lib/python3.6/site-packages/django/template/base.py", line 1040, in render
    output = self.filter_expression.resolve(context)
  File "/home/adrian/skyfolk/venv/lib/python3.6/site-packages/django/template/base.py", line 708, in resolve
    obj = self.var.resolve(context)
  File "/home/adrian/skyfolk/venv/lib/python3.6/site-packages/django/template/base.py", line 849, in resolve
    value = self._resolve_lookup(context)
  File "/home/adrian/skyfolk/venv/lib/python3.6/site-packages/django/template/base.py", line 890, in _resolve_lookup
    current = getattr(current, bit)
  File "/home/adrian/skyfolk/venv/lib/python3.6/site-packages/django/db/models/fields/files.py", line 69, in url
    self._require_file()
  File "/home/adrian/skyfolk/venv/lib/python3.6/site-packages/django/db/models/fields/files.py", line 46, in _require_file
    raise ValueError("The '%s' attribute has no file associated with it." % self.field.name)
ValueError: The 'video' attribute has no file associated with it.
