2018-01-23 22:20:21,867 ERROR exception 22546 Internal Server Error: /submit_photo/
Traceback (most recent call last):
  File "/home/adrian/skyfolk/venv/lib/python3.6/site-packages/django/core/handlers/exception.py", line 41, in inner
    response = get_response(request)
  File "/home/adrian/skyfolk/venv/lib/python3.6/site-packages/django/core/handlers/base.py", line 249, in _legacy_get_response
    response = self._get_response(request)
  File "/home/adrian/skyfolk/venv/lib/python3.6/site-packages/django/core/handlers/base.py", line 187, in _get_response
    response = self.process_exception_by_middleware(e, request)
  File "/home/adrian/skyfolk/venv/lib/python3.6/site-packages/channels/handler.py", line 243, in process_exception_by_middleware
    return super(AsgiHandler, self).process_exception_by_middleware(exception, request)
  File "/home/adrian/skyfolk/venv/lib/python3.6/site-packages/django/core/handlers/base.py", line 185, in _get_response
    response = wrapped_callback(request, *callback_args, **callback_kwargs)
  File "/home/adrian/skyfolk/venv/lib/python3.6/site-packages/django/views/decorators/http.py", line 40, in inner
    return func(request, *args, **kwargs)
  File "/home/adrian/skyfolk/venv/lib/python3.6/site-packages/django/contrib/auth/decorators.py", line 23, in _wrapped_view
    return view_func(request, *args, **kwargs)
  File "/home/adrian/skyfolk/photologue/views.py", line 179, in upload_photo
    obj.save()
  File "/home/adrian/skyfolk/photologue/models.py", line 497, in save
    self.slug = uuslug(str(self.owner_id) + self.title, instance=self)
  File "/home/adrian/skyfolk/venv/lib/python3.6/site-packages/uuslug/uuslug.py", line 44, in uuslug
    save_order=save_order, stopwords=stopwords)
  File "/home/adrian/skyfolk/venv/lib/python3.6/site-packages/uuslug/uuslug.py", line 19, in slugify
    word_boundary, separator, save_order, stopwords))
TypeError: __call__() takes 2 positional arguments but 10 were given
2018-01-23 22:20:35,259 ERROR exception 22546 Internal Server Error: /submit_photo/
Traceback (most recent call last):
  File "/home/adrian/skyfolk/venv/lib/python3.6/site-packages/django/core/handlers/exception.py", line 41, in inner
    response = get_response(request)
  File "/home/adrian/skyfolk/venv/lib/python3.6/site-packages/django/core/handlers/base.py", line 249, in _legacy_get_response
    response = self._get_response(request)
  File "/home/adrian/skyfolk/venv/lib/python3.6/site-packages/django/core/handlers/base.py", line 187, in _get_response
    response = self.process_exception_by_middleware(e, request)
  File "/home/adrian/skyfolk/venv/lib/python3.6/site-packages/channels/handler.py", line 243, in process_exception_by_middleware
    return super(AsgiHandler, self).process_exception_by_middleware(exception, request)
  File "/home/adrian/skyfolk/venv/lib/python3.6/site-packages/django/core/handlers/base.py", line 185, in _get_response
    response = wrapped_callback(request, *callback_args, **callback_kwargs)
  File "/home/adrian/skyfolk/venv/lib/python3.6/site-packages/django/views/decorators/http.py", line 40, in inner
    return func(request, *args, **kwargs)
  File "/home/adrian/skyfolk/venv/lib/python3.6/site-packages/django/contrib/auth/decorators.py", line 23, in _wrapped_view
    return view_func(request, *args, **kwargs)
  File "/home/adrian/skyfolk/photologue/views.py", line 179, in upload_photo
    obj.save()
  File "/home/adrian/skyfolk/photologue/models.py", line 497, in save
    self.slug = uuslug(str(self.owner_id) + self.title, instance=self)
  File "/home/adrian/skyfolk/venv/lib/python3.6/site-packages/uuslug/uuslug.py", line 44, in uuslug
    save_order=save_order, stopwords=stopwords)
  File "/home/adrian/skyfolk/venv/lib/python3.6/site-packages/uuslug/uuslug.py", line 19, in slugify
    word_boundary, separator, save_order, stopwords))
TypeError: __call__() takes 2 positional arguments but 10 were given
2018-01-23 22:22:52,068 ERROR exception 24359 Internal Server Error: /submit_photo/
Traceback (most recent call last):
  File "/home/adrian/skyfolk/venv/lib/python3.6/site-packages/django/core/handlers/exception.py", line 41, in inner
    response = get_response(request)
  File "/home/adrian/skyfolk/venv/lib/python3.6/site-packages/django/core/handlers/base.py", line 249, in _legacy_get_response
    response = self._get_response(request)
  File "/home/adrian/skyfolk/venv/lib/python3.6/site-packages/django/core/handlers/base.py", line 187, in _get_response
    response = self.process_exception_by_middleware(e, request)
  File "/home/adrian/skyfolk/venv/lib/python3.6/site-packages/channels/handler.py", line 243, in process_exception_by_middleware
    return super(AsgiHandler, self).process_exception_by_middleware(exception, request)
  File "/home/adrian/skyfolk/venv/lib/python3.6/site-packages/django/core/handlers/base.py", line 185, in _get_response
    response = wrapped_callback(request, *callback_args, **callback_kwargs)
  File "/home/adrian/skyfolk/venv/lib/python3.6/site-packages/django/views/decorators/http.py", line 40, in inner
    return func(request, *args, **kwargs)
  File "/home/adrian/skyfolk/venv/lib/python3.6/site-packages/django/contrib/auth/decorators.py", line 23, in _wrapped_view
    return view_func(request, *args, **kwargs)
  File "/home/adrian/skyfolk/photologue/views.py", line 179, in upload_photo
    obj.save()
  File "/home/adrian/skyfolk/photologue/models.py", line 497, in save
    self.slug = uuslug(str(self.owner_id) + self.title, instance=self, max_length=250)
  File "/home/adrian/skyfolk/venv/lib/python3.6/site-packages/uuslug/uuslug.py", line 44, in uuslug
    save_order=save_order, stopwords=stopwords)
  File "/home/adrian/skyfolk/venv/lib/python3.6/site-packages/uuslug/uuslug.py", line 19, in slugify
    word_boundary, separator, save_order, stopwords))
TypeError: __call__() takes 2 positional arguments but 10 were given
2018-01-23 22:23:02,537 ERROR exception 24527 Internal Server Error: /submit_photo/
Traceback (most recent call last):
  File "/home/adrian/skyfolk/venv/lib/python3.6/site-packages/django/core/handlers/exception.py", line 41, in inner
    response = get_response(request)
  File "/home/adrian/skyfolk/venv/lib/python3.6/site-packages/django/core/handlers/base.py", line 249, in _legacy_get_response
    response = self._get_response(request)
  File "/home/adrian/skyfolk/venv/lib/python3.6/site-packages/django/core/handlers/base.py", line 187, in _get_response
    response = self.process_exception_by_middleware(e, request)
  File "/home/adrian/skyfolk/venv/lib/python3.6/site-packages/channels/handler.py", line 243, in process_exception_by_middleware
    return super(AsgiHandler, self).process_exception_by_middleware(exception, request)
  File "/home/adrian/skyfolk/venv/lib/python3.6/site-packages/django/core/handlers/base.py", line 185, in _get_response
    response = wrapped_callback(request, *callback_args, **callback_kwargs)
  File "/home/adrian/skyfolk/venv/lib/python3.6/site-packages/django/views/decorators/http.py", line 40, in inner
    return func(request, *args, **kwargs)
  File "/home/adrian/skyfolk/venv/lib/python3.6/site-packages/django/contrib/auth/decorators.py", line 23, in _wrapped_view
    return view_func(request, *args, **kwargs)
  File "/home/adrian/skyfolk/photologue/views.py", line 179, in upload_photo
    obj.save()
  File "/home/adrian/skyfolk/photologue/models.py", line 497, in save
    self.slug = uuslug(self.title, instance=self, max_length=250)
  File "/home/adrian/skyfolk/venv/lib/python3.6/site-packages/uuslug/uuslug.py", line 44, in uuslug
    save_order=save_order, stopwords=stopwords)
  File "/home/adrian/skyfolk/venv/lib/python3.6/site-packages/uuslug/uuslug.py", line 19, in slugify
    word_boundary, separator, save_order, stopwords))
TypeError: __call__() takes 2 positional arguments but 10 were given
2018-01-23 22:27:06,990 ERROR exception 25126 Internal Server Error: /submit_photo/
Traceback (most recent call last):
  File "/home/adrian/skyfolk/venv/lib/python3.6/site-packages/django/core/handlers/exception.py", line 41, in inner
    response = get_response(request)
  File "/home/adrian/skyfolk/venv/lib/python3.6/site-packages/django/core/handlers/base.py", line 249, in _legacy_get_response
    response = self._get_response(request)
  File "/home/adrian/skyfolk/venv/lib/python3.6/site-packages/django/core/handlers/base.py", line 187, in _get_response
    response = self.process_exception_by_middleware(e, request)
  File "/home/adrian/skyfolk/venv/lib/python3.6/site-packages/channels/handler.py", line 243, in process_exception_by_middleware
    return super(AsgiHandler, self).process_exception_by_middleware(exception, request)
  File "/home/adrian/skyfolk/venv/lib/python3.6/site-packages/django/core/handlers/base.py", line 185, in _get_response
    response = wrapped_callback(request, *callback_args, **callback_kwargs)
  File "/home/adrian/skyfolk/venv/lib/python3.6/site-packages/django/views/decorators/http.py", line 40, in inner
    return func(request, *args, **kwargs)
  File "/home/adrian/skyfolk/venv/lib/python3.6/site-packages/django/contrib/auth/decorators.py", line 23, in _wrapped_view
    return view_func(request, *args, **kwargs)
  File "/home/adrian/skyfolk/photologue/views.py", line 179, in upload_photo
    obj.save()
  File "/home/adrian/skyfolk/photologue/models.py", line 497, in save
    self.slug = uuslug(str(self.owner_id) + self.title, instance=self)
  File "/home/adrian/skyfolk/venv/lib/python3.6/site-packages/uuslug/uuslug.py", line 44, in uuslug
    save_order=save_order, stopwords=stopwords)
  File "/home/adrian/skyfolk/venv/lib/python3.6/site-packages/uuslug/uuslug.py", line 19, in slugify
    word_boundary, separator, save_order, stopwords))
TypeError: __call__() takes 2 positional arguments but 10 were given
2018-01-23 22:28:06,722 ERROR exception 25126 Internal Server Error: /submit_photo/
Traceback (most recent call last):
  File "/home/adrian/skyfolk/venv/lib/python3.6/site-packages/django/core/handlers/exception.py", line 41, in inner
    response = get_response(request)
  File "/home/adrian/skyfolk/venv/lib/python3.6/site-packages/django/core/handlers/base.py", line 249, in _legacy_get_response
    response = self._get_response(request)
  File "/home/adrian/skyfolk/venv/lib/python3.6/site-packages/django/core/handlers/base.py", line 187, in _get_response
    response = self.process_exception_by_middleware(e, request)
  File "/home/adrian/skyfolk/venv/lib/python3.6/site-packages/channels/handler.py", line 243, in process_exception_by_middleware
    return super(AsgiHandler, self).process_exception_by_middleware(exception, request)
  File "/home/adrian/skyfolk/venv/lib/python3.6/site-packages/django/core/handlers/base.py", line 185, in _get_response
    response = wrapped_callback(request, *callback_args, **callback_kwargs)
  File "/home/adrian/skyfolk/venv/lib/python3.6/site-packages/django/views/decorators/http.py", line 40, in inner
    return func(request, *args, **kwargs)
  File "/home/adrian/skyfolk/venv/lib/python3.6/site-packages/django/contrib/auth/decorators.py", line 23, in _wrapped_view
    return view_func(request, *args, **kwargs)
  File "/home/adrian/skyfolk/photologue/views.py", line 179, in upload_photo
    obj.save()
  File "/home/adrian/skyfolk/photologue/models.py", line 497, in save
    self.slug = uuslug(str(self.owner_id) + self.title, instance=self)
  File "/home/adrian/skyfolk/venv/lib/python3.6/site-packages/uuslug/uuslug.py", line 44, in uuslug
    save_order=save_order, stopwords=stopwords)
  File "/home/adrian/skyfolk/venv/lib/python3.6/site-packages/uuslug/uuslug.py", line 19, in slugify
    word_boundary, separator, save_order, stopwords))
TypeError: __call__() takes 2 positional arguments but 10 were given
2018-01-23 22:34:58,585 ERROR exception 27315 Internal Server Error: /submit_photo/
Traceback (most recent call last):
  File "/home/adrian/skyfolk/venv/lib/python3.6/site-packages/django/core/handlers/exception.py", line 41, in inner
    response = get_response(request)
  File "/home/adrian/skyfolk/venv/lib/python3.6/site-packages/django/core/handlers/base.py", line 249, in _legacy_get_response
    response = self._get_response(request)
  File "/home/adrian/skyfolk/venv/lib/python3.6/site-packages/django/core/handlers/base.py", line 187, in _get_response
    response = self.process_exception_by_middleware(e, request)
  File "/home/adrian/skyfolk/venv/lib/python3.6/site-packages/channels/handler.py", line 243, in process_exception_by_middleware
    return super(AsgiHandler, self).process_exception_by_middleware(exception, request)
  File "/home/adrian/skyfolk/venv/lib/python3.6/site-packages/django/core/handlers/base.py", line 185, in _get_response
    response = wrapped_callback(request, *callback_args, **callback_kwargs)
  File "/home/adrian/skyfolk/venv/lib/python3.6/site-packages/django/views/decorators/http.py", line 40, in inner
    return func(request, *args, **kwargs)
  File "/home/adrian/skyfolk/venv/lib/python3.6/site-packages/django/contrib/auth/decorators.py", line 23, in _wrapped_view
    return view_func(request, *args, **kwargs)
  File "/home/adrian/skyfolk/photologue/views.py", line 179, in upload_photo
    obj.save()
  File "/home/adrian/skyfolk/photologue/models.py", line 497, in save
    print(uuslug(self.title, instance=self))
  File "/home/adrian/skyfolk/venv/lib/python3.6/site-packages/uuslug/uuslug.py", line 44, in uuslug
    save_order=save_order, stopwords=stopwords)
  File "/home/adrian/skyfolk/venv/lib/python3.6/site-packages/uuslug/uuslug.py", line 19, in slugify
    word_boundary, separator, save_order, stopwords))
TypeError: __call__() takes 2 positional arguments but 10 were given
2018-01-23 22:38:18,017 ERROR exception 28058 Internal Server Error: /submit_photo/
Traceback (most recent call last):
  File "/home/adrian/skyfolk/venv/lib/python3.6/site-packages/django/core/handlers/exception.py", line 41, in inner
    response = get_response(request)
  File "/home/adrian/skyfolk/venv/lib/python3.6/site-packages/django/core/handlers/base.py", line 249, in _legacy_get_response
    response = self._get_response(request)
  File "/home/adrian/skyfolk/venv/lib/python3.6/site-packages/django/core/handlers/base.py", line 187, in _get_response
    response = self.process_exception_by_middleware(e, request)
  File "/home/adrian/skyfolk/venv/lib/python3.6/site-packages/channels/handler.py", line 243, in process_exception_by_middleware
    return super(AsgiHandler, self).process_exception_by_middleware(exception, request)
  File "/home/adrian/skyfolk/venv/lib/python3.6/site-packages/django/core/handlers/base.py", line 185, in _get_response
    response = wrapped_callback(request, *callback_args, **callback_kwargs)
  File "/home/adrian/skyfolk/venv/lib/python3.6/site-packages/django/views/decorators/http.py", line 40, in inner
    return func(request, *args, **kwargs)
  File "/home/adrian/skyfolk/venv/lib/python3.6/site-packages/django/contrib/auth/decorators.py", line 23, in _wrapped_view
    return view_func(request, *args, **kwargs)
  File "/home/adrian/skyfolk/photologue/views.py", line 179, in upload_photo
    obj.save()
  File "/home/adrian/skyfolk/photologue/models.py", line 497, in save
    self.slug = uuslug(str(self.owner_id) + self.title, self)
  File "/home/adrian/skyfolk/venv/lib/python3.6/site-packages/uuslug/uuslug.py", line 44, in uuslug
    save_order=save_order, stopwords=stopwords)
  File "/home/adrian/skyfolk/venv/lib/python3.6/site-packages/uuslug/uuslug.py", line 19, in slugify
    word_boundary, separator, save_order, stopwords))
TypeError: __call__() takes 2 positional arguments but 10 were given
2018-01-23 22:41:27,180 ERROR exception 29171 Internal Server Error: /submit_photo/
Traceback (most recent call last):
  File "/home/adrian/skyfolk/venv/lib/python3.6/site-packages/django/core/handlers/exception.py", line 41, in inner
    response = get_response(request)
  File "/home/adrian/skyfolk/venv/lib/python3.6/site-packages/django/core/handlers/base.py", line 249, in _legacy_get_response
    response = self._get_response(request)
  File "/home/adrian/skyfolk/venv/lib/python3.6/site-packages/django/core/handlers/base.py", line 187, in _get_response
    response = self.process_exception_by_middleware(e, request)
  File "/home/adrian/skyfolk/venv/lib/python3.6/site-packages/channels/handler.py", line 243, in process_exception_by_middleware
    return super(AsgiHandler, self).process_exception_by_middleware(exception, request)
  File "/home/adrian/skyfolk/venv/lib/python3.6/site-packages/django/core/handlers/base.py", line 185, in _get_response
    response = wrapped_callback(request, *callback_args, **callback_kwargs)
  File "/home/adrian/skyfolk/venv/lib/python3.6/site-packages/django/views/decorators/http.py", line 40, in inner
    return func(request, *args, **kwargs)
  File "/home/adrian/skyfolk/venv/lib/python3.6/site-packages/django/contrib/auth/decorators.py", line 23, in _wrapped_view
    return view_func(request, *args, **kwargs)
  File "/home/adrian/skyfolk/photologue/views.py", line 179, in upload_photo
    obj.save()
  File "/home/adrian/skyfolk/photologue/models.py", line 496, in save
    self.slug = uuslug(str(self.owner_id) + self.title, self)
  File "/home/adrian/skyfolk/venv/lib/python3.6/site-packages/uuslug/uuslug.py", line 44, in uuslug
    save_order=save_order, stopwords=stopwords)
  File "/home/adrian/skyfolk/venv/lib/python3.6/site-packages/uuslug/uuslug.py", line 19, in slugify
    word_boundary, separator, save_order, stopwords))
TypeError: __call__() takes 2 positional arguments but 10 were given
2018-01-23 22:51:24,761 ERROR exception 3579 Internal Server Error: /accounts/login/
Traceback (most recent call last):
  File "/home/adrian/skyfolk/venv/lib/python3.5/site-packages/django/core/handlers/exception.py", line 41, in inner
    response = get_response(request)
  File "/home/adrian/skyfolk/venv/lib/python3.5/site-packages/django/core/handlers/base.py", line 249, in _legacy_get_response
    response = self._get_response(request)
  File "/home/adrian/skyfolk/venv/lib/python3.5/site-packages/django/core/handlers/base.py", line 187, in _get_response
    response = self.process_exception_by_middleware(e, request)
  File "/home/adrian/skyfolk/venv/lib/python3.5/site-packages/channels/handler.py", line 243, in process_exception_by_middleware
    return super(AsgiHandler, self).process_exception_by_middleware(exception, request)
  File "/home/adrian/skyfolk/venv/lib/python3.5/site-packages/django/core/handlers/base.py", line 185, in _get_response
    response = wrapped_callback(request, *callback_args, **callback_kwargs)
  File "/home/adrian/skyfolk/venv/lib/python3.5/site-packages/django/views/generic/base.py", line 68, in view
    return self.dispatch(request, *args, **kwargs)
  File "/home/adrian/skyfolk/venv/lib/python3.5/site-packages/django/utils/decorators.py", line 67, in _wrapper
    return bound_func(*args, **kwargs)
  File "/home/adrian/skyfolk/venv/lib/python3.5/site-packages/django/views/decorators/debug.py", line 76, in sensitive_post_parameters_wrapper
    return view(request, *args, **kwargs)
  File "/home/adrian/skyfolk/venv/lib/python3.5/site-packages/django/utils/decorators.py", line 63, in bound_func
    return func.__get__(self, type(self))(*args2, **kwargs2)
  File "/home/adrian/skyfolk/venv/lib/python3.5/site-packages/allauth/account/views.py", line 133, in dispatch
    return super(LoginView, self).dispatch(request, *args, **kwargs)
  File "/home/adrian/skyfolk/venv/lib/python3.5/site-packages/allauth/account/views.py", line 79, in dispatch
    **kwargs)
  File "/home/adrian/skyfolk/venv/lib/python3.5/site-packages/django/views/generic/base.py", line 88, in dispatch
    return handler(request, *args, **kwargs)
  File "/home/adrian/skyfolk/venv/lib/python3.5/site-packages/allauth/account/views.py", line 102, in post
    response = self.form_valid(form)
  File "/home/adrian/skyfolk/venv/lib/python3.5/site-packages/allauth/account/views.py", line 146, in form_valid
    return form.login(self.request, redirect_url=success_url)
  File "/home/adrian/skyfolk/user_profile/forms.py", line 33, in login
    user_profile = NodeProfile.nodes.get(user_id=self.user.id)
  File "/home/adrian/skyfolk/venv/lib/python3.5/site-packages/neomodel/match.py", line 507, in get
    result = self.query_cls(self).build_ast()._execute()
  File "/home/adrian/skyfolk/venv/lib/python3.5/site-packages/neomodel/match.py", line 411, in _execute
    results, _ = db.cypher_query(query, self._query_params)
  File "/home/adrian/skyfolk/venv/lib/python3.5/site-packages/neomodel/util.py", line 27, in wrapper
    self.set_connection(config.DATABASE_URL)
  File "/home/adrian/skyfolk/venv/lib/python3.5/site-packages/neomodel/util.py", line 61, in set_connection
    max_pool_size=config.MAX_POOL_SIZE)
  File "/home/adrian/skyfolk/venv/lib/python3.5/site-packages/neo4j/v1/api.py", line 112, in driver
    return driver_class(uri, **config)
  File "/home/adrian/skyfolk/venv/lib/python3.5/site-packages/neo4j/v1/direct.py", line 63, in __init__
    pool.acquire()
  File "/home/adrian/skyfolk/venv/lib/python3.5/site-packages/neo4j/v1/direct.py", line 44, in acquire
    raise ServiceUnavailable("Cannot acquire connection to {!r}".format(self.address))
neo4j.exceptions.ServiceUnavailable: Cannot acquire connection to Address(host='localhost', port=7687)
2018-01-23 22:51:53,169 ERROR exception 4227 Internal Server Error: /accounts/login/
Traceback (most recent call last):
  File "/home/adrian/skyfolk/venv/lib/python3.5/site-packages/urllib3/connection.py", line 141, in _new_conn
    (self.host, self.port), self.timeout, **extra_kw)
  File "/home/adrian/skyfolk/venv/lib/python3.5/site-packages/urllib3/util/connection.py", line 83, in create_connection
    raise err
  File "/home/adrian/skyfolk/venv/lib/python3.5/site-packages/urllib3/util/connection.py", line 73, in create_connection
    sock.connect(sa)
ConnectionRefusedError: [Errno 111] Connection refused

During handling of the above exception, another exception occurred:

Traceback (most recent call last):
  File "/home/adrian/skyfolk/venv/lib/python3.5/site-packages/elasticsearch/connection/http_urllib3.py", line 114, in perform_request
    response = self.pool.urlopen(method, url, body, retries=False, headers=self.headers, **kw)
  File "/home/adrian/skyfolk/venv/lib/python3.5/site-packages/urllib3/connectionpool.py", line 639, in urlopen
    _stacktrace=sys.exc_info()[2])
  File "/home/adrian/skyfolk/venv/lib/python3.5/site-packages/urllib3/util/retry.py", line 333, in increment
    raise six.reraise(type(error), error, _stacktrace)
  File "/home/adrian/skyfolk/venv/lib/python3.5/site-packages/urllib3/packages/six.py", line 686, in reraise
    raise value
  File "/home/adrian/skyfolk/venv/lib/python3.5/site-packages/urllib3/connectionpool.py", line 601, in urlopen
    chunked=chunked)
  File "/home/adrian/skyfolk/venv/lib/python3.5/site-packages/urllib3/connectionpool.py", line 357, in _make_request
    conn.request(method, url, **httplib_request_kw)
  File "/usr/lib/python3.5/http/client.py", line 1106, in request
    self._send_request(method, url, body, headers)
  File "/usr/lib/python3.5/http/client.py", line 1151, in _send_request
    self.endheaders(body)
  File "/usr/lib/python3.5/http/client.py", line 1102, in endheaders
    self._send_output(message_body)
  File "/usr/lib/python3.5/http/client.py", line 934, in _send_output
    self.send(msg)
  File "/usr/lib/python3.5/http/client.py", line 877, in send
    self.connect()
  File "/home/adrian/skyfolk/venv/lib/python3.5/site-packages/urllib3/connection.py", line 166, in connect
    conn = self._new_conn()
  File "/home/adrian/skyfolk/venv/lib/python3.5/site-packages/urllib3/connection.py", line 150, in _new_conn
    self, "Failed to establish a new connection: %s" % e)
urllib3.exceptions.NewConnectionError: <urllib3.connection.HTTPConnection object at 0x7f8e6ee5e0f0>: Failed to establish a new connection: [Errno 111] Connection refused

During handling of the above exception, another exception occurred:

Traceback (most recent call last):
  File "/home/adrian/skyfolk/venv/lib/python3.5/site-packages/django/core/handlers/exception.py", line 41, in inner
    response = get_response(request)
  File "/home/adrian/skyfolk/venv/lib/python3.5/site-packages/django/core/handlers/base.py", line 249, in _legacy_get_response
    response = self._get_response(request)
  File "/home/adrian/skyfolk/venv/lib/python3.5/site-packages/django/core/handlers/base.py", line 187, in _get_response
    response = self.process_exception_by_middleware(e, request)
  File "/home/adrian/skyfolk/venv/lib/python3.5/site-packages/channels/handler.py", line 243, in process_exception_by_middleware
    return super(AsgiHandler, self).process_exception_by_middleware(exception, request)
  File "/home/adrian/skyfolk/venv/lib/python3.5/site-packages/django/core/handlers/base.py", line 185, in _get_response
    response = wrapped_callback(request, *callback_args, **callback_kwargs)
  File "/home/adrian/skyfolk/venv/lib/python3.5/site-packages/django/views/generic/base.py", line 68, in view
    return self.dispatch(request, *args, **kwargs)
  File "/home/adrian/skyfolk/venv/lib/python3.5/site-packages/django/utils/decorators.py", line 67, in _wrapper
    return bound_func(*args, **kwargs)
  File "/home/adrian/skyfolk/venv/lib/python3.5/site-packages/django/views/decorators/debug.py", line 76, in sensitive_post_parameters_wrapper
    return view(request, *args, **kwargs)
  File "/home/adrian/skyfolk/venv/lib/python3.5/site-packages/django/utils/decorators.py", line 63, in bound_func
    return func.__get__(self, type(self))(*args2, **kwargs2)
  File "/home/adrian/skyfolk/venv/lib/python3.5/site-packages/allauth/account/views.py", line 133, in dispatch
    return super(LoginView, self).dispatch(request, *args, **kwargs)
  File "/home/adrian/skyfolk/venv/lib/python3.5/site-packages/allauth/account/views.py", line 79, in dispatch
    **kwargs)
  File "/home/adrian/skyfolk/venv/lib/python3.5/site-packages/django/views/generic/base.py", line 88, in dispatch
    return handler(request, *args, **kwargs)
  File "/home/adrian/skyfolk/venv/lib/python3.5/site-packages/allauth/account/views.py", line 102, in post
    response = self.form_valid(form)
  File "/home/adrian/skyfolk/venv/lib/python3.5/site-packages/allauth/account/views.py", line 146, in form_valid
    return form.login(self.request, redirect_url=success_url)
  File "/home/adrian/skyfolk/user_profile/forms.py", line 72, in login
    return super(CustomLoginForm, self).login(request=request, redirect_url=redirect_url)
  File "/home/adrian/skyfolk/venv/lib/python3.5/site-packages/allauth/account/forms.py", line 177, in login
    redirect_url=redirect_url)
  File "/home/adrian/skyfolk/venv/lib/python3.5/site-packages/allauth/account/utils.py", line 155, in perform_login
    adapter.login(request, user)
  File "/home/adrian/skyfolk/venv/lib/python3.5/site-packages/allauth/account/adapter.py", line 388, in login
    django_login(request, user)
  File "/home/adrian/skyfolk/venv/lib/python3.5/site-packages/django/contrib/auth/__init__.py", line 160, in login
    user_logged_in.send(sender=user.__class__, request=request, user=user)
  File "/home/adrian/skyfolk/venv/lib/python3.5/site-packages/django/dispatch/dispatcher.py", line 193, in send
    for receiver in self._live_receivers(sender)
  File "/home/adrian/skyfolk/venv/lib/python3.5/site-packages/django/dispatch/dispatcher.py", line 193, in <listcomp>
    for receiver in self._live_receivers(sender)
  File "/home/adrian/skyfolk/venv/lib/python3.5/site-packages/django/contrib/auth/models.py", line 25, in update_last_login
    user.save(update_fields=['last_login'])
  File "/home/adrian/skyfolk/venv/lib/python3.5/site-packages/django/contrib/auth/base_user.py", line 80, in save
    super(AbstractBaseUser, self).save(*args, **kwargs)
  File "/home/adrian/skyfolk/venv/lib/python3.5/site-packages/django/db/models/base.py", line 808, in save
    force_update=force_update, update_fields=update_fields)
  File "/home/adrian/skyfolk/venv/lib/python3.5/site-packages/django/db/models/base.py", line 848, in save_base
    update_fields=update_fields, raw=raw, using=using,
  File "/home/adrian/skyfolk/venv/lib/python3.5/site-packages/django/dispatch/dispatcher.py", line 193, in send
    for receiver in self._live_receivers(sender)
  File "/home/adrian/skyfolk/venv/lib/python3.5/site-packages/django/dispatch/dispatcher.py", line 193, in <listcomp>
    for receiver in self._live_receivers(sender)
  File "/home/adrian/skyfolk/user_profile/signals.py", line 106, in create_user_profile
    instance.profile.save()
  File "/home/adrian/skyfolk/venv/lib/python3.5/site-packages/django/db/models/base.py", line 808, in save
    force_update=force_update, update_fields=update_fields)
  File "/home/adrian/skyfolk/venv/lib/python3.5/site-packages/django/db/models/base.py", line 848, in save_base
    update_fields=update_fields, raw=raw, using=using,
  File "/home/adrian/skyfolk/venv/lib/python3.5/site-packages/django/dispatch/dispatcher.py", line 193, in send
    for receiver in self._live_receivers(sender)
  File "/home/adrian/skyfolk/venv/lib/python3.5/site-packages/django/dispatch/dispatcher.py", line 193, in <listcomp>
    for receiver in self._live_receivers(sender)
  File "/home/adrian/skyfolk/venv/lib/python3.5/site-packages/haystack/signals.py", line 52, in handle_save
    index.update_object(instance, using=using)
  File "/home/adrian/skyfolk/venv/lib/python3.5/site-packages/haystack/indexes.py", line 284, in update_object
    backend.update(self, [instance])
  File "/home/adrian/skyfolk/venv/lib/python3.5/site-packages/haystack/backends/elasticsearch_backend.py", line 190, in update
    bulk(self.conn, prepped_docs, index=self.index_name, doc_type='modelresult')
  File "/home/adrian/skyfolk/venv/lib/python3.5/site-packages/elasticsearch/helpers/__init__.py", line 195, in bulk
    for ok, item in streaming_bulk(client, actions, **kwargs):
  File "/home/adrian/skyfolk/venv/lib/python3.5/site-packages/elasticsearch/helpers/__init__.py", line 163, in streaming_bulk
    for result in _process_bulk_chunk(client, bulk_actions, raise_on_exception, raise_on_error, **kwargs):
  File "/home/adrian/skyfolk/venv/lib/python3.5/site-packages/elasticsearch/helpers/__init__.py", line 92, in _process_bulk_chunk
    raise e
  File "/home/adrian/skyfolk/venv/lib/python3.5/site-packages/elasticsearch/helpers/__init__.py", line 88, in _process_bulk_chunk
    resp = client.bulk('\n'.join(bulk_actions) + '\n', **kwargs)
  File "/home/adrian/skyfolk/venv/lib/python3.5/site-packages/elasticsearch/client/utils.py", line 73, in _wrapped
    return func(*args, params=params, **kwargs)
  File "/home/adrian/skyfolk/venv/lib/python3.5/site-packages/elasticsearch/client/__init__.py", line 1165, in bulk
    doc_type, '_bulk'), params=params, body=self._bulk_body(body))
  File "/home/adrian/skyfolk/venv/lib/python3.5/site-packages/elasticsearch/transport.py", line 312, in perform_request
    status, headers, data = connection.perform_request(method, url, params, body, ignore=ignore, timeout=timeout)
  File "/home/adrian/skyfolk/venv/lib/python3.5/site-packages/elasticsearch/connection/http_urllib3.py", line 123, in perform_request
    raise ConnectionError('N/A', str(e), e)
elasticsearch.exceptions.ConnectionError: ConnectionError(<urllib3.connection.HTTPConnection object at 0x7f8e6ee5e0f0>: Failed to establish a new connection: [Errno 111] Connection refused) caused by: NewConnectionError(<urllib3.connection.HTTPConnection object at 0x7f8e6ee5e0f0>: Failed to establish a new connection: [Errno 111] Connection refused)
2018-01-23 22:52:07,190 ERROR exception 4227 Internal Server Error: /accounts/login/
Traceback (most recent call last):
  File "/home/adrian/skyfolk/venv/lib/python3.5/site-packages/urllib3/connection.py", line 141, in _new_conn
    (self.host, self.port), self.timeout, **extra_kw)
  File "/home/adrian/skyfolk/venv/lib/python3.5/site-packages/urllib3/util/connection.py", line 83, in create_connection
    raise err
  File "/home/adrian/skyfolk/venv/lib/python3.5/site-packages/urllib3/util/connection.py", line 73, in create_connection
    sock.connect(sa)
ConnectionRefusedError: [Errno 111] Connection refused

During handling of the above exception, another exception occurred:

Traceback (most recent call last):
  File "/home/adrian/skyfolk/venv/lib/python3.5/site-packages/elasticsearch/connection/http_urllib3.py", line 114, in perform_request
    response = self.pool.urlopen(method, url, body, retries=False, headers=self.headers, **kw)
  File "/home/adrian/skyfolk/venv/lib/python3.5/site-packages/urllib3/connectionpool.py", line 639, in urlopen
    _stacktrace=sys.exc_info()[2])
  File "/home/adrian/skyfolk/venv/lib/python3.5/site-packages/urllib3/util/retry.py", line 333, in increment
    raise six.reraise(type(error), error, _stacktrace)
  File "/home/adrian/skyfolk/venv/lib/python3.5/site-packages/urllib3/packages/six.py", line 686, in reraise
    raise value
  File "/home/adrian/skyfolk/venv/lib/python3.5/site-packages/urllib3/connectionpool.py", line 601, in urlopen
    chunked=chunked)
  File "/home/adrian/skyfolk/venv/lib/python3.5/site-packages/urllib3/connectionpool.py", line 357, in _make_request
    conn.request(method, url, **httplib_request_kw)
  File "/usr/lib/python3.5/http/client.py", line 1106, in request
    self._send_request(method, url, body, headers)
  File "/usr/lib/python3.5/http/client.py", line 1151, in _send_request
    self.endheaders(body)
  File "/usr/lib/python3.5/http/client.py", line 1102, in endheaders
    self._send_output(message_body)
  File "/usr/lib/python3.5/http/client.py", line 934, in _send_output
    self.send(msg)
  File "/usr/lib/python3.5/http/client.py", line 877, in send
    self.connect()
  File "/home/adrian/skyfolk/venv/lib/python3.5/site-packages/urllib3/connection.py", line 166, in connect
    conn = self._new_conn()
  File "/home/adrian/skyfolk/venv/lib/python3.5/site-packages/urllib3/connection.py", line 150, in _new_conn
    self, "Failed to establish a new connection: %s" % e)
urllib3.exceptions.NewConnectionError: <urllib3.connection.HTTPConnection object at 0x7f8e6e582978>: Failed to establish a new connection: [Errno 111] Connection refused

During handling of the above exception, another exception occurred:

Traceback (most recent call last):
  File "/home/adrian/skyfolk/venv/lib/python3.5/site-packages/django/core/handlers/exception.py", line 41, in inner
    response = get_response(request)
  File "/home/adrian/skyfolk/venv/lib/python3.5/site-packages/django/core/handlers/base.py", line 249, in _legacy_get_response
    response = self._get_response(request)
  File "/home/adrian/skyfolk/venv/lib/python3.5/site-packages/django/core/handlers/base.py", line 187, in _get_response
    response = self.process_exception_by_middleware(e, request)
  File "/home/adrian/skyfolk/venv/lib/python3.5/site-packages/channels/handler.py", line 243, in process_exception_by_middleware
    return super(AsgiHandler, self).process_exception_by_middleware(exception, request)
  File "/home/adrian/skyfolk/venv/lib/python3.5/site-packages/django/core/handlers/base.py", line 185, in _get_response
    response = wrapped_callback(request, *callback_args, **callback_kwargs)
  File "/home/adrian/skyfolk/venv/lib/python3.5/site-packages/django/views/generic/base.py", line 68, in view
    return self.dispatch(request, *args, **kwargs)
  File "/home/adrian/skyfolk/venv/lib/python3.5/site-packages/django/utils/decorators.py", line 67, in _wrapper
    return bound_func(*args, **kwargs)
  File "/home/adrian/skyfolk/venv/lib/python3.5/site-packages/django/views/decorators/debug.py", line 76, in sensitive_post_parameters_wrapper
    return view(request, *args, **kwargs)
  File "/home/adrian/skyfolk/venv/lib/python3.5/site-packages/django/utils/decorators.py", line 63, in bound_func
    return func.__get__(self, type(self))(*args2, **kwargs2)
  File "/home/adrian/skyfolk/venv/lib/python3.5/site-packages/allauth/account/views.py", line 133, in dispatch
    return super(LoginView, self).dispatch(request, *args, **kwargs)
  File "/home/adrian/skyfolk/venv/lib/python3.5/site-packages/allauth/account/views.py", line 79, in dispatch
    **kwargs)
  File "/home/adrian/skyfolk/venv/lib/python3.5/site-packages/django/views/generic/base.py", line 88, in dispatch
    return handler(request, *args, **kwargs)
  File "/home/adrian/skyfolk/venv/lib/python3.5/site-packages/allauth/account/views.py", line 102, in post
    response = self.form_valid(form)
  File "/home/adrian/skyfolk/venv/lib/python3.5/site-packages/allauth/account/views.py", line 146, in form_valid
    return form.login(self.request, redirect_url=success_url)
  File "/home/adrian/skyfolk/user_profile/forms.py", line 72, in login
    return super(CustomLoginForm, self).login(request=request, redirect_url=redirect_url)
  File "/home/adrian/skyfolk/venv/lib/python3.5/site-packages/allauth/account/forms.py", line 177, in login
    redirect_url=redirect_url)
  File "/home/adrian/skyfolk/venv/lib/python3.5/site-packages/allauth/account/utils.py", line 155, in perform_login
    adapter.login(request, user)
  File "/home/adrian/skyfolk/venv/lib/python3.5/site-packages/allauth/account/adapter.py", line 388, in login
    django_login(request, user)
  File "/home/adrian/skyfolk/venv/lib/python3.5/site-packages/django/contrib/auth/__init__.py", line 160, in login
    user_logged_in.send(sender=user.__class__, request=request, user=user)
  File "/home/adrian/skyfolk/venv/lib/python3.5/site-packages/django/dispatch/dispatcher.py", line 193, in send
    for receiver in self._live_receivers(sender)
  File "/home/adrian/skyfolk/venv/lib/python3.5/site-packages/django/dispatch/dispatcher.py", line 193, in <listcomp>
    for receiver in self._live_receivers(sender)
  File "/home/adrian/skyfolk/venv/lib/python3.5/site-packages/django/contrib/auth/models.py", line 25, in update_last_login
    user.save(update_fields=['last_login'])
  File "/home/adrian/skyfolk/venv/lib/python3.5/site-packages/django/contrib/auth/base_user.py", line 80, in save
    super(AbstractBaseUser, self).save(*args, **kwargs)
  File "/home/adrian/skyfolk/venv/lib/python3.5/site-packages/django/db/models/base.py", line 808, in save
    force_update=force_update, update_fields=update_fields)
  File "/home/adrian/skyfolk/venv/lib/python3.5/site-packages/django/db/models/base.py", line 848, in save_base
    update_fields=update_fields, raw=raw, using=using,
  File "/home/adrian/skyfolk/venv/lib/python3.5/site-packages/django/dispatch/dispatcher.py", line 193, in send
    for receiver in self._live_receivers(sender)
  File "/home/adrian/skyfolk/venv/lib/python3.5/site-packages/django/dispatch/dispatcher.py", line 193, in <listcomp>
    for receiver in self._live_receivers(sender)
  File "/home/adrian/skyfolk/user_profile/signals.py", line 106, in create_user_profile
    instance.profile.save()
  File "/home/adrian/skyfolk/venv/lib/python3.5/site-packages/django/db/models/base.py", line 808, in save
    force_update=force_update, update_fields=update_fields)
  File "/home/adrian/skyfolk/venv/lib/python3.5/site-packages/django/db/models/base.py", line 848, in save_base
    update_fields=update_fields, raw=raw, using=using,
  File "/home/adrian/skyfolk/venv/lib/python3.5/site-packages/django/dispatch/dispatcher.py", line 193, in send
    for receiver in self._live_receivers(sender)
  File "/home/adrian/skyfolk/venv/lib/python3.5/site-packages/django/dispatch/dispatcher.py", line 193, in <listcomp>
    for receiver in self._live_receivers(sender)
  File "/home/adrian/skyfolk/venv/lib/python3.5/site-packages/haystack/signals.py", line 52, in handle_save
    index.update_object(instance, using=using)
  File "/home/adrian/skyfolk/venv/lib/python3.5/site-packages/haystack/indexes.py", line 284, in update_object
    backend.update(self, [instance])
  File "/home/adrian/skyfolk/venv/lib/python3.5/site-packages/haystack/backends/elasticsearch_backend.py", line 190, in update
    bulk(self.conn, prepped_docs, index=self.index_name, doc_type='modelresult')
  File "/home/adrian/skyfolk/venv/lib/python3.5/site-packages/elasticsearch/helpers/__init__.py", line 195, in bulk
    for ok, item in streaming_bulk(client, actions, **kwargs):
  File "/home/adrian/skyfolk/venv/lib/python3.5/site-packages/elasticsearch/helpers/__init__.py", line 163, in streaming_bulk
    for result in _process_bulk_chunk(client, bulk_actions, raise_on_exception, raise_on_error, **kwargs):
  File "/home/adrian/skyfolk/venv/lib/python3.5/site-packages/elasticsearch/helpers/__init__.py", line 92, in _process_bulk_chunk
    raise e
  File "/home/adrian/skyfolk/venv/lib/python3.5/site-packages/elasticsearch/helpers/__init__.py", line 88, in _process_bulk_chunk
    resp = client.bulk('\n'.join(bulk_actions) + '\n', **kwargs)
  File "/home/adrian/skyfolk/venv/lib/python3.5/site-packages/elasticsearch/client/utils.py", line 73, in _wrapped
    return func(*args, params=params, **kwargs)
  File "/home/adrian/skyfolk/venv/lib/python3.5/site-packages/elasticsearch/client/__init__.py", line 1165, in bulk
    doc_type, '_bulk'), params=params, body=self._bulk_body(body))
  File "/home/adrian/skyfolk/venv/lib/python3.5/site-packages/elasticsearch/transport.py", line 312, in perform_request
    status, headers, data = connection.perform_request(method, url, params, body, ignore=ignore, timeout=timeout)
  File "/home/adrian/skyfolk/venv/lib/python3.5/site-packages/elasticsearch/connection/http_urllib3.py", line 123, in perform_request
    raise ConnectionError('N/A', str(e), e)
elasticsearch.exceptions.ConnectionError: ConnectionError(<urllib3.connection.HTTPConnection object at 0x7f8e6e582978>: Failed to establish a new connection: [Errno 111] Connection refused) caused by: NewConnectionError(<urllib3.connection.HTTPConnection object at 0x7f8e6e582978>: Failed to establish a new connection: [Errno 111] Connection refused)
2018-01-23 23:21:05,697 ERROR exception 22033 Internal Server Error: /accounts/login/
Traceback (most recent call last):
  File "/home/adrian/skyfolk/venv/lib/python3.5/site-packages/urllib3/connection.py", line 141, in _new_conn
    (self.host, self.port), self.timeout, **extra_kw)
  File "/home/adrian/skyfolk/venv/lib/python3.5/site-packages/urllib3/util/connection.py", line 83, in create_connection
    raise err
  File "/home/adrian/skyfolk/venv/lib/python3.5/site-packages/urllib3/util/connection.py", line 73, in create_connection
    sock.connect(sa)
ConnectionRefusedError: [Errno 111] Connection refused

During handling of the above exception, another exception occurred:

Traceback (most recent call last):
  File "/home/adrian/skyfolk/venv/lib/python3.5/site-packages/elasticsearch/connection/http_urllib3.py", line 114, in perform_request
    response = self.pool.urlopen(method, url, body, retries=False, headers=self.headers, **kw)
  File "/home/adrian/skyfolk/venv/lib/python3.5/site-packages/urllib3/connectionpool.py", line 639, in urlopen
    _stacktrace=sys.exc_info()[2])
  File "/home/adrian/skyfolk/venv/lib/python3.5/site-packages/urllib3/util/retry.py", line 333, in increment
    raise six.reraise(type(error), error, _stacktrace)
  File "/home/adrian/skyfolk/venv/lib/python3.5/site-packages/urllib3/packages/six.py", line 686, in reraise
    raise value
  File "/home/adrian/skyfolk/venv/lib/python3.5/site-packages/urllib3/connectionpool.py", line 601, in urlopen
    chunked=chunked)
  File "/home/adrian/skyfolk/venv/lib/python3.5/site-packages/urllib3/connectionpool.py", line 357, in _make_request
    conn.request(method, url, **httplib_request_kw)
  File "/usr/lib/python3.5/http/client.py", line 1106, in request
    self._send_request(method, url, body, headers)
  File "/usr/lib/python3.5/http/client.py", line 1151, in _send_request
    self.endheaders(body)
  File "/usr/lib/python3.5/http/client.py", line 1102, in endheaders
    self._send_output(message_body)
  File "/usr/lib/python3.5/http/client.py", line 934, in _send_output
    self.send(msg)
  File "/usr/lib/python3.5/http/client.py", line 877, in send
    self.connect()
  File "/home/adrian/skyfolk/venv/lib/python3.5/site-packages/urllib3/connection.py", line 166, in connect
    conn = self._new_conn()
  File "/home/adrian/skyfolk/venv/lib/python3.5/site-packages/urllib3/connection.py", line 150, in _new_conn
    self, "Failed to establish a new connection: %s" % e)
urllib3.exceptions.NewConnectionError: <urllib3.connection.HTTPConnection object at 0x7f09efd2fc18>: Failed to establish a new connection: [Errno 111] Connection refused

During handling of the above exception, another exception occurred:

Traceback (most recent call last):
  File "/home/adrian/skyfolk/venv/lib/python3.5/site-packages/django/core/handlers/exception.py", line 41, in inner
    response = get_response(request)
  File "/home/adrian/skyfolk/venv/lib/python3.5/site-packages/django/core/handlers/base.py", line 249, in _legacy_get_response
    response = self._get_response(request)
  File "/home/adrian/skyfolk/venv/lib/python3.5/site-packages/django/core/handlers/base.py", line 187, in _get_response
    response = self.process_exception_by_middleware(e, request)
  File "/home/adrian/skyfolk/venv/lib/python3.5/site-packages/channels/handler.py", line 243, in process_exception_by_middleware
    return super(AsgiHandler, self).process_exception_by_middleware(exception, request)
  File "/home/adrian/skyfolk/venv/lib/python3.5/site-packages/django/core/handlers/base.py", line 185, in _get_response
    response = wrapped_callback(request, *callback_args, **callback_kwargs)
  File "/home/adrian/skyfolk/venv/lib/python3.5/site-packages/django/views/generic/base.py", line 68, in view
    return self.dispatch(request, *args, **kwargs)
  File "/home/adrian/skyfolk/venv/lib/python3.5/site-packages/django/utils/decorators.py", line 67, in _wrapper
    return bound_func(*args, **kwargs)
  File "/home/adrian/skyfolk/venv/lib/python3.5/site-packages/django/views/decorators/debug.py", line 76, in sensitive_post_parameters_wrapper
    return view(request, *args, **kwargs)
  File "/home/adrian/skyfolk/venv/lib/python3.5/site-packages/django/utils/decorators.py", line 63, in bound_func
    return func.__get__(self, type(self))(*args2, **kwargs2)
  File "/home/adrian/skyfolk/venv/lib/python3.5/site-packages/allauth/account/views.py", line 133, in dispatch
    return super(LoginView, self).dispatch(request, *args, **kwargs)
  File "/home/adrian/skyfolk/venv/lib/python3.5/site-packages/allauth/account/views.py", line 79, in dispatch
    **kwargs)
  File "/home/adrian/skyfolk/venv/lib/python3.5/site-packages/django/views/generic/base.py", line 88, in dispatch
    return handler(request, *args, **kwargs)
  File "/home/adrian/skyfolk/venv/lib/python3.5/site-packages/allauth/account/views.py", line 102, in post
    response = self.form_valid(form)
  File "/home/adrian/skyfolk/venv/lib/python3.5/site-packages/allauth/account/views.py", line 146, in form_valid
    return form.login(self.request, redirect_url=success_url)
  File "/home/adrian/skyfolk/user_profile/forms.py", line 72, in login
    return super(CustomLoginForm, self).login(request=request, redirect_url=redirect_url)
  File "/home/adrian/skyfolk/venv/lib/python3.5/site-packages/allauth/account/forms.py", line 177, in login
    redirect_url=redirect_url)
  File "/home/adrian/skyfolk/venv/lib/python3.5/site-packages/allauth/account/utils.py", line 155, in perform_login
    adapter.login(request, user)
  File "/home/adrian/skyfolk/venv/lib/python3.5/site-packages/allauth/account/adapter.py", line 388, in login
    django_login(request, user)
  File "/home/adrian/skyfolk/venv/lib/python3.5/site-packages/django/contrib/auth/__init__.py", line 160, in login
    user_logged_in.send(sender=user.__class__, request=request, user=user)
  File "/home/adrian/skyfolk/venv/lib/python3.5/site-packages/django/dispatch/dispatcher.py", line 193, in send
    for receiver in self._live_receivers(sender)
  File "/home/adrian/skyfolk/venv/lib/python3.5/site-packages/django/dispatch/dispatcher.py", line 193, in <listcomp>
    for receiver in self._live_receivers(sender)
  File "/home/adrian/skyfolk/venv/lib/python3.5/site-packages/django/contrib/auth/models.py", line 25, in update_last_login
    user.save(update_fields=['last_login'])
  File "/home/adrian/skyfolk/venv/lib/python3.5/site-packages/django/contrib/auth/base_user.py", line 80, in save
    super(AbstractBaseUser, self).save(*args, **kwargs)
  File "/home/adrian/skyfolk/venv/lib/python3.5/site-packages/django/db/models/base.py", line 808, in save
    force_update=force_update, update_fields=update_fields)
  File "/home/adrian/skyfolk/venv/lib/python3.5/site-packages/django/db/models/base.py", line 848, in save_base
    update_fields=update_fields, raw=raw, using=using,
  File "/home/adrian/skyfolk/venv/lib/python3.5/site-packages/django/dispatch/dispatcher.py", line 193, in send
    for receiver in self._live_receivers(sender)
  File "/home/adrian/skyfolk/venv/lib/python3.5/site-packages/django/dispatch/dispatcher.py", line 193, in <listcomp>
    for receiver in self._live_receivers(sender)
  File "/home/adrian/skyfolk/user_profile/signals.py", line 106, in create_user_profile
    instance.profile.save()
  File "/home/adrian/skyfolk/venv/lib/python3.5/site-packages/django/db/models/base.py", line 808, in save
    force_update=force_update, update_fields=update_fields)
  File "/home/adrian/skyfolk/venv/lib/python3.5/site-packages/django/db/models/base.py", line 848, in save_base
    update_fields=update_fields, raw=raw, using=using,
  File "/home/adrian/skyfolk/venv/lib/python3.5/site-packages/django/dispatch/dispatcher.py", line 193, in send
    for receiver in self._live_receivers(sender)
  File "/home/adrian/skyfolk/venv/lib/python3.5/site-packages/django/dispatch/dispatcher.py", line 193, in <listcomp>
    for receiver in self._live_receivers(sender)
  File "/home/adrian/skyfolk/venv/lib/python3.5/site-packages/haystack/signals.py", line 52, in handle_save
    index.update_object(instance, using=using)
  File "/home/adrian/skyfolk/venv/lib/python3.5/site-packages/haystack/indexes.py", line 284, in update_object
    backend.update(self, [instance])
  File "/home/adrian/skyfolk/venv/lib/python3.5/site-packages/haystack/backends/elasticsearch_backend.py", line 190, in update
    bulk(self.conn, prepped_docs, index=self.index_name, doc_type='modelresult')
  File "/home/adrian/skyfolk/venv/lib/python3.5/site-packages/elasticsearch/helpers/__init__.py", line 195, in bulk
    for ok, item in streaming_bulk(client, actions, **kwargs):
  File "/home/adrian/skyfolk/venv/lib/python3.5/site-packages/elasticsearch/helpers/__init__.py", line 163, in streaming_bulk
    for result in _process_bulk_chunk(client, bulk_actions, raise_on_exception, raise_on_error, **kwargs):
  File "/home/adrian/skyfolk/venv/lib/python3.5/site-packages/elasticsearch/helpers/__init__.py", line 92, in _process_bulk_chunk
    raise e
  File "/home/adrian/skyfolk/venv/lib/python3.5/site-packages/elasticsearch/helpers/__init__.py", line 88, in _process_bulk_chunk
    resp = client.bulk('\n'.join(bulk_actions) + '\n', **kwargs)
  File "/home/adrian/skyfolk/venv/lib/python3.5/site-packages/elasticsearch/client/utils.py", line 73, in _wrapped
    return func(*args, params=params, **kwargs)
  File "/home/adrian/skyfolk/venv/lib/python3.5/site-packages/elasticsearch/client/__init__.py", line 1165, in bulk
    doc_type, '_bulk'), params=params, body=self._bulk_body(body))
  File "/home/adrian/skyfolk/venv/lib/python3.5/site-packages/elasticsearch/transport.py", line 312, in perform_request
    status, headers, data = connection.perform_request(method, url, params, body, ignore=ignore, timeout=timeout)
  File "/home/adrian/skyfolk/venv/lib/python3.5/site-packages/elasticsearch/connection/http_urllib3.py", line 123, in perform_request
    raise ConnectionError('N/A', str(e), e)
elasticsearch.exceptions.ConnectionError: ConnectionError(<urllib3.connection.HTTPConnection object at 0x7f09efd2fc18>: Failed to establish a new connection: [Errno 111] Connection refused) caused by: NewConnectionError(<urllib3.connection.HTTPConnection object at 0x7f09efd2fc18>: Failed to establish a new connection: [Errno 111] Connection refused)
2018-01-24 15:55:32,664 ERROR exception 18999 Internal Server Error: /submit_photo/
Traceback (most recent call last):
  File "/home/adrian/skyfolk/venv/lib/python3.5/site-packages/django/core/handlers/exception.py", line 41, in inner
    response = get_response(request)
  File "/home/adrian/skyfolk/venv/lib/python3.5/site-packages/django/core/handlers/base.py", line 249, in _legacy_get_response
    response = self._get_response(request)
  File "/home/adrian/skyfolk/venv/lib/python3.5/site-packages/django/core/handlers/base.py", line 187, in _get_response
    response = self.process_exception_by_middleware(e, request)
  File "/home/adrian/skyfolk/venv/lib/python3.5/site-packages/channels/handler.py", line 243, in process_exception_by_middleware
    return super(AsgiHandler, self).process_exception_by_middleware(exception, request)
  File "/home/adrian/skyfolk/venv/lib/python3.5/site-packages/django/core/handlers/base.py", line 185, in _get_response
    response = wrapped_callback(request, *callback_args, **callback_kwargs)
  File "/home/adrian/skyfolk/venv/lib/python3.5/site-packages/django/views/decorators/http.py", line 40, in inner
    return func(request, *args, **kwargs)
  File "/home/adrian/skyfolk/venv/lib/python3.5/site-packages/django/contrib/auth/decorators.py", line 23, in _wrapped_view
    return view_func(request, *args, **kwargs)
  File "/home/adrian/skyfolk/photologue/views.py", line 179, in upload_photo
    obj.save()
  File "/home/adrian/skyfolk/photologue/models.py", line 497, in save
    self.slug = uuslug(str(self.owner_id) + self.title, instance=self)
  File "/home/adrian/skyfolk/venv/lib/python3.5/site-packages/uuslug/uuslug.py", line 44, in uuslug
    save_order=save_order, stopwords=stopwords)
  File "/home/adrian/skyfolk/venv/lib/python3.5/site-packages/uuslug/uuslug.py", line 19, in slugify
    word_boundary, separator, save_order, stopwords))
TypeError: __call__() takes 2 positional arguments but 10 were given
2018-01-24 16:54:44,873 ERROR exception 27261 Internal Server Error: /submit_photo/
Traceback (most recent call last):
  File "/home/adrian/skyfolk/venv/lib/python3.5/site-packages/django/core/handlers/exception.py", line 41, in inner
    response = get_response(request)
  File "/home/adrian/skyfolk/venv/lib/python3.5/site-packages/django/core/handlers/base.py", line 249, in _legacy_get_response
    response = self._get_response(request)
  File "/home/adrian/skyfolk/venv/lib/python3.5/site-packages/django/core/handlers/base.py", line 187, in _get_response
    response = self.process_exception_by_middleware(e, request)
  File "/home/adrian/skyfolk/venv/lib/python3.5/site-packages/channels/handler.py", line 243, in process_exception_by_middleware
    return super(AsgiHandler, self).process_exception_by_middleware(exception, request)
  File "/home/adrian/skyfolk/venv/lib/python3.5/site-packages/django/core/handlers/base.py", line 185, in _get_response
    response = wrapped_callback(request, *callback_args, **callback_kwargs)
  File "/home/adrian/skyfolk/venv/lib/python3.5/site-packages/django/views/decorators/http.py", line 40, in inner
    return func(request, *args, **kwargs)
  File "/home/adrian/skyfolk/venv/lib/python3.5/site-packages/django/contrib/auth/decorators.py", line 23, in _wrapped_view
    return view_func(request, *args, **kwargs)
  File "/home/adrian/skyfolk/photologue/views.py", line 179, in upload_photo
    obj.save()
  File "/home/adrian/skyfolk/photologue/models.py", line 502, in save
    self.get_remote_image()
  File "/home/adrian/skyfolk/photologue/models.py", line 523, in get_remote_image
    raise ValidationError(_("Couldn't retreive image. (There was an error reaching the server)"))
django.core.exceptions.ValidationError: ["Couldn't retreive image. (There was an error reaching the server)"]
2018-01-24 16:56:20,983 ERROR exception 27736 Internal Server Error: /submit_photo/
Traceback (most recent call last):
  File "/home/adrian/skyfolk/venv/lib/python3.5/site-packages/django/core/handlers/exception.py", line 41, in inner
    response = get_response(request)
  File "/home/adrian/skyfolk/venv/lib/python3.5/site-packages/django/core/handlers/base.py", line 249, in _legacy_get_response
    response = self._get_response(request)
  File "/home/adrian/skyfolk/venv/lib/python3.5/site-packages/django/core/handlers/base.py", line 187, in _get_response
    response = self.process_exception_by_middleware(e, request)
  File "/home/adrian/skyfolk/venv/lib/python3.5/site-packages/channels/handler.py", line 243, in process_exception_by_middleware
    return super(AsgiHandler, self).process_exception_by_middleware(exception, request)
  File "/home/adrian/skyfolk/venv/lib/python3.5/site-packages/django/core/handlers/base.py", line 185, in _get_response
    response = wrapped_callback(request, *callback_args, **callback_kwargs)
  File "/home/adrian/skyfolk/venv/lib/python3.5/site-packages/django/views/decorators/http.py", line 40, in inner
    return func(request, *args, **kwargs)
  File "/home/adrian/skyfolk/venv/lib/python3.5/site-packages/django/contrib/auth/decorators.py", line 23, in _wrapped_view
    return view_func(request, *args, **kwargs)
  File "/home/adrian/skyfolk/photologue/views.py", line 179, in upload_photo
    obj.save()
  File "/home/adrian/skyfolk/photologue/models.py", line 502, in save
    self.get_remote_image()
  File "/home/adrian/skyfolk/photologue/models.py", line 523, in get_remote_image
    raise ValidationError(_("Couldn't retreive image. (There was an error reaching the server)"))
django.core.exceptions.ValidationError: ["Couldn't retreive image. (There was an error reaching the server)"]
2018-01-24 16:59:12,459 ERROR exception 28511 Internal Server Error: /submit_photo/
Traceback (most recent call last):
  File "/home/adrian/skyfolk/venv/lib/python3.5/site-packages/django/core/handlers/exception.py", line 41, in inner
    response = get_response(request)
  File "/home/adrian/skyfolk/venv/lib/python3.5/site-packages/django/core/handlers/base.py", line 249, in _legacy_get_response
    response = self._get_response(request)
  File "/home/adrian/skyfolk/venv/lib/python3.5/site-packages/django/core/handlers/base.py", line 187, in _get_response
    response = self.process_exception_by_middleware(e, request)
  File "/home/adrian/skyfolk/venv/lib/python3.5/site-packages/channels/handler.py", line 243, in process_exception_by_middleware
    return super(AsgiHandler, self).process_exception_by_middleware(exception, request)
  File "/home/adrian/skyfolk/venv/lib/python3.5/site-packages/django/core/handlers/base.py", line 185, in _get_response
    response = wrapped_callback(request, *callback_args, **callback_kwargs)
  File "/home/adrian/skyfolk/venv/lib/python3.5/site-packages/django/views/decorators/http.py", line 40, in inner
    return func(request, *args, **kwargs)
  File "/home/adrian/skyfolk/venv/lib/python3.5/site-packages/django/contrib/auth/decorators.py", line 23, in _wrapped_view
    return view_func(request, *args, **kwargs)
  File "/home/adrian/skyfolk/photologue/views.py", line 179, in upload_photo
    obj.save()
  File "/home/adrian/skyfolk/photologue/models.py", line 502, in save
    self.get_remote_image()
  File "/home/adrian/skyfolk/photologue/models.py", line 523, in get_remote_image
    raise ValidationError(_("Couldn't retreive image. (There was an error reaching the server)"))
django.core.exceptions.ValidationError: ["Couldn't retreive image. (There was an error reaching the server)"]
