2018-02-15 23:38:35,406 ERROR exception 14758 Internal Server Error: /search/autocomplete/
Traceback (most recent call last):
  File "/home/adrian/skyfolk/venv/lib/python3.6/site-packages/django/core/handlers/exception.py", line 41, in inner
    response = get_response(request)
  File "/home/adrian/skyfolk/venv/lib/python3.6/site-packages/django/core/handlers/base.py", line 249, in _legacy_get_response
    response = self._get_response(request)
  File "/home/adrian/skyfolk/venv/lib/python3.6/site-packages/django/core/handlers/base.py", line 187, in _get_response
    response = self.process_exception_by_middleware(e, request)
  File "/home/adrian/skyfolk/venv/lib/python3.6/site-packages/channels/handler.py", line 243, in process_exception_by_middleware
    return super(AsgiHandler, self).process_exception_by_middleware(exception, request)
  File "/home/adrian/skyfolk/venv/lib/python3.6/site-packages/django/core/handlers/base.py", line 185, in _get_response
    response = wrapped_callback(request, *callback_args, **callback_kwargs)
  File "/home/adrian/skyfolk/user_profile/views.py", line 1339, in autocomplete
    sqs = SearchQuerySet().models(Profile).filter(SQ(username=q) | SQ(firstname=q) | SQ(lastname=q))[:7]
  File "/home/adrian/skyfolk/venv/lib/python3.6/site-packages/haystack/query.py", line 363, in models
    if model not in connections[self.query._using].get_unified_index().get_indexed_models():
  File "/home/adrian/skyfolk/venv/lib/python3.6/site-packages/haystack/utils/loading.py", line 305, in get_indexed_models
    return list(self.get_indexes().keys())
  File "/home/adrian/skyfolk/venv/lib/python3.6/site-packages/haystack/utils/loading.py", line 299, in get_indexes
    self.build()
  File "/home/adrian/skyfolk/venv/lib/python3.6/site-packages/haystack/utils/loading.py", line 222, in build
    indexes = self.collect_indexes()
  File "/home/adrian/skyfolk/venv/lib/python3.6/site-packages/haystack/utils/loading.py", line 191, in collect_indexes
    search_index_module = importlib.import_module("%s.search_indexes" % app_mod.__name__)
  File "/home/adrian/skyfolk/venv/lib/python3.6/importlib/__init__.py", line 126, in import_module
    return _bootstrap._gcd_import(name[level:], package, level)
  File "<frozen importlib._bootstrap>", line 994, in _gcd_import
  File "<frozen importlib._bootstrap>", line 971, in _find_and_load
  File "<frozen importlib._bootstrap>", line 955, in _find_and_load_unlocked
  File "<frozen importlib._bootstrap>", line 665, in _load_unlocked
  File "<frozen importlib._bootstrap_external>", line 678, in exec_module
  File "<frozen importlib._bootstrap>", line 219, in _call_with_frames_removed
  File "/home/adrian/skyfolk/publications/search_indexes.py", line 6, in <module>
    class PublicationIndex(indexes.RealTimeSearchIndex, indexes.Indexable):
AttributeError: module 'haystack.indexes' has no attribute 'RealTimeSearchIndex'
2018-02-15 23:38:35,583 ERROR exception 14758 Internal Server Error: /search/autocomplete/
Traceback (most recent call last):
  File "/home/adrian/skyfolk/venv/lib/python3.6/site-packages/django/core/handlers/exception.py", line 41, in inner
    response = get_response(request)
  File "/home/adrian/skyfolk/venv/lib/python3.6/site-packages/django/core/handlers/base.py", line 249, in _legacy_get_response
    response = self._get_response(request)
  File "/home/adrian/skyfolk/venv/lib/python3.6/site-packages/django/core/handlers/base.py", line 187, in _get_response
    response = self.process_exception_by_middleware(e, request)
  File "/home/adrian/skyfolk/venv/lib/python3.6/site-packages/channels/handler.py", line 243, in process_exception_by_middleware
    return super(AsgiHandler, self).process_exception_by_middleware(exception, request)
  File "/home/adrian/skyfolk/venv/lib/python3.6/site-packages/django/core/handlers/base.py", line 185, in _get_response
    response = wrapped_callback(request, *callback_args, **callback_kwargs)
  File "/home/adrian/skyfolk/user_profile/views.py", line 1339, in autocomplete
    sqs = SearchQuerySet().models(Profile).filter(SQ(username=q) | SQ(firstname=q) | SQ(lastname=q))[:7]
  File "/home/adrian/skyfolk/venv/lib/python3.6/site-packages/haystack/query.py", line 363, in models
    if model not in connections[self.query._using].get_unified_index().get_indexed_models():
  File "/home/adrian/skyfolk/venv/lib/python3.6/site-packages/haystack/utils/loading.py", line 305, in get_indexed_models
    return list(self.get_indexes().keys())
  File "/home/adrian/skyfolk/venv/lib/python3.6/site-packages/haystack/utils/loading.py", line 299, in get_indexes
    self.build()
  File "/home/adrian/skyfolk/venv/lib/python3.6/site-packages/haystack/utils/loading.py", line 222, in build
    indexes = self.collect_indexes()
  File "/home/adrian/skyfolk/venv/lib/python3.6/site-packages/haystack/utils/loading.py", line 191, in collect_indexes
    search_index_module = importlib.import_module("%s.search_indexes" % app_mod.__name__)
  File "/home/adrian/skyfolk/venv/lib/python3.6/importlib/__init__.py", line 126, in import_module
    return _bootstrap._gcd_import(name[level:], package, level)
  File "<frozen importlib._bootstrap>", line 994, in _gcd_import
  File "<frozen importlib._bootstrap>", line 971, in _find_and_load
  File "<frozen importlib._bootstrap>", line 955, in _find_and_load_unlocked
  File "<frozen importlib._bootstrap>", line 665, in _load_unlocked
  File "<frozen importlib._bootstrap_external>", line 678, in exec_module
  File "<frozen importlib._bootstrap>", line 219, in _call_with_frames_removed
  File "/home/adrian/skyfolk/publications/search_indexes.py", line 6, in <module>
    class PublicationIndex(indexes.RealTimeSearchIndex, indexes.Indexable):
AttributeError: module 'haystack.indexes' has no attribute 'RealTimeSearchIndex'
2018-02-15 23:38:35,641 ERROR exception 14758 Internal Server Error: /search/autocomplete/
Traceback (most recent call last):
  File "/home/adrian/skyfolk/venv/lib/python3.6/site-packages/django/core/handlers/exception.py", line 41, in inner
    response = get_response(request)
  File "/home/adrian/skyfolk/venv/lib/python3.6/site-packages/django/core/handlers/base.py", line 249, in _legacy_get_response
    response = self._get_response(request)
  File "/home/adrian/skyfolk/venv/lib/python3.6/site-packages/django/core/handlers/base.py", line 187, in _get_response
    response = self.process_exception_by_middleware(e, request)
  File "/home/adrian/skyfolk/venv/lib/python3.6/site-packages/channels/handler.py", line 243, in process_exception_by_middleware
    return super(AsgiHandler, self).process_exception_by_middleware(exception, request)
  File "/home/adrian/skyfolk/venv/lib/python3.6/site-packages/django/core/handlers/base.py", line 185, in _get_response
    response = wrapped_callback(request, *callback_args, **callback_kwargs)
  File "/home/adrian/skyfolk/user_profile/views.py", line 1339, in autocomplete
    sqs = SearchQuerySet().models(Profile).filter(SQ(username=q) | SQ(firstname=q) | SQ(lastname=q))[:7]
  File "/home/adrian/skyfolk/venv/lib/python3.6/site-packages/haystack/query.py", line 363, in models
    if model not in connections[self.query._using].get_unified_index().get_indexed_models():
  File "/home/adrian/skyfolk/venv/lib/python3.6/site-packages/haystack/utils/loading.py", line 305, in get_indexed_models
    return list(self.get_indexes().keys())
  File "/home/adrian/skyfolk/venv/lib/python3.6/site-packages/haystack/utils/loading.py", line 299, in get_indexes
    self.build()
  File "/home/adrian/skyfolk/venv/lib/python3.6/site-packages/haystack/utils/loading.py", line 222, in build
    indexes = self.collect_indexes()
  File "/home/adrian/skyfolk/venv/lib/python3.6/site-packages/haystack/utils/loading.py", line 191, in collect_indexes
    search_index_module = importlib.import_module("%s.search_indexes" % app_mod.__name__)
  File "/home/adrian/skyfolk/venv/lib/python3.6/importlib/__init__.py", line 126, in import_module
    return _bootstrap._gcd_import(name[level:], package, level)
  File "<frozen importlib._bootstrap>", line 994, in _gcd_import
  File "<frozen importlib._bootstrap>", line 971, in _find_and_load
  File "<frozen importlib._bootstrap>", line 955, in _find_and_load_unlocked
  File "<frozen importlib._bootstrap>", line 665, in _load_unlocked
  File "<frozen importlib._bootstrap_external>", line 678, in exec_module
  File "<frozen importlib._bootstrap>", line 219, in _call_with_frames_removed
  File "/home/adrian/skyfolk/publications/search_indexes.py", line 6, in <module>
    class PublicationIndex(indexes.RealTimeSearchIndex, indexes.Indexable):
AttributeError: module 'haystack.indexes' has no attribute 'RealTimeSearchIndex'
2018-02-15 23:38:36,386 ERROR exception 14758 Internal Server Error: /search/autocomplete/
Traceback (most recent call last):
  File "/home/adrian/skyfolk/venv/lib/python3.6/site-packages/django/core/handlers/exception.py", line 41, in inner
    response = get_response(request)
  File "/home/adrian/skyfolk/venv/lib/python3.6/site-packages/django/core/handlers/base.py", line 249, in _legacy_get_response
    response = self._get_response(request)
  File "/home/adrian/skyfolk/venv/lib/python3.6/site-packages/django/core/handlers/base.py", line 187, in _get_response
    response = self.process_exception_by_middleware(e, request)
  File "/home/adrian/skyfolk/venv/lib/python3.6/site-packages/channels/handler.py", line 243, in process_exception_by_middleware
    return super(AsgiHandler, self).process_exception_by_middleware(exception, request)
  File "/home/adrian/skyfolk/venv/lib/python3.6/site-packages/django/core/handlers/base.py", line 185, in _get_response
    response = wrapped_callback(request, *callback_args, **callback_kwargs)
  File "/home/adrian/skyfolk/user_profile/views.py", line 1339, in autocomplete
    sqs = SearchQuerySet().models(Profile).filter(SQ(username=q) | SQ(firstname=q) | SQ(lastname=q))[:7]
  File "/home/adrian/skyfolk/venv/lib/python3.6/site-packages/haystack/query.py", line 363, in models
    if model not in connections[self.query._using].get_unified_index().get_indexed_models():
  File "/home/adrian/skyfolk/venv/lib/python3.6/site-packages/haystack/utils/loading.py", line 305, in get_indexed_models
    return list(self.get_indexes().keys())
  File "/home/adrian/skyfolk/venv/lib/python3.6/site-packages/haystack/utils/loading.py", line 299, in get_indexes
    self.build()
  File "/home/adrian/skyfolk/venv/lib/python3.6/site-packages/haystack/utils/loading.py", line 222, in build
    indexes = self.collect_indexes()
  File "/home/adrian/skyfolk/venv/lib/python3.6/site-packages/haystack/utils/loading.py", line 191, in collect_indexes
    search_index_module = importlib.import_module("%s.search_indexes" % app_mod.__name__)
  File "/home/adrian/skyfolk/venv/lib/python3.6/importlib/__init__.py", line 126, in import_module
    return _bootstrap._gcd_import(name[level:], package, level)
  File "<frozen importlib._bootstrap>", line 994, in _gcd_import
  File "<frozen importlib._bootstrap>", line 971, in _find_and_load
  File "<frozen importlib._bootstrap>", line 955, in _find_and_load_unlocked
  File "<frozen importlib._bootstrap>", line 665, in _load_unlocked
  File "<frozen importlib._bootstrap_external>", line 678, in exec_module
  File "<frozen importlib._bootstrap>", line 219, in _call_with_frames_removed
  File "/home/adrian/skyfolk/publications/search_indexes.py", line 6, in <module>
    class PublicationIndex(indexes.RealTimeSearchIndex, indexes.Indexable):
AttributeError: module 'haystack.indexes' has no attribute 'RealTimeSearchIndex'
2018-02-15 23:38:36,446 ERROR exception 14758 Internal Server Error: /user-search/
Traceback (most recent call last):
  File "/home/adrian/skyfolk/venv/lib/python3.6/site-packages/django/core/handlers/exception.py", line 41, in inner
    response = get_response(request)
  File "/home/adrian/skyfolk/venv/lib/python3.6/site-packages/django/core/handlers/base.py", line 249, in _legacy_get_response
    response = self._get_response(request)
  File "/home/adrian/skyfolk/venv/lib/python3.6/site-packages/django/core/handlers/base.py", line 187, in _get_response
    response = self.process_exception_by_middleware(e, request)
  File "/home/adrian/skyfolk/venv/lib/python3.6/site-packages/channels/handler.py", line 243, in process_exception_by_middleware
    return super(AsgiHandler, self).process_exception_by_middleware(exception, request)
  File "/home/adrian/skyfolk/venv/lib/python3.6/site-packages/django/core/handlers/base.py", line 185, in _get_response
    response = wrapped_callback(request, *callback_args, **callback_kwargs)
  File "/home/adrian/skyfolk/venv/lib/python3.6/site-packages/django/views/generic/base.py", line 68, in view
    return self.dispatch(request, *args, **kwargs)
  File "/home/adrian/skyfolk/venv/lib/python3.6/site-packages/django/utils/decorators.py", line 67, in _wrapper
    return bound_func(*args, **kwargs)
  File "/home/adrian/skyfolk/venv/lib/python3.6/site-packages/django/contrib/auth/decorators.py", line 23, in _wrapped_view
    return view_func(request, *args, **kwargs)
  File "/home/adrian/skyfolk/venv/lib/python3.6/site-packages/django/utils/decorators.py", line 63, in bound_func
    return func.__get__(self, type(self))(*args2, **kwargs2)
  File "/home/adrian/skyfolk/user_profile/views.py", line 1354, in dispatch
    return super(SearchUsuarioView, self).dispatch(request, *args, **kwargs)
  File "/home/adrian/skyfolk/venv/lib/python3.6/site-packages/django/views/generic/base.py", line 88, in dispatch
    return handler(request, *args, **kwargs)
  File "/home/adrian/skyfolk/venv/lib/python3.6/site-packages/haystack/generic_views.py", line 120, in get
    form = self.get_form(form_class)
  File "/home/adrian/skyfolk/venv/lib/python3.6/site-packages/django/views/generic/edit.py", line 45, in get_form
    return form_class(**self.get_form_kwargs())
  File "/home/adrian/skyfolk/venv/lib/python3.6/site-packages/haystack/generic_views.py", line 65, in get_form_kwargs
    kwargs.update({'searchqueryset': self.get_queryset()})
  File "/home/adrian/skyfolk/user_profile/views.py", line 1463, in get_queryset
    return queryset.filter(content=q).models(*models)
  File "/home/adrian/skyfolk/venv/lib/python3.6/site-packages/haystack/query.py", line 363, in models
    if model not in connections[self.query._using].get_unified_index().get_indexed_models():
  File "/home/adrian/skyfolk/venv/lib/python3.6/site-packages/haystack/utils/loading.py", line 305, in get_indexed_models
    return list(self.get_indexes().keys())
  File "/home/adrian/skyfolk/venv/lib/python3.6/site-packages/haystack/utils/loading.py", line 299, in get_indexes
    self.build()
  File "/home/adrian/skyfolk/venv/lib/python3.6/site-packages/haystack/utils/loading.py", line 222, in build
    indexes = self.collect_indexes()
  File "/home/adrian/skyfolk/venv/lib/python3.6/site-packages/haystack/utils/loading.py", line 191, in collect_indexes
    search_index_module = importlib.import_module("%s.search_indexes" % app_mod.__name__)
  File "/home/adrian/skyfolk/venv/lib/python3.6/importlib/__init__.py", line 126, in import_module
    return _bootstrap._gcd_import(name[level:], package, level)
  File "<frozen importlib._bootstrap>", line 994, in _gcd_import
  File "<frozen importlib._bootstrap>", line 971, in _find_and_load
  File "<frozen importlib._bootstrap>", line 955, in _find_and_load_unlocked
  File "<frozen importlib._bootstrap>", line 665, in _load_unlocked
  File "<frozen importlib._bootstrap_external>", line 678, in exec_module
  File "<frozen importlib._bootstrap>", line 219, in _call_with_frames_removed
  File "/home/adrian/skyfolk/publications/search_indexes.py", line 6, in <module>
    class PublicationIndex(indexes.RealTimeSearchIndex, indexes.Indexable):
AttributeError: module 'haystack.indexes' has no attribute 'RealTimeSearchIndex'
2018-02-15 23:52:47,549 ERROR exception 18917 Internal Server Error: /user-search/
Traceback (most recent call last):
  File "/home/adrian/skyfolk/venv/lib/python3.6/site-packages/django/core/handlers/exception.py", line 41, in inner
    response = get_response(request)
  File "/home/adrian/skyfolk/venv/lib/python3.6/site-packages/django/core/handlers/base.py", line 249, in _legacy_get_response
    response = self._get_response(request)
  File "/home/adrian/skyfolk/venv/lib/python3.6/site-packages/django/core/handlers/base.py", line 187, in _get_response
    response = self.process_exception_by_middleware(e, request)
  File "/home/adrian/skyfolk/venv/lib/python3.6/site-packages/channels/handler.py", line 243, in process_exception_by_middleware
    return super(AsgiHandler, self).process_exception_by_middleware(exception, request)
  File "/home/adrian/skyfolk/venv/lib/python3.6/site-packages/django/core/handlers/base.py", line 185, in _get_response
    response = wrapped_callback(request, *callback_args, **callback_kwargs)
  File "/home/adrian/skyfolk/venv/lib/python3.6/site-packages/django/views/generic/base.py", line 68, in view
    return self.dispatch(request, *args, **kwargs)
  File "/home/adrian/skyfolk/venv/lib/python3.6/site-packages/django/utils/decorators.py", line 67, in _wrapper
    return bound_func(*args, **kwargs)
  File "/home/adrian/skyfolk/venv/lib/python3.6/site-packages/django/contrib/auth/decorators.py", line 23, in _wrapped_view
    return view_func(request, *args, **kwargs)
  File "/home/adrian/skyfolk/venv/lib/python3.6/site-packages/django/utils/decorators.py", line 63, in bound_func
    return func.__get__(self, type(self))(*args2, **kwargs2)
  File "/home/adrian/skyfolk/user_profile/views.py", line 1354, in dispatch
    return super(SearchUsuarioView, self).dispatch(request, *args, **kwargs)
  File "/home/adrian/skyfolk/venv/lib/python3.6/site-packages/django/views/generic/base.py", line 88, in dispatch
    return handler(request, *args, **kwargs)
  File "/home/adrian/skyfolk/venv/lib/python3.6/site-packages/haystack/generic_views.py", line 120, in get
    form = self.get_form(form_class)
  File "/home/adrian/skyfolk/venv/lib/python3.6/site-packages/django/views/generic/edit.py", line 45, in get_form
    return form_class(**self.get_form_kwargs())
  File "/home/adrian/skyfolk/venv/lib/python3.6/site-packages/haystack/generic_views.py", line 65, in get_form_kwargs
    kwargs.update({'searchqueryset': self.get_queryset()})
  File "/home/adrian/skyfolk/user_profile/views.py", line 1404, in get_queryset
    .select_related('author').prefetch_related('images').filter(delete=False)
  File "/home/adrian/skyfolk/venv/lib/python3.6/site-packages/django/db/models/query.py", line 784, in filter
    return self._filter_or_exclude(False, *args, **kwargs)
  File "/home/adrian/skyfolk/venv/lib/python3.6/site-packages/django/db/models/query.py", line 802, in _filter_or_exclude
    clone.query.add_q(Q(*args, **kwargs))
  File "/home/adrian/skyfolk/venv/lib/python3.6/site-packages/django/db/models/sql/query.py", line 1250, in add_q
    clause, _ = self._add_q(q_object, self.used_aliases)
  File "/home/adrian/skyfolk/venv/lib/python3.6/site-packages/django/db/models/sql/query.py", line 1276, in _add_q
    allow_joins=allow_joins, split_subq=split_subq,
  File "/home/adrian/skyfolk/venv/lib/python3.6/site-packages/django/db/models/sql/query.py", line 1154, in build_filter
    lookups, parts, reffed_expression = self.solve_lookup_type(arg)
  File "/home/adrian/skyfolk/venv/lib/python3.6/site-packages/django/db/models/sql/query.py", line 1034, in solve_lookup_type
    _, field, _, lookup_parts = self.names_to_path(lookup_splitted, self.get_meta())
  File "/home/adrian/skyfolk/venv/lib/python3.6/site-packages/django/db/models/sql/query.py", line 1352, in names_to_path
    "Choices are: %s" % (name, ", ".join(available)))
django.core.exceptions.FieldError: Cannot resolve keyword 'delete' into field. Choices are: author, author_id, board_owner, board_owner_id, content, created, deleted, event_type, extra_content, id, images, level, lft, parent, parent_id, publication, reply, rght, shared_group_publication, shared_group_publication_id, shared_publication, shared_publication_id, tagged_items, tags, tree_id, user_give_me_hate, user_give_me_like, videos
