2018-01-30 13:45:10,931 ERROR exception 8784 Internal Server Error: /dashboard/edit/new_workspace/
Traceback (most recent call last):
  File "/home/adrian/skyfolk/venv/lib/python3.6/site-packages/django/core/handlers/exception.py", line 41, in inner
    response = get_response(request)
  File "/home/adrian/skyfolk/venv/lib/python3.6/site-packages/django/core/handlers/base.py", line 249, in _legacy_get_response
    response = self._get_response(request)
  File "/home/adrian/skyfolk/venv/lib/python3.6/site-packages/django/core/handlers/base.py", line 187, in _get_response
    response = self.process_exception_by_middleware(e, request)
  File "/home/adrian/skyfolk/venv/lib/python3.6/site-packages/channels/handler.py", line 243, in process_exception_by_middleware
    return super(AsgiHandler, self).process_exception_by_middleware(exception, request)
  File "/home/adrian/skyfolk/venv/lib/python3.6/site-packages/django/core/handlers/base.py", line 185, in _get_response
    response = wrapped_callback(request, *callback_args, **callback_kwargs)
  File "/home/adrian/skyfolk/venv/lib/python3.6/site-packages/django/contrib/auth/decorators.py", line 23, in _wrapped_view
    return view_func(request, *args, **kwargs)
  File "/home/adrian/skyfolk/dash/views.py", line 232, in edit_dashboard
    return render(request, template_name, context)
  File "/home/adrian/skyfolk/venv/lib/python3.6/site-packages/django/shortcuts.py", line 30, in render
    content = loader.render_to_string(template_name, context, request, using=using)
  File "/home/adrian/skyfolk/venv/lib/python3.6/site-packages/django/template/loader.py", line 68, in render_to_string
    return template.render(context, request)
  File "/home/adrian/skyfolk/venv/lib/python3.6/site-packages/django/template/backends/django.py", line 66, in render
    return self.template.render(context)
  File "/home/adrian/skyfolk/venv/lib/python3.6/site-packages/django/template/base.py", line 207, in render
    return self._render(context)
  File "/home/adrian/skyfolk/venv/lib/python3.6/site-packages/django/test/utils.py", line 107, in instrumented_test_render
    return self.nodelist.render(context)
  File "/home/adrian/skyfolk/venv/lib/python3.6/site-packages/django/template/base.py", line 990, in render
    bit = node.render_annotated(context)
  File "/home/adrian/skyfolk/venv/lib/python3.6/site-packages/django/template/base.py", line 957, in render_annotated
    return self.render(context)
  File "/home/adrian/skyfolk/venv/lib/python3.6/site-packages/django/template/loader_tags.py", line 177, in render
    return compiled_parent._render(context)
  File "/home/adrian/skyfolk/venv/lib/python3.6/site-packages/django/test/utils.py", line 107, in instrumented_test_render
    return self.nodelist.render(context)
  File "/home/adrian/skyfolk/venv/lib/python3.6/site-packages/django/template/base.py", line 990, in render
    bit = node.render_annotated(context)
  File "/home/adrian/skyfolk/venv/lib/python3.6/site-packages/django/template/base.py", line 957, in render_annotated
    return self.render(context)
  File "/home/adrian/skyfolk/venv/lib/python3.6/site-packages/django/template/loader_tags.py", line 177, in render
    return compiled_parent._render(context)
  File "/home/adrian/skyfolk/venv/lib/python3.6/site-packages/django/test/utils.py", line 107, in instrumented_test_render
    return self.nodelist.render(context)
  File "/home/adrian/skyfolk/venv/lib/python3.6/site-packages/django/template/base.py", line 990, in render
    bit = node.render_annotated(context)
  File "/home/adrian/skyfolk/venv/lib/python3.6/site-packages/django/template/base.py", line 957, in render_annotated
    return self.render(context)
  File "/home/adrian/skyfolk/venv/lib/python3.6/site-packages/django/template/loader_tags.py", line 177, in render
    return compiled_parent._render(context)
  File "/home/adrian/skyfolk/venv/lib/python3.6/site-packages/django/test/utils.py", line 107, in instrumented_test_render
    return self.nodelist.render(context)
  File "/home/adrian/skyfolk/venv/lib/python3.6/site-packages/django/template/base.py", line 990, in render
    bit = node.render_annotated(context)
  File "/home/adrian/skyfolk/venv/lib/python3.6/site-packages/django/template/base.py", line 957, in render_annotated
    return self.render(context)
  File "/home/adrian/skyfolk/venv/lib/python3.6/site-packages/django/template/loader_tags.py", line 177, in render
    return compiled_parent._render(context)
  File "/home/adrian/skyfolk/venv/lib/python3.6/site-packages/django/test/utils.py", line 107, in instrumented_test_render
    return self.nodelist.render(context)
  File "/home/adrian/skyfolk/venv/lib/python3.6/site-packages/django/template/base.py", line 990, in render
    bit = node.render_annotated(context)
  File "/home/adrian/skyfolk/venv/lib/python3.6/site-packages/django/template/base.py", line 957, in render_annotated
    return self.render(context)
  File "/home/adrian/skyfolk/venv/lib/python3.6/site-packages/django/template/loader_tags.py", line 72, in render
    result = block.nodelist.render(context)
  File "/home/adrian/skyfolk/venv/lib/python3.6/site-packages/django/template/base.py", line 990, in render
    bit = node.render_annotated(context)
  File "/home/adrian/skyfolk/venv/lib/python3.6/site-packages/django/template/base.py", line 957, in render_annotated
    return self.render(context)
  File "/home/adrian/skyfolk/venv/lib/python3.6/site-packages/django/template/loader_tags.py", line 72, in render
    result = block.nodelist.render(context)
  File "/home/adrian/skyfolk/venv/lib/python3.6/site-packages/django/template/base.py", line 990, in render
    bit = node.render_annotated(context)
  File "/home/adrian/skyfolk/venv/lib/python3.6/site-packages/django/template/base.py", line 957, in render_annotated
    return self.render(context)
  File "/home/adrian/skyfolk/venv/lib/python3.6/site-packages/django/template/defaulttags.py", line 216, in render
    nodelist.append(node.render_annotated(context))
  File "/home/adrian/skyfolk/venv/lib/python3.6/site-packages/django/template/base.py", line 957, in render_annotated
    return self.render(context)
  File "/home/adrian/skyfolk/venv/lib/python3.6/site-packages/django/template/base.py", line 1040, in render
    output = self.filter_expression.resolve(context)
  File "/home/adrian/skyfolk/venv/lib/python3.6/site-packages/django/template/base.py", line 708, in resolve
    obj = self.var.resolve(context)
  File "/home/adrian/skyfolk/venv/lib/python3.6/site-packages/django/template/base.py", line 849, in resolve
    value = self._resolve_lookup(context)
  File "/home/adrian/skyfolk/venv/lib/python3.6/site-packages/django/template/base.py", line 911, in _resolve_lookup
    current = current()
  File "/home/adrian/skyfolk/dash/base.py", line 556, in render_for_edit
    return render_to_string(self.get_edit_template_name(), context)
  File "/home/adrian/skyfolk/venv/lib/python3.6/site-packages/django/template/loader.py", line 68, in render_to_string
    return template.render(context, request)
  File "/home/adrian/skyfolk/venv/lib/python3.6/site-packages/django/template/backends/django.py", line 66, in render
    return self.template.render(context)
  File "/home/adrian/skyfolk/venv/lib/python3.6/site-packages/django/template/base.py", line 207, in render
    return self._render(context)
  File "/home/adrian/skyfolk/venv/lib/python3.6/site-packages/django/test/utils.py", line 107, in instrumented_test_render
    return self.nodelist.render(context)
  File "/home/adrian/skyfolk/venv/lib/python3.6/site-packages/django/template/base.py", line 990, in render
    bit = node.render_annotated(context)
  File "/home/adrian/skyfolk/venv/lib/python3.6/site-packages/django/template/base.py", line 957, in render_annotated
    return self.render(context)
  File "/home/adrian/skyfolk/venv/lib/python3.6/site-packages/django/template/defaulttags.py", line 216, in render
    nodelist.append(node.render_annotated(context))
  File "/home/adrian/skyfolk/venv/lib/python3.6/site-packages/django/template/base.py", line 957, in render_annotated
    return self.render(context)
  File "/home/adrian/skyfolk/venv/lib/python3.6/site-packages/django/template/base.py", line 1040, in render
    output = self.filter_expression.resolve(context)
  File "/home/adrian/skyfolk/venv/lib/python3.6/site-packages/django/template/base.py", line 708, in resolve
    obj = self.var.resolve(context)
  File "/home/adrian/skyfolk/venv/lib/python3.6/site-packages/django/template/base.py", line 849, in resolve
    value = self._resolve_lookup(context)
  File "/home/adrian/skyfolk/venv/lib/python3.6/site-packages/django/template/base.py", line 911, in _resolve_lookup
    current = current()
  File "/home/adrian/skyfolk/dash/base.py", line 1152, in render
    render = widget.render(request=request)
  File "/home/adrian/skyfolk/dash/contrib/plugins/service/dash_widgets.py", line 27, in render
    print(trigger.consumer.name.app_label)
AttributeError: 'ServicesActivated' object has no attribute 'app_label'
2018-01-30 13:45:41,889 ERROR exception 8941 Internal Server Error: /dashboard/edit/new_workspace/
Traceback (most recent call last):
  File "/home/adrian/skyfolk/venv/lib/python3.6/site-packages/django/core/handlers/exception.py", line 41, in inner
    response = get_response(request)
  File "/home/adrian/skyfolk/venv/lib/python3.6/site-packages/django/core/handlers/base.py", line 249, in _legacy_get_response
    response = self._get_response(request)
  File "/home/adrian/skyfolk/venv/lib/python3.6/site-packages/django/core/handlers/base.py", line 187, in _get_response
    response = self.process_exception_by_middleware(e, request)
  File "/home/adrian/skyfolk/venv/lib/python3.6/site-packages/channels/handler.py", line 243, in process_exception_by_middleware
    return super(AsgiHandler, self).process_exception_by_middleware(exception, request)
  File "/home/adrian/skyfolk/venv/lib/python3.6/site-packages/django/core/handlers/base.py", line 185, in _get_response
    response = wrapped_callback(request, *callback_args, **callback_kwargs)
  File "/home/adrian/skyfolk/venv/lib/python3.6/site-packages/django/contrib/auth/decorators.py", line 23, in _wrapped_view
    return view_func(request, *args, **kwargs)
  File "/home/adrian/skyfolk/dash/views.py", line 232, in edit_dashboard
    return render(request, template_name, context)
  File "/home/adrian/skyfolk/venv/lib/python3.6/site-packages/django/shortcuts.py", line 30, in render
    content = loader.render_to_string(template_name, context, request, using=using)
  File "/home/adrian/skyfolk/venv/lib/python3.6/site-packages/django/template/loader.py", line 68, in render_to_string
    return template.render(context, request)
  File "/home/adrian/skyfolk/venv/lib/python3.6/site-packages/django/template/backends/django.py", line 66, in render
    return self.template.render(context)
  File "/home/adrian/skyfolk/venv/lib/python3.6/site-packages/django/template/base.py", line 207, in render
    return self._render(context)
  File "/home/adrian/skyfolk/venv/lib/python3.6/site-packages/django/test/utils.py", line 107, in instrumented_test_render
    return self.nodelist.render(context)
  File "/home/adrian/skyfolk/venv/lib/python3.6/site-packages/django/template/base.py", line 990, in render
    bit = node.render_annotated(context)
  File "/home/adrian/skyfolk/venv/lib/python3.6/site-packages/django/template/base.py", line 957, in render_annotated
    return self.render(context)
  File "/home/adrian/skyfolk/venv/lib/python3.6/site-packages/django/template/loader_tags.py", line 177, in render
    return compiled_parent._render(context)
  File "/home/adrian/skyfolk/venv/lib/python3.6/site-packages/django/test/utils.py", line 107, in instrumented_test_render
    return self.nodelist.render(context)
  File "/home/adrian/skyfolk/venv/lib/python3.6/site-packages/django/template/base.py", line 990, in render
    bit = node.render_annotated(context)
  File "/home/adrian/skyfolk/venv/lib/python3.6/site-packages/django/template/base.py", line 957, in render_annotated
    return self.render(context)
  File "/home/adrian/skyfolk/venv/lib/python3.6/site-packages/django/template/loader_tags.py", line 177, in render
    return compiled_parent._render(context)
  File "/home/adrian/skyfolk/venv/lib/python3.6/site-packages/django/test/utils.py", line 107, in instrumented_test_render
    return self.nodelist.render(context)
  File "/home/adrian/skyfolk/venv/lib/python3.6/site-packages/django/template/base.py", line 990, in render
    bit = node.render_annotated(context)
  File "/home/adrian/skyfolk/venv/lib/python3.6/site-packages/django/template/base.py", line 957, in render_annotated
    return self.render(context)
  File "/home/adrian/skyfolk/venv/lib/python3.6/site-packages/django/template/loader_tags.py", line 177, in render
    return compiled_parent._render(context)
  File "/home/adrian/skyfolk/venv/lib/python3.6/site-packages/django/test/utils.py", line 107, in instrumented_test_render
    return self.nodelist.render(context)
  File "/home/adrian/skyfolk/venv/lib/python3.6/site-packages/django/template/base.py", line 990, in render
    bit = node.render_annotated(context)
  File "/home/adrian/skyfolk/venv/lib/python3.6/site-packages/django/template/base.py", line 957, in render_annotated
    return self.render(context)
  File "/home/adrian/skyfolk/venv/lib/python3.6/site-packages/django/template/loader_tags.py", line 177, in render
    return compiled_parent._render(context)
  File "/home/adrian/skyfolk/venv/lib/python3.6/site-packages/django/test/utils.py", line 107, in instrumented_test_render
    return self.nodelist.render(context)
  File "/home/adrian/skyfolk/venv/lib/python3.6/site-packages/django/template/base.py", line 990, in render
    bit = node.render_annotated(context)
  File "/home/adrian/skyfolk/venv/lib/python3.6/site-packages/django/template/base.py", line 957, in render_annotated
    return self.render(context)
  File "/home/adrian/skyfolk/venv/lib/python3.6/site-packages/django/template/loader_tags.py", line 72, in render
    result = block.nodelist.render(context)
  File "/home/adrian/skyfolk/venv/lib/python3.6/site-packages/django/template/base.py", line 990, in render
    bit = node.render_annotated(context)
  File "/home/adrian/skyfolk/venv/lib/python3.6/site-packages/django/template/base.py", line 957, in render_annotated
    return self.render(context)
  File "/home/adrian/skyfolk/venv/lib/python3.6/site-packages/django/template/loader_tags.py", line 72, in render
    result = block.nodelist.render(context)
  File "/home/adrian/skyfolk/venv/lib/python3.6/site-packages/django/template/base.py", line 990, in render
    bit = node.render_annotated(context)
  File "/home/adrian/skyfolk/venv/lib/python3.6/site-packages/django/template/base.py", line 957, in render_annotated
    return self.render(context)
  File "/home/adrian/skyfolk/venv/lib/python3.6/site-packages/django/template/defaulttags.py", line 216, in render
    nodelist.append(node.render_annotated(context))
  File "/home/adrian/skyfolk/venv/lib/python3.6/site-packages/django/template/base.py", line 957, in render_annotated
    return self.render(context)
  File "/home/adrian/skyfolk/venv/lib/python3.6/site-packages/django/template/base.py", line 1040, in render
    output = self.filter_expression.resolve(context)
  File "/home/adrian/skyfolk/venv/lib/python3.6/site-packages/django/template/base.py", line 708, in resolve
    obj = self.var.resolve(context)
  File "/home/adrian/skyfolk/venv/lib/python3.6/site-packages/django/template/base.py", line 849, in resolve
    value = self._resolve_lookup(context)
  File "/home/adrian/skyfolk/venv/lib/python3.6/site-packages/django/template/base.py", line 911, in _resolve_lookup
    current = current()
  File "/home/adrian/skyfolk/dash/base.py", line 556, in render_for_edit
    return render_to_string(self.get_edit_template_name(), context)
  File "/home/adrian/skyfolk/venv/lib/python3.6/site-packages/django/template/loader.py", line 68, in render_to_string
    return template.render(context, request)
  File "/home/adrian/skyfolk/venv/lib/python3.6/site-packages/django/template/backends/django.py", line 66, in render
    return self.template.render(context)
  File "/home/adrian/skyfolk/venv/lib/python3.6/site-packages/django/template/base.py", line 207, in render
    return self._render(context)
  File "/home/adrian/skyfolk/venv/lib/python3.6/site-packages/django/test/utils.py", line 107, in instrumented_test_render
    return self.nodelist.render(context)
  File "/home/adrian/skyfolk/venv/lib/python3.6/site-packages/django/template/base.py", line 990, in render
    bit = node.render_annotated(context)
  File "/home/adrian/skyfolk/venv/lib/python3.6/site-packages/django/template/base.py", line 957, in render_annotated
    return self.render(context)
  File "/home/adrian/skyfolk/venv/lib/python3.6/site-packages/django/template/defaulttags.py", line 216, in render
    nodelist.append(node.render_annotated(context))
  File "/home/adrian/skyfolk/venv/lib/python3.6/site-packages/django/template/base.py", line 957, in render_annotated
    return self.render(context)
  File "/home/adrian/skyfolk/venv/lib/python3.6/site-packages/django/template/base.py", line 1040, in render
    output = self.filter_expression.resolve(context)
  File "/home/adrian/skyfolk/venv/lib/python3.6/site-packages/django/template/base.py", line 708, in resolve
    obj = self.var.resolve(context)
  File "/home/adrian/skyfolk/venv/lib/python3.6/site-packages/django/template/base.py", line 849, in resolve
    value = self._resolve_lookup(context)
  File "/home/adrian/skyfolk/venv/lib/python3.6/site-packages/django/template/base.py", line 911, in _resolve_lookup
    current = current()
  File "/home/adrian/skyfolk/dash/base.py", line 1152, in render
    render = widget.render(request=request)
  File "/home/adrian/skyfolk/dash/contrib/plugins/service/dash_widgets.py", line 28, in render
    model_consumer = apps.get_model(trigger.consumer.name.name)
  File "/home/adrian/skyfolk/venv/lib/python3.6/site-packages/django/apps/registry.py", line 198, in get_model
    app_label, model_name = app_label.split('.')
ValueError: not enough values to unpack (expected 2, got 1)
2018-01-30 13:46:11,746 ERROR exception 9048 Internal Server Error: /dashboard/edit/new_workspace/
Traceback (most recent call last):
  File "/home/adrian/skyfolk/venv/lib/python3.6/site-packages/django/apps/config.py", line 169, in get_model
    return self.models[model_name.lower()]
KeyError: 'servicereddit'

During handling of the above exception, another exception occurred:

Traceback (most recent call last):
  File "/home/adrian/skyfolk/venv/lib/python3.6/site-packages/django/core/handlers/exception.py", line 41, in inner
    response = get_response(request)
  File "/home/adrian/skyfolk/venv/lib/python3.6/site-packages/django/core/handlers/base.py", line 249, in _legacy_get_response
    response = self._get_response(request)
  File "/home/adrian/skyfolk/venv/lib/python3.6/site-packages/django/core/handlers/base.py", line 187, in _get_response
    response = self.process_exception_by_middleware(e, request)
  File "/home/adrian/skyfolk/venv/lib/python3.6/site-packages/channels/handler.py", line 243, in process_exception_by_middleware
    return super(AsgiHandler, self).process_exception_by_middleware(exception, request)
  File "/home/adrian/skyfolk/venv/lib/python3.6/site-packages/django/core/handlers/base.py", line 185, in _get_response
    response = wrapped_callback(request, *callback_args, **callback_kwargs)
  File "/home/adrian/skyfolk/venv/lib/python3.6/site-packages/django/contrib/auth/decorators.py", line 23, in _wrapped_view
    return view_func(request, *args, **kwargs)
  File "/home/adrian/skyfolk/dash/views.py", line 232, in edit_dashboard
    return render(request, template_name, context)
  File "/home/adrian/skyfolk/venv/lib/python3.6/site-packages/django/shortcuts.py", line 30, in render
    content = loader.render_to_string(template_name, context, request, using=using)
  File "/home/adrian/skyfolk/venv/lib/python3.6/site-packages/django/template/loader.py", line 68, in render_to_string
    return template.render(context, request)
  File "/home/adrian/skyfolk/venv/lib/python3.6/site-packages/django/template/backends/django.py", line 66, in render
    return self.template.render(context)
  File "/home/adrian/skyfolk/venv/lib/python3.6/site-packages/django/template/base.py", line 207, in render
    return self._render(context)
  File "/home/adrian/skyfolk/venv/lib/python3.6/site-packages/django/test/utils.py", line 107, in instrumented_test_render
    return self.nodelist.render(context)
  File "/home/adrian/skyfolk/venv/lib/python3.6/site-packages/django/template/base.py", line 990, in render
    bit = node.render_annotated(context)
  File "/home/adrian/skyfolk/venv/lib/python3.6/site-packages/django/template/base.py", line 957, in render_annotated
    return self.render(context)
  File "/home/adrian/skyfolk/venv/lib/python3.6/site-packages/django/template/loader_tags.py", line 177, in render
    return compiled_parent._render(context)
  File "/home/adrian/skyfolk/venv/lib/python3.6/site-packages/django/test/utils.py", line 107, in instrumented_test_render
    return self.nodelist.render(context)
  File "/home/adrian/skyfolk/venv/lib/python3.6/site-packages/django/template/base.py", line 990, in render
    bit = node.render_annotated(context)
  File "/home/adrian/skyfolk/venv/lib/python3.6/site-packages/django/template/base.py", line 957, in render_annotated
    return self.render(context)
  File "/home/adrian/skyfolk/venv/lib/python3.6/site-packages/django/template/loader_tags.py", line 177, in render
    return compiled_parent._render(context)
  File "/home/adrian/skyfolk/venv/lib/python3.6/site-packages/django/test/utils.py", line 107, in instrumented_test_render
    return self.nodelist.render(context)
  File "/home/adrian/skyfolk/venv/lib/python3.6/site-packages/django/template/base.py", line 990, in render
    bit = node.render_annotated(context)
  File "/home/adrian/skyfolk/venv/lib/python3.6/site-packages/django/template/base.py", line 957, in render_annotated
    return self.render(context)
  File "/home/adrian/skyfolk/venv/lib/python3.6/site-packages/django/template/loader_tags.py", line 177, in render
    return compiled_parent._render(context)
  File "/home/adrian/skyfolk/venv/lib/python3.6/site-packages/django/test/utils.py", line 107, in instrumented_test_render
    return self.nodelist.render(context)
  File "/home/adrian/skyfolk/venv/lib/python3.6/site-packages/django/template/base.py", line 990, in render
    bit = node.render_annotated(context)
  File "/home/adrian/skyfolk/venv/lib/python3.6/site-packages/django/template/base.py", line 957, in render_annotated
    return self.render(context)
  File "/home/adrian/skyfolk/venv/lib/python3.6/site-packages/django/template/loader_tags.py", line 177, in render
    return compiled_parent._render(context)
  File "/home/adrian/skyfolk/venv/lib/python3.6/site-packages/django/test/utils.py", line 107, in instrumented_test_render
    return self.nodelist.render(context)
  File "/home/adrian/skyfolk/venv/lib/python3.6/site-packages/django/template/base.py", line 990, in render
    bit = node.render_annotated(context)
  File "/home/adrian/skyfolk/venv/lib/python3.6/site-packages/django/template/base.py", line 957, in render_annotated
    return self.render(context)
  File "/home/adrian/skyfolk/venv/lib/python3.6/site-packages/django/template/loader_tags.py", line 72, in render
    result = block.nodelist.render(context)
  File "/home/adrian/skyfolk/venv/lib/python3.6/site-packages/django/template/base.py", line 990, in render
    bit = node.render_annotated(context)
  File "/home/adrian/skyfolk/venv/lib/python3.6/site-packages/django/template/base.py", line 957, in render_annotated
    return self.render(context)
  File "/home/adrian/skyfolk/venv/lib/python3.6/site-packages/django/template/loader_tags.py", line 72, in render
    result = block.nodelist.render(context)
  File "/home/adrian/skyfolk/venv/lib/python3.6/site-packages/django/template/base.py", line 990, in render
    bit = node.render_annotated(context)
  File "/home/adrian/skyfolk/venv/lib/python3.6/site-packages/django/template/base.py", line 957, in render_annotated
    return self.render(context)
  File "/home/adrian/skyfolk/venv/lib/python3.6/site-packages/django/template/defaulttags.py", line 216, in render
    nodelist.append(node.render_annotated(context))
  File "/home/adrian/skyfolk/venv/lib/python3.6/site-packages/django/template/base.py", line 957, in render_annotated
    return self.render(context)
  File "/home/adrian/skyfolk/venv/lib/python3.6/site-packages/django/template/base.py", line 1040, in render
    output = self.filter_expression.resolve(context)
  File "/home/adrian/skyfolk/venv/lib/python3.6/site-packages/django/template/base.py", line 708, in resolve
    obj = self.var.resolve(context)
  File "/home/adrian/skyfolk/venv/lib/python3.6/site-packages/django/template/base.py", line 849, in resolve
    value = self._resolve_lookup(context)
  File "/home/adrian/skyfolk/venv/lib/python3.6/site-packages/django/template/base.py", line 911, in _resolve_lookup
    current = current()
  File "/home/adrian/skyfolk/dash/base.py", line 556, in render_for_edit
    return render_to_string(self.get_edit_template_name(), context)
  File "/home/adrian/skyfolk/venv/lib/python3.6/site-packages/django/template/loader.py", line 68, in render_to_string
    return template.render(context, request)
  File "/home/adrian/skyfolk/venv/lib/python3.6/site-packages/django/template/backends/django.py", line 66, in render
    return self.template.render(context)
  File "/home/adrian/skyfolk/venv/lib/python3.6/site-packages/django/template/base.py", line 207, in render
    return self._render(context)
  File "/home/adrian/skyfolk/venv/lib/python3.6/site-packages/django/test/utils.py", line 107, in instrumented_test_render
    return self.nodelist.render(context)
  File "/home/adrian/skyfolk/venv/lib/python3.6/site-packages/django/template/base.py", line 990, in render
    bit = node.render_annotated(context)
  File "/home/adrian/skyfolk/venv/lib/python3.6/site-packages/django/template/base.py", line 957, in render_annotated
    return self.render(context)
  File "/home/adrian/skyfolk/venv/lib/python3.6/site-packages/django/template/defaulttags.py", line 216, in render
    nodelist.append(node.render_annotated(context))
  File "/home/adrian/skyfolk/venv/lib/python3.6/site-packages/django/template/base.py", line 957, in render_annotated
    return self.render(context)
  File "/home/adrian/skyfolk/venv/lib/python3.6/site-packages/django/template/base.py", line 1040, in render
    output = self.filter_expression.resolve(context)
  File "/home/adrian/skyfolk/venv/lib/python3.6/site-packages/django/template/base.py", line 708, in resolve
    obj = self.var.resolve(context)
  File "/home/adrian/skyfolk/venv/lib/python3.6/site-packages/django/template/base.py", line 849, in resolve
    value = self._resolve_lookup(context)
  File "/home/adrian/skyfolk/venv/lib/python3.6/site-packages/django/template/base.py", line 911, in _resolve_lookup
    current = current()
  File "/home/adrian/skyfolk/dash/base.py", line 1152, in render
    render = widget.render(request=request)
  File "/home/adrian/skyfolk/dash/contrib/plugins/service/dash_widgets.py", line 27, in render
    model_consumer = apps.get_model(trigger.consumer.name._meta.app_label, trigger.consumer.name.name)
  File "/home/adrian/skyfolk/venv/lib/python3.6/site-packages/django/apps/registry.py", line 205, in get_model
    return app_config.get_model(model_name, require_ready=require_ready)
  File "/home/adrian/skyfolk/venv/lib/python3.6/site-packages/django/apps/config.py", line 172, in get_model
    "App '%s' doesn't have a '%s' model." % (self.label, model_name))
LookupError: App 'dash_services' doesn't have a 'ServiceReddit' model.
2018-01-30 13:47:47,992 INFO publish 9276 adrian - ServiceTwitter - ServiceRss - Rss - 2 new data
2018-01-30 13:47:48,272 INFO publish 9276 adrian - ServiceReddit - ServiceRss - reddit to rss - 2 new data
2018-01-30 13:47:48,547 INFO publish 9276 adrian - ServiceTwitter - ServiceReddit - lolazo - 0 new data
2018-01-30 13:48:14,539 INFO publish 9448 adrian - ServiceReddit - ServiceRss - reddit to rss - 2 new data
2018-01-30 13:58:24,200 ERROR exception 11015 Internal Server Error: /th/service/add/ServiceEvernote
Traceback (most recent call last):
  File "/home/adrian/skyfolk/venv/lib/python3.6/site-packages/django/core/handlers/exception.py", line 41, in inner
    response = get_response(request)
  File "/home/adrian/skyfolk/venv/lib/python3.6/site-packages/django/core/handlers/base.py", line 249, in _legacy_get_response
    response = self._get_response(request)
  File "/home/adrian/skyfolk/venv/lib/python3.6/site-packages/django/core/handlers/base.py", line 187, in _get_response
    response = self.process_exception_by_middleware(e, request)
  File "/home/adrian/skyfolk/venv/lib/python3.6/site-packages/channels/handler.py", line 243, in process_exception_by_middleware
    return super(AsgiHandler, self).process_exception_by_middleware(exception, request)
  File "/home/adrian/skyfolk/venv/lib/python3.6/site-packages/django/core/handlers/base.py", line 185, in _get_response
    response = wrapped_callback(request, *callback_args, **callback_kwargs)
  File "/home/adrian/skyfolk/venv/lib/python3.6/site-packages/django/views/generic/base.py", line 68, in view
    return self.dispatch(request, *args, **kwargs)
  File "/home/adrian/skyfolk/venv/lib/python3.6/site-packages/django/utils/decorators.py", line 67, in _wrapper
    return bound_func(*args, **kwargs)
  File "/home/adrian/skyfolk/venv/lib/python3.6/site-packages/django/contrib/auth/decorators.py", line 23, in _wrapped_view
    return view_func(request, *args, **kwargs)
  File "/home/adrian/skyfolk/venv/lib/python3.6/site-packages/django/utils/decorators.py", line 63, in bound_func
    return func.__get__(self, type(self))(*args2, **kwargs2)
  File "/home/adrian/skyfolk/dash_services/views_userservices.py", line 110, in dispatch
    return super(UserServiceCreateView, self).dispatch(*args, **kwargs)
  File "/home/adrian/skyfolk/venv/lib/python3.6/site-packages/django/views/generic/base.py", line 88, in dispatch
    return handler(request, *args, **kwargs)
  File "/home/adrian/skyfolk/venv/lib/python3.6/site-packages/django/views/generic/edit.py", line 217, in post
    return super(BaseCreateView, self).post(request, *args, **kwargs)
  File "/home/adrian/skyfolk/venv/lib/python3.6/site-packages/django/views/generic/edit.py", line 183, in post
    return self.form_valid(form)
  File "/home/adrian/skyfolk/dash_services/views_userservices.py", line 122, in form_valid
    default_provider.load_services()
  File "/home/adrian/skyfolk/dash_services/service_provider.py", line 15, in load_services
    klass = import_from_path(class_path)
  File "/home/adrian/skyfolk/dash_services/service_provider.py", line 39, in import_from_path
    return getattr(__import__(module_name, fromlist=[class_name]), class_name)
  File "/home/adrian/skyfolk/th_evernote/my_evernote.py", line 9, in <module>
    from django_th.services.services import ServicesMgr
ModuleNotFoundError: No module named 'django_th'
2018-01-30 13:59:33,079 ERROR exception 11338 Internal Server Error: /th/service/add/ServiceEvernote
Traceback (most recent call last):
  File "/home/adrian/skyfolk/venv/lib/python3.6/site-packages/django/core/handlers/exception.py", line 41, in inner
    response = get_response(request)
  File "/home/adrian/skyfolk/venv/lib/python3.6/site-packages/django/core/handlers/base.py", line 249, in _legacy_get_response
    response = self._get_response(request)
  File "/home/adrian/skyfolk/venv/lib/python3.6/site-packages/django/core/handlers/base.py", line 187, in _get_response
    response = self.process_exception_by_middleware(e, request)
  File "/home/adrian/skyfolk/venv/lib/python3.6/site-packages/channels/handler.py", line 243, in process_exception_by_middleware
    return super(AsgiHandler, self).process_exception_by_middleware(exception, request)
  File "/home/adrian/skyfolk/venv/lib/python3.6/site-packages/django/core/handlers/base.py", line 185, in _get_response
    response = wrapped_callback(request, *callback_args, **callback_kwargs)
  File "/home/adrian/skyfolk/venv/lib/python3.6/site-packages/django/views/generic/base.py", line 68, in view
    return self.dispatch(request, *args, **kwargs)
  File "/home/adrian/skyfolk/venv/lib/python3.6/site-packages/django/utils/decorators.py", line 67, in _wrapper
    return bound_func(*args, **kwargs)
  File "/home/adrian/skyfolk/venv/lib/python3.6/site-packages/django/contrib/auth/decorators.py", line 23, in _wrapped_view
    return view_func(request, *args, **kwargs)
  File "/home/adrian/skyfolk/venv/lib/python3.6/site-packages/django/utils/decorators.py", line 63, in bound_func
    return func.__get__(self, type(self))(*args2, **kwargs2)
  File "/home/adrian/skyfolk/dash_services/views_userservices.py", line 110, in dispatch
    return super(UserServiceCreateView, self).dispatch(*args, **kwargs)
  File "/home/adrian/skyfolk/venv/lib/python3.6/site-packages/django/views/generic/base.py", line 88, in dispatch
    return handler(request, *args, **kwargs)
  File "/home/adrian/skyfolk/venv/lib/python3.6/site-packages/django/views/generic/edit.py", line 217, in post
    return super(BaseCreateView, self).post(request, *args, **kwargs)
  File "/home/adrian/skyfolk/venv/lib/python3.6/site-packages/django/views/generic/edit.py", line 183, in post
    return self.form_valid(form)
  File "/home/adrian/skyfolk/dash_services/views_userservices.py", line 130, in form_valid
    return redirect(lets_auth(self.request))
  File "/home/adrian/skyfolk/th_evernote/my_evernote.py", line 276, in auth
    request.session['oauth_token'] = request_token['oauth_token']
KeyError: 'oauth_token'
2018-01-30 14:02:12,258 ERROR exception 11338 Internal Server Error: /th/service/renew/4
Traceback (most recent call last):
  File "/home/adrian/skyfolk/venv/lib/python3.6/site-packages/django/core/handlers/exception.py", line 41, in inner
    response = get_response(request)
  File "/home/adrian/skyfolk/venv/lib/python3.6/site-packages/django/core/handlers/base.py", line 249, in _legacy_get_response
    response = self._get_response(request)
  File "/home/adrian/skyfolk/venv/lib/python3.6/site-packages/django/core/handlers/base.py", line 187, in _get_response
    response = self.process_exception_by_middleware(e, request)
  File "/home/adrian/skyfolk/venv/lib/python3.6/site-packages/channels/handler.py", line 243, in process_exception_by_middleware
    return super(AsgiHandler, self).process_exception_by_middleware(exception, request)
  File "/home/adrian/skyfolk/venv/lib/python3.6/site-packages/django/core/handlers/base.py", line 185, in _get_response
    response = wrapped_callback(request, *callback_args, **callback_kwargs)
  File "/home/adrian/skyfolk/dash_services/views_userservices.py", line 35, in renew_service
    return redirect(lets_auth(request))
  File "/home/adrian/skyfolk/th_evernote/my_evernote.py", line 276, in auth
    request.session['oauth_token'] = request_token['oauth_token']
KeyError: 'oauth_token'
2018-01-30 14:02:44,412 ERROR exception 11816 Internal Server Error: /th/service/renew/4
Traceback (most recent call last):
  File "/home/adrian/skyfolk/venv/lib/python3.6/site-packages/django/core/handlers/exception.py", line 41, in inner
    response = get_response(request)
  File "/home/adrian/skyfolk/venv/lib/python3.6/site-packages/django/core/handlers/base.py", line 249, in _legacy_get_response
    response = self._get_response(request)
  File "/home/adrian/skyfolk/venv/lib/python3.6/site-packages/django/core/handlers/base.py", line 187, in _get_response
    response = self.process_exception_by_middleware(e, request)
  File "/home/adrian/skyfolk/venv/lib/python3.6/site-packages/channels/handler.py", line 243, in process_exception_by_middleware
    return super(AsgiHandler, self).process_exception_by_middleware(exception, request)
  File "/home/adrian/skyfolk/venv/lib/python3.6/site-packages/django/core/handlers/base.py", line 185, in _get_response
    response = wrapped_callback(request, *callback_args, **callback_kwargs)
  File "/home/adrian/skyfolk/dash_services/views_userservices.py", line 35, in renew_service
    return redirect(lets_auth(request))
  File "/home/adrian/skyfolk/th_evernote/my_evernote.py", line 277, in auth
    request.session['oauth_token'] = request_token['oauth_token']
KeyError: 'oauth_token'
2018-01-30 14:04:19,196 ERROR exception 11816 Internal Server Error: /th/service/renew/4
Traceback (most recent call last):
  File "/home/adrian/skyfolk/venv/lib/python3.6/site-packages/django/core/handlers/exception.py", line 41, in inner
    response = get_response(request)
  File "/home/adrian/skyfolk/venv/lib/python3.6/site-packages/django/core/handlers/base.py", line 249, in _legacy_get_response
    response = self._get_response(request)
  File "/home/adrian/skyfolk/venv/lib/python3.6/site-packages/django/core/handlers/base.py", line 187, in _get_response
    response = self.process_exception_by_middleware(e, request)
  File "/home/adrian/skyfolk/venv/lib/python3.6/site-packages/channels/handler.py", line 243, in process_exception_by_middleware
    return super(AsgiHandler, self).process_exception_by_middleware(exception, request)
  File "/home/adrian/skyfolk/venv/lib/python3.6/site-packages/django/core/handlers/base.py", line 185, in _get_response
    response = wrapped_callback(request, *callback_args, **callback_kwargs)
  File "/home/adrian/skyfolk/dash_services/views_userservices.py", line 35, in renew_service
    return redirect(lets_auth(request))
  File "/home/adrian/skyfolk/th_evernote/my_evernote.py", line 277, in auth
    request.session['oauth_token'] = request_token['oauth_token']
KeyError: 'oauth_token'
2018-01-30 14:05:32,726 ERROR exception 12151 Internal Server Error: /th/service/renew/4
Traceback (most recent call last):
  File "/home/adrian/skyfolk/venv/lib/python3.6/site-packages/django/core/handlers/exception.py", line 41, in inner
    response = get_response(request)
  File "/home/adrian/skyfolk/venv/lib/python3.6/site-packages/django/core/handlers/base.py", line 249, in _legacy_get_response
    response = self._get_response(request)
  File "/home/adrian/skyfolk/venv/lib/python3.6/site-packages/django/core/handlers/base.py", line 187, in _get_response
    response = self.process_exception_by_middleware(e, request)
  File "/home/adrian/skyfolk/venv/lib/python3.6/site-packages/channels/handler.py", line 243, in process_exception_by_middleware
    return super(AsgiHandler, self).process_exception_by_middleware(exception, request)
  File "/home/adrian/skyfolk/venv/lib/python3.6/site-packages/django/core/handlers/base.py", line 185, in _get_response
    response = wrapped_callback(request, *callback_args, **callback_kwargs)
  File "/home/adrian/skyfolk/dash_services/views_userservices.py", line 35, in renew_service
    return redirect(lets_auth(request))
  File "/home/adrian/skyfolk/th_evernote/my_evernote.py", line 277, in auth
    request.session['oauth_token'] = request_token['oauth_token']
KeyError: 'oauth_token'
2018-01-30 14:07:20,883 ERROR exception 12219 Internal Server Error: /th/service/add/ServiceEvernote
Traceback (most recent call last):
  File "/home/adrian/skyfolk/venv/lib/python3.6/site-packages/django/core/handlers/exception.py", line 41, in inner
    response = get_response(request)
  File "/home/adrian/skyfolk/venv/lib/python3.6/site-packages/django/core/handlers/base.py", line 249, in _legacy_get_response
    response = self._get_response(request)
  File "/home/adrian/skyfolk/venv/lib/python3.6/site-packages/django/core/handlers/base.py", line 187, in _get_response
    response = self.process_exception_by_middleware(e, request)
  File "/home/adrian/skyfolk/venv/lib/python3.6/site-packages/channels/handler.py", line 243, in process_exception_by_middleware
    return super(AsgiHandler, self).process_exception_by_middleware(exception, request)
  File "/home/adrian/skyfolk/venv/lib/python3.6/site-packages/django/core/handlers/base.py", line 185, in _get_response
    response = wrapped_callback(request, *callback_args, **callback_kwargs)
  File "/home/adrian/skyfolk/venv/lib/python3.6/site-packages/django/views/generic/base.py", line 68, in view
    return self.dispatch(request, *args, **kwargs)
  File "/home/adrian/skyfolk/venv/lib/python3.6/site-packages/django/utils/decorators.py", line 67, in _wrapper
    return bound_func(*args, **kwargs)
  File "/home/adrian/skyfolk/venv/lib/python3.6/site-packages/django/contrib/auth/decorators.py", line 23, in _wrapped_view
    return view_func(request, *args, **kwargs)
  File "/home/adrian/skyfolk/venv/lib/python3.6/site-packages/django/utils/decorators.py", line 63, in bound_func
    return func.__get__(self, type(self))(*args2, **kwargs2)
  File "/home/adrian/skyfolk/dash_services/views_userservices.py", line 110, in dispatch
    return super(UserServiceCreateView, self).dispatch(*args, **kwargs)
  File "/home/adrian/skyfolk/venv/lib/python3.6/site-packages/django/views/generic/base.py", line 88, in dispatch
    return handler(request, *args, **kwargs)
  File "/home/adrian/skyfolk/venv/lib/python3.6/site-packages/django/views/generic/edit.py", line 217, in post
    return super(BaseCreateView, self).post(request, *args, **kwargs)
  File "/home/adrian/skyfolk/venv/lib/python3.6/site-packages/django/views/generic/edit.py", line 183, in post
    return self.form_valid(form)
  File "/home/adrian/skyfolk/dash_services/views_userservices.py", line 130, in form_valid
    return redirect(lets_auth(self.request))
  File "/home/adrian/skyfolk/th_evernote/my_evernote.py", line 279, in auth
    request.session['oauth_token'] = request_token['oauth_token']
KeyError: 'oauth_token'
2018-01-30 14:08:19,790 ERROR exception 12524 Internal Server Error: /th/service/add/ServiceEvernote
Traceback (most recent call last):
  File "/home/adrian/skyfolk/venv/lib/python3.6/site-packages/django/core/handlers/exception.py", line 41, in inner
    response = get_response(request)
  File "/home/adrian/skyfolk/venv/lib/python3.6/site-packages/django/core/handlers/base.py", line 249, in _legacy_get_response
    response = self._get_response(request)
  File "/home/adrian/skyfolk/venv/lib/python3.6/site-packages/django/core/handlers/base.py", line 187, in _get_response
    response = self.process_exception_by_middleware(e, request)
  File "/home/adrian/skyfolk/venv/lib/python3.6/site-packages/channels/handler.py", line 243, in process_exception_by_middleware
    return super(AsgiHandler, self).process_exception_by_middleware(exception, request)
  File "/home/adrian/skyfolk/venv/lib/python3.6/site-packages/django/core/handlers/base.py", line 185, in _get_response
    response = wrapped_callback(request, *callback_args, **callback_kwargs)
  File "/home/adrian/skyfolk/venv/lib/python3.6/site-packages/django/views/generic/base.py", line 68, in view
    return self.dispatch(request, *args, **kwargs)
  File "/home/adrian/skyfolk/venv/lib/python3.6/site-packages/django/utils/decorators.py", line 67, in _wrapper
    return bound_func(*args, **kwargs)
  File "/home/adrian/skyfolk/venv/lib/python3.6/site-packages/django/contrib/auth/decorators.py", line 23, in _wrapped_view
    return view_func(request, *args, **kwargs)
  File "/home/adrian/skyfolk/venv/lib/python3.6/site-packages/django/utils/decorators.py", line 63, in bound_func
    return func.__get__(self, type(self))(*args2, **kwargs2)
  File "/home/adrian/skyfolk/dash_services/views_userservices.py", line 110, in dispatch
    return super(UserServiceCreateView, self).dispatch(*args, **kwargs)
  File "/home/adrian/skyfolk/venv/lib/python3.6/site-packages/django/views/generic/base.py", line 88, in dispatch
    return handler(request, *args, **kwargs)
  File "/home/adrian/skyfolk/venv/lib/python3.6/site-packages/django/views/generic/edit.py", line 217, in post
    return super(BaseCreateView, self).post(request, *args, **kwargs)
  File "/home/adrian/skyfolk/venv/lib/python3.6/site-packages/django/views/generic/edit.py", line 183, in post
    return self.form_valid(form)
  File "/home/adrian/skyfolk/dash_services/views_userservices.py", line 130, in form_valid
    return redirect(lets_auth(self.request))
  File "/home/adrian/skyfolk/th_evernote/my_evernote.py", line 276, in auth
    request.session['oauth_token'] = request_token['oauth_token']
KeyError: 'oauth_token'
2018-01-30 15:57:48,528 ERROR exception 13786 Internal Server Error: /th/service/add/ServiceEvernote
Traceback (most recent call last):
  File "/home/adrian/skyfolk/venv/lib/python3.6/site-packages/django/core/handlers/exception.py", line 41, in inner
    response = get_response(request)
  File "/home/adrian/skyfolk/venv/lib/python3.6/site-packages/django/core/handlers/base.py", line 249, in _legacy_get_response
    response = self._get_response(request)
  File "/home/adrian/skyfolk/venv/lib/python3.6/site-packages/django/core/handlers/base.py", line 187, in _get_response
    response = self.process_exception_by_middleware(e, request)
  File "/home/adrian/skyfolk/venv/lib/python3.6/site-packages/channels/handler.py", line 243, in process_exception_by_middleware
    return super(AsgiHandler, self).process_exception_by_middleware(exception, request)
  File "/home/adrian/skyfolk/venv/lib/python3.6/site-packages/django/core/handlers/base.py", line 185, in _get_response
    response = wrapped_callback(request, *callback_args, **callback_kwargs)
  File "/home/adrian/skyfolk/venv/lib/python3.6/site-packages/django/views/generic/base.py", line 68, in view
    return self.dispatch(request, *args, **kwargs)
  File "/home/adrian/skyfolk/venv/lib/python3.6/site-packages/django/utils/decorators.py", line 67, in _wrapper
    return bound_func(*args, **kwargs)
  File "/home/adrian/skyfolk/venv/lib/python3.6/site-packages/django/contrib/auth/decorators.py", line 23, in _wrapped_view
    return view_func(request, *args, **kwargs)
  File "/home/adrian/skyfolk/venv/lib/python3.6/site-packages/django/utils/decorators.py", line 63, in bound_func
    return func.__get__(self, type(self))(*args2, **kwargs2)
  File "/home/adrian/skyfolk/dash_services/views_userservices.py", line 110, in dispatch
    return super(UserServiceCreateView, self).dispatch(*args, **kwargs)
  File "/home/adrian/skyfolk/venv/lib/python3.6/site-packages/django/views/generic/base.py", line 88, in dispatch
    return handler(request, *args, **kwargs)
  File "/home/adrian/skyfolk/venv/lib/python3.6/site-packages/django/views/generic/edit.py", line 217, in post
    return super(BaseCreateView, self).post(request, *args, **kwargs)
  File "/home/adrian/skyfolk/venv/lib/python3.6/site-packages/django/views/generic/edit.py", line 183, in post
    return self.form_valid(form)
  File "/home/adrian/skyfolk/dash_services/views_userservices.py", line 130, in form_valid
    return redirect(lets_auth(self.request))
  File "/home/adrian/skyfolk/th_evernote/my_evernote.py", line 276, in auth
    request.session['oauth_token'] = request_token['oauth_token']
KeyError: 'oauth_token'
2018-01-30 15:58:36,178 ERROR exception 13959 Internal Server Error: /th/service/add/ServiceEvernote
Traceback (most recent call last):
  File "/home/adrian/skyfolk/venv/lib/python3.6/site-packages/django/core/handlers/exception.py", line 41, in inner
    response = get_response(request)
  File "/home/adrian/skyfolk/venv/lib/python3.6/site-packages/django/core/handlers/base.py", line 249, in _legacy_get_response
    response = self._get_response(request)
  File "/home/adrian/skyfolk/venv/lib/python3.6/site-packages/django/core/handlers/base.py", line 187, in _get_response
    response = self.process_exception_by_middleware(e, request)
  File "/home/adrian/skyfolk/venv/lib/python3.6/site-packages/channels/handler.py", line 243, in process_exception_by_middleware
    return super(AsgiHandler, self).process_exception_by_middleware(exception, request)
  File "/home/adrian/skyfolk/venv/lib/python3.6/site-packages/django/core/handlers/base.py", line 185, in _get_response
    response = wrapped_callback(request, *callback_args, **callback_kwargs)
  File "/home/adrian/skyfolk/venv/lib/python3.6/site-packages/django/views/generic/base.py", line 68, in view
    return self.dispatch(request, *args, **kwargs)
  File "/home/adrian/skyfolk/venv/lib/python3.6/site-packages/django/utils/decorators.py", line 67, in _wrapper
    return bound_func(*args, **kwargs)
  File "/home/adrian/skyfolk/venv/lib/python3.6/site-packages/django/contrib/auth/decorators.py", line 23, in _wrapped_view
    return view_func(request, *args, **kwargs)
  File "/home/adrian/skyfolk/venv/lib/python3.6/site-packages/django/utils/decorators.py", line 63, in bound_func
    return func.__get__(self, type(self))(*args2, **kwargs2)
  File "/home/adrian/skyfolk/dash_services/views_userservices.py", line 110, in dispatch
    return super(UserServiceCreateView, self).dispatch(*args, **kwargs)
  File "/home/adrian/skyfolk/venv/lib/python3.6/site-packages/django/views/generic/base.py", line 88, in dispatch
    return handler(request, *args, **kwargs)
  File "/home/adrian/skyfolk/venv/lib/python3.6/site-packages/django/views/generic/edit.py", line 217, in post
    return super(BaseCreateView, self).post(request, *args, **kwargs)
  File "/home/adrian/skyfolk/venv/lib/python3.6/site-packages/django/views/generic/edit.py", line 183, in post
    return self.form_valid(form)
  File "/home/adrian/skyfolk/dash_services/views_userservices.py", line 130, in form_valid
    return redirect(lets_auth(self.request))
  File "/home/adrian/skyfolk/th_evernote/my_evernote.py", line 277, in auth
    request.session['oauth_token'] = request_token['oauth_token']
KeyError: 'oauth_token'
2018-01-30 16:03:53,805 INFO publish 15734 adrian - ServiceTwitter - ServiceEvernote - Twitter to evernote - 0 new data
2018-01-30 16:04:58,118 INFO publish 16046 adrian - ServiceTwitter - ServiceRss - Rss - 2 new data
2018-01-30 16:04:58,360 INFO publish 16046 adrian - ServiceReddit - ServiceRss - reddit to rss - 2 new data
2018-01-30 16:04:59,571 WARNING publish 16046 adrian - ServiceTwitter - ServiceEvernote - Twitter to evernote AN ERROR OCCURS 
2018-01-30 16:06:56,027 INFO publish 17315 adrian - ServiceTwitter - ServiceRss - Rss - 2 new data
2018-01-30 16:06:56,302 INFO publish 17315 adrian - ServiceReddit - ServiceRss - reddit to rss - 2 new data
2018-01-30 16:08:22,142 INFO publish 17571 adrian - ServiceTwitter - ServiceRss - Rss - 2 new data
2018-01-30 16:08:22,417 INFO publish 17571 adrian - ServiceReddit - ServiceRss - reddit to rss - 2 new data
2018-01-30 16:28:56,811 ERROR exception 21039 Internal Server Error: /th/service/renew/4
Traceback (most recent call last):
  File "/home/adrian/skyfolk/venv/lib/python3.6/site-packages/django/core/handlers/exception.py", line 41, in inner
    response = get_response(request)
  File "/home/adrian/skyfolk/venv/lib/python3.6/site-packages/django/core/handlers/base.py", line 249, in _legacy_get_response
    response = self._get_response(request)
  File "/home/adrian/skyfolk/venv/lib/python3.6/site-packages/django/core/handlers/base.py", line 187, in _get_response
    response = self.process_exception_by_middleware(e, request)
  File "/home/adrian/skyfolk/venv/lib/python3.6/site-packages/channels/handler.py", line 243, in process_exception_by_middleware
    return super(AsgiHandler, self).process_exception_by_middleware(exception, request)
  File "/home/adrian/skyfolk/venv/lib/python3.6/site-packages/django/core/handlers/base.py", line 185, in _get_response
    response = wrapped_callback(request, *callback_args, **callback_kwargs)
  File "/home/adrian/skyfolk/dash_services/views_userservices.py", line 29, in renew_service
    default_provider.load_services()
  File "/home/adrian/skyfolk/dash_services/service_provider.py", line 15, in load_services
    klass = import_from_path(class_path)
  File "/home/adrian/skyfolk/dash_services/service_provider.py", line 39, in import_from_path
    return getattr(__import__(module_name, fromlist=[class_name]), class_name)
  File "/home/adrian/skyfolk/th_evernote/my_evernote.py", line 10, in <module>
    from das.models import UserService, ServicesActivated, update_result
ModuleNotFoundError: No module named 'das'
2018-01-30 16:29:18,404 ERROR exception 21039 Internal Server Error: /th/service/renew/4
Traceback (most recent call last):
  File "/home/adrian/skyfolk/venv/lib/python3.6/site-packages/django/core/handlers/exception.py", line 41, in inner
    response = get_response(request)
  File "/home/adrian/skyfolk/venv/lib/python3.6/site-packages/django/core/handlers/base.py", line 249, in _legacy_get_response
    response = self._get_response(request)
  File "/home/adrian/skyfolk/venv/lib/python3.6/site-packages/django/core/handlers/base.py", line 187, in _get_response
    response = self.process_exception_by_middleware(e, request)
  File "/home/adrian/skyfolk/venv/lib/python3.6/site-packages/channels/handler.py", line 243, in process_exception_by_middleware
    return super(AsgiHandler, self).process_exception_by_middleware(exception, request)
  File "/home/adrian/skyfolk/venv/lib/python3.6/site-packages/django/core/handlers/base.py", line 185, in _get_response
    response = wrapped_callback(request, *callback_args, **callback_kwargs)
  File "/home/adrian/skyfolk/dash_services/views_userservices.py", line 35, in renew_service
    return redirect(lets_auth(request))
  File "/home/adrian/skyfolk/th_evernote/my_evernote.py", line 276, in auth
    request.session['oauth_token'] = request_token['oauth_token']
KeyError: 'oauth_token'
2018-01-30 16:29:21,283 ERROR exception 21039 Internal Server Error: /th/service/renew/4
Traceback (most recent call last):
  File "/home/adrian/skyfolk/venv/lib/python3.6/site-packages/django/core/handlers/exception.py", line 41, in inner
    response = get_response(request)
  File "/home/adrian/skyfolk/venv/lib/python3.6/site-packages/django/core/handlers/base.py", line 249, in _legacy_get_response
    response = self._get_response(request)
  File "/home/adrian/skyfolk/venv/lib/python3.6/site-packages/django/core/handlers/base.py", line 187, in _get_response
    response = self.process_exception_by_middleware(e, request)
  File "/home/adrian/skyfolk/venv/lib/python3.6/site-packages/channels/handler.py", line 243, in process_exception_by_middleware
    return super(AsgiHandler, self).process_exception_by_middleware(exception, request)
  File "/home/adrian/skyfolk/venv/lib/python3.6/site-packages/django/core/handlers/base.py", line 185, in _get_response
    response = wrapped_callback(request, *callback_args, **callback_kwargs)
  File "/home/adrian/skyfolk/dash_services/views_userservices.py", line 35, in renew_service
    return redirect(lets_auth(request))
  File "/home/adrian/skyfolk/th_evernote/my_evernote.py", line 276, in auth
    request.session['oauth_token'] = request_token['oauth_token']
KeyError: 'oauth_token'
2018-01-30 16:29:45,975 ERROR exception 21039 Internal Server Error: /th/service/renew/4
Traceback (most recent call last):
  File "/home/adrian/skyfolk/venv/lib/python3.6/site-packages/django/core/handlers/exception.py", line 41, in inner
    response = get_response(request)
  File "/home/adrian/skyfolk/venv/lib/python3.6/site-packages/django/core/handlers/base.py", line 249, in _legacy_get_response
    response = self._get_response(request)
  File "/home/adrian/skyfolk/venv/lib/python3.6/site-packages/django/core/handlers/base.py", line 187, in _get_response
    response = self.process_exception_by_middleware(e, request)
  File "/home/adrian/skyfolk/venv/lib/python3.6/site-packages/channels/handler.py", line 243, in process_exception_by_middleware
    return super(AsgiHandler, self).process_exception_by_middleware(exception, request)
  File "/home/adrian/skyfolk/venv/lib/python3.6/site-packages/django/core/handlers/base.py", line 185, in _get_response
    response = wrapped_callback(request, *callback_args, **callback_kwargs)
  File "/home/adrian/skyfolk/dash_services/views_userservices.py", line 35, in renew_service
    return redirect(lets_auth(request))
  File "/home/adrian/skyfolk/th_evernote/my_evernote.py", line 276, in auth
    request.session['oauth_token'] = request_token['oauth_token']
KeyError: 'oauth_token'
2018-01-30 16:29:48,075 ERROR exception 21039 Internal Server Error: /th/service/renew/4
Traceback (most recent call last):
  File "/home/adrian/skyfolk/venv/lib/python3.6/site-packages/django/core/handlers/exception.py", line 41, in inner
    response = get_response(request)
  File "/home/adrian/skyfolk/venv/lib/python3.6/site-packages/django/core/handlers/base.py", line 249, in _legacy_get_response
    response = self._get_response(request)
  File "/home/adrian/skyfolk/venv/lib/python3.6/site-packages/django/core/handlers/base.py", line 187, in _get_response
    response = self.process_exception_by_middleware(e, request)
  File "/home/adrian/skyfolk/venv/lib/python3.6/site-packages/channels/handler.py", line 243, in process_exception_by_middleware
    return super(AsgiHandler, self).process_exception_by_middleware(exception, request)
  File "/home/adrian/skyfolk/venv/lib/python3.6/site-packages/django/core/handlers/base.py", line 185, in _get_response
    response = wrapped_callback(request, *callback_args, **callback_kwargs)
  File "/home/adrian/skyfolk/dash_services/views_userservices.py", line 35, in renew_service
    return redirect(lets_auth(request))
  File "/home/adrian/skyfolk/th_evernote/my_evernote.py", line 276, in auth
    request.session['oauth_token'] = request_token['oauth_token']
KeyError: 'oauth_token'
