2018-02-18 14:29:45,748 ERROR exception 22727 Internal Server Error: /
Traceback (most recent call last):
  File "/home/adrian/skyfolk/venv/lib/python3.6/site-packages/django/db/backends/utils.py", line 64, in execute
    return self.cursor.execute(sql, params)
  File "/home/adrian/skyfolk/venv/lib/python3.6/site-packages/django/db/backends/sqlite3/base.py", line 328, in execute
    return Database.Cursor.execute(self, query, params)
sqlite3.OperationalError: no such table: django_site

The above exception was the direct cause of the following exception:

Traceback (most recent call last):
  File "/home/adrian/skyfolk/venv/lib/python3.6/site-packages/django/core/handlers/exception.py", line 41, in inner
    response = get_response(request)
  File "/home/adrian/skyfolk/venv/lib/python3.6/site-packages/django/core/handlers/base.py", line 249, in _legacy_get_response
    response = self._get_response(request)
  File "/home/adrian/skyfolk/venv/lib/python3.6/site-packages/django/core/handlers/base.py", line 187, in _get_response
    response = self.process_exception_by_middleware(e, request)
  File "/home/adrian/skyfolk/venv/lib/python3.6/site-packages/channels/handler.py", line 243, in process_exception_by_middleware
    return super(AsgiHandler, self).process_exception_by_middleware(exception, request)
  File "/home/adrian/skyfolk/venv/lib/python3.6/site-packages/django/core/handlers/base.py", line 185, in _get_response
    response = wrapped_callback(request, *callback_args, **callback_kwargs)
  File "/home/adrian/skyfolk/venv/lib/python3.6/site-packages/django/views/generic/base.py", line 68, in view
    return self.dispatch(request, *args, **kwargs)
  File "/home/adrian/skyfolk/venv/lib/python3.6/site-packages/django/utils/decorators.py", line 67, in _wrapper
    return bound_func(*args, **kwargs)
  File "/home/adrian/skyfolk/venv/lib/python3.6/site-packages/django/views/decorators/debug.py", line 76, in sensitive_post_parameters_wrapper
    return view(request, *args, **kwargs)
  File "/home/adrian/skyfolk/venv/lib/python3.6/site-packages/django/utils/decorators.py", line 63, in bound_func
    return func.__get__(self, type(self))(*args2, **kwargs2)
  File "/home/adrian/skyfolk/venv/lib/python3.6/site-packages/allauth/account/views.py", line 137, in dispatch
    return super(LoginView, self).dispatch(request, *args, **kwargs)
  File "/home/adrian/skyfolk/venv/lib/python3.6/site-packages/allauth/account/views.py", line 80, in dispatch
    **kwargs)
  File "/home/adrian/skyfolk/venv/lib/python3.6/site-packages/django/views/generic/base.py", line 88, in dispatch
    return handler(request, *args, **kwargs)
  File "/home/adrian/skyfolk/venv/lib/python3.6/site-packages/allauth/account/views.py", line 94, in get
    request, *args, **kwargs)
  File "/home/adrian/skyfolk/venv/lib/python3.6/site-packages/django/views/generic/edit.py", line 174, in get
    return self.render_to_response(self.get_context_data())
  File "/home/adrian/skyfolk/venv/lib/python3.6/site-packages/allauth/account/views.py", line 168, in get_context_data
    site = get_current_site(self.request)
  File "/home/adrian/skyfolk/venv/lib/python3.6/site-packages/django/contrib/sites/shortcuts.py", line 15, in get_current_site
    return Site.objects.get_current(request)
  File "/home/adrian/skyfolk/venv/lib/python3.6/site-packages/django/contrib/sites/models.py", line 63, in get_current
    return self._get_site_by_id(site_id)
  File "/home/adrian/skyfolk/venv/lib/python3.6/site-packages/django/contrib/sites/models.py", line 35, in _get_site_by_id
    site = self.get(pk=site_id)
  File "/home/adrian/skyfolk/venv/lib/python3.6/site-packages/django/db/models/manager.py", line 85, in manager_method
    return getattr(self.get_queryset(), name)(*args, **kwargs)
  File "/home/adrian/skyfolk/venv/lib/python3.6/site-packages/django/db/models/query.py", line 374, in get
    num = len(clone)
  File "/home/adrian/skyfolk/venv/lib/python3.6/site-packages/django/db/models/query.py", line 232, in __len__
    self._fetch_all()
  File "/home/adrian/skyfolk/venv/lib/python3.6/site-packages/django/db/models/query.py", line 1118, in _fetch_all
    self._result_cache = list(self._iterable_class(self))
  File "/home/adrian/skyfolk/venv/lib/python3.6/site-packages/django/db/models/query.py", line 53, in __iter__
    results = compiler.execute_sql(chunked_fetch=self.chunked_fetch)
  File "/home/adrian/skyfolk/venv/lib/python3.6/site-packages/django/db/models/sql/compiler.py", line 899, in execute_sql
    raise original_exception
  File "/home/adrian/skyfolk/venv/lib/python3.6/site-packages/django/db/models/sql/compiler.py", line 889, in execute_sql
    cursor.execute(sql, params)
  File "/home/adrian/skyfolk/venv/lib/python3.6/site-packages/debug_toolbar/panels/sql/tracking.py", line 164, in execute
    return self._record(self.cursor.execute, sql, params)
  File "/home/adrian/skyfolk/venv/lib/python3.6/site-packages/debug_toolbar/panels/sql/tracking.py", line 106, in _record
    return method(sql, params)
  File "/home/adrian/skyfolk/venv/lib/python3.6/site-packages/django/db/backends/utils.py", line 79, in execute
    return super(CursorDebugWrapper, self).execute(sql, params)
  File "/home/adrian/skyfolk/venv/lib/python3.6/site-packages/django/db/backends/utils.py", line 64, in execute
    return self.cursor.execute(sql, params)
  File "/home/adrian/skyfolk/venv/lib/python3.6/site-packages/django/db/utils.py", line 94, in __exit__
    six.reraise(dj_exc_type, dj_exc_value, traceback)
  File "/home/adrian/skyfolk/venv/lib/python3.6/site-packages/django/utils/six.py", line 685, in reraise
    raise value.with_traceback(tb)
  File "/home/adrian/skyfolk/venv/lib/python3.6/site-packages/django/db/backends/utils.py", line 64, in execute
    return self.cursor.execute(sql, params)
  File "/home/adrian/skyfolk/venv/lib/python3.6/site-packages/django/db/backends/sqlite3/base.py", line 328, in execute
    return Database.Cursor.execute(self, query, params)
django.db.utils.OperationalError: no such table: django_site
2018-02-18 14:35:09,940 ERROR exception 24057 Internal Server Error: /groups/
Traceback (most recent call last):
  File "/home/adrian/skyfolk/venv/lib/python3.6/site-packages/django/core/handlers/exception.py", line 41, in inner
    response = get_response(request)
  File "/home/adrian/skyfolk/venv/lib/python3.6/site-packages/django/core/handlers/base.py", line 249, in _legacy_get_response
    response = self._get_response(request)
  File "/home/adrian/skyfolk/venv/lib/python3.6/site-packages/django/core/handlers/base.py", line 187, in _get_response
    response = self.process_exception_by_middleware(e, request)
  File "/home/adrian/skyfolk/venv/lib/python3.6/site-packages/channels/handler.py", line 243, in process_exception_by_middleware
    return super(AsgiHandler, self).process_exception_by_middleware(exception, request)
  File "/home/adrian/skyfolk/venv/lib/python3.6/site-packages/django/core/handlers/base.py", line 185, in _get_response
    response = wrapped_callback(request, *callback_args, **callback_kwargs)
  File "/home/adrian/skyfolk/venv/lib/python3.6/site-packages/django/views/generic/base.py", line 68, in view
    return self.dispatch(request, *args, **kwargs)
  File "/home/adrian/skyfolk/venv/lib/python3.6/site-packages/django/utils/decorators.py", line 67, in _wrapper
    return bound_func(*args, **kwargs)
  File "/home/adrian/skyfolk/venv/lib/python3.6/site-packages/django/contrib/auth/decorators.py", line 23, in _wrapped_view
    return view_func(request, *args, **kwargs)
  File "/home/adrian/skyfolk/venv/lib/python3.6/site-packages/django/utils/decorators.py", line 63, in bound_func
    return func.__get__(self, type(self))(*args2, **kwargs2)
  File "/home/adrian/skyfolk/user_groups/views.py", line 137, in dispatch
    return super(UserGroupList, self).dispatch(request, *args, **kwargs)
  File "/home/adrian/skyfolk/venv/lib/python3.6/site-packages/django/views/generic/base.py", line 88, in dispatch
    return handler(request, *args, **kwargs)
  File "/home/adrian/skyfolk/venv/lib/python3.6/site-packages/django/views/generic/list.py", line 160, in get
    self.object_list = self.get_queryset()
  File "/home/adrian/skyfolk/user_groups/views.py", line 149, in get_queryset
    return UserGroups.objects.filter(group_ptr__in=self.request.user.groups.all())
  File "/home/adrian/skyfolk/venv/lib/python3.6/site-packages/django/db/models/manager.py", line 85, in manager_method
    return getattr(self.get_queryset(), name)(*args, **kwargs)
  File "/home/adrian/skyfolk/venv/lib/python3.6/site-packages/django/db/models/query.py", line 784, in filter
    return self._filter_or_exclude(False, *args, **kwargs)
  File "/home/adrian/skyfolk/venv/lib/python3.6/site-packages/django/db/models/query.py", line 802, in _filter_or_exclude
    clone.query.add_q(Q(*args, **kwargs))
  File "/home/adrian/skyfolk/venv/lib/python3.6/site-packages/django/db/models/sql/query.py", line 1250, in add_q
    clause, _ = self._add_q(q_object, self.used_aliases)
  File "/home/adrian/skyfolk/venv/lib/python3.6/site-packages/django/db/models/sql/query.py", line 1276, in _add_q
    allow_joins=allow_joins, split_subq=split_subq,
  File "/home/adrian/skyfolk/venv/lib/python3.6/site-packages/django/db/models/sql/query.py", line 1154, in build_filter
    lookups, parts, reffed_expression = self.solve_lookup_type(arg)
  File "/home/adrian/skyfolk/venv/lib/python3.6/site-packages/django/db/models/sql/query.py", line 1034, in solve_lookup_type
    _, field, _, lookup_parts = self.names_to_path(lookup_splitted, self.get_meta())
  File "/home/adrian/skyfolk/venv/lib/python3.6/site-packages/django/db/models/sql/query.py", line 1352, in names_to_path
    "Choices are: %s" % (name, ", ".join(available)))
django.core.exceptions.FieldError: Cannot resolve keyword 'group_ptr' into field. Choices are: avatar, back_image, created, description, group_photos, group_videos, grouptheme, id, is_public, name, owner, owner_id, publicationgroup, slug, tagged_items, tags, to_group_request, to_likegroup, users
2018-02-18 15:07:07,617 ERROR exception 30760 Internal Server Error: /groups/
Traceback (most recent call last):
  File "/home/adrian/skyfolk/venv/lib/python3.6/site-packages/django/core/handlers/exception.py", line 41, in inner
    response = get_response(request)
  File "/home/adrian/skyfolk/venv/lib/python3.6/site-packages/django/core/handlers/base.py", line 249, in _legacy_get_response
    response = self._get_response(request)
  File "/home/adrian/skyfolk/venv/lib/python3.6/site-packages/django/core/handlers/base.py", line 187, in _get_response
    response = self.process_exception_by_middleware(e, request)
  File "/home/adrian/skyfolk/venv/lib/python3.6/site-packages/channels/handler.py", line 243, in process_exception_by_middleware
    return super(AsgiHandler, self).process_exception_by_middleware(exception, request)
  File "/home/adrian/skyfolk/venv/lib/python3.6/site-packages/django/core/handlers/base.py", line 185, in _get_response
    response = wrapped_callback(request, *callback_args, **callback_kwargs)
  File "/home/adrian/skyfolk/venv/lib/python3.6/site-packages/django/views/generic/base.py", line 68, in view
    return self.dispatch(request, *args, **kwargs)
  File "/home/adrian/skyfolk/venv/lib/python3.6/site-packages/django/utils/decorators.py", line 67, in _wrapper
    return bound_func(*args, **kwargs)
  File "/home/adrian/skyfolk/venv/lib/python3.6/site-packages/django/contrib/auth/decorators.py", line 23, in _wrapped_view
    return view_func(request, *args, **kwargs)
  File "/home/adrian/skyfolk/venv/lib/python3.6/site-packages/django/utils/decorators.py", line 63, in bound_func
    return func.__get__(self, type(self))(*args2, **kwargs2)
  File "/home/adrian/skyfolk/user_groups/views.py", line 137, in dispatch
    return super(UserGroupList, self).dispatch(request, *args, **kwargs)
  File "/home/adrian/skyfolk/venv/lib/python3.6/site-packages/django/views/generic/base.py", line 88, in dispatch
    return handler(request, *args, **kwargs)
  File "/home/adrian/skyfolk/venv/lib/python3.6/site-packages/django/views/generic/list.py", line 160, in get
    self.object_list = self.get_queryset()
  File "/home/adrian/skyfolk/user_groups/views.py", line 149, in get_queryset
    return UserGroups.objects.filter(group_ptr__in=self.request.user.usergroups.all())
  File "/home/adrian/skyfolk/venv/lib/python3.6/site-packages/django/utils/functional.py", line 239, in inner
    return func(self._wrapped, *args)
AttributeError: 'User' object has no attribute 'usergroups'
2018-02-18 15:07:18,984 ERROR exception 30827 Internal Server Error: /groups/
Traceback (most recent call last):
  File "/home/adrian/skyfolk/venv/lib/python3.6/site-packages/django/core/handlers/exception.py", line 41, in inner
    response = get_response(request)
  File "/home/adrian/skyfolk/venv/lib/python3.6/site-packages/django/core/handlers/base.py", line 249, in _legacy_get_response
    response = self._get_response(request)
  File "/home/adrian/skyfolk/venv/lib/python3.6/site-packages/django/core/handlers/base.py", line 187, in _get_response
    response = self.process_exception_by_middleware(e, request)
  File "/home/adrian/skyfolk/venv/lib/python3.6/site-packages/channels/handler.py", line 243, in process_exception_by_middleware
    return super(AsgiHandler, self).process_exception_by_middleware(exception, request)
  File "/home/adrian/skyfolk/venv/lib/python3.6/site-packages/django/core/handlers/base.py", line 185, in _get_response
    response = wrapped_callback(request, *callback_args, **callback_kwargs)
  File "/home/adrian/skyfolk/venv/lib/python3.6/site-packages/django/views/generic/base.py", line 68, in view
    return self.dispatch(request, *args, **kwargs)
  File "/home/adrian/skyfolk/venv/lib/python3.6/site-packages/django/utils/decorators.py", line 67, in _wrapper
    return bound_func(*args, **kwargs)
  File "/home/adrian/skyfolk/venv/lib/python3.6/site-packages/django/contrib/auth/decorators.py", line 23, in _wrapped_view
    return view_func(request, *args, **kwargs)
  File "/home/adrian/skyfolk/venv/lib/python3.6/site-packages/django/utils/decorators.py", line 63, in bound_func
    return func.__get__(self, type(self))(*args2, **kwargs2)
  File "/home/adrian/skyfolk/user_groups/views.py", line 137, in dispatch
    return super(UserGroupList, self).dispatch(request, *args, **kwargs)
  File "/home/adrian/skyfolk/venv/lib/python3.6/site-packages/django/views/generic/base.py", line 88, in dispatch
    return handler(request, *args, **kwargs)
  File "/home/adrian/skyfolk/venv/lib/python3.6/site-packages/django/views/generic/list.py", line 160, in get
    self.object_list = self.get_queryset()
  File "/home/adrian/skyfolk/user_groups/views.py", line 149, in get_queryset
    return UserGroups.objects.filter(group_ptr__in=self.request.user.user_groups.all())
  File "/home/adrian/skyfolk/venv/lib/python3.6/site-packages/django/utils/functional.py", line 239, in inner
    return func(self._wrapped, *args)
AttributeError: 'User' object has no attribute 'user_groups'
2018-02-18 15:08:13,696 ERROR exception 31078 Internal Server Error: /groups/
Traceback (most recent call last):
  File "/home/adrian/skyfolk/venv/lib/python3.6/site-packages/django/core/handlers/exception.py", line 41, in inner
    response = get_response(request)
  File "/home/adrian/skyfolk/venv/lib/python3.6/site-packages/django/core/handlers/base.py", line 249, in _legacy_get_response
    response = self._get_response(request)
  File "/home/adrian/skyfolk/venv/lib/python3.6/site-packages/django/core/handlers/base.py", line 187, in _get_response
    response = self.process_exception_by_middleware(e, request)
  File "/home/adrian/skyfolk/venv/lib/python3.6/site-packages/channels/handler.py", line 243, in process_exception_by_middleware
    return super(AsgiHandler, self).process_exception_by_middleware(exception, request)
  File "/home/adrian/skyfolk/venv/lib/python3.6/site-packages/django/core/handlers/base.py", line 185, in _get_response
    response = wrapped_callback(request, *callback_args, **callback_kwargs)
  File "/home/adrian/skyfolk/venv/lib/python3.6/site-packages/django/views/generic/base.py", line 68, in view
    return self.dispatch(request, *args, **kwargs)
  File "/home/adrian/skyfolk/venv/lib/python3.6/site-packages/django/utils/decorators.py", line 67, in _wrapper
    return bound_func(*args, **kwargs)
  File "/home/adrian/skyfolk/venv/lib/python3.6/site-packages/django/contrib/auth/decorators.py", line 23, in _wrapped_view
    return view_func(request, *args, **kwargs)
  File "/home/adrian/skyfolk/venv/lib/python3.6/site-packages/django/utils/decorators.py", line 63, in bound_func
    return func.__get__(self, type(self))(*args2, **kwargs2)
  File "/home/adrian/skyfolk/user_groups/views.py", line 137, in dispatch
    return super(UserGroupList, self).dispatch(request, *args, **kwargs)
  File "/home/adrian/skyfolk/venv/lib/python3.6/site-packages/django/views/generic/base.py", line 88, in dispatch
    return handler(request, *args, **kwargs)
  File "/home/adrian/skyfolk/venv/lib/python3.6/site-packages/django/views/generic/list.py", line 160, in get
    self.object_list = self.get_queryset()
  File "/home/adrian/skyfolk/user_groups/views.py", line 149, in get_queryset
    return UserGroups.objects.filter(group_ptr__in=self.request.user.user_groups.all())
  File "/home/adrian/skyfolk/venv/lib/python3.6/site-packages/django/db/models/manager.py", line 85, in manager_method
    return getattr(self.get_queryset(), name)(*args, **kwargs)
  File "/home/adrian/skyfolk/venv/lib/python3.6/site-packages/django/db/models/query.py", line 784, in filter
    return self._filter_or_exclude(False, *args, **kwargs)
  File "/home/adrian/skyfolk/venv/lib/python3.6/site-packages/django/db/models/query.py", line 802, in _filter_or_exclude
    clone.query.add_q(Q(*args, **kwargs))
  File "/home/adrian/skyfolk/venv/lib/python3.6/site-packages/django/db/models/sql/query.py", line 1250, in add_q
    clause, _ = self._add_q(q_object, self.used_aliases)
  File "/home/adrian/skyfolk/venv/lib/python3.6/site-packages/django/db/models/sql/query.py", line 1276, in _add_q
    allow_joins=allow_joins, split_subq=split_subq,
  File "/home/adrian/skyfolk/venv/lib/python3.6/site-packages/django/db/models/sql/query.py", line 1154, in build_filter
    lookups, parts, reffed_expression = self.solve_lookup_type(arg)
  File "/home/adrian/skyfolk/venv/lib/python3.6/site-packages/django/db/models/sql/query.py", line 1034, in solve_lookup_type
    _, field, _, lookup_parts = self.names_to_path(lookup_splitted, self.get_meta())
  File "/home/adrian/skyfolk/venv/lib/python3.6/site-packages/django/db/models/sql/query.py", line 1352, in names_to_path
    "Choices are: %s" % (name, ", ".join(available)))
django.core.exceptions.FieldError: Cannot resolve keyword 'group_ptr' into field. Choices are: avatar, back_image, created, description, group_photos, group_videos, grouptheme, id, is_public, name, owner, owner_id, publicationgroup, slug, tagged_items, tags, to_group_request, to_likegroup, users
2018-02-18 15:14:32,021 ERROR exception 328 Internal Server Error: /groups/profile/2/
Traceback (most recent call last):
  File "/home/adrian/skyfolk/venv/lib/python3.6/site-packages/django/core/handlers/exception.py", line 41, in inner
    response = get_response(request)
  File "/home/adrian/skyfolk/venv/lib/python3.6/site-packages/django/core/handlers/base.py", line 249, in _legacy_get_response
    response = self._get_response(request)
  File "/home/adrian/skyfolk/venv/lib/python3.6/site-packages/django/core/handlers/base.py", line 187, in _get_response
    response = self.process_exception_by_middleware(e, request)
  File "/home/adrian/skyfolk/venv/lib/python3.6/site-packages/channels/handler.py", line 243, in process_exception_by_middleware
    return super(AsgiHandler, self).process_exception_by_middleware(exception, request)
  File "/home/adrian/skyfolk/venv/lib/python3.6/site-packages/django/core/handlers/base.py", line 185, in _get_response
    response = wrapped_callback(request, *callback_args, **callback_kwargs)
  File "/home/adrian/skyfolk/venv/lib/python3.6/site-packages/django/contrib/auth/decorators.py", line 23, in _wrapped_view
    return view_func(request, *args, **kwargs)
  File "/home/adrian/skyfolk/venv/lib/python3.6/site-packages/django/views/decorators/csrf.py", line 58, in wrapped_view
    return view_func(*args, **kwargs)
  File "/home/adrian/skyfolk/venv/lib/python3.6/site-packages/django/views/generic/base.py", line 68, in view
    return self.dispatch(request, *args, **kwargs)
  File "/home/adrian/skyfolk/venv/lib/python3.6/site-packages/rest_framework/views.py", line 489, in dispatch
    response = self.handle_exception(exc)
  File "/home/adrian/skyfolk/venv/lib/python3.6/site-packages/rest_framework/views.py", line 449, in handle_exception
    self.raise_uncaught_exception(exc)
  File "/home/adrian/skyfolk/venv/lib/python3.6/site-packages/rest_framework/views.py", line 486, in dispatch
    response = handler(request, *args, **kwargs)
  File "/home/adrian/skyfolk/user_groups/views.py", line 639, in get
    queryset = UserGroups.objects.filter(id__in=user.user_groups.all()).annotate(members=Count('user')) \
  File "/home/adrian/skyfolk/venv/lib/python3.6/site-packages/django/db/models/query.py", line 945, in annotate
    clone.query.add_annotation(annotation, alias, is_summary=False)
  File "/home/adrian/skyfolk/venv/lib/python3.6/site-packages/django/db/models/sql/query.py", line 973, in add_annotation
    summarize=is_summary)
  File "/home/adrian/skyfolk/venv/lib/python3.6/site-packages/django/db/models/aggregates.py", line 19, in resolve_expression
    c = super(Aggregate, self).resolve_expression(query, allow_joins, reuse, summarize)
  File "/home/adrian/skyfolk/venv/lib/python3.6/site-packages/django/db/models/expressions.py", line 548, in resolve_expression
    c.source_expressions[pos] = arg.resolve_expression(query, allow_joins, reuse, summarize, for_save)
  File "/home/adrian/skyfolk/venv/lib/python3.6/site-packages/django/db/models/expressions.py", line 471, in resolve_expression
    return query.resolve_ref(self.name, allow_joins, reuse, summarize)
  File "/home/adrian/skyfolk/venv/lib/python3.6/site-packages/django/db/models/sql/query.py", line 1477, in resolve_ref
    self.get_initial_alias(), reuse)
  File "/home/adrian/skyfolk/venv/lib/python3.6/site-packages/django/db/models/sql/query.py", line 1417, in setup_joins
    names, opts, allow_many, fail_on_missing=True)
  File "/home/adrian/skyfolk/venv/lib/python3.6/site-packages/django/db/models/sql/query.py", line 1352, in names_to_path
    "Choices are: %s" % (name, ", ".join(available)))
django.core.exceptions.FieldError: Cannot resolve keyword 'user' into field. Choices are: avatar, back_image, created, description, group_photos, group_videos, grouptheme, id, is_public, name, owner, owner_id, publicationgroup, slug, tagged_items, tags, to_group_request, to_likegroup, users
2018-02-18 15:14:34,777 ERROR exception 328 Internal Server Error: /groups/profile/2/
Traceback (most recent call last):
  File "/home/adrian/skyfolk/venv/lib/python3.6/site-packages/django/core/handlers/exception.py", line 41, in inner
    response = get_response(request)
  File "/home/adrian/skyfolk/venv/lib/python3.6/site-packages/django/core/handlers/base.py", line 249, in _legacy_get_response
    response = self._get_response(request)
  File "/home/adrian/skyfolk/venv/lib/python3.6/site-packages/django/core/handlers/base.py", line 187, in _get_response
    response = self.process_exception_by_middleware(e, request)
  File "/home/adrian/skyfolk/venv/lib/python3.6/site-packages/channels/handler.py", line 243, in process_exception_by_middleware
    return super(AsgiHandler, self).process_exception_by_middleware(exception, request)
  File "/home/adrian/skyfolk/venv/lib/python3.6/site-packages/django/core/handlers/base.py", line 185, in _get_response
    response = wrapped_callback(request, *callback_args, **callback_kwargs)
  File "/home/adrian/skyfolk/venv/lib/python3.6/site-packages/django/contrib/auth/decorators.py", line 23, in _wrapped_view
    return view_func(request, *args, **kwargs)
  File "/home/adrian/skyfolk/venv/lib/python3.6/site-packages/django/views/decorators/csrf.py", line 58, in wrapped_view
    return view_func(*args, **kwargs)
  File "/home/adrian/skyfolk/venv/lib/python3.6/site-packages/django/views/generic/base.py", line 68, in view
    return self.dispatch(request, *args, **kwargs)
  File "/home/adrian/skyfolk/venv/lib/python3.6/site-packages/rest_framework/views.py", line 489, in dispatch
    response = self.handle_exception(exc)
  File "/home/adrian/skyfolk/venv/lib/python3.6/site-packages/rest_framework/views.py", line 449, in handle_exception
    self.raise_uncaught_exception(exc)
  File "/home/adrian/skyfolk/venv/lib/python3.6/site-packages/rest_framework/views.py", line 486, in dispatch
    response = handler(request, *args, **kwargs)
  File "/home/adrian/skyfolk/user_groups/views.py", line 639, in get
    queryset = UserGroups.objects.filter(id__in=user.user_groups.all()).annotate(members=Count('user')) \
  File "/home/adrian/skyfolk/venv/lib/python3.6/site-packages/django/db/models/query.py", line 945, in annotate
    clone.query.add_annotation(annotation, alias, is_summary=False)
  File "/home/adrian/skyfolk/venv/lib/python3.6/site-packages/django/db/models/sql/query.py", line 973, in add_annotation
    summarize=is_summary)
  File "/home/adrian/skyfolk/venv/lib/python3.6/site-packages/django/db/models/aggregates.py", line 19, in resolve_expression
    c = super(Aggregate, self).resolve_expression(query, allow_joins, reuse, summarize)
  File "/home/adrian/skyfolk/venv/lib/python3.6/site-packages/django/db/models/expressions.py", line 548, in resolve_expression
    c.source_expressions[pos] = arg.resolve_expression(query, allow_joins, reuse, summarize, for_save)
  File "/home/adrian/skyfolk/venv/lib/python3.6/site-packages/django/db/models/expressions.py", line 471, in resolve_expression
    return query.resolve_ref(self.name, allow_joins, reuse, summarize)
  File "/home/adrian/skyfolk/venv/lib/python3.6/site-packages/django/db/models/sql/query.py", line 1477, in resolve_ref
    self.get_initial_alias(), reuse)
  File "/home/adrian/skyfolk/venv/lib/python3.6/site-packages/django/db/models/sql/query.py", line 1417, in setup_joins
    names, opts, allow_many, fail_on_missing=True)
  File "/home/adrian/skyfolk/venv/lib/python3.6/site-packages/django/db/models/sql/query.py", line 1352, in names_to_path
    "Choices are: %s" % (name, ", ".join(available)))
django.core.exceptions.FieldError: Cannot resolve keyword 'user' into field. Choices are: avatar, back_image, created, description, group_photos, group_videos, grouptheme, id, is_public, name, owner, owner_id, publicationgroup, slug, tagged_items, tags, to_group_request, to_likegroup, users
2018-02-18 15:17:13,467 ERROR exception 757 Internal Server Error: /groups/create/theme/
Traceback (most recent call last):
  File "/home/adrian/skyfolk/venv/lib/python3.6/site-packages/django/core/handlers/exception.py", line 41, in inner
    response = get_response(request)
  File "/home/adrian/skyfolk/venv/lib/python3.6/site-packages/django/core/handlers/base.py", line 249, in _legacy_get_response
    response = self._get_response(request)
  File "/home/adrian/skyfolk/venv/lib/python3.6/site-packages/django/core/handlers/base.py", line 187, in _get_response
    response = self.process_exception_by_middleware(e, request)
  File "/home/adrian/skyfolk/venv/lib/python3.6/site-packages/channels/handler.py", line 243, in process_exception_by_middleware
    return super(AsgiHandler, self).process_exception_by_middleware(exception, request)
  File "/home/adrian/skyfolk/venv/lib/python3.6/site-packages/django/core/handlers/base.py", line 185, in _get_response
    response = wrapped_callback(request, *callback_args, **callback_kwargs)
  File "/home/adrian/skyfolk/venv/lib/python3.6/site-packages/django/views/generic/base.py", line 68, in view
    return self.dispatch(request, *args, **kwargs)
  File "/home/adrian/skyfolk/venv/lib/python3.6/site-packages/django/utils/decorators.py", line 67, in _wrapper
    return bound_func(*args, **kwargs)
  File "/home/adrian/skyfolk/venv/lib/python3.6/site-packages/django/contrib/auth/decorators.py", line 23, in _wrapped_view
    return view_func(request, *args, **kwargs)
  File "/home/adrian/skyfolk/venv/lib/python3.6/site-packages/django/utils/decorators.py", line 63, in bound_func
    return func.__get__(self, type(self))(*args2, **kwargs2)
  File "/home/adrian/skyfolk/user_groups/views.py", line 667, in dispatch
    return super(CreateGroupThemeView, self).dispatch(request, *args, **kwargs)
  File "/home/adrian/skyfolk/venv/lib/python3.6/site-packages/django/views/generic/base.py", line 88, in dispatch
    return handler(request, *args, **kwargs)
  File "/home/adrian/skyfolk/venv/lib/python3.6/site-packages/django/views/generic/edit.py", line 217, in post
    return super(BaseCreateView, self).post(request, *args, **kwargs)
  File "/home/adrian/skyfolk/venv/lib/python3.6/site-packages/django/views/generic/edit.py", line 183, in post
    return self.form_valid(form)
  File "/home/adrian/skyfolk/user_groups/views.py", line 674, in form_valid
    group = UserGroups.objects.get(id=board_group)
  File "/home/adrian/skyfolk/venv/lib/python3.6/site-packages/django/db/models/manager.py", line 85, in manager_method
    return getattr(self.get_queryset(), name)(*args, **kwargs)
  File "/home/adrian/skyfolk/venv/lib/python3.6/site-packages/django/db/models/query.py", line 371, in get
    clone = self.filter(*args, **kwargs)
  File "/home/adrian/skyfolk/venv/lib/python3.6/site-packages/django/db/models/query.py", line 784, in filter
    return self._filter_or_exclude(False, *args, **kwargs)
  File "/home/adrian/skyfolk/venv/lib/python3.6/site-packages/django/db/models/query.py", line 802, in _filter_or_exclude
    clone.query.add_q(Q(*args, **kwargs))
  File "/home/adrian/skyfolk/venv/lib/python3.6/site-packages/django/db/models/sql/query.py", line 1250, in add_q
    clause, _ = self._add_q(q_object, self.used_aliases)
  File "/home/adrian/skyfolk/venv/lib/python3.6/site-packages/django/db/models/sql/query.py", line 1276, in _add_q
    allow_joins=allow_joins, split_subq=split_subq,
  File "/home/adrian/skyfolk/venv/lib/python3.6/site-packages/django/db/models/sql/query.py", line 1210, in build_filter
    condition = self.build_lookup(lookups, col, value)
  File "/home/adrian/skyfolk/venv/lib/python3.6/site-packages/django/db/models/sql/query.py", line 1104, in build_lookup
    return final_lookup(lhs, rhs)
  File "/home/adrian/skyfolk/venv/lib/python3.6/site-packages/django/db/models/lookups.py", line 24, in __init__
    self.rhs = self.get_prep_lookup()
  File "/home/adrian/skyfolk/venv/lib/python3.6/site-packages/django/db/models/lookups.py", line 74, in get_prep_lookup
    return self.lhs.output_field.get_prep_value(self.rhs)
  File "/home/adrian/skyfolk/venv/lib/python3.6/site-packages/django/db/models/fields/__init__.py", line 966, in get_prep_value
    return int(value)
TypeError: int() argument must be a string, a bytes-like object or a number, not 'UserGroups'
2018-02-22 17:25:25,558 ERROR exception 10 Internal Server Error: /accounts/signup/
Traceback (most recent call last):
  File "/usr/local/lib/python3.6/site-packages/django/core/handlers/exception.py", line 41, in inner
    response = get_response(request)
  File "/usr/local/lib/python3.6/site-packages/django/core/handlers/base.py", line 249, in _legacy_get_response
    response = self._get_response(request)
  File "/usr/local/lib/python3.6/site-packages/django/core/handlers/base.py", line 187, in _get_response
    response = self.process_exception_by_middleware(e, request)
  File "/usr/local/lib/python3.6/site-packages/channels/handler.py", line 243, in process_exception_by_middleware
    return super(AsgiHandler, self).process_exception_by_middleware(exception, request)
  File "/usr/local/lib/python3.6/site-packages/django/core/handlers/base.py", line 185, in _get_response
    response = wrapped_callback(request, *callback_args, **callback_kwargs)
  File "/usr/local/lib/python3.6/site-packages/django/views/generic/base.py", line 68, in view
    return self.dispatch(request, *args, **kwargs)
  File "/usr/local/lib/python3.6/site-packages/django/utils/decorators.py", line 67, in _wrapper
    return bound_func(*args, **kwargs)
  File "/usr/local/lib/python3.6/site-packages/django/views/decorators/debug.py", line 76, in sensitive_post_parameters_wrapper
    return view(request, *args, **kwargs)
  File "/usr/local/lib/python3.6/site-packages/django/utils/decorators.py", line 63, in bound_func
    return func.__get__(self, type(self))(*args2, **kwargs2)
  File "/usr/local/lib/python3.6/site-packages/allauth/account/views.py", line 210, in dispatch
    return super(SignupView, self).dispatch(request, *args, **kwargs)
  File "/usr/local/lib/python3.6/site-packages/allauth/account/views.py", line 79, in dispatch
    **kwargs)
  File "/usr/local/lib/python3.6/site-packages/allauth/account/views.py", line 188, in dispatch
    **kwargs)
  File "/usr/local/lib/python3.6/site-packages/django/views/generic/base.py", line 88, in dispatch
    return handler(request, *args, **kwargs)
  File "/usr/local/lib/python3.6/site-packages/allauth/account/views.py", line 102, in post
    response = self.form_valid(form)
  File "/usr/local/lib/python3.6/site-packages/allauth/account/views.py", line 231, in form_valid
    self.get_success_url())
  File "/usr/local/lib/python3.6/site-packages/allauth/account/utils.py", line 188, in complete_signup
    signal_kwargs=signal_kwargs)
  File "/usr/local/lib/python3.6/site-packages/allauth/account/utils.py", line 148, in perform_login
    send_email_confirmation(request, user, signup=signup)
  File "/usr/local/lib/python3.6/site-packages/allauth/account/utils.py", line 319, in send_email_confirmation
    signup=signup)
  File "/usr/local/lib/python3.6/site-packages/allauth/account/models.py", line 60, in send_confirmation
    confirmation.send(request, signup=signup)
  File "/usr/local/lib/python3.6/site-packages/allauth/account/models.py", line 166, in send
    get_adapter(request).send_confirmation_mail(request, self, signup)
  File "/usr/local/lib/python3.6/site-packages/allauth/account/adapter.py", line 447, in send_confirmation_mail
    ctx)
  File "/usr/local/lib/python3.6/site-packages/allauth/account/adapter.py", line 140, in send_mail
    msg.send()
  File "/usr/local/lib/python3.6/site-packages/django/core/mail/message.py", line 348, in send
    return self.get_connection(fail_silently).send_messages([self])
  File "/usr/local/lib/python3.6/site-packages/django/core/mail/backends/smtp.py", line 104, in send_messages
    new_conn_created = self.open()
  File "/usr/local/lib/python3.6/site-packages/django/core/mail/backends/smtp.py", line 64, in open
    self.connection = self.connection_class(self.host, self.port, **connection_params)
  File "/usr/local/lib/python3.6/smtplib.py", line 251, in __init__
    (code, msg) = self.connect(host, port)
  File "/usr/local/lib/python3.6/smtplib.py", line 336, in connect
    self.sock = self._get_socket(host, port, self.timeout)
  File "/usr/local/lib/python3.6/smtplib.py", line 307, in _get_socket
    self.source_address)
  File "/usr/local/lib/python3.6/socket.py", line 724, in create_connection
    raise err
  File "/usr/local/lib/python3.6/socket.py", line 713, in create_connection
    sock.connect(sa)
OSError: [Errno 99] Cannot assign requested address
2018-02-22 17:26:07,355 ERROR exception 10 Internal Server Error: /accounts/signup/
Traceback (most recent call last):
  File "/usr/local/lib/python3.6/site-packages/django/core/handlers/exception.py", line 41, in inner
    response = get_response(request)
  File "/usr/local/lib/python3.6/site-packages/django/core/handlers/base.py", line 249, in _legacy_get_response
    response = self._get_response(request)
  File "/usr/local/lib/python3.6/site-packages/django/core/handlers/base.py", line 187, in _get_response
    response = self.process_exception_by_middleware(e, request)
  File "/usr/local/lib/python3.6/site-packages/channels/handler.py", line 243, in process_exception_by_middleware
    return super(AsgiHandler, self).process_exception_by_middleware(exception, request)
  File "/usr/local/lib/python3.6/site-packages/django/core/handlers/base.py", line 185, in _get_response
    response = wrapped_callback(request, *callback_args, **callback_kwargs)
  File "/usr/local/lib/python3.6/site-packages/django/views/generic/base.py", line 68, in view
    return self.dispatch(request, *args, **kwargs)
  File "/usr/local/lib/python3.6/site-packages/django/utils/decorators.py", line 67, in _wrapper
    return bound_func(*args, **kwargs)
  File "/usr/local/lib/python3.6/site-packages/django/views/decorators/debug.py", line 76, in sensitive_post_parameters_wrapper
    return view(request, *args, **kwargs)
  File "/usr/local/lib/python3.6/site-packages/django/utils/decorators.py", line 63, in bound_func
    return func.__get__(self, type(self))(*args2, **kwargs2)
  File "/usr/local/lib/python3.6/site-packages/allauth/account/views.py", line 210, in dispatch
    return super(SignupView, self).dispatch(request, *args, **kwargs)
  File "/usr/local/lib/python3.6/site-packages/allauth/account/views.py", line 79, in dispatch
    **kwargs)
  File "/usr/local/lib/python3.6/site-packages/allauth/account/views.py", line 188, in dispatch
    **kwargs)
  File "/usr/local/lib/python3.6/site-packages/django/views/generic/base.py", line 88, in dispatch
    return handler(request, *args, **kwargs)
  File "/usr/local/lib/python3.6/site-packages/allauth/account/views.py", line 102, in post
    response = self.form_valid(form)
  File "/usr/local/lib/python3.6/site-packages/allauth/account/views.py", line 231, in form_valid
    self.get_success_url())
  File "/usr/local/lib/python3.6/site-packages/allauth/account/utils.py", line 188, in complete_signup
    signal_kwargs=signal_kwargs)
  File "/usr/local/lib/python3.6/site-packages/allauth/account/utils.py", line 148, in perform_login
    send_email_confirmation(request, user, signup=signup)
  File "/usr/local/lib/python3.6/site-packages/allauth/account/utils.py", line 319, in send_email_confirmation
    signup=signup)
  File "/usr/local/lib/python3.6/site-packages/allauth/account/models.py", line 60, in send_confirmation
    confirmation.send(request, signup=signup)
  File "/usr/local/lib/python3.6/site-packages/allauth/account/models.py", line 166, in send
    get_adapter(request).send_confirmation_mail(request, self, signup)
  File "/usr/local/lib/python3.6/site-packages/allauth/account/adapter.py", line 447, in send_confirmation_mail
    ctx)
  File "/usr/local/lib/python3.6/site-packages/allauth/account/adapter.py", line 140, in send_mail
    msg.send()
  File "/usr/local/lib/python3.6/site-packages/django/core/mail/message.py", line 348, in send
    return self.get_connection(fail_silently).send_messages([self])
  File "/usr/local/lib/python3.6/site-packages/django/core/mail/backends/smtp.py", line 104, in send_messages
    new_conn_created = self.open()
  File "/usr/local/lib/python3.6/site-packages/django/core/mail/backends/smtp.py", line 64, in open
    self.connection = self.connection_class(self.host, self.port, **connection_params)
  File "/usr/local/lib/python3.6/smtplib.py", line 251, in __init__
    (code, msg) = self.connect(host, port)
  File "/usr/local/lib/python3.6/smtplib.py", line 336, in connect
    self.sock = self._get_socket(host, port, self.timeout)
  File "/usr/local/lib/python3.6/smtplib.py", line 307, in _get_socket
    self.source_address)
  File "/usr/local/lib/python3.6/socket.py", line 724, in create_connection
    raise err
  File "/usr/local/lib/python3.6/socket.py", line 713, in create_connection
    sock.connect(sa)
OSError: [Errno 99] Cannot assign requested address
2018-02-22 17:28:18,939 ERROR exception 9 Internal Server Error: /accounts/signup/
Traceback (most recent call last):
  File "/usr/local/lib/python3.6/site-packages/django/core/handlers/exception.py", line 41, in inner
    response = get_response(request)
  File "/usr/local/lib/python3.6/site-packages/django/core/handlers/base.py", line 249, in _legacy_get_response
    response = self._get_response(request)
  File "/usr/local/lib/python3.6/site-packages/django/core/handlers/base.py", line 187, in _get_response
    response = self.process_exception_by_middleware(e, request)
  File "/usr/local/lib/python3.6/site-packages/channels/handler.py", line 243, in process_exception_by_middleware
    return super(AsgiHandler, self).process_exception_by_middleware(exception, request)
  File "/usr/local/lib/python3.6/site-packages/django/core/handlers/base.py", line 185, in _get_response
    response = wrapped_callback(request, *callback_args, **callback_kwargs)
  File "/usr/local/lib/python3.6/site-packages/django/views/generic/base.py", line 68, in view
    return self.dispatch(request, *args, **kwargs)
  File "/usr/local/lib/python3.6/site-packages/django/utils/decorators.py", line 67, in _wrapper
    return bound_func(*args, **kwargs)
  File "/usr/local/lib/python3.6/site-packages/django/views/decorators/debug.py", line 76, in sensitive_post_parameters_wrapper
    return view(request, *args, **kwargs)
  File "/usr/local/lib/python3.6/site-packages/django/utils/decorators.py", line 63, in bound_func
    return func.__get__(self, type(self))(*args2, **kwargs2)
  File "/usr/local/lib/python3.6/site-packages/allauth/account/views.py", line 210, in dispatch
    return super(SignupView, self).dispatch(request, *args, **kwargs)
  File "/usr/local/lib/python3.6/site-packages/allauth/account/views.py", line 79, in dispatch
    **kwargs)
  File "/usr/local/lib/python3.6/site-packages/allauth/account/views.py", line 188, in dispatch
    **kwargs)
  File "/usr/local/lib/python3.6/site-packages/django/views/generic/base.py", line 88, in dispatch
    return handler(request, *args, **kwargs)
  File "/usr/local/lib/python3.6/site-packages/allauth/account/views.py", line 102, in post
    response = self.form_valid(form)
  File "/usr/local/lib/python3.6/site-packages/allauth/account/views.py", line 231, in form_valid
    self.get_success_url())
  File "/usr/local/lib/python3.6/site-packages/allauth/account/utils.py", line 188, in complete_signup
    signal_kwargs=signal_kwargs)
  File "/usr/local/lib/python3.6/site-packages/allauth/account/utils.py", line 148, in perform_login
    send_email_confirmation(request, user, signup=signup)
  File "/usr/local/lib/python3.6/site-packages/allauth/account/utils.py", line 319, in send_email_confirmation
    signup=signup)
  File "/usr/local/lib/python3.6/site-packages/allauth/account/models.py", line 60, in send_confirmation
    confirmation.send(request, signup=signup)
  File "/usr/local/lib/python3.6/site-packages/allauth/account/models.py", line 166, in send
    get_adapter(request).send_confirmation_mail(request, self, signup)
  File "/usr/local/lib/python3.6/site-packages/allauth/account/adapter.py", line 447, in send_confirmation_mail
    ctx)
  File "/usr/local/lib/python3.6/site-packages/allauth/account/adapter.py", line 140, in send_mail
    msg.send()
  File "/usr/local/lib/python3.6/site-packages/django/core/mail/message.py", line 348, in send
    return self.get_connection(fail_silently).send_messages([self])
  File "/usr/local/lib/python3.6/site-packages/django/core/mail/backends/smtp.py", line 111, in send_messages
    sent = self._send(message)
  File "/usr/local/lib/python3.6/site-packages/django/core/mail/backends/smtp.py", line 127, in _send
    self.connection.sendmail(from_email, recipients, message.as_bytes(linesep='\r\n'))
  File "/usr/local/lib/python3.6/smtplib.py", line 881, in sendmail
    raise SMTPRecipientsRefused(senderrs)
smtplib.SMTPRecipientsRefused: {'jejej@es.es': (454, b'4.7.1 <jejej@es.es>: Relay access denied')}
2018-02-22 17:32:38,327 ERROR exception 9 Internal Server Error: /accounts/signup/
Traceback (most recent call last):
  File "/usr/local/lib/python3.6/site-packages/django/core/handlers/exception.py", line 41, in inner
    response = get_response(request)
  File "/usr/local/lib/python3.6/site-packages/django/core/handlers/base.py", line 249, in _legacy_get_response
    response = self._get_response(request)
  File "/usr/local/lib/python3.6/site-packages/django/core/handlers/base.py", line 187, in _get_response
    response = self.process_exception_by_middleware(e, request)
  File "/usr/local/lib/python3.6/site-packages/channels/handler.py", line 243, in process_exception_by_middleware
    return super(AsgiHandler, self).process_exception_by_middleware(exception, request)
  File "/usr/local/lib/python3.6/site-packages/django/core/handlers/base.py", line 185, in _get_response
    response = wrapped_callback(request, *callback_args, **callback_kwargs)
  File "/usr/local/lib/python3.6/site-packages/django/views/generic/base.py", line 68, in view
    return self.dispatch(request, *args, **kwargs)
  File "/usr/local/lib/python3.6/site-packages/django/utils/decorators.py", line 67, in _wrapper
    return bound_func(*args, **kwargs)
  File "/usr/local/lib/python3.6/site-packages/django/views/decorators/debug.py", line 76, in sensitive_post_parameters_wrapper
    return view(request, *args, **kwargs)
  File "/usr/local/lib/python3.6/site-packages/django/utils/decorators.py", line 63, in bound_func
    return func.__get__(self, type(self))(*args2, **kwargs2)
  File "/usr/local/lib/python3.6/site-packages/allauth/account/views.py", line 210, in dispatch
    return super(SignupView, self).dispatch(request, *args, **kwargs)
  File "/usr/local/lib/python3.6/site-packages/allauth/account/views.py", line 79, in dispatch
    **kwargs)
  File "/usr/local/lib/python3.6/site-packages/allauth/account/views.py", line 188, in dispatch
    **kwargs)
  File "/usr/local/lib/python3.6/site-packages/django/views/generic/base.py", line 88, in dispatch
    return handler(request, *args, **kwargs)
  File "/usr/local/lib/python3.6/site-packages/allauth/account/views.py", line 102, in post
    response = self.form_valid(form)
  File "/usr/local/lib/python3.6/site-packages/allauth/account/views.py", line 231, in form_valid
    self.get_success_url())
  File "/usr/local/lib/python3.6/site-packages/allauth/account/utils.py", line 188, in complete_signup
    signal_kwargs=signal_kwargs)
  File "/usr/local/lib/python3.6/site-packages/allauth/account/utils.py", line 148, in perform_login
    send_email_confirmation(request, user, signup=signup)
  File "/usr/local/lib/python3.6/site-packages/allauth/account/utils.py", line 319, in send_email_confirmation
    signup=signup)
  File "/usr/local/lib/python3.6/site-packages/allauth/account/models.py", line 60, in send_confirmation
    confirmation.send(request, signup=signup)
  File "/usr/local/lib/python3.6/site-packages/allauth/account/models.py", line 166, in send
    get_adapter(request).send_confirmation_mail(request, self, signup)
  File "/usr/local/lib/python3.6/site-packages/allauth/account/adapter.py", line 447, in send_confirmation_mail
    ctx)
  File "/usr/local/lib/python3.6/site-packages/allauth/account/adapter.py", line 140, in send_mail
    msg.send()
  File "/usr/local/lib/python3.6/site-packages/django/core/mail/message.py", line 348, in send
    return self.get_connection(fail_silently).send_messages([self])
  File "/usr/local/lib/python3.6/site-packages/django/core/mail/backends/smtp.py", line 104, in send_messages
    new_conn_created = self.open()
  File "/usr/local/lib/python3.6/site-packages/django/core/mail/backends/smtp.py", line 69, in open
    self.connection.starttls(keyfile=self.ssl_keyfile, certfile=self.ssl_certfile)
  File "/usr/local/lib/python3.6/smtplib.py", line 752, in starttls
    "STARTTLS extension not supported by server.")
smtplib.SMTPNotSupportedError: STARTTLS extension not supported by server.
2018-02-22 17:35:14,048 ERROR exception 9 Internal Server Error: /accounts/signup/
Traceback (most recent call last):
  File "/usr/local/lib/python3.6/site-packages/django/core/handlers/exception.py", line 41, in inner
    response = get_response(request)
  File "/usr/local/lib/python3.6/site-packages/django/core/handlers/base.py", line 249, in _legacy_get_response
    response = self._get_response(request)
  File "/usr/local/lib/python3.6/site-packages/django/core/handlers/base.py", line 187, in _get_response
    response = self.process_exception_by_middleware(e, request)
  File "/usr/local/lib/python3.6/site-packages/channels/handler.py", line 243, in process_exception_by_middleware
    return super(AsgiHandler, self).process_exception_by_middleware(exception, request)
  File "/usr/local/lib/python3.6/site-packages/django/core/handlers/base.py", line 185, in _get_response
    response = wrapped_callback(request, *callback_args, **callback_kwargs)
  File "/usr/local/lib/python3.6/site-packages/django/views/generic/base.py", line 68, in view
    return self.dispatch(request, *args, **kwargs)
  File "/usr/local/lib/python3.6/site-packages/django/utils/decorators.py", line 67, in _wrapper
    return bound_func(*args, **kwargs)
  File "/usr/local/lib/python3.6/site-packages/django/views/decorators/debug.py", line 76, in sensitive_post_parameters_wrapper
    return view(request, *args, **kwargs)
  File "/usr/local/lib/python3.6/site-packages/django/utils/decorators.py", line 63, in bound_func
    return func.__get__(self, type(self))(*args2, **kwargs2)
  File "/usr/local/lib/python3.6/site-packages/allauth/account/views.py", line 210, in dispatch
    return super(SignupView, self).dispatch(request, *args, **kwargs)
  File "/usr/local/lib/python3.6/site-packages/allauth/account/views.py", line 79, in dispatch
    **kwargs)
  File "/usr/local/lib/python3.6/site-packages/allauth/account/views.py", line 188, in dispatch
    **kwargs)
  File "/usr/local/lib/python3.6/site-packages/django/views/generic/base.py", line 88, in dispatch
    return handler(request, *args, **kwargs)
  File "/usr/local/lib/python3.6/site-packages/allauth/account/views.py", line 102, in post
    response = self.form_valid(form)
  File "/usr/local/lib/python3.6/site-packages/allauth/account/views.py", line 231, in form_valid
    self.get_success_url())
  File "/usr/local/lib/python3.6/site-packages/allauth/account/utils.py", line 188, in complete_signup
    signal_kwargs=signal_kwargs)
  File "/usr/local/lib/python3.6/site-packages/allauth/account/utils.py", line 148, in perform_login
    send_email_confirmation(request, user, signup=signup)
  File "/usr/local/lib/python3.6/site-packages/allauth/account/utils.py", line 319, in send_email_confirmation
    signup=signup)
  File "/usr/local/lib/python3.6/site-packages/allauth/account/models.py", line 60, in send_confirmation
    confirmation.send(request, signup=signup)
  File "/usr/local/lib/python3.6/site-packages/allauth/account/models.py", line 166, in send
    get_adapter(request).send_confirmation_mail(request, self, signup)
  File "/usr/local/lib/python3.6/site-packages/allauth/account/adapter.py", line 447, in send_confirmation_mail
    ctx)
  File "/usr/local/lib/python3.6/site-packages/allauth/account/adapter.py", line 140, in send_mail
    msg.send()
  File "/usr/local/lib/python3.6/site-packages/django/core/mail/message.py", line 348, in send
    return self.get_connection(fail_silently).send_messages([self])
  File "/usr/local/lib/python3.6/site-packages/django/core/mail/backends/smtp.py", line 111, in send_messages
    sent = self._send(message)
  File "/usr/local/lib/python3.6/site-packages/django/core/mail/backends/smtp.py", line 127, in _send
    self.connection.sendmail(from_email, recipients, message.as_bytes(linesep='\r\n'))
  File "/usr/local/lib/python3.6/smtplib.py", line 881, in sendmail
    raise SMTPRecipientsRefused(senderrs)
smtplib.SMTPRecipientsRefused: {'je14jej@es.es': (454, b'4.7.1 <je14jej@es.es>: Relay access denied')}
2018-02-22 17:36:08,206 ERROR exception 9 Internal Server Error: /accounts/signup/
Traceback (most recent call last):
  File "/usr/local/lib/python3.6/site-packages/django/core/handlers/exception.py", line 41, in inner
    response = get_response(request)
  File "/usr/local/lib/python3.6/site-packages/django/core/handlers/base.py", line 249, in _legacy_get_response
    response = self._get_response(request)
  File "/usr/local/lib/python3.6/site-packages/django/core/handlers/base.py", line 187, in _get_response
    response = self.process_exception_by_middleware(e, request)
  File "/usr/local/lib/python3.6/site-packages/channels/handler.py", line 243, in process_exception_by_middleware
    return super(AsgiHandler, self).process_exception_by_middleware(exception, request)
  File "/usr/local/lib/python3.6/site-packages/django/core/handlers/base.py", line 185, in _get_response
    response = wrapped_callback(request, *callback_args, **callback_kwargs)
  File "/usr/local/lib/python3.6/site-packages/django/views/generic/base.py", line 68, in view
    return self.dispatch(request, *args, **kwargs)
  File "/usr/local/lib/python3.6/site-packages/django/utils/decorators.py", line 67, in _wrapper
    return bound_func(*args, **kwargs)
  File "/usr/local/lib/python3.6/site-packages/django/views/decorators/debug.py", line 76, in sensitive_post_parameters_wrapper
    return view(request, *args, **kwargs)
  File "/usr/local/lib/python3.6/site-packages/django/utils/decorators.py", line 63, in bound_func
    return func.__get__(self, type(self))(*args2, **kwargs2)
  File "/usr/local/lib/python3.6/site-packages/allauth/account/views.py", line 210, in dispatch
    return super(SignupView, self).dispatch(request, *args, **kwargs)
  File "/usr/local/lib/python3.6/site-packages/allauth/account/views.py", line 79, in dispatch
    **kwargs)
  File "/usr/local/lib/python3.6/site-packages/allauth/account/views.py", line 188, in dispatch
    **kwargs)
  File "/usr/local/lib/python3.6/site-packages/django/views/generic/base.py", line 88, in dispatch
    return handler(request, *args, **kwargs)
  File "/usr/local/lib/python3.6/site-packages/allauth/account/views.py", line 102, in post
    response = self.form_valid(form)
  File "/usr/local/lib/python3.6/site-packages/allauth/account/views.py", line 231, in form_valid
    self.get_success_url())
  File "/usr/local/lib/python3.6/site-packages/allauth/account/utils.py", line 188, in complete_signup
    signal_kwargs=signal_kwargs)
  File "/usr/local/lib/python3.6/site-packages/allauth/account/utils.py", line 148, in perform_login
    send_email_confirmation(request, user, signup=signup)
  File "/usr/local/lib/python3.6/site-packages/allauth/account/utils.py", line 319, in send_email_confirmation
    signup=signup)
  File "/usr/local/lib/python3.6/site-packages/allauth/account/models.py", line 60, in send_confirmation
    confirmation.send(request, signup=signup)
  File "/usr/local/lib/python3.6/site-packages/allauth/account/models.py", line 166, in send
    get_adapter(request).send_confirmation_mail(request, self, signup)
  File "/usr/local/lib/python3.6/site-packages/allauth/account/adapter.py", line 447, in send_confirmation_mail
    ctx)
  File "/usr/local/lib/python3.6/site-packages/allauth/account/adapter.py", line 140, in send_mail
    msg.send()
  File "/usr/local/lib/python3.6/site-packages/django/core/mail/message.py", line 348, in send
    return self.get_connection(fail_silently).send_messages([self])
  File "/usr/local/lib/python3.6/site-packages/django/core/mail/backends/smtp.py", line 111, in send_messages
    sent = self._send(message)
  File "/usr/local/lib/python3.6/site-packages/django/core/mail/backends/smtp.py", line 127, in _send
    self.connection.sendmail(from_email, recipients, message.as_bytes(linesep='\r\n'))
  File "/usr/local/lib/python3.6/smtplib.py", line 881, in sendmail
    raise SMTPRecipientsRefused(senderrs)
smtplib.SMTPRecipientsRefused: {'asdasd2@es.es': (454, b'4.7.1 <asdasd2@es.es>: Relay access denied')}
2018-02-22 17:40:26,687 ERROR exception 9 Internal Server Error: /accounts/signup/
Traceback (most recent call last):
  File "/usr/local/lib/python3.6/site-packages/django/core/handlers/exception.py", line 41, in inner
    response = get_response(request)
  File "/usr/local/lib/python3.6/site-packages/django/core/handlers/base.py", line 249, in _legacy_get_response
    response = self._get_response(request)
  File "/usr/local/lib/python3.6/site-packages/django/core/handlers/base.py", line 187, in _get_response
    response = self.process_exception_by_middleware(e, request)
  File "/usr/local/lib/python3.6/site-packages/channels/handler.py", line 243, in process_exception_by_middleware
    return super(AsgiHandler, self).process_exception_by_middleware(exception, request)
  File "/usr/local/lib/python3.6/site-packages/django/core/handlers/base.py", line 185, in _get_response
    response = wrapped_callback(request, *callback_args, **callback_kwargs)
  File "/usr/local/lib/python3.6/site-packages/django/views/generic/base.py", line 68, in view
    return self.dispatch(request, *args, **kwargs)
  File "/usr/local/lib/python3.6/site-packages/django/utils/decorators.py", line 67, in _wrapper
    return bound_func(*args, **kwargs)
  File "/usr/local/lib/python3.6/site-packages/django/views/decorators/debug.py", line 76, in sensitive_post_parameters_wrapper
    return view(request, *args, **kwargs)
  File "/usr/local/lib/python3.6/site-packages/django/utils/decorators.py", line 63, in bound_func
    return func.__get__(self, type(self))(*args2, **kwargs2)
  File "/usr/local/lib/python3.6/site-packages/allauth/account/views.py", line 210, in dispatch
    return super(SignupView, self).dispatch(request, *args, **kwargs)
  File "/usr/local/lib/python3.6/site-packages/allauth/account/views.py", line 79, in dispatch
    **kwargs)
  File "/usr/local/lib/python3.6/site-packages/allauth/account/views.py", line 188, in dispatch
    **kwargs)
  File "/usr/local/lib/python3.6/site-packages/django/views/generic/base.py", line 88, in dispatch
    return handler(request, *args, **kwargs)
  File "/usr/local/lib/python3.6/site-packages/allauth/account/views.py", line 102, in post
    response = self.form_valid(form)
  File "/usr/local/lib/python3.6/site-packages/allauth/account/views.py", line 231, in form_valid
    self.get_success_url())
  File "/usr/local/lib/python3.6/site-packages/allauth/account/utils.py", line 188, in complete_signup
    signal_kwargs=signal_kwargs)
  File "/usr/local/lib/python3.6/site-packages/allauth/account/utils.py", line 148, in perform_login
    send_email_confirmation(request, user, signup=signup)
  File "/usr/local/lib/python3.6/site-packages/allauth/account/utils.py", line 319, in send_email_confirmation
    signup=signup)
  File "/usr/local/lib/python3.6/site-packages/allauth/account/models.py", line 60, in send_confirmation
    confirmation.send(request, signup=signup)
  File "/usr/local/lib/python3.6/site-packages/allauth/account/models.py", line 166, in send
    get_adapter(request).send_confirmation_mail(request, self, signup)
  File "/usr/local/lib/python3.6/site-packages/allauth/account/adapter.py", line 447, in send_confirmation_mail
    ctx)
  File "/usr/local/lib/python3.6/site-packages/allauth/account/adapter.py", line 140, in send_mail
    msg.send()
  File "/usr/local/lib/python3.6/site-packages/django/core/mail/message.py", line 348, in send
    return self.get_connection(fail_silently).send_messages([self])
  File "/usr/local/lib/python3.6/site-packages/django/core/mail/backends/smtp.py", line 111, in send_messages
    sent = self._send(message)
  File "/usr/local/lib/python3.6/site-packages/django/core/mail/backends/smtp.py", line 127, in _send
    self.connection.sendmail(from_email, recipients, message.as_bytes(linesep='\r\n'))
  File "/usr/local/lib/python3.6/smtplib.py", line 881, in sendmail
    raise SMTPRecipientsRefused(senderrs)
smtplib.SMTPRecipientsRefused: {'vida@loca.es': (454, b'4.7.1 <vida@loca.es>: Relay access denied')}
