2018-02-17 17:54:13,827 ERROR exception 10 Internal Server Error: /config/email/
Traceback (most recent call last):
  File "/usr/local/lib/python3.6/site-packages/django/core/handlers/exception.py", line 41, in inner
    response = get_response(request)
  File "/usr/local/lib/python3.6/site-packages/django/core/handlers/base.py", line 249, in _legacy_get_response
    response = self._get_response(request)
  File "/usr/local/lib/python3.6/site-packages/django/core/handlers/base.py", line 187, in _get_response
    response = self.process_exception_by_middleware(e, request)
  File "/usr/local/lib/python3.6/site-packages/channels/handler.py", line 243, in process_exception_by_middleware
    return super(AsgiHandler, self).process_exception_by_middleware(exception, request)
  File "/usr/local/lib/python3.6/site-packages/django/core/handlers/base.py", line 185, in _get_response
    response = wrapped_callback(request, *callback_args, **callback_kwargs)
  File "/usr/local/lib/python3.6/site-packages/django/contrib/auth/decorators.py", line 23, in _wrapped_view
    return view_func(request, *args, **kwargs)
  File "/usr/local/lib/python3.6/site-packages/django/views/generic/base.py", line 68, in view
    return self.dispatch(request, *args, **kwargs)
  File "/usr/local/lib/python3.6/site-packages/allauth/account/views.py", line 378, in dispatch
    return super(EmailView, self).dispatch(request, *args, **kwargs)
  File "/usr/local/lib/python3.6/site-packages/django/views/generic/base.py", line 88, in dispatch
    return handler(request, *args, **kwargs)
  File "/usr/local/lib/python3.6/site-packages/allauth/account/views.py", line 405, in post
    res = self._action_send(request)
  File "/usr/local/lib/python3.6/site-packages/allauth/account/views.py", line 433, in _action_send
    email_address.send_confirmation(request)
  File "/usr/local/lib/python3.6/site-packages/allauth/account/models.py", line 60, in send_confirmation
    confirmation.send(request, signup=signup)
  File "/usr/local/lib/python3.6/site-packages/allauth/account/models.py", line 166, in send
    get_adapter(request).send_confirmation_mail(request, self, signup)
  File "/usr/local/lib/python3.6/site-packages/allauth/account/adapter.py", line 447, in send_confirmation_mail
    ctx)
  File "/usr/local/lib/python3.6/site-packages/allauth/account/adapter.py", line 140, in send_mail
    msg.send()
  File "/usr/local/lib/python3.6/site-packages/django/core/mail/message.py", line 348, in send
    return self.get_connection(fail_silently).send_messages([self])
  File "/usr/local/lib/python3.6/site-packages/django/core/mail/backends/smtp.py", line 104, in send_messages
    new_conn_created = self.open()
  File "/usr/local/lib/python3.6/site-packages/django/core/mail/backends/smtp.py", line 71, in open
    self.connection.login(force_str(self.username), force_str(self.password))
  File "/usr/local/lib/python3.6/smtplib.py", line 730, in login
    raise last_exception
  File "/usr/local/lib/python3.6/smtplib.py", line 721, in login
    initial_response_ok=initial_response_ok)
  File "/usr/local/lib/python3.6/smtplib.py", line 642, in auth
    raise SMTPAuthenticationError(code, resp)
smtplib.SMTPAuthenticationError: (534, b'5.7.14 <https://accounts.google.com/signin/continue?sarp=1&scc=1&plt=AKgnsbs3\n5.7.14 dC_vTd3R8Stcy0w9JqxnkBSJ3Gcx6zbjjyJ7bqjFzlOOrm2zVqxaeYns4is9MHXkKDLBAn\n5.7.14 181nuJoJZk7QjbYls0qhm35sRmDm4O1tEQvPtS0U8bHR9lgKqEXKOdoihSHMamoRoMmbcA\n5.7.14 RBW-ki46zeHZNDWFme8u7BrvHphBtXs77qo-fy2UtcAllX7WHeX7veJBx6CSb0rub2m5G6\n5.7.14 X2OFui6o1J4V_EsYH2CDR_RI_Lj-k> Please log in via your web browser and\n5.7.14 then try again.\n5.7.14  Learn more at\n5.7.14  https://support.google.com/mail/answer/78754 c1sm9962218wre.10 - gsmtp')
2018-02-17 17:54:29,889 ERROR exception 10 Internal Server Error: /config/email/
Traceback (most recent call last):
  File "/usr/local/lib/python3.6/site-packages/django/core/handlers/exception.py", line 41, in inner
    response = get_response(request)
  File "/usr/local/lib/python3.6/site-packages/django/core/handlers/base.py", line 249, in _legacy_get_response
    response = self._get_response(request)
  File "/usr/local/lib/python3.6/site-packages/django/core/handlers/base.py", line 187, in _get_response
    response = self.process_exception_by_middleware(e, request)
  File "/usr/local/lib/python3.6/site-packages/channels/handler.py", line 243, in process_exception_by_middleware
    return super(AsgiHandler, self).process_exception_by_middleware(exception, request)
  File "/usr/local/lib/python3.6/site-packages/django/core/handlers/base.py", line 185, in _get_response
    response = wrapped_callback(request, *callback_args, **callback_kwargs)
  File "/usr/local/lib/python3.6/site-packages/django/contrib/auth/decorators.py", line 23, in _wrapped_view
    return view_func(request, *args, **kwargs)
  File "/usr/local/lib/python3.6/site-packages/django/views/generic/base.py", line 68, in view
    return self.dispatch(request, *args, **kwargs)
  File "/usr/local/lib/python3.6/site-packages/allauth/account/views.py", line 378, in dispatch
    return super(EmailView, self).dispatch(request, *args, **kwargs)
  File "/usr/local/lib/python3.6/site-packages/django/views/generic/base.py", line 88, in dispatch
    return handler(request, *args, **kwargs)
  File "/usr/local/lib/python3.6/site-packages/allauth/account/views.py", line 405, in post
    res = self._action_send(request)
  File "/usr/local/lib/python3.6/site-packages/allauth/account/views.py", line 433, in _action_send
    email_address.send_confirmation(request)
  File "/usr/local/lib/python3.6/site-packages/allauth/account/models.py", line 60, in send_confirmation
    confirmation.send(request, signup=signup)
  File "/usr/local/lib/python3.6/site-packages/allauth/account/models.py", line 166, in send
    get_adapter(request).send_confirmation_mail(request, self, signup)
  File "/usr/local/lib/python3.6/site-packages/allauth/account/adapter.py", line 447, in send_confirmation_mail
    ctx)
  File "/usr/local/lib/python3.6/site-packages/allauth/account/adapter.py", line 140, in send_mail
    msg.send()
  File "/usr/local/lib/python3.6/site-packages/django/core/mail/message.py", line 348, in send
    return self.get_connection(fail_silently).send_messages([self])
  File "/usr/local/lib/python3.6/site-packages/django/core/mail/backends/smtp.py", line 104, in send_messages
    new_conn_created = self.open()
  File "/usr/local/lib/python3.6/site-packages/django/core/mail/backends/smtp.py", line 71, in open
    self.connection.login(force_str(self.username), force_str(self.password))
  File "/usr/local/lib/python3.6/smtplib.py", line 730, in login
    raise last_exception
  File "/usr/local/lib/python3.6/smtplib.py", line 721, in login
    initial_response_ok=initial_response_ok)
  File "/usr/local/lib/python3.6/smtplib.py", line 642, in auth
    raise SMTPAuthenticationError(code, resp)
smtplib.SMTPAuthenticationError: (534, b'5.7.14 <https://accounts.google.com/signin/continue?sarp=1&scc=1&plt=AKgnsbuB\n5.7.14 -UG-kFINWIowXl9S1CGufYNc_gZbLYxFhI-5dpRENeRuATPuf5b5Y55Ka_fvLwhyJHj3wF\n5.7.14 652sAAJB-7mMaX0gLyQsNr4LeRm4SNOKiJNOe46_STVDJccQJsNBLwRF8Ykj6tUZQ5XC46\n5.7.14 PnN1Z6Pv8iQt3IscMzXyvP1w5Q8G9UcoTjpFwRcGUNQB544VMP5il8lb-cjm4ll7OCSrm1\n5.7.14 FopbpmCQAwS5w0GaZwLxU2G0BAfpc> Please log in via your web browser and\n5.7.14 then try again.\n5.7.14  Learn more at\n5.7.14  https://support.google.com/mail/answer/78754 s126sm12311380wmd.43 - gsmtp')
2018-02-17 17:54:42,281 ERROR exception 10 Internal Server Error: /config/email/
Traceback (most recent call last):
  File "/usr/local/lib/python3.6/site-packages/django/core/handlers/exception.py", line 41, in inner
    response = get_response(request)
  File "/usr/local/lib/python3.6/site-packages/django/core/handlers/base.py", line 249, in _legacy_get_response
    response = self._get_response(request)
  File "/usr/local/lib/python3.6/site-packages/django/core/handlers/base.py", line 187, in _get_response
    response = self.process_exception_by_middleware(e, request)
  File "/usr/local/lib/python3.6/site-packages/channels/handler.py", line 243, in process_exception_by_middleware
    return super(AsgiHandler, self).process_exception_by_middleware(exception, request)
  File "/usr/local/lib/python3.6/site-packages/django/core/handlers/base.py", line 185, in _get_response
    response = wrapped_callback(request, *callback_args, **callback_kwargs)
  File "/usr/local/lib/python3.6/site-packages/django/contrib/auth/decorators.py", line 23, in _wrapped_view
    return view_func(request, *args, **kwargs)
  File "/usr/local/lib/python3.6/site-packages/django/views/generic/base.py", line 68, in view
    return self.dispatch(request, *args, **kwargs)
  File "/usr/local/lib/python3.6/site-packages/allauth/account/views.py", line 378, in dispatch
    return super(EmailView, self).dispatch(request, *args, **kwargs)
  File "/usr/local/lib/python3.6/site-packages/django/views/generic/base.py", line 88, in dispatch
    return handler(request, *args, **kwargs)
  File "/usr/local/lib/python3.6/site-packages/allauth/account/views.py", line 405, in post
    res = self._action_send(request)
  File "/usr/local/lib/python3.6/site-packages/allauth/account/views.py", line 433, in _action_send
    email_address.send_confirmation(request)
  File "/usr/local/lib/python3.6/site-packages/allauth/account/models.py", line 60, in send_confirmation
    confirmation.send(request, signup=signup)
  File "/usr/local/lib/python3.6/site-packages/allauth/account/models.py", line 166, in send
    get_adapter(request).send_confirmation_mail(request, self, signup)
  File "/usr/local/lib/python3.6/site-packages/allauth/account/adapter.py", line 447, in send_confirmation_mail
    ctx)
  File "/usr/local/lib/python3.6/site-packages/allauth/account/adapter.py", line 140, in send_mail
    msg.send()
  File "/usr/local/lib/python3.6/site-packages/django/core/mail/message.py", line 348, in send
    return self.get_connection(fail_silently).send_messages([self])
  File "/usr/local/lib/python3.6/site-packages/django/core/mail/backends/smtp.py", line 104, in send_messages
    new_conn_created = self.open()
  File "/usr/local/lib/python3.6/site-packages/django/core/mail/backends/smtp.py", line 71, in open
    self.connection.login(force_str(self.username), force_str(self.password))
  File "/usr/local/lib/python3.6/smtplib.py", line 730, in login
    raise last_exception
  File "/usr/local/lib/python3.6/smtplib.py", line 721, in login
    initial_response_ok=initial_response_ok)
  File "/usr/local/lib/python3.6/smtplib.py", line 642, in auth
    raise SMTPAuthenticationError(code, resp)
smtplib.SMTPAuthenticationError: (534, b'5.7.14 <https://accounts.google.com/signin/continue?sarp=1&scc=1&plt=AKgnsbvu\n5.7.14 8i1CZwqP71y2fFNJPuB4uByOa7pEFg5RGonaYPd5iUtnHJAOaIpxwGLGFVjcCilK2_vHgP\n5.7.14 IGULL4UrhcFXzhyTnYyYyze0Nf8Pph8R2l82ONSefvNx0JNKC26dlzuvHCtBVYONDBRpw1\n5.7.14 ZqD1cswwWaqC5yVGr4c4yzHx312Hq5Uzzhh2ks80O2SynjX9poJY9EXJaziRA5e5yL_Crx\n5.7.14 SOqqY36KbxV_SPnZp7CMQlU5BTzik> Please log in via your web browser and\n5.7.14 then try again.\n5.7.14  Learn more at\n5.7.14  https://support.google.com/mail/answer/78754 n24sm20852440wmi.21 - gsmtp')
2018-02-17 17:54:44,917 ERROR exception 10 Internal Server Error: /config/email/
Traceback (most recent call last):
  File "/usr/local/lib/python3.6/site-packages/django/core/handlers/exception.py", line 41, in inner
    response = get_response(request)
  File "/usr/local/lib/python3.6/site-packages/django/core/handlers/base.py", line 249, in _legacy_get_response
    response = self._get_response(request)
  File "/usr/local/lib/python3.6/site-packages/django/core/handlers/base.py", line 187, in _get_response
    response = self.process_exception_by_middleware(e, request)
  File "/usr/local/lib/python3.6/site-packages/channels/handler.py", line 243, in process_exception_by_middleware
    return super(AsgiHandler, self).process_exception_by_middleware(exception, request)
  File "/usr/local/lib/python3.6/site-packages/django/core/handlers/base.py", line 185, in _get_response
    response = wrapped_callback(request, *callback_args, **callback_kwargs)
  File "/usr/local/lib/python3.6/site-packages/django/contrib/auth/decorators.py", line 23, in _wrapped_view
    return view_func(request, *args, **kwargs)
  File "/usr/local/lib/python3.6/site-packages/django/views/generic/base.py", line 68, in view
    return self.dispatch(request, *args, **kwargs)
  File "/usr/local/lib/python3.6/site-packages/allauth/account/views.py", line 378, in dispatch
    return super(EmailView, self).dispatch(request, *args, **kwargs)
  File "/usr/local/lib/python3.6/site-packages/django/views/generic/base.py", line 88, in dispatch
    return handler(request, *args, **kwargs)
  File "/usr/local/lib/python3.6/site-packages/allauth/account/views.py", line 405, in post
    res = self._action_send(request)
  File "/usr/local/lib/python3.6/site-packages/allauth/account/views.py", line 433, in _action_send
    email_address.send_confirmation(request)
  File "/usr/local/lib/python3.6/site-packages/allauth/account/models.py", line 60, in send_confirmation
    confirmation.send(request, signup=signup)
  File "/usr/local/lib/python3.6/site-packages/allauth/account/models.py", line 166, in send
    get_adapter(request).send_confirmation_mail(request, self, signup)
  File "/usr/local/lib/python3.6/site-packages/allauth/account/adapter.py", line 447, in send_confirmation_mail
    ctx)
  File "/usr/local/lib/python3.6/site-packages/allauth/account/adapter.py", line 140, in send_mail
    msg.send()
  File "/usr/local/lib/python3.6/site-packages/django/core/mail/message.py", line 348, in send
    return self.get_connection(fail_silently).send_messages([self])
  File "/usr/local/lib/python3.6/site-packages/django/core/mail/backends/smtp.py", line 104, in send_messages
    new_conn_created = self.open()
  File "/usr/local/lib/python3.6/site-packages/django/core/mail/backends/smtp.py", line 71, in open
    self.connection.login(force_str(self.username), force_str(self.password))
  File "/usr/local/lib/python3.6/smtplib.py", line 730, in login
    raise last_exception
  File "/usr/local/lib/python3.6/smtplib.py", line 721, in login
    initial_response_ok=initial_response_ok)
  File "/usr/local/lib/python3.6/smtplib.py", line 642, in auth
    raise SMTPAuthenticationError(code, resp)
smtplib.SMTPAuthenticationError: (534, b'5.7.14 <https://accounts.google.com/signin/continue?sarp=1&scc=1&plt=AKgnsbsr\n5.7.14 xXZQHuRe7zQFfaENHAmTalA0VHtA91EpHjVCNN0i8_HDDuxPgd7VppGr27ecvA2lKd3c7g\n5.7.14 smrbpYslioQJxcMsmWexIP1X884Yn0Z7HClhala4nJc0aU50WSWliSiQ4BVqMXnllMCBDf\n5.7.14 4Fz154gQa53WurofeBkjEFqxVOIUD5e4bqZVDkdmALgs5s8h_0mj_jj3ZArfgLYCKqZT6R\n5.7.14 bxXkb4cnBVgI30eJBYZkSEZutYTRY> Please log in via your web browser and\n5.7.14 then try again.\n5.7.14  Learn more at\n5.7.14  https://support.google.com/mail/answer/78754 n20sm5422332wrg.84 - gsmtp')
2018-02-17 17:55:46,601 ERROR exception 10 Internal Server Error: /config/email/
Traceback (most recent call last):
  File "/usr/local/lib/python3.6/site-packages/django/core/handlers/exception.py", line 41, in inner
    response = get_response(request)
  File "/usr/local/lib/python3.6/site-packages/django/core/handlers/base.py", line 249, in _legacy_get_response
    response = self._get_response(request)
  File "/usr/local/lib/python3.6/site-packages/django/core/handlers/base.py", line 187, in _get_response
    response = self.process_exception_by_middleware(e, request)
  File "/usr/local/lib/python3.6/site-packages/channels/handler.py", line 243, in process_exception_by_middleware
    return super(AsgiHandler, self).process_exception_by_middleware(exception, request)
  File "/usr/local/lib/python3.6/site-packages/django/core/handlers/base.py", line 185, in _get_response
    response = wrapped_callback(request, *callback_args, **callback_kwargs)
  File "/usr/local/lib/python3.6/site-packages/django/contrib/auth/decorators.py", line 23, in _wrapped_view
    return view_func(request, *args, **kwargs)
  File "/usr/local/lib/python3.6/site-packages/django/views/generic/base.py", line 68, in view
    return self.dispatch(request, *args, **kwargs)
  File "/usr/local/lib/python3.6/site-packages/allauth/account/views.py", line 378, in dispatch
    return super(EmailView, self).dispatch(request, *args, **kwargs)
  File "/usr/local/lib/python3.6/site-packages/django/views/generic/base.py", line 88, in dispatch
    return handler(request, *args, **kwargs)
  File "/usr/local/lib/python3.6/site-packages/allauth/account/views.py", line 405, in post
    res = self._action_send(request)
  File "/usr/local/lib/python3.6/site-packages/allauth/account/views.py", line 433, in _action_send
    email_address.send_confirmation(request)
  File "/usr/local/lib/python3.6/site-packages/allauth/account/models.py", line 60, in send_confirmation
    confirmation.send(request, signup=signup)
  File "/usr/local/lib/python3.6/site-packages/allauth/account/models.py", line 166, in send
    get_adapter(request).send_confirmation_mail(request, self, signup)
  File "/usr/local/lib/python3.6/site-packages/allauth/account/adapter.py", line 447, in send_confirmation_mail
    ctx)
  File "/usr/local/lib/python3.6/site-packages/allauth/account/adapter.py", line 140, in send_mail
    msg.send()
  File "/usr/local/lib/python3.6/site-packages/django/core/mail/message.py", line 348, in send
    return self.get_connection(fail_silently).send_messages([self])
  File "/usr/local/lib/python3.6/site-packages/django/core/mail/backends/smtp.py", line 104, in send_messages
    new_conn_created = self.open()
  File "/usr/local/lib/python3.6/site-packages/django/core/mail/backends/smtp.py", line 71, in open
    self.connection.login(force_str(self.username), force_str(self.password))
  File "/usr/local/lib/python3.6/smtplib.py", line 730, in login
    raise last_exception
  File "/usr/local/lib/python3.6/smtplib.py", line 721, in login
    initial_response_ok=initial_response_ok)
  File "/usr/local/lib/python3.6/smtplib.py", line 642, in auth
    raise SMTPAuthenticationError(code, resp)
smtplib.SMTPAuthenticationError: (534, b'5.7.14 <https://accounts.google.com/signin/continue?sarp=1&scc=1&plt=AKgnsbvi\n5.7.14 _35tiquRbuNCbN96EISgM8G7wDmFaPzbNJBxHwxmF9VL-n8XvgpNyi8QqBKmFj9a24GOaH\n5.7.14 DDKGqfcrU5y7WNiDS5IwCFtKmwnuQXNltAKtB9vvAumvVgHUKBdW_tZjizHckADk0ahauu\n5.7.14 OXyADPvI22mPbf0xjz4wll9V9EXZn7fjHwpA6P_LRh408E1qnTk_7RFu26bO62UROmlSkY\n5.7.14 UEL6Wrp8a0_-py2-u938FwppOp-lU> Please log in via your web browser and\n5.7.14 then try again.\n5.7.14  Learn more at\n5.7.14  https://support.google.com/mail/answer/78754 h13sm27647472wrc.89 - gsmtp')
2018-02-17 17:55:49,686 ERROR exception 10 Internal Server Error: /config/email/
Traceback (most recent call last):
  File "/usr/local/lib/python3.6/site-packages/django/core/handlers/exception.py", line 41, in inner
    response = get_response(request)
  File "/usr/local/lib/python3.6/site-packages/django/core/handlers/base.py", line 249, in _legacy_get_response
    response = self._get_response(request)
  File "/usr/local/lib/python3.6/site-packages/django/core/handlers/base.py", line 187, in _get_response
    response = self.process_exception_by_middleware(e, request)
  File "/usr/local/lib/python3.6/site-packages/channels/handler.py", line 243, in process_exception_by_middleware
    return super(AsgiHandler, self).process_exception_by_middleware(exception, request)
  File "/usr/local/lib/python3.6/site-packages/django/core/handlers/base.py", line 185, in _get_response
    response = wrapped_callback(request, *callback_args, **callback_kwargs)
  File "/usr/local/lib/python3.6/site-packages/django/contrib/auth/decorators.py", line 23, in _wrapped_view
    return view_func(request, *args, **kwargs)
  File "/usr/local/lib/python3.6/site-packages/django/views/generic/base.py", line 68, in view
    return self.dispatch(request, *args, **kwargs)
  File "/usr/local/lib/python3.6/site-packages/allauth/account/views.py", line 378, in dispatch
    return super(EmailView, self).dispatch(request, *args, **kwargs)
  File "/usr/local/lib/python3.6/site-packages/django/views/generic/base.py", line 88, in dispatch
    return handler(request, *args, **kwargs)
  File "/usr/local/lib/python3.6/site-packages/allauth/account/views.py", line 405, in post
    res = self._action_send(request)
  File "/usr/local/lib/python3.6/site-packages/allauth/account/views.py", line 433, in _action_send
    email_address.send_confirmation(request)
  File "/usr/local/lib/python3.6/site-packages/allauth/account/models.py", line 60, in send_confirmation
    confirmation.send(request, signup=signup)
  File "/usr/local/lib/python3.6/site-packages/allauth/account/models.py", line 166, in send
    get_adapter(request).send_confirmation_mail(request, self, signup)
  File "/usr/local/lib/python3.6/site-packages/allauth/account/adapter.py", line 447, in send_confirmation_mail
    ctx)
  File "/usr/local/lib/python3.6/site-packages/allauth/account/adapter.py", line 140, in send_mail
    msg.send()
  File "/usr/local/lib/python3.6/site-packages/django/core/mail/message.py", line 348, in send
    return self.get_connection(fail_silently).send_messages([self])
  File "/usr/local/lib/python3.6/site-packages/django/core/mail/backends/smtp.py", line 104, in send_messages
    new_conn_created = self.open()
  File "/usr/local/lib/python3.6/site-packages/django/core/mail/backends/smtp.py", line 71, in open
    self.connection.login(force_str(self.username), force_str(self.password))
  File "/usr/local/lib/python3.6/smtplib.py", line 730, in login
    raise last_exception
  File "/usr/local/lib/python3.6/smtplib.py", line 721, in login
    initial_response_ok=initial_response_ok)
  File "/usr/local/lib/python3.6/smtplib.py", line 642, in auth
    raise SMTPAuthenticationError(code, resp)
smtplib.SMTPAuthenticationError: (534, b'5.7.14 <https://accounts.google.com/signin/continue?sarp=1&scc=1&plt=AKgnsbvs\n5.7.14 PaDtT6HKZz_enh7VWMjrg74JONPLc0b2m_qKhzoYNkds8mRu2lHHiG9aNv-fIN4Ou6wpr9\n5.7.14 f2OYYv0PlX_cQN3uDzNTmpwq20KIjH_zFUsNitUFbBnfOsAqVX60xtrdTTIvjHZsV5tPmk\n5.7.14 gNQAIcF3HxS5JuToo-JPsvK8VVWtzZpDpL8q2Iu5FMeKztXD7cB1Eck1fZm6ynbT_plPYM\n5.7.14 K-Gb3a9koFX6ZAE6OSiReD2SLar20> Please log in via your web browser and\n5.7.14 then try again.\n5.7.14  Learn more at\n5.7.14  https://support.google.com/mail/answer/78754 e5sm452573wre.51 - gsmtp')
2018-02-17 17:55:52,535 ERROR exception 10 Internal Server Error: /config/email/
Traceback (most recent call last):
  File "/usr/local/lib/python3.6/site-packages/django/core/handlers/exception.py", line 41, in inner
    response = get_response(request)
  File "/usr/local/lib/python3.6/site-packages/django/core/handlers/base.py", line 249, in _legacy_get_response
    response = self._get_response(request)
  File "/usr/local/lib/python3.6/site-packages/django/core/handlers/base.py", line 187, in _get_response
    response = self.process_exception_by_middleware(e, request)
  File "/usr/local/lib/python3.6/site-packages/channels/handler.py", line 243, in process_exception_by_middleware
    return super(AsgiHandler, self).process_exception_by_middleware(exception, request)
  File "/usr/local/lib/python3.6/site-packages/django/core/handlers/base.py", line 185, in _get_response
    response = wrapped_callback(request, *callback_args, **callback_kwargs)
  File "/usr/local/lib/python3.6/site-packages/django/contrib/auth/decorators.py", line 23, in _wrapped_view
    return view_func(request, *args, **kwargs)
  File "/usr/local/lib/python3.6/site-packages/django/views/generic/base.py", line 68, in view
    return self.dispatch(request, *args, **kwargs)
  File "/usr/local/lib/python3.6/site-packages/allauth/account/views.py", line 378, in dispatch
    return super(EmailView, self).dispatch(request, *args, **kwargs)
  File "/usr/local/lib/python3.6/site-packages/django/views/generic/base.py", line 88, in dispatch
    return handler(request, *args, **kwargs)
  File "/usr/local/lib/python3.6/site-packages/allauth/account/views.py", line 405, in post
    res = self._action_send(request)
  File "/usr/local/lib/python3.6/site-packages/allauth/account/views.py", line 433, in _action_send
    email_address.send_confirmation(request)
  File "/usr/local/lib/python3.6/site-packages/allauth/account/models.py", line 60, in send_confirmation
    confirmation.send(request, signup=signup)
  File "/usr/local/lib/python3.6/site-packages/allauth/account/models.py", line 166, in send
    get_adapter(request).send_confirmation_mail(request, self, signup)
  File "/usr/local/lib/python3.6/site-packages/allauth/account/adapter.py", line 447, in send_confirmation_mail
    ctx)
  File "/usr/local/lib/python3.6/site-packages/allauth/account/adapter.py", line 140, in send_mail
    msg.send()
  File "/usr/local/lib/python3.6/site-packages/django/core/mail/message.py", line 348, in send
    return self.get_connection(fail_silently).send_messages([self])
  File "/usr/local/lib/python3.6/site-packages/django/core/mail/backends/smtp.py", line 104, in send_messages
    new_conn_created = self.open()
  File "/usr/local/lib/python3.6/site-packages/django/core/mail/backends/smtp.py", line 71, in open
    self.connection.login(force_str(self.username), force_str(self.password))
  File "/usr/local/lib/python3.6/smtplib.py", line 730, in login
    raise last_exception
  File "/usr/local/lib/python3.6/smtplib.py", line 721, in login
    initial_response_ok=initial_response_ok)
  File "/usr/local/lib/python3.6/smtplib.py", line 642, in auth
    raise SMTPAuthenticationError(code, resp)
smtplib.SMTPAuthenticationError: (534, b'5.7.14 <https://accounts.google.com/signin/continue?sarp=1&scc=1&plt=AKgnsbue\n5.7.14 HJR4m0h0_rMbRphF-hDZCcn3WYEA3TcVcfZQJCt8Sxe94fM39E-QxCfdTKBYnoT2hGe6FI\n5.7.14 sLgMNQs1tyJMW2XeeLN8MbemX2cCodHObYQTP7IuC88oA6ix3hcoSjbbY7mWV_EnSGdqPX\n5.7.14 l1_UDVvoby7I_tkJRJhSTudebRqi4dDAbXl0ow7B-7OVZu6DxilTgj21fmoeuGm0KZ2Vs3\n5.7.14 2nHnQJeyGlYLw6yWjrCtQkl0oKjlI> Please log in via your web browser and\n5.7.14 then try again.\n5.7.14  Learn more at\n5.7.14  https://support.google.com/mail/answer/78754 o11sm20655725wra.28 - gsmtp')
2018-02-17 17:55:53,935 ERROR exception 10 Internal Server Error: /config/email/
Traceback (most recent call last):
  File "/usr/local/lib/python3.6/site-packages/django/core/handlers/exception.py", line 41, in inner
    response = get_response(request)
  File "/usr/local/lib/python3.6/site-packages/django/core/handlers/base.py", line 249, in _legacy_get_response
    response = self._get_response(request)
  File "/usr/local/lib/python3.6/site-packages/django/core/handlers/base.py", line 187, in _get_response
    response = self.process_exception_by_middleware(e, request)
  File "/usr/local/lib/python3.6/site-packages/channels/handler.py", line 243, in process_exception_by_middleware
    return super(AsgiHandler, self).process_exception_by_middleware(exception, request)
  File "/usr/local/lib/python3.6/site-packages/django/core/handlers/base.py", line 185, in _get_response
    response = wrapped_callback(request, *callback_args, **callback_kwargs)
  File "/usr/local/lib/python3.6/site-packages/django/contrib/auth/decorators.py", line 23, in _wrapped_view
    return view_func(request, *args, **kwargs)
  File "/usr/local/lib/python3.6/site-packages/django/views/generic/base.py", line 68, in view
    return self.dispatch(request, *args, **kwargs)
  File "/usr/local/lib/python3.6/site-packages/allauth/account/views.py", line 378, in dispatch
    return super(EmailView, self).dispatch(request, *args, **kwargs)
  File "/usr/local/lib/python3.6/site-packages/django/views/generic/base.py", line 88, in dispatch
    return handler(request, *args, **kwargs)
  File "/usr/local/lib/python3.6/site-packages/allauth/account/views.py", line 405, in post
    res = self._action_send(request)
  File "/usr/local/lib/python3.6/site-packages/allauth/account/views.py", line 433, in _action_send
    email_address.send_confirmation(request)
  File "/usr/local/lib/python3.6/site-packages/allauth/account/models.py", line 60, in send_confirmation
    confirmation.send(request, signup=signup)
  File "/usr/local/lib/python3.6/site-packages/allauth/account/models.py", line 166, in send
    get_adapter(request).send_confirmation_mail(request, self, signup)
  File "/usr/local/lib/python3.6/site-packages/allauth/account/adapter.py", line 447, in send_confirmation_mail
    ctx)
  File "/usr/local/lib/python3.6/site-packages/allauth/account/adapter.py", line 140, in send_mail
    msg.send()
  File "/usr/local/lib/python3.6/site-packages/django/core/mail/message.py", line 348, in send
    return self.get_connection(fail_silently).send_messages([self])
  File "/usr/local/lib/python3.6/site-packages/django/core/mail/backends/smtp.py", line 104, in send_messages
    new_conn_created = self.open()
  File "/usr/local/lib/python3.6/site-packages/django/core/mail/backends/smtp.py", line 71, in open
    self.connection.login(force_str(self.username), force_str(self.password))
  File "/usr/local/lib/python3.6/smtplib.py", line 730, in login
    raise last_exception
  File "/usr/local/lib/python3.6/smtplib.py", line 721, in login
    initial_response_ok=initial_response_ok)
  File "/usr/local/lib/python3.6/smtplib.py", line 642, in auth
    raise SMTPAuthenticationError(code, resp)
smtplib.SMTPAuthenticationError: (534, b'5.7.14 <https://accounts.google.com/signin/continue?sarp=1&scc=1&plt=AKgnsbtZ\n5.7.14 Hl8avkEUcrcMv8Wj9QktDG-Qzv0LPYjEkbgcsabbOzCNZZZDLeOJbbq34zohAgKfOBIQVB\n5.7.14 Lr9pC1gh72ef__HdcEbFr5J2xykO-UbITFYXz9v-l_2ezHzsgGv_NdPihiVnTILcz46lC6\n5.7.14 PwywkHAxBQaVhPtOGipOxJ46I_P9wYMjSdwNsDFp5B18Glw_FaA6WwVdzh0vSR3JoMn_Mb\n5.7.14 Cpk-nyQc6BYsrCdumKD1ztUUvtpTw> Please log in via your web browser and\n5.7.14 then try again.\n5.7.14  Learn more at\n5.7.14  https://support.google.com/mail/answer/78754 r1sm18695253wmg.22 - gsmtp')
2018-02-17 17:55:55,193 ERROR exception 10 Internal Server Error: /config/email/
Traceback (most recent call last):
  File "/usr/local/lib/python3.6/site-packages/django/core/handlers/exception.py", line 41, in inner
    response = get_response(request)
  File "/usr/local/lib/python3.6/site-packages/django/core/handlers/base.py", line 249, in _legacy_get_response
    response = self._get_response(request)
  File "/usr/local/lib/python3.6/site-packages/django/core/handlers/base.py", line 187, in _get_response
    response = self.process_exception_by_middleware(e, request)
  File "/usr/local/lib/python3.6/site-packages/channels/handler.py", line 243, in process_exception_by_middleware
    return super(AsgiHandler, self).process_exception_by_middleware(exception, request)
  File "/usr/local/lib/python3.6/site-packages/django/core/handlers/base.py", line 185, in _get_response
    response = wrapped_callback(request, *callback_args, **callback_kwargs)
  File "/usr/local/lib/python3.6/site-packages/django/contrib/auth/decorators.py", line 23, in _wrapped_view
    return view_func(request, *args, **kwargs)
  File "/usr/local/lib/python3.6/site-packages/django/views/generic/base.py", line 68, in view
    return self.dispatch(request, *args, **kwargs)
  File "/usr/local/lib/python3.6/site-packages/allauth/account/views.py", line 378, in dispatch
    return super(EmailView, self).dispatch(request, *args, **kwargs)
  File "/usr/local/lib/python3.6/site-packages/django/views/generic/base.py", line 88, in dispatch
    return handler(request, *args, **kwargs)
  File "/usr/local/lib/python3.6/site-packages/allauth/account/views.py", line 405, in post
    res = self._action_send(request)
  File "/usr/local/lib/python3.6/site-packages/allauth/account/views.py", line 433, in _action_send
    email_address.send_confirmation(request)
  File "/usr/local/lib/python3.6/site-packages/allauth/account/models.py", line 60, in send_confirmation
    confirmation.send(request, signup=signup)
  File "/usr/local/lib/python3.6/site-packages/allauth/account/models.py", line 166, in send
    get_adapter(request).send_confirmation_mail(request, self, signup)
  File "/usr/local/lib/python3.6/site-packages/allauth/account/adapter.py", line 447, in send_confirmation_mail
    ctx)
  File "/usr/local/lib/python3.6/site-packages/allauth/account/adapter.py", line 140, in send_mail
    msg.send()
  File "/usr/local/lib/python3.6/site-packages/django/core/mail/message.py", line 348, in send
    return self.get_connection(fail_silently).send_messages([self])
  File "/usr/local/lib/python3.6/site-packages/django/core/mail/backends/smtp.py", line 104, in send_messages
    new_conn_created = self.open()
  File "/usr/local/lib/python3.6/site-packages/django/core/mail/backends/smtp.py", line 71, in open
    self.connection.login(force_str(self.username), force_str(self.password))
  File "/usr/local/lib/python3.6/smtplib.py", line 730, in login
    raise last_exception
  File "/usr/local/lib/python3.6/smtplib.py", line 721, in login
    initial_response_ok=initial_response_ok)
  File "/usr/local/lib/python3.6/smtplib.py", line 642, in auth
    raise SMTPAuthenticationError(code, resp)
smtplib.SMTPAuthenticationError: (534, b'5.7.14 <https://accounts.google.com/signin/continue?sarp=1&scc=1&plt=AKgnsbsQ\n5.7.14 QmZZo2Lj1uGOZHGrnLTI5H_aEx8fdUh06kRLrrV1Of_JoibP3cVsw9PWzDJSMHEBUexqu4\n5.7.14 9F1PE3y1cyr4scGhxX4FyPVc6fbNPBFKZrAnK_m-i0DwxLOEVCFRo4QxtXm6zzC6GFTvAU\n5.7.14 e6vdlGeGyuvs2kHh9zltvacyA-7d8dh5uWUvbSrxy-xn2cjCVO5qEdSGiD0RQuRUaqUDdw\n5.7.14 SeZJPNzpBefDBNXVSlTUbCUh2jsEA> Please log in via your web browser and\n5.7.14 then try again.\n5.7.14  Learn more at\n5.7.14  https://support.google.com/mail/answer/78754 137sm17715411wmm.46 - gsmtp')
2018-02-17 17:55:56,371 ERROR exception 10 Internal Server Error: /config/email/
Traceback (most recent call last):
  File "/usr/local/lib/python3.6/site-packages/django/core/handlers/exception.py", line 41, in inner
    response = get_response(request)
  File "/usr/local/lib/python3.6/site-packages/django/core/handlers/base.py", line 249, in _legacy_get_response
    response = self._get_response(request)
  File "/usr/local/lib/python3.6/site-packages/django/core/handlers/base.py", line 187, in _get_response
    response = self.process_exception_by_middleware(e, request)
  File "/usr/local/lib/python3.6/site-packages/channels/handler.py", line 243, in process_exception_by_middleware
    return super(AsgiHandler, self).process_exception_by_middleware(exception, request)
  File "/usr/local/lib/python3.6/site-packages/django/core/handlers/base.py", line 185, in _get_response
    response = wrapped_callback(request, *callback_args, **callback_kwargs)
  File "/usr/local/lib/python3.6/site-packages/django/contrib/auth/decorators.py", line 23, in _wrapped_view
    return view_func(request, *args, **kwargs)
  File "/usr/local/lib/python3.6/site-packages/django/views/generic/base.py", line 68, in view
    return self.dispatch(request, *args, **kwargs)
  File "/usr/local/lib/python3.6/site-packages/allauth/account/views.py", line 378, in dispatch
    return super(EmailView, self).dispatch(request, *args, **kwargs)
  File "/usr/local/lib/python3.6/site-packages/django/views/generic/base.py", line 88, in dispatch
    return handler(request, *args, **kwargs)
  File "/usr/local/lib/python3.6/site-packages/allauth/account/views.py", line 405, in post
    res = self._action_send(request)
  File "/usr/local/lib/python3.6/site-packages/allauth/account/views.py", line 433, in _action_send
    email_address.send_confirmation(request)
  File "/usr/local/lib/python3.6/site-packages/allauth/account/models.py", line 60, in send_confirmation
    confirmation.send(request, signup=signup)
  File "/usr/local/lib/python3.6/site-packages/allauth/account/models.py", line 166, in send
    get_adapter(request).send_confirmation_mail(request, self, signup)
  File "/usr/local/lib/python3.6/site-packages/allauth/account/adapter.py", line 447, in send_confirmation_mail
    ctx)
  File "/usr/local/lib/python3.6/site-packages/allauth/account/adapter.py", line 140, in send_mail
    msg.send()
  File "/usr/local/lib/python3.6/site-packages/django/core/mail/message.py", line 348, in send
    return self.get_connection(fail_silently).send_messages([self])
  File "/usr/local/lib/python3.6/site-packages/django/core/mail/backends/smtp.py", line 104, in send_messages
    new_conn_created = self.open()
  File "/usr/local/lib/python3.6/site-packages/django/core/mail/backends/smtp.py", line 71, in open
    self.connection.login(force_str(self.username), force_str(self.password))
  File "/usr/local/lib/python3.6/smtplib.py", line 730, in login
    raise last_exception
  File "/usr/local/lib/python3.6/smtplib.py", line 721, in login
    initial_response_ok=initial_response_ok)
  File "/usr/local/lib/python3.6/smtplib.py", line 642, in auth
    raise SMTPAuthenticationError(code, resp)
smtplib.SMTPAuthenticationError: (534, b'5.7.14 <https://accounts.google.com/signin/continue?sarp=1&scc=1&plt=AKgnsbtV\n5.7.14 l0MNTgt2Edn54GGTMElyPlfrr6AVUpDnfkONdWn1T7BzMCMnisiXZDoDNBEUJYRVYne_U5\n5.7.14 g4dyCcNq6jqWLtrfUn5KzSTDqBRujTyPpsuXfM8dJpzxTCMmVtX-s1tUppKtHEO_ozlR9U\n5.7.14 b6Eq5AWr7Hicv-noIiYayFv5_2sGHz2vwHeK6RBzo-9tyzMJH3xQyLU8VpCwyp7u9fRmAP\n5.7.14 30WHiVKy3balkrrTxMpihhFePe1_E> Please log in via your web browser and\n5.7.14 then try again.\n5.7.14  Learn more at\n5.7.14  https://support.google.com/mail/answer/78754 r1sm18695330wmg.22 - gsmtp')
2018-02-17 17:55:57,688 ERROR exception 10 Internal Server Error: /config/email/
Traceback (most recent call last):
  File "/usr/local/lib/python3.6/site-packages/django/core/handlers/exception.py", line 41, in inner
    response = get_response(request)
  File "/usr/local/lib/python3.6/site-packages/django/core/handlers/base.py", line 249, in _legacy_get_response
    response = self._get_response(request)
  File "/usr/local/lib/python3.6/site-packages/django/core/handlers/base.py", line 187, in _get_response
    response = self.process_exception_by_middleware(e, request)
  File "/usr/local/lib/python3.6/site-packages/channels/handler.py", line 243, in process_exception_by_middleware
    return super(AsgiHandler, self).process_exception_by_middleware(exception, request)
  File "/usr/local/lib/python3.6/site-packages/django/core/handlers/base.py", line 185, in _get_response
    response = wrapped_callback(request, *callback_args, **callback_kwargs)
  File "/usr/local/lib/python3.6/site-packages/django/contrib/auth/decorators.py", line 23, in _wrapped_view
    return view_func(request, *args, **kwargs)
  File "/usr/local/lib/python3.6/site-packages/django/views/generic/base.py", line 68, in view
    return self.dispatch(request, *args, **kwargs)
  File "/usr/local/lib/python3.6/site-packages/allauth/account/views.py", line 378, in dispatch
    return super(EmailView, self).dispatch(request, *args, **kwargs)
  File "/usr/local/lib/python3.6/site-packages/django/views/generic/base.py", line 88, in dispatch
    return handler(request, *args, **kwargs)
  File "/usr/local/lib/python3.6/site-packages/allauth/account/views.py", line 405, in post
    res = self._action_send(request)
  File "/usr/local/lib/python3.6/site-packages/allauth/account/views.py", line 433, in _action_send
    email_address.send_confirmation(request)
  File "/usr/local/lib/python3.6/site-packages/allauth/account/models.py", line 60, in send_confirmation
    confirmation.send(request, signup=signup)
  File "/usr/local/lib/python3.6/site-packages/allauth/account/models.py", line 166, in send
    get_adapter(request).send_confirmation_mail(request, self, signup)
  File "/usr/local/lib/python3.6/site-packages/allauth/account/adapter.py", line 447, in send_confirmation_mail
    ctx)
  File "/usr/local/lib/python3.6/site-packages/allauth/account/adapter.py", line 140, in send_mail
    msg.send()
  File "/usr/local/lib/python3.6/site-packages/django/core/mail/message.py", line 348, in send
    return self.get_connection(fail_silently).send_messages([self])
  File "/usr/local/lib/python3.6/site-packages/django/core/mail/backends/smtp.py", line 104, in send_messages
    new_conn_created = self.open()
  File "/usr/local/lib/python3.6/site-packages/django/core/mail/backends/smtp.py", line 71, in open
    self.connection.login(force_str(self.username), force_str(self.password))
  File "/usr/local/lib/python3.6/smtplib.py", line 730, in login
    raise last_exception
  File "/usr/local/lib/python3.6/smtplib.py", line 721, in login
    initial_response_ok=initial_response_ok)
  File "/usr/local/lib/python3.6/smtplib.py", line 642, in auth
    raise SMTPAuthenticationError(code, resp)
smtplib.SMTPAuthenticationError: (534, b'5.7.14 <https://accounts.google.com/signin/continue?sarp=1&scc=1&plt=AKgnsbtd\n5.7.14 JVkfLB6Zb06SZuQTPxA8DwTkjaGJeTm78LIy9Nr95Ta0D53qkbZD-8D8mQE44Wc20Mbe81\n5.7.14 ER4LgAs7Li6FCAzDnyXr-3PX6peg0KPDrC3n9m6XWsNufqKyt9g-RccvL_g-ipl0qBCAYw\n5.7.14 Es1Y89JCV-jot9HeIXDSeDSpg3cQ8gLF6LwKpkIsTbGYvA7cbhAzhEi46mm5AG68i6a9NI\n5.7.14 afOtLTrJEBwr-cnwjUrir4B9lGUwE> Please log in via your web browser and\n5.7.14 then try again.\n5.7.14  Learn more at\n5.7.14  https://support.google.com/mail/answer/78754 u20sm14015019wrg.13 - gsmtp')
2018-02-17 17:55:58,890 ERROR exception 10 Internal Server Error: /config/email/
Traceback (most recent call last):
  File "/usr/local/lib/python3.6/site-packages/django/core/handlers/exception.py", line 41, in inner
    response = get_response(request)
  File "/usr/local/lib/python3.6/site-packages/django/core/handlers/base.py", line 249, in _legacy_get_response
    response = self._get_response(request)
  File "/usr/local/lib/python3.6/site-packages/django/core/handlers/base.py", line 187, in _get_response
    response = self.process_exception_by_middleware(e, request)
  File "/usr/local/lib/python3.6/site-packages/channels/handler.py", line 243, in process_exception_by_middleware
    return super(AsgiHandler, self).process_exception_by_middleware(exception, request)
  File "/usr/local/lib/python3.6/site-packages/django/core/handlers/base.py", line 185, in _get_response
    response = wrapped_callback(request, *callback_args, **callback_kwargs)
  File "/usr/local/lib/python3.6/site-packages/django/contrib/auth/decorators.py", line 23, in _wrapped_view
    return view_func(request, *args, **kwargs)
  File "/usr/local/lib/python3.6/site-packages/django/views/generic/base.py", line 68, in view
    return self.dispatch(request, *args, **kwargs)
  File "/usr/local/lib/python3.6/site-packages/allauth/account/views.py", line 378, in dispatch
    return super(EmailView, self).dispatch(request, *args, **kwargs)
  File "/usr/local/lib/python3.6/site-packages/django/views/generic/base.py", line 88, in dispatch
    return handler(request, *args, **kwargs)
  File "/usr/local/lib/python3.6/site-packages/allauth/account/views.py", line 405, in post
    res = self._action_send(request)
  File "/usr/local/lib/python3.6/site-packages/allauth/account/views.py", line 433, in _action_send
    email_address.send_confirmation(request)
  File "/usr/local/lib/python3.6/site-packages/allauth/account/models.py", line 60, in send_confirmation
    confirmation.send(request, signup=signup)
  File "/usr/local/lib/python3.6/site-packages/allauth/account/models.py", line 166, in send
    get_adapter(request).send_confirmation_mail(request, self, signup)
  File "/usr/local/lib/python3.6/site-packages/allauth/account/adapter.py", line 447, in send_confirmation_mail
    ctx)
  File "/usr/local/lib/python3.6/site-packages/allauth/account/adapter.py", line 140, in send_mail
    msg.send()
  File "/usr/local/lib/python3.6/site-packages/django/core/mail/message.py", line 348, in send
    return self.get_connection(fail_silently).send_messages([self])
  File "/usr/local/lib/python3.6/site-packages/django/core/mail/backends/smtp.py", line 104, in send_messages
    new_conn_created = self.open()
  File "/usr/local/lib/python3.6/site-packages/django/core/mail/backends/smtp.py", line 71, in open
    self.connection.login(force_str(self.username), force_str(self.password))
  File "/usr/local/lib/python3.6/smtplib.py", line 730, in login
    raise last_exception
  File "/usr/local/lib/python3.6/smtplib.py", line 721, in login
    initial_response_ok=initial_response_ok)
  File "/usr/local/lib/python3.6/smtplib.py", line 642, in auth
    raise SMTPAuthenticationError(code, resp)
smtplib.SMTPAuthenticationError: (534, b'5.7.14 <https://accounts.google.com/signin/continue?sarp=1&scc=1&plt=AKgnsbtC\n5.7.14 ljnP3ZBYlOSZtCvrqG6225Rwv5THA41iF9xOxkDT9iEVEfOnoeofMcCk3wv7cc9cKbfqfc\n5.7.14 uFNZl84Hx8ALfbsxnmA0k1YQ56CSwiGCp_3M5DOiaBHLDqgZnH_qM-X2EJXzt6HrEvH_sd\n5.7.14 uBTa9cJzcKJN0LoFXJDNIl0HoYFvI7h_tVFiE2bIOQOigD0wAXlgtu_K6oxLJKHzBaTFe5\n5.7.14 u2awRdfNseO7WE1OQQ44hk9a2SZus> Please log in via your web browser and\n5.7.14 then try again.\n5.7.14  Learn more at\n5.7.14  https://support.google.com/mail/answer/78754 b133sm14870189wmh.4 - gsmtp')
2018-02-17 17:56:10,567 ERROR exception 10 Internal Server Error: /config/email/
Traceback (most recent call last):
  File "/usr/local/lib/python3.6/site-packages/django/core/handlers/exception.py", line 41, in inner
    response = get_response(request)
  File "/usr/local/lib/python3.6/site-packages/django/core/handlers/base.py", line 249, in _legacy_get_response
    response = self._get_response(request)
  File "/usr/local/lib/python3.6/site-packages/django/core/handlers/base.py", line 187, in _get_response
    response = self.process_exception_by_middleware(e, request)
  File "/usr/local/lib/python3.6/site-packages/channels/handler.py", line 243, in process_exception_by_middleware
    return super(AsgiHandler, self).process_exception_by_middleware(exception, request)
  File "/usr/local/lib/python3.6/site-packages/django/core/handlers/base.py", line 185, in _get_response
    response = wrapped_callback(request, *callback_args, **callback_kwargs)
  File "/usr/local/lib/python3.6/site-packages/django/contrib/auth/decorators.py", line 23, in _wrapped_view
    return view_func(request, *args, **kwargs)
  File "/usr/local/lib/python3.6/site-packages/django/views/generic/base.py", line 68, in view
    return self.dispatch(request, *args, **kwargs)
  File "/usr/local/lib/python3.6/site-packages/allauth/account/views.py", line 378, in dispatch
    return super(EmailView, self).dispatch(request, *args, **kwargs)
  File "/usr/local/lib/python3.6/site-packages/django/views/generic/base.py", line 88, in dispatch
    return handler(request, *args, **kwargs)
  File "/usr/local/lib/python3.6/site-packages/allauth/account/views.py", line 405, in post
    res = self._action_send(request)
  File "/usr/local/lib/python3.6/site-packages/allauth/account/views.py", line 433, in _action_send
    email_address.send_confirmation(request)
  File "/usr/local/lib/python3.6/site-packages/allauth/account/models.py", line 60, in send_confirmation
    confirmation.send(request, signup=signup)
  File "/usr/local/lib/python3.6/site-packages/allauth/account/models.py", line 166, in send
    get_adapter(request).send_confirmation_mail(request, self, signup)
  File "/usr/local/lib/python3.6/site-packages/allauth/account/adapter.py", line 447, in send_confirmation_mail
    ctx)
  File "/usr/local/lib/python3.6/site-packages/allauth/account/adapter.py", line 140, in send_mail
    msg.send()
  File "/usr/local/lib/python3.6/site-packages/django/core/mail/message.py", line 348, in send
    return self.get_connection(fail_silently).send_messages([self])
  File "/usr/local/lib/python3.6/site-packages/django/core/mail/backends/smtp.py", line 104, in send_messages
    new_conn_created = self.open()
  File "/usr/local/lib/python3.6/site-packages/django/core/mail/backends/smtp.py", line 71, in open
    self.connection.login(force_str(self.username), force_str(self.password))
  File "/usr/local/lib/python3.6/smtplib.py", line 730, in login
    raise last_exception
  File "/usr/local/lib/python3.6/smtplib.py", line 721, in login
    initial_response_ok=initial_response_ok)
  File "/usr/local/lib/python3.6/smtplib.py", line 642, in auth
    raise SMTPAuthenticationError(code, resp)
smtplib.SMTPAuthenticationError: (534, b'5.7.14 <https://accounts.google.com/signin/continue?sarp=1&scc=1&plt=AKgnsbux\n5.7.14 nE1EB48O5GOKyTXi-v5TqnLJY2bupBFYkcNJRGgDEqLrZFkcQUkohhvqQNPgVUI5AWwGfO\n5.7.14 8dTXFKXFJAYvVPw9gzLljnCV3ULuPRcKlbxoVnSqdic3wS0pTTdmy7dIbXqyKxoaEnp5pm\n5.7.14 j5wtU71hd2gayhZCarsB_bDpTpB1-buLTglL-27_tpcL-vJ5r-mkynPfQyHnTlRBam_mU_\n5.7.14 pVKEaAqZwPid3MT5fe2_mczTvzg2Q> Please log in via your web browser and\n5.7.14 then try again.\n5.7.14  Learn more at\n5.7.14  https://support.google.com/mail/answer/78754 i75sm14725624wmg.41 - gsmtp')
2018-02-17 17:57:43,658 ERROR exception 10 Internal Server Error: /config/email/
Traceback (most recent call last):
  File "/usr/local/lib/python3.6/site-packages/django/core/handlers/exception.py", line 41, in inner
    response = get_response(request)
  File "/usr/local/lib/python3.6/site-packages/django/core/handlers/base.py", line 249, in _legacy_get_response
    response = self._get_response(request)
  File "/usr/local/lib/python3.6/site-packages/django/core/handlers/base.py", line 187, in _get_response
    response = self.process_exception_by_middleware(e, request)
  File "/usr/local/lib/python3.6/site-packages/channels/handler.py", line 243, in process_exception_by_middleware
    return super(AsgiHandler, self).process_exception_by_middleware(exception, request)
  File "/usr/local/lib/python3.6/site-packages/django/core/handlers/base.py", line 185, in _get_response
    response = wrapped_callback(request, *callback_args, **callback_kwargs)
  File "/usr/local/lib/python3.6/site-packages/django/contrib/auth/decorators.py", line 23, in _wrapped_view
    return view_func(request, *args, **kwargs)
  File "/usr/local/lib/python3.6/site-packages/django/views/generic/base.py", line 68, in view
    return self.dispatch(request, *args, **kwargs)
  File "/usr/local/lib/python3.6/site-packages/allauth/account/views.py", line 378, in dispatch
    return super(EmailView, self).dispatch(request, *args, **kwargs)
  File "/usr/local/lib/python3.6/site-packages/django/views/generic/base.py", line 88, in dispatch
    return handler(request, *args, **kwargs)
  File "/usr/local/lib/python3.6/site-packages/allauth/account/views.py", line 405, in post
    res = self._action_send(request)
  File "/usr/local/lib/python3.6/site-packages/allauth/account/views.py", line 433, in _action_send
    email_address.send_confirmation(request)
  File "/usr/local/lib/python3.6/site-packages/allauth/account/models.py", line 60, in send_confirmation
    confirmation.send(request, signup=signup)
  File "/usr/local/lib/python3.6/site-packages/allauth/account/models.py", line 166, in send
    get_adapter(request).send_confirmation_mail(request, self, signup)
  File "/usr/local/lib/python3.6/site-packages/allauth/account/adapter.py", line 447, in send_confirmation_mail
    ctx)
  File "/usr/local/lib/python3.6/site-packages/allauth/account/adapter.py", line 140, in send_mail
    msg.send()
  File "/usr/local/lib/python3.6/site-packages/django/core/mail/message.py", line 348, in send
    return self.get_connection(fail_silently).send_messages([self])
  File "/usr/local/lib/python3.6/site-packages/django/core/mail/backends/smtp.py", line 104, in send_messages
    new_conn_created = self.open()
  File "/usr/local/lib/python3.6/site-packages/django/core/mail/backends/smtp.py", line 64, in open
    self.connection = self.connection_class(self.host, self.port, **connection_params)
  File "/usr/local/lib/python3.6/smtplib.py", line 251, in __init__
    (code, msg) = self.connect(host, port)
  File "/usr/local/lib/python3.6/smtplib.py", line 336, in connect
    self.sock = self._get_socket(host, port, self.timeout)
  File "/usr/local/lib/python3.6/smtplib.py", line 307, in _get_socket
    self.source_address)
  File "/usr/local/lib/python3.6/socket.py", line 724, in create_connection
    raise err
  File "/usr/local/lib/python3.6/socket.py", line 713, in create_connection
    sock.connect(sa)
ConnectionRefusedError: [Errno 111] Connection refused
2018-02-17 17:57:48,952 ERROR exception 10 Internal Server Error: /config/email/
Traceback (most recent call last):
  File "/usr/local/lib/python3.6/site-packages/django/core/handlers/exception.py", line 41, in inner
    response = get_response(request)
  File "/usr/local/lib/python3.6/site-packages/django/core/handlers/base.py", line 249, in _legacy_get_response
    response = self._get_response(request)
  File "/usr/local/lib/python3.6/site-packages/django/core/handlers/base.py", line 187, in _get_response
    response = self.process_exception_by_middleware(e, request)
  File "/usr/local/lib/python3.6/site-packages/channels/handler.py", line 243, in process_exception_by_middleware
    return super(AsgiHandler, self).process_exception_by_middleware(exception, request)
  File "/usr/local/lib/python3.6/site-packages/django/core/handlers/base.py", line 185, in _get_response
    response = wrapped_callback(request, *callback_args, **callback_kwargs)
  File "/usr/local/lib/python3.6/site-packages/django/contrib/auth/decorators.py", line 23, in _wrapped_view
    return view_func(request, *args, **kwargs)
  File "/usr/local/lib/python3.6/site-packages/django/views/generic/base.py", line 68, in view
    return self.dispatch(request, *args, **kwargs)
  File "/usr/local/lib/python3.6/site-packages/allauth/account/views.py", line 378, in dispatch
    return super(EmailView, self).dispatch(request, *args, **kwargs)
  File "/usr/local/lib/python3.6/site-packages/django/views/generic/base.py", line 88, in dispatch
    return handler(request, *args, **kwargs)
  File "/usr/local/lib/python3.6/site-packages/allauth/account/views.py", line 405, in post
    res = self._action_send(request)
  File "/usr/local/lib/python3.6/site-packages/allauth/account/views.py", line 433, in _action_send
    email_address.send_confirmation(request)
  File "/usr/local/lib/python3.6/site-packages/allauth/account/models.py", line 60, in send_confirmation
    confirmation.send(request, signup=signup)
  File "/usr/local/lib/python3.6/site-packages/allauth/account/models.py", line 166, in send
    get_adapter(request).send_confirmation_mail(request, self, signup)
  File "/usr/local/lib/python3.6/site-packages/allauth/account/adapter.py", line 447, in send_confirmation_mail
    ctx)
  File "/usr/local/lib/python3.6/site-packages/allauth/account/adapter.py", line 140, in send_mail
    msg.send()
  File "/usr/local/lib/python3.6/site-packages/django/core/mail/message.py", line 348, in send
    return self.get_connection(fail_silently).send_messages([self])
  File "/usr/local/lib/python3.6/site-packages/django/core/mail/backends/smtp.py", line 104, in send_messages
    new_conn_created = self.open()
  File "/usr/local/lib/python3.6/site-packages/django/core/mail/backends/smtp.py", line 64, in open
    self.connection = self.connection_class(self.host, self.port, **connection_params)
  File "/usr/local/lib/python3.6/smtplib.py", line 251, in __init__
    (code, msg) = self.connect(host, port)
  File "/usr/local/lib/python3.6/smtplib.py", line 336, in connect
    self.sock = self._get_socket(host, port, self.timeout)
  File "/usr/local/lib/python3.6/smtplib.py", line 307, in _get_socket
    self.source_address)
  File "/usr/local/lib/python3.6/socket.py", line 724, in create_connection
    raise err
  File "/usr/local/lib/python3.6/socket.py", line 713, in create_connection
    sock.connect(sa)
ConnectionRefusedError: [Errno 111] Connection refused
2018-02-17 18:01:03,843 ERROR exception 10 Internal Server Error: /config/email/
Traceback (most recent call last):
  File "/usr/local/lib/python3.6/site-packages/django/core/handlers/exception.py", line 41, in inner
    response = get_response(request)
  File "/usr/local/lib/python3.6/site-packages/django/core/handlers/base.py", line 249, in _legacy_get_response
    response = self._get_response(request)
  File "/usr/local/lib/python3.6/site-packages/django/core/handlers/base.py", line 187, in _get_response
    response = self.process_exception_by_middleware(e, request)
  File "/usr/local/lib/python3.6/site-packages/channels/handler.py", line 243, in process_exception_by_middleware
    return super(AsgiHandler, self).process_exception_by_middleware(exception, request)
  File "/usr/local/lib/python3.6/site-packages/django/core/handlers/base.py", line 185, in _get_response
    response = wrapped_callback(request, *callback_args, **callback_kwargs)
  File "/usr/local/lib/python3.6/site-packages/django/contrib/auth/decorators.py", line 23, in _wrapped_view
    return view_func(request, *args, **kwargs)
  File "/usr/local/lib/python3.6/site-packages/django/views/generic/base.py", line 68, in view
    return self.dispatch(request, *args, **kwargs)
  File "/usr/local/lib/python3.6/site-packages/allauth/account/views.py", line 378, in dispatch
    return super(EmailView, self).dispatch(request, *args, **kwargs)
  File "/usr/local/lib/python3.6/site-packages/django/views/generic/base.py", line 88, in dispatch
    return handler(request, *args, **kwargs)
  File "/usr/local/lib/python3.6/site-packages/allauth/account/views.py", line 405, in post
    res = self._action_send(request)
  File "/usr/local/lib/python3.6/site-packages/allauth/account/views.py", line 433, in _action_send
    email_address.send_confirmation(request)
  File "/usr/local/lib/python3.6/site-packages/allauth/account/models.py", line 60, in send_confirmation
    confirmation.send(request, signup=signup)
  File "/usr/local/lib/python3.6/site-packages/allauth/account/models.py", line 166, in send
    get_adapter(request).send_confirmation_mail(request, self, signup)
  File "/usr/local/lib/python3.6/site-packages/allauth/account/adapter.py", line 447, in send_confirmation_mail
    ctx)
  File "/usr/local/lib/python3.6/site-packages/allauth/account/adapter.py", line 140, in send_mail
    msg.send()
  File "/usr/local/lib/python3.6/site-packages/django/core/mail/message.py", line 348, in send
    return self.get_connection(fail_silently).send_messages([self])
  File "/usr/local/lib/python3.6/site-packages/django/core/mail/backends/smtp.py", line 104, in send_messages
    new_conn_created = self.open()
  File "/usr/local/lib/python3.6/site-packages/django/core/mail/backends/smtp.py", line 64, in open
    self.connection = self.connection_class(self.host, self.port, **connection_params)
  File "/usr/local/lib/python3.6/smtplib.py", line 251, in __init__
    (code, msg) = self.connect(host, port)
  File "/usr/local/lib/python3.6/smtplib.py", line 336, in connect
    self.sock = self._get_socket(host, port, self.timeout)
  File "/usr/local/lib/python3.6/smtplib.py", line 307, in _get_socket
    self.source_address)
  File "/usr/local/lib/python3.6/socket.py", line 724, in create_connection
    raise err
  File "/usr/local/lib/python3.6/socket.py", line 713, in create_connection
    sock.connect(sa)
ConnectionRefusedError: [Errno 111] Connection refused
