2018-01-24 23:17:16,655 ERROR exception 30943 Internal Server Error: /publication/add_like/
Traceback (most recent call last):
  File "/home/adrian/skyfolk/venv/lib/python3.6/site-packages/django/db/backends/utils.py", line 65, in execute
    return self.cursor.execute(sql, params)
  File "/home/adrian/skyfolk/venv/lib/python3.6/site-packages/django/db/backends/sqlite3/base.py", line 328, in execute
    return Database.Cursor.execute(self, query, params)
sqlite3.OperationalError: database is locked

The above exception was the direct cause of the following exception:

Traceback (most recent call last):
  File "/home/adrian/skyfolk/venv/lib/python3.6/site-packages/django/core/handlers/exception.py", line 41, in inner
    response = get_response(request)
  File "/home/adrian/skyfolk/venv/lib/python3.6/site-packages/django/core/handlers/base.py", line 249, in _legacy_get_response
    response = self._get_response(request)
  File "/home/adrian/skyfolk/venv/lib/python3.6/site-packages/django/core/handlers/base.py", line 187, in _get_response
    response = self.process_exception_by_middleware(e, request)
  File "/home/adrian/skyfolk/venv/lib/python3.6/site-packages/channels/handler.py", line 243, in process_exception_by_middleware
    return super(AsgiHandler, self).process_exception_by_middleware(exception, request)
  File "/home/adrian/skyfolk/venv/lib/python3.6/site-packages/django/core/handlers/base.py", line 185, in _get_response
    response = wrapped_callback(request, *callback_args, **callback_kwargs)
  File "/home/adrian/skyfolk/venv/lib/python3.6/site-packages/django/contrib/auth/decorators.py", line 23, in _wrapped_view
    return view_func(request, *args, **kwargs)
  File "/usr/lib/python3.6/contextlib.py", line 52, in inner
    return func(*args, **kwds)
  File "/home/adrian/skyfolk/publications/views.py", line 419, in add_like
    publication.user_give_me_like.remove(request.user)
  File "/home/adrian/skyfolk/venv/lib/python3.6/site-packages/django/db/models/fields/related_descriptors.py", line 950, in remove
    self._remove_items(self.source_field_name, self.target_field_name, *objs)
  File "/home/adrian/skyfolk/venv/lib/python3.6/site-packages/django/db/models/fields/related_descriptors.py", line 1146, in _remove_items
    self.through._default_manager.using(db).filter(filters).delete()
  File "/home/adrian/skyfolk/venv/lib/python3.6/site-packages/django/db/models/query.py", line 617, in delete
    deleted, _rows_count = collector.delete()
  File "/home/adrian/skyfolk/venv/lib/python3.6/site-packages/django/db/models/deletion.py", line 302, in delete
    count = query.delete_batch(pk_list, self.using)
  File "/home/adrian/skyfolk/venv/lib/python3.6/site-packages/django/db/models/sql/subqueries.py", line 45, in delete_batch
    num_deleted += self.do_query(self.get_meta().db_table, self.where, using=using)
  File "/home/adrian/skyfolk/venv/lib/python3.6/site-packages/django/db/models/sql/subqueries.py", line 28, in do_query
    cursor = self.get_compiler(using).execute_sql(CURSOR)
  File "/home/adrian/skyfolk/venv/lib/python3.6/site-packages/django/db/models/sql/compiler.py", line 894, in execute_sql
    raise original_exception
  File "/home/adrian/skyfolk/venv/lib/python3.6/site-packages/django/db/models/sql/compiler.py", line 884, in execute_sql
    cursor.execute(sql, params)
  File "/home/adrian/skyfolk/venv/lib/python3.6/site-packages/django/db/backends/utils.py", line 80, in execute
    return super(CursorDebugWrapper, self).execute(sql, params)
  File "/home/adrian/skyfolk/venv/lib/python3.6/site-packages/django/db/backends/utils.py", line 65, in execute
    return self.cursor.execute(sql, params)
  File "/home/adrian/skyfolk/venv/lib/python3.6/site-packages/django/db/utils.py", line 94, in __exit__
    six.reraise(dj_exc_type, dj_exc_value, traceback)
  File "/home/adrian/skyfolk/venv/lib/python3.6/site-packages/django/utils/six.py", line 685, in reraise
    raise value.with_traceback(tb)
  File "/home/adrian/skyfolk/venv/lib/python3.6/site-packages/django/db/backends/utils.py", line 65, in execute
    return self.cursor.execute(sql, params)
  File "/home/adrian/skyfolk/venv/lib/python3.6/site-packages/django/db/backends/sqlite3/base.py", line 328, in execute
    return Database.Cursor.execute(self, query, params)
django.db.utils.OperationalError: database is locked
2018-01-24 23:17:16,828 ERROR exception 30943 Internal Server Error: /publication/add_like/
Traceback (most recent call last):
  File "/home/adrian/skyfolk/venv/lib/python3.6/site-packages/django/db/backends/utils.py", line 65, in execute
    return self.cursor.execute(sql, params)
  File "/home/adrian/skyfolk/venv/lib/python3.6/site-packages/django/db/backends/sqlite3/base.py", line 328, in execute
    return Database.Cursor.execute(self, query, params)
sqlite3.OperationalError: database is locked

The above exception was the direct cause of the following exception:

Traceback (most recent call last):
  File "/home/adrian/skyfolk/venv/lib/python3.6/site-packages/django/core/handlers/exception.py", line 41, in inner
    response = get_response(request)
  File "/home/adrian/skyfolk/venv/lib/python3.6/site-packages/django/core/handlers/base.py", line 249, in _legacy_get_response
    response = self._get_response(request)
  File "/home/adrian/skyfolk/venv/lib/python3.6/site-packages/django/core/handlers/base.py", line 187, in _get_response
    response = self.process_exception_by_middleware(e, request)
  File "/home/adrian/skyfolk/venv/lib/python3.6/site-packages/channels/handler.py", line 243, in process_exception_by_middleware
    return super(AsgiHandler, self).process_exception_by_middleware(exception, request)
  File "/home/adrian/skyfolk/venv/lib/python3.6/site-packages/django/core/handlers/base.py", line 185, in _get_response
    response = wrapped_callback(request, *callback_args, **callback_kwargs)
  File "/home/adrian/skyfolk/venv/lib/python3.6/site-packages/django/contrib/auth/decorators.py", line 23, in _wrapped_view
    return view_func(request, *args, **kwargs)
  File "/usr/lib/python3.6/contextlib.py", line 52, in inner
    return func(*args, **kwds)
  File "/home/adrian/skyfolk/publications/views.py", line 432, in add_like
    publication.user_give_me_like.add(user)
  File "/home/adrian/skyfolk/venv/lib/python3.6/site-packages/django/db/models/fields/related_descriptors.py", line 934, in add
    self._add_items(self.source_field_name, self.target_field_name, *objs)
  File "/home/adrian/skyfolk/venv/lib/python3.6/site-packages/django/db/models/fields/related_descriptors.py", line 1103, in _add_items
    for obj_id in new_ids
  File "/home/adrian/skyfolk/venv/lib/python3.6/site-packages/django/db/models/query.py", line 443, in bulk_create
    ids = self._batched_insert(objs_without_pk, fields, batch_size)
  File "/home/adrian/skyfolk/venv/lib/python3.6/site-packages/django/db/models/query.py", line 1099, in _batched_insert
    self._insert(item, fields=fields, using=self.db)
  File "/home/adrian/skyfolk/venv/lib/python3.6/site-packages/django/db/models/query.py", line 1076, in _insert
    return query.get_compiler(using=using).execute_sql(return_id)
  File "/home/adrian/skyfolk/venv/lib/python3.6/site-packages/django/db/models/sql/compiler.py", line 1107, in execute_sql
    cursor.execute(sql, params)
  File "/home/adrian/skyfolk/venv/lib/python3.6/site-packages/django/db/backends/utils.py", line 80, in execute
    return super(CursorDebugWrapper, self).execute(sql, params)
  File "/home/adrian/skyfolk/venv/lib/python3.6/site-packages/django/db/backends/utils.py", line 65, in execute
    return self.cursor.execute(sql, params)
  File "/home/adrian/skyfolk/venv/lib/python3.6/site-packages/django/db/utils.py", line 94, in __exit__
    six.reraise(dj_exc_type, dj_exc_value, traceback)
  File "/home/adrian/skyfolk/venv/lib/python3.6/site-packages/django/utils/six.py", line 685, in reraise
    raise value.with_traceback(tb)
  File "/home/adrian/skyfolk/venv/lib/python3.6/site-packages/django/db/backends/utils.py", line 65, in execute
    return self.cursor.execute(sql, params)
  File "/home/adrian/skyfolk/venv/lib/python3.6/site-packages/django/db/backends/sqlite3/base.py", line 328, in execute
    return Database.Cursor.execute(self, query, params)
django.db.utils.OperationalError: database is locked
2018-01-24 23:56:01,517 ERROR exception 8517 Internal Server Error: /submit_photo/
Traceback (most recent call last):
  File "/home/adrian/skyfolk/venv/lib/python3.6/site-packages/django/core/handlers/exception.py", line 41, in inner
    response = get_response(request)
  File "/home/adrian/skyfolk/venv/lib/python3.6/site-packages/django/core/handlers/base.py", line 249, in _legacy_get_response
    response = self._get_response(request)
  File "/home/adrian/skyfolk/venv/lib/python3.6/site-packages/django/core/handlers/base.py", line 187, in _get_response
    response = self.process_exception_by_middleware(e, request)
  File "/home/adrian/skyfolk/venv/lib/python3.6/site-packages/channels/handler.py", line 243, in process_exception_by_middleware
    return super(AsgiHandler, self).process_exception_by_middleware(exception, request)
  File "/home/adrian/skyfolk/venv/lib/python3.6/site-packages/django/core/handlers/base.py", line 185, in _get_response
    response = wrapped_callback(request, *callback_args, **callback_kwargs)
  File "/home/adrian/skyfolk/venv/lib/python3.6/site-packages/django/views/decorators/http.py", line 40, in inner
    return func(request, *args, **kwargs)
  File "/home/adrian/skyfolk/venv/lib/python3.6/site-packages/django/contrib/auth/decorators.py", line 23, in _wrapped_view
    return view_func(request, *args, **kwargs)
  File "/home/adrian/skyfolk/photologue/views.py", line 179, in upload_photo
    obj.save()
  File "/home/adrian/skyfolk/photologue/models.py", line 504, in save
    super(Photo, self).save(*args, **kwargs)
  File "/home/adrian/skyfolk/photologue/models.py", line 430, in save
    super(ImageModel, self).save(*args, **kwargs)
  File "/home/adrian/skyfolk/venv/lib/python3.6/site-packages/django/db/models/base.py", line 808, in save
    force_update=force_update, update_fields=update_fields)
  File "/home/adrian/skyfolk/venv/lib/python3.6/site-packages/django/db/models/base.py", line 848, in save_base
    update_fields=update_fields, raw=raw, using=using,
  File "/home/adrian/skyfolk/venv/lib/python3.6/site-packages/django/dispatch/dispatcher.py", line 193, in send
    for receiver in self._live_receivers(sender)
  File "/home/adrian/skyfolk/venv/lib/python3.6/site-packages/django/dispatch/dispatcher.py", line 193, in <listcomp>
    for receiver in self._live_receivers(sender)
  File "/home/adrian/skyfolk/photologue/models.py", line 1065, in generate_thumb
    generate_thumbnails.delay(instance=instance.pk)
  File "/home/adrian/skyfolk/venv/lib/python3.6/site-packages/celery/app/task.py", line 413, in delay
    return self.apply_async(args, kwargs)
  File "/home/adrian/skyfolk/venv/lib/python3.6/site-packages/celery/app/task.py", line 518, in apply_async
    check_arguments(*(args or ()), **(kwargs or {}))
TypeError: generate_thumbnails() missing 1 required positional argument: 'self'
2018-01-25 11:48:24,345 ERROR exception 30083 Internal Server Error: /profile/adrian/
Traceback (most recent call last):
  File "/home/adrian/skyfolk/venv/lib/python3.6/site-packages/django/core/handlers/exception.py", line 41, in inner
    response = get_response(request)
  File "/home/adrian/skyfolk/venv/lib/python3.6/site-packages/django/core/handlers/base.py", line 249, in _legacy_get_response
    response = self._get_response(request)
  File "/home/adrian/skyfolk/venv/lib/python3.6/site-packages/django/core/handlers/base.py", line 187, in _get_response
    response = self.process_exception_by_middleware(e, request)
  File "/home/adrian/skyfolk/venv/lib/python3.6/site-packages/channels/handler.py", line 243, in process_exception_by_middleware
    return super(AsgiHandler, self).process_exception_by_middleware(exception, request)
  File "/home/adrian/skyfolk/venv/lib/python3.6/site-packages/django/core/handlers/base.py", line 185, in _get_response
    response = wrapped_callback(request, *callback_args, **callback_kwargs)
  File "/home/adrian/skyfolk/venv/lib/python3.6/site-packages/django/contrib/auth/decorators.py", line 23, in _wrapped_view
    return view_func(request, *args, **kwargs)
  File "/home/adrian/skyfolk/user_profile/views.py", line 347, in profile_view
    fill_profile_dashboard(request, user, username, context)
  File "/home/adrian/skyfolk/user_profile/views.py", line 171, in fill_profile_dashboard
    as_instance=True)
  File "/home/adrian/skyfolk/dash/base.py", line 1734, in get_layout
    _("Layout `{0}` does not exist!").format(layout_uid)
dash.exceptions.LayoutDoesNotExist: Layout `android` does not exist!
2018-01-25 11:48:39,599 ERROR exception 30083 Internal Server Error: /profile/adrian/
Traceback (most recent call last):
  File "/home/adrian/skyfolk/venv/lib/python3.6/site-packages/django/core/handlers/exception.py", line 41, in inner
    response = get_response(request)
  File "/home/adrian/skyfolk/venv/lib/python3.6/site-packages/django/core/handlers/base.py", line 249, in _legacy_get_response
    response = self._get_response(request)
  File "/home/adrian/skyfolk/venv/lib/python3.6/site-packages/django/core/handlers/base.py", line 187, in _get_response
    response = self.process_exception_by_middleware(e, request)
  File "/home/adrian/skyfolk/venv/lib/python3.6/site-packages/channels/handler.py", line 243, in process_exception_by_middleware
    return super(AsgiHandler, self).process_exception_by_middleware(exception, request)
  File "/home/adrian/skyfolk/venv/lib/python3.6/site-packages/django/core/handlers/base.py", line 185, in _get_response
    response = wrapped_callback(request, *callback_args, **callback_kwargs)
  File "/home/adrian/skyfolk/venv/lib/python3.6/site-packages/django/contrib/auth/decorators.py", line 23, in _wrapped_view
    return view_func(request, *args, **kwargs)
  File "/home/adrian/skyfolk/user_profile/views.py", line 347, in profile_view
    fill_profile_dashboard(request, user, username, context)
  File "/home/adrian/skyfolk/user_profile/views.py", line 171, in fill_profile_dashboard
    as_instance=True)
  File "/home/adrian/skyfolk/dash/base.py", line 1734, in get_layout
    _("Layout `{0}` does not exist!").format(layout_uid)
dash.exceptions.LayoutDoesNotExist: Layout `android` does not exist!
2018-01-25 12:37:54,187 ERROR exception 20518 Internal Server Error: /dashboard/entry/add/main/video_5x5/ws/132/pos/1/
Traceback (most recent call last):
  File "/home/adrian/skyfolk/venv/lib/python3.6/site-packages/django/core/handlers/exception.py", line 41, in inner
    response = get_response(request)
  File "/home/adrian/skyfolk/venv/lib/python3.6/site-packages/django/core/handlers/base.py", line 249, in _legacy_get_response
    response = self._get_response(request)
  File "/home/adrian/skyfolk/venv/lib/python3.6/site-packages/django/core/handlers/base.py", line 187, in _get_response
    response = self.process_exception_by_middleware(e, request)
  File "/home/adrian/skyfolk/venv/lib/python3.6/site-packages/channels/handler.py", line 243, in process_exception_by_middleware
    return super(AsgiHandler, self).process_exception_by_middleware(exception, request)
  File "/home/adrian/skyfolk/venv/lib/python3.6/site-packages/django/core/handlers/base.py", line 185, in _get_response
    response = wrapped_callback(request, *callback_args, **callback_kwargs)
  File "/home/adrian/skyfolk/venv/lib/python3.6/site-packages/django/views/generic/base.py", line 68, in view
    return self.dispatch(request, *args, **kwargs)
  File "/home/adrian/skyfolk/venv/lib/python3.6/site-packages/django/utils/decorators.py", line 67, in _wrapper
    return bound_func(*args, **kwargs)
  File "/home/adrian/skyfolk/venv/lib/python3.6/site-packages/django/contrib/auth/decorators.py", line 23, in _wrapped_view
    return view_func(request, *args, **kwargs)
  File "/home/adrian/skyfolk/venv/lib/python3.6/site-packages/django/utils/decorators.py", line 63, in bound_func
    return func.__get__(self, type(self))(*args2, **kwargs2)
  File "/home/adrian/skyfolk/dash/views.py", line 291, in dispatch
    position=None, )
  File "/home/adrian/skyfolk/venv/lib/python3.6/site-packages/django/contrib/auth/decorators.py", line 23, in _wrapped_view
    return view_func(request, *args, **kwargs)
  File "/home/adrian/skyfolk/venv/lib/python3.6/site-packages/django/contrib/auth/decorators.py", line 23, in _wrapped_view
    return view_func(request, *args, **kwargs)
  File "/home/adrian/skyfolk/dash/views.py", line 582, in add_dashboard_entry
    workspace_slug = slugify_workspace(workspace)
  File "/home/adrian/skyfolk/dash/helpers.py", line 25, in slugify_workspace
    return slugify(val.lower()).lower()
AttributeError: 'DashboardWorkspace' object has no attribute 'lower'
2018-01-25 12:38:07,411 ERROR exception 20518 Internal Server Error: /dashboard/entry/add/main/image_2x2/ws/132/pos/1/
Traceback (most recent call last):
  File "/home/adrian/skyfolk/venv/lib/python3.6/site-packages/django/core/handlers/exception.py", line 41, in inner
    response = get_response(request)
  File "/home/adrian/skyfolk/venv/lib/python3.6/site-packages/django/core/handlers/base.py", line 249, in _legacy_get_response
    response = self._get_response(request)
  File "/home/adrian/skyfolk/venv/lib/python3.6/site-packages/django/core/handlers/base.py", line 187, in _get_response
    response = self.process_exception_by_middleware(e, request)
  File "/home/adrian/skyfolk/venv/lib/python3.6/site-packages/channels/handler.py", line 243, in process_exception_by_middleware
    return super(AsgiHandler, self).process_exception_by_middleware(exception, request)
  File "/home/adrian/skyfolk/venv/lib/python3.6/site-packages/django/core/handlers/base.py", line 185, in _get_response
    response = wrapped_callback(request, *callback_args, **callback_kwargs)
  File "/home/adrian/skyfolk/venv/lib/python3.6/site-packages/django/views/generic/base.py", line 68, in view
    return self.dispatch(request, *args, **kwargs)
  File "/home/adrian/skyfolk/venv/lib/python3.6/site-packages/django/utils/decorators.py", line 67, in _wrapper
    return bound_func(*args, **kwargs)
  File "/home/adrian/skyfolk/venv/lib/python3.6/site-packages/django/contrib/auth/decorators.py", line 23, in _wrapped_view
    return view_func(request, *args, **kwargs)
  File "/home/adrian/skyfolk/venv/lib/python3.6/site-packages/django/utils/decorators.py", line 63, in bound_func
    return func.__get__(self, type(self))(*args2, **kwargs2)
  File "/home/adrian/skyfolk/dash/views.py", line 291, in dispatch
    position=None, )
  File "/home/adrian/skyfolk/venv/lib/python3.6/site-packages/django/contrib/auth/decorators.py", line 23, in _wrapped_view
    return view_func(request, *args, **kwargs)
  File "/home/adrian/skyfolk/venv/lib/python3.6/site-packages/django/contrib/auth/decorators.py", line 23, in _wrapped_view
    return view_func(request, *args, **kwargs)
  File "/home/adrian/skyfolk/dash/views.py", line 582, in add_dashboard_entry
    workspace_slug = slugify_workspace(workspace)
  File "/home/adrian/skyfolk/dash/helpers.py", line 25, in slugify_workspace
    return slugify(val.lower()).lower()
AttributeError: 'DashboardWorkspace' object has no attribute 'lower'
2018-01-25 12:38:31,840 ERROR exception 20518 Internal Server Error: /dashboard/entry/add/main/image_1x1/ws/132/pos/1/
Traceback (most recent call last):
  File "/home/adrian/skyfolk/venv/lib/python3.6/site-packages/django/core/handlers/exception.py", line 41, in inner
    response = get_response(request)
  File "/home/adrian/skyfolk/venv/lib/python3.6/site-packages/django/core/handlers/base.py", line 249, in _legacy_get_response
    response = self._get_response(request)
  File "/home/adrian/skyfolk/venv/lib/python3.6/site-packages/django/core/handlers/base.py", line 187, in _get_response
    response = self.process_exception_by_middleware(e, request)
  File "/home/adrian/skyfolk/venv/lib/python3.6/site-packages/channels/handler.py", line 243, in process_exception_by_middleware
    return super(AsgiHandler, self).process_exception_by_middleware(exception, request)
  File "/home/adrian/skyfolk/venv/lib/python3.6/site-packages/django/core/handlers/base.py", line 185, in _get_response
    response = wrapped_callback(request, *callback_args, **callback_kwargs)
  File "/home/adrian/skyfolk/venv/lib/python3.6/site-packages/django/views/generic/base.py", line 68, in view
    return self.dispatch(request, *args, **kwargs)
  File "/home/adrian/skyfolk/venv/lib/python3.6/site-packages/django/utils/decorators.py", line 67, in _wrapper
    return bound_func(*args, **kwargs)
  File "/home/adrian/skyfolk/venv/lib/python3.6/site-packages/django/contrib/auth/decorators.py", line 23, in _wrapped_view
    return view_func(request, *args, **kwargs)
  File "/home/adrian/skyfolk/venv/lib/python3.6/site-packages/django/utils/decorators.py", line 63, in bound_func
    return func.__get__(self, type(self))(*args2, **kwargs2)
  File "/home/adrian/skyfolk/dash/views.py", line 291, in dispatch
    position=None, )
  File "/home/adrian/skyfolk/venv/lib/python3.6/site-packages/django/contrib/auth/decorators.py", line 23, in _wrapped_view
    return view_func(request, *args, **kwargs)
  File "/home/adrian/skyfolk/venv/lib/python3.6/site-packages/django/contrib/auth/decorators.py", line 23, in _wrapped_view
    return view_func(request, *args, **kwargs)
  File "/home/adrian/skyfolk/dash/views.py", line 582, in add_dashboard_entry
    workspace_slug = slugify_workspace(workspace)
  File "/home/adrian/skyfolk/dash/helpers.py", line 25, in slugify_workspace
    return slugify(val.lower()).lower()
AttributeError: 'DashboardWorkspace' object has no attribute 'lower'
2018-01-25 12:39:49,921 ERROR exception 21666 Internal Server Error: /dashboard/entry/add/main/image_1x1/ws/132/pos/1/
Traceback (most recent call last):
  File "/home/adrian/skyfolk/venv/lib/python3.6/site-packages/django/core/handlers/exception.py", line 41, in inner
    response = get_response(request)
  File "/home/adrian/skyfolk/venv/lib/python3.6/site-packages/django/core/handlers/base.py", line 249, in _legacy_get_response
    response = self._get_response(request)
  File "/home/adrian/skyfolk/venv/lib/python3.6/site-packages/django/core/handlers/base.py", line 187, in _get_response
    response = self.process_exception_by_middleware(e, request)
  File "/home/adrian/skyfolk/venv/lib/python3.6/site-packages/channels/handler.py", line 243, in process_exception_by_middleware
    return super(AsgiHandler, self).process_exception_by_middleware(exception, request)
  File "/home/adrian/skyfolk/venv/lib/python3.6/site-packages/django/core/handlers/base.py", line 185, in _get_response
    response = wrapped_callback(request, *callback_args, **callback_kwargs)
  File "/home/adrian/skyfolk/venv/lib/python3.6/site-packages/django/views/generic/base.py", line 68, in view
    return self.dispatch(request, *args, **kwargs)
  File "/home/adrian/skyfolk/venv/lib/python3.6/site-packages/django/utils/decorators.py", line 67, in _wrapper
    return bound_func(*args, **kwargs)
  File "/home/adrian/skyfolk/venv/lib/python3.6/site-packages/django/contrib/auth/decorators.py", line 23, in _wrapped_view
    return view_func(request, *args, **kwargs)
  File "/home/adrian/skyfolk/venv/lib/python3.6/site-packages/django/utils/decorators.py", line 63, in bound_func
    return func.__get__(self, type(self))(*args2, **kwargs2)
  File "/home/adrian/skyfolk/dash/views.py", line 291, in dispatch
    position=None)
  File "/home/adrian/skyfolk/venv/lib/python3.6/site-packages/django/contrib/auth/decorators.py", line 23, in _wrapped_view
    return view_func(request, *args, **kwargs)
  File "/home/adrian/skyfolk/venv/lib/python3.6/site-packages/django/contrib/auth/decorators.py", line 23, in _wrapped_view
    return view_func(request, *args, **kwargs)
  File "/home/adrian/skyfolk/dash/views.py", line 582, in add_dashboard_entry
    workspace_slug = slugify_workspace(workspace)
  File "/home/adrian/skyfolk/dash/helpers.py", line 25, in slugify_workspace
    return slugify(val.lower()).lower()
AttributeError: 'DashboardWorkspace' object has no attribute 'lower'
2018-01-25 12:40:30,821 ERROR exception 21888 Internal Server Error: /dashboard/entry/add/main/image_1x1/ws/132/pos/1/
Traceback (most recent call last):
  File "/home/adrian/skyfolk/venv/lib/python3.6/site-packages/django/core/handlers/exception.py", line 41, in inner
    response = get_response(request)
  File "/home/adrian/skyfolk/venv/lib/python3.6/site-packages/django/core/handlers/base.py", line 249, in _legacy_get_response
    response = self._get_response(request)
  File "/home/adrian/skyfolk/venv/lib/python3.6/site-packages/django/core/handlers/base.py", line 187, in _get_response
    response = self.process_exception_by_middleware(e, request)
  File "/home/adrian/skyfolk/venv/lib/python3.6/site-packages/channels/handler.py", line 243, in process_exception_by_middleware
    return super(AsgiHandler, self).process_exception_by_middleware(exception, request)
  File "/home/adrian/skyfolk/venv/lib/python3.6/site-packages/django/core/handlers/base.py", line 185, in _get_response
    response = wrapped_callback(request, *callback_args, **callback_kwargs)
  File "/home/adrian/skyfolk/venv/lib/python3.6/site-packages/django/views/generic/base.py", line 68, in view
    return self.dispatch(request, *args, **kwargs)
  File "/home/adrian/skyfolk/venv/lib/python3.6/site-packages/django/utils/decorators.py", line 67, in _wrapper
    return bound_func(*args, **kwargs)
  File "/home/adrian/skyfolk/venv/lib/python3.6/site-packages/django/contrib/auth/decorators.py", line 23, in _wrapped_view
    return view_func(request, *args, **kwargs)
  File "/home/adrian/skyfolk/venv/lib/python3.6/site-packages/django/utils/decorators.py", line 63, in bound_func
    return func.__get__(self, type(self))(*args2, **kwargs2)
  File "/home/adrian/skyfolk/dash/views.py", line 292, in dispatch
    position=position)
  File "/home/adrian/skyfolk/venv/lib/python3.6/site-packages/django/contrib/auth/decorators.py", line 23, in _wrapped_view
    return view_func(request, *args, **kwargs)
  File "/home/adrian/skyfolk/venv/lib/python3.6/site-packages/django/contrib/auth/decorators.py", line 23, in _wrapped_view
    return view_func(request, *args, **kwargs)
  File "/home/adrian/skyfolk/dash/views.py", line 583, in add_dashboard_entry
    workspace_slug = slugify_workspace(workspace)
  File "/home/adrian/skyfolk/dash/helpers.py", line 25, in slugify_workspace
    return slugify(val.lower()).lower()
AttributeError: 'DashboardWorkspace' object has no attribute 'lower'
2018-01-25 12:41:53,932 ERROR exception 22185 Internal Server Error: /dashboard/entry/add/main/image_1x1/ws/132/pos/1/
Traceback (most recent call last):
  File "/home/adrian/skyfolk/venv/lib/python3.6/site-packages/django/core/handlers/exception.py", line 41, in inner
    response = get_response(request)
  File "/home/adrian/skyfolk/venv/lib/python3.6/site-packages/django/core/handlers/base.py", line 249, in _legacy_get_response
    response = self._get_response(request)
  File "/home/adrian/skyfolk/venv/lib/python3.6/site-packages/django/core/handlers/base.py", line 187, in _get_response
    response = self.process_exception_by_middleware(e, request)
  File "/home/adrian/skyfolk/venv/lib/python3.6/site-packages/channels/handler.py", line 243, in process_exception_by_middleware
    return super(AsgiHandler, self).process_exception_by_middleware(exception, request)
  File "/home/adrian/skyfolk/venv/lib/python3.6/site-packages/django/core/handlers/base.py", line 185, in _get_response
    response = wrapped_callback(request, *callback_args, **callback_kwargs)
  File "/home/adrian/skyfolk/venv/lib/python3.6/site-packages/django/views/generic/base.py", line 68, in view
    return self.dispatch(request, *args, **kwargs)
  File "/home/adrian/skyfolk/venv/lib/python3.6/site-packages/django/utils/decorators.py", line 67, in _wrapper
    return bound_func(*args, **kwargs)
  File "/home/adrian/skyfolk/venv/lib/python3.6/site-packages/django/contrib/auth/decorators.py", line 23, in _wrapped_view
    return view_func(request, *args, **kwargs)
  File "/home/adrian/skyfolk/venv/lib/python3.6/site-packages/django/utils/decorators.py", line 63, in bound_func
    return func.__get__(self, type(self))(*args2, **kwargs2)
  File "/home/adrian/skyfolk/dash/views.py", line 293, in dispatch
    position=position)
  File "/home/adrian/skyfolk/venv/lib/python3.6/site-packages/django/contrib/auth/decorators.py", line 23, in _wrapped_view
    return view_func(request, *args, **kwargs)
  File "/home/adrian/skyfolk/venv/lib/python3.6/site-packages/django/contrib/auth/decorators.py", line 23, in _wrapped_view
    return view_func(request, *args, **kwargs)
  File "/home/adrian/skyfolk/dash/views.py", line 584, in add_dashboard_entry
    workspace_slug = slugify_workspace(workspace)
  File "/home/adrian/skyfolk/dash/helpers.py", line 25, in slugify_workspace
    return slugify(val.lower()).lower()
AttributeError: 'DashboardWorkspace' object has no attribute 'lower'
2018-01-25 12:42:37,640 ERROR exception 22349 Internal Server Error: /dashboard/entry/add/main/image_1x1/ws/132/pos/1/
Traceback (most recent call last):
  File "/home/adrian/skyfolk/venv/lib/python3.6/site-packages/django/core/handlers/exception.py", line 41, in inner
    response = get_response(request)
  File "/home/adrian/skyfolk/venv/lib/python3.6/site-packages/django/core/handlers/base.py", line 249, in _legacy_get_response
    response = self._get_response(request)
  File "/home/adrian/skyfolk/venv/lib/python3.6/site-packages/django/core/handlers/base.py", line 187, in _get_response
    response = self.process_exception_by_middleware(e, request)
  File "/home/adrian/skyfolk/venv/lib/python3.6/site-packages/channels/handler.py", line 243, in process_exception_by_middleware
    return super(AsgiHandler, self).process_exception_by_middleware(exception, request)
  File "/home/adrian/skyfolk/venv/lib/python3.6/site-packages/django/core/handlers/base.py", line 185, in _get_response
    response = wrapped_callback(request, *callback_args, **callback_kwargs)
  File "/home/adrian/skyfolk/venv/lib/python3.6/site-packages/django/views/generic/base.py", line 68, in view
    return self.dispatch(request, *args, **kwargs)
  File "/home/adrian/skyfolk/venv/lib/python3.6/site-packages/django/utils/decorators.py", line 67, in _wrapper
    return bound_func(*args, **kwargs)
  File "/home/adrian/skyfolk/venv/lib/python3.6/site-packages/django/contrib/auth/decorators.py", line 23, in _wrapped_view
    return view_func(request, *args, **kwargs)
  File "/home/adrian/skyfolk/venv/lib/python3.6/site-packages/django/utils/decorators.py", line 63, in bound_func
    return func.__get__(self, type(self))(*args2, **kwargs2)
  File "/home/adrian/skyfolk/dash/views.py", line 294, in dispatch
    position=position)
  File "/home/adrian/skyfolk/venv/lib/python3.6/site-packages/django/contrib/auth/decorators.py", line 23, in _wrapped_view
    return view_func(request, *args, **kwargs)
  File "/home/adrian/skyfolk/venv/lib/python3.6/site-packages/django/contrib/auth/decorators.py", line 23, in _wrapped_view
    return view_func(request, *args, **kwargs)
  File "/home/adrian/skyfolk/dash/views.py", line 585, in add_dashboard_entry
    workspace_slug = slugify_workspace(workspace)
  File "/home/adrian/skyfolk/dash/helpers.py", line 25, in slugify_workspace
    return slugify(val.lower()).lower()
AttributeError: 'DashboardWorkspace' object has no attribute 'lower'
2018-01-25 12:43:17,861 ERROR exception 22568 Internal Server Error: /dashboard/entry/add/main/image_1x1/ws/132/pos/1/
Traceback (most recent call last):
  File "/home/adrian/skyfolk/venv/lib/python3.6/site-packages/django/core/handlers/exception.py", line 41, in inner
    response = get_response(request)
  File "/home/adrian/skyfolk/venv/lib/python3.6/site-packages/django/core/handlers/base.py", line 249, in _legacy_get_response
    response = self._get_response(request)
  File "/home/adrian/skyfolk/venv/lib/python3.6/site-packages/django/core/handlers/base.py", line 187, in _get_response
    response = self.process_exception_by_middleware(e, request)
  File "/home/adrian/skyfolk/venv/lib/python3.6/site-packages/channels/handler.py", line 243, in process_exception_by_middleware
    return super(AsgiHandler, self).process_exception_by_middleware(exception, request)
  File "/home/adrian/skyfolk/venv/lib/python3.6/site-packages/django/core/handlers/base.py", line 185, in _get_response
    response = wrapped_callback(request, *callback_args, **callback_kwargs)
  File "/home/adrian/skyfolk/venv/lib/python3.6/site-packages/django/views/generic/base.py", line 68, in view
    return self.dispatch(request, *args, **kwargs)
  File "/home/adrian/skyfolk/venv/lib/python3.6/site-packages/django/utils/decorators.py", line 67, in _wrapper
    return bound_func(*args, **kwargs)
  File "/home/adrian/skyfolk/venv/lib/python3.6/site-packages/django/contrib/auth/decorators.py", line 23, in _wrapped_view
    return view_func(request, *args, **kwargs)
  File "/home/adrian/skyfolk/venv/lib/python3.6/site-packages/django/utils/decorators.py", line 63, in bound_func
    return func.__get__(self, type(self))(*args2, **kwargs2)
  File "/home/adrian/skyfolk/dash/views.py", line 294, in dispatch
    position=position)
  File "/home/adrian/skyfolk/venv/lib/python3.6/site-packages/django/contrib/auth/decorators.py", line 23, in _wrapped_view
    return view_func(request, *args, **kwargs)
  File "/home/adrian/skyfolk/venv/lib/python3.6/site-packages/django/contrib/auth/decorators.py", line 23, in _wrapped_view
    return view_func(request, *args, **kwargs)
  File "/home/adrian/skyfolk/dash/views.py", line 585, in add_dashboard_entry
    workspace_slug = slugify_workspace(workspace)
  File "/home/adrian/skyfolk/dash/helpers.py", line 25, in slugify_workspace
    return slugify(val).lower()
  File "/home/adrian/skyfolk/venv/lib/python3.6/site-packages/autoslug/utils.py", line 31, in slugify
    return django_slugify(unidecode(value))
  File "/home/adrian/skyfolk/venv/lib/python3.6/site-packages/unidecode/__init__.py", line 48, in unidecode_expect_ascii
    bytestring = string.encode('ASCII')
AttributeError: 'DashboardWorkspace' object has no attribute 'encode'
2018-01-25 12:43:27,092 ERROR exception 22682 Internal Server Error: /dashboard/entry/add/main/image_1x1/ws/132/pos/1/
Traceback (most recent call last):
  File "/home/adrian/skyfolk/venv/lib/python3.6/site-packages/django/core/handlers/exception.py", line 41, in inner
    response = get_response(request)
  File "/home/adrian/skyfolk/venv/lib/python3.6/site-packages/django/core/handlers/base.py", line 249, in _legacy_get_response
    response = self._get_response(request)
  File "/home/adrian/skyfolk/venv/lib/python3.6/site-packages/django/core/handlers/base.py", line 187, in _get_response
    response = self.process_exception_by_middleware(e, request)
  File "/home/adrian/skyfolk/venv/lib/python3.6/site-packages/channels/handler.py", line 243, in process_exception_by_middleware
    return super(AsgiHandler, self).process_exception_by_middleware(exception, request)
  File "/home/adrian/skyfolk/venv/lib/python3.6/site-packages/django/core/handlers/base.py", line 185, in _get_response
    response = wrapped_callback(request, *callback_args, **callback_kwargs)
  File "/home/adrian/skyfolk/venv/lib/python3.6/site-packages/django/views/generic/base.py", line 68, in view
    return self.dispatch(request, *args, **kwargs)
  File "/home/adrian/skyfolk/venv/lib/python3.6/site-packages/django/utils/decorators.py", line 67, in _wrapper
    return bound_func(*args, **kwargs)
  File "/home/adrian/skyfolk/venv/lib/python3.6/site-packages/django/contrib/auth/decorators.py", line 23, in _wrapped_view
    return view_func(request, *args, **kwargs)
  File "/home/adrian/skyfolk/venv/lib/python3.6/site-packages/django/utils/decorators.py", line 63, in bound_func
    return func.__get__(self, type(self))(*args2, **kwargs2)
  File "/home/adrian/skyfolk/dash/views.py", line 294, in dispatch
    position=position)
  File "/home/adrian/skyfolk/venv/lib/python3.6/site-packages/django/contrib/auth/decorators.py", line 23, in _wrapped_view
    return view_func(request, *args, **kwargs)
  File "/home/adrian/skyfolk/venv/lib/python3.6/site-packages/django/contrib/auth/decorators.py", line 23, in _wrapped_view
    return view_func(request, *args, **kwargs)
  File "/home/adrian/skyfolk/dash/views.py", line 585, in add_dashboard_entry
    workspace_slug = slugify_workspace(workspace)
  File "/home/adrian/skyfolk/dash/helpers.py", line 25, in slugify_workspace
    return slugify(val)
  File "/home/adrian/skyfolk/venv/lib/python3.6/site-packages/autoslug/utils.py", line 31, in slugify
    return django_slugify(unidecode(value))
  File "/home/adrian/skyfolk/venv/lib/python3.6/site-packages/unidecode/__init__.py", line 48, in unidecode_expect_ascii
    bytestring = string.encode('ASCII')
AttributeError: 'DashboardWorkspace' object has no attribute 'encode'
2018-01-25 12:44:22,639 ERROR exception 23250 Internal Server Error: /dashboard/entry/add/main/image_1x1/ws/132/pos/1/
Traceback (most recent call last):
  File "/home/adrian/skyfolk/venv/lib/python3.6/site-packages/django/core/handlers/exception.py", line 41, in inner
    response = get_response(request)
  File "/home/adrian/skyfolk/venv/lib/python3.6/site-packages/django/core/handlers/base.py", line 249, in _legacy_get_response
    response = self._get_response(request)
  File "/home/adrian/skyfolk/venv/lib/python3.6/site-packages/django/core/handlers/base.py", line 187, in _get_response
    response = self.process_exception_by_middleware(e, request)
  File "/home/adrian/skyfolk/venv/lib/python3.6/site-packages/channels/handler.py", line 243, in process_exception_by_middleware
    return super(AsgiHandler, self).process_exception_by_middleware(exception, request)
  File "/home/adrian/skyfolk/venv/lib/python3.6/site-packages/django/core/handlers/base.py", line 185, in _get_response
    response = wrapped_callback(request, *callback_args, **callback_kwargs)
  File "/home/adrian/skyfolk/venv/lib/python3.6/site-packages/django/views/generic/base.py", line 68, in view
    return self.dispatch(request, *args, **kwargs)
  File "/home/adrian/skyfolk/venv/lib/python3.6/site-packages/django/utils/decorators.py", line 67, in _wrapper
    return bound_func(*args, **kwargs)
  File "/home/adrian/skyfolk/venv/lib/python3.6/site-packages/django/contrib/auth/decorators.py", line 23, in _wrapped_view
    return view_func(request, *args, **kwargs)
  File "/home/adrian/skyfolk/venv/lib/python3.6/site-packages/django/utils/decorators.py", line 63, in bound_func
    return func.__get__(self, type(self))(*args2, **kwargs2)
  File "/home/adrian/skyfolk/dash/views.py", line 294, in dispatch
    position=position)
  File "/home/adrian/skyfolk/venv/lib/python3.6/site-packages/django/contrib/auth/decorators.py", line 23, in _wrapped_view
    return view_func(request, *args, **kwargs)
  File "/home/adrian/skyfolk/venv/lib/python3.6/site-packages/django/contrib/auth/decorators.py", line 23, in _wrapped_view
    return view_func(request, *args, **kwargs)
  File "/home/adrian/skyfolk/dash/views.py", line 585, in add_dashboard_entry
    workspace_slug = slugify_workspace(workspace)
  File "/home/adrian/skyfolk/dash/helpers.py", line 25, in slugify_workspace
    return slugify(val.lower()).lower()
AttributeError: 'DashboardWorkspace' object has no attribute 'lower'
2018-01-25 12:45:02,716 ERROR exception 23681 Internal Server Error: /dashboard/entry/add/main/image_1x1/ws/132/pos/1/
Traceback (most recent call last):
  File "/home/adrian/skyfolk/venv/lib/python3.6/site-packages/django/core/handlers/exception.py", line 41, in inner
    response = get_response(request)
  File "/home/adrian/skyfolk/venv/lib/python3.6/site-packages/django/core/handlers/base.py", line 249, in _legacy_get_response
    response = self._get_response(request)
  File "/home/adrian/skyfolk/venv/lib/python3.6/site-packages/django/core/handlers/base.py", line 187, in _get_response
    response = self.process_exception_by_middleware(e, request)
  File "/home/adrian/skyfolk/venv/lib/python3.6/site-packages/channels/handler.py", line 243, in process_exception_by_middleware
    return super(AsgiHandler, self).process_exception_by_middleware(exception, request)
  File "/home/adrian/skyfolk/venv/lib/python3.6/site-packages/django/core/handlers/base.py", line 185, in _get_response
    response = wrapped_callback(request, *callback_args, **callback_kwargs)
  File "/home/adrian/skyfolk/venv/lib/python3.6/site-packages/django/views/generic/base.py", line 68, in view
    return self.dispatch(request, *args, **kwargs)
  File "/home/adrian/skyfolk/venv/lib/python3.6/site-packages/django/utils/decorators.py", line 67, in _wrapper
    return bound_func(*args, **kwargs)
  File "/home/adrian/skyfolk/venv/lib/python3.6/site-packages/django/contrib/auth/decorators.py", line 23, in _wrapped_view
    return view_func(request, *args, **kwargs)
  File "/home/adrian/skyfolk/venv/lib/python3.6/site-packages/django/utils/decorators.py", line 63, in bound_func
    return func.__get__(self, type(self))(*args2, **kwargs2)
  File "/home/adrian/skyfolk/dash/views.py", line 294, in dispatch
    position=position)
  File "/home/adrian/skyfolk/venv/lib/python3.6/site-packages/django/contrib/auth/decorators.py", line 23, in _wrapped_view
    return view_func(request, *args, **kwargs)
  File "/home/adrian/skyfolk/venv/lib/python3.6/site-packages/django/contrib/auth/decorators.py", line 23, in _wrapped_view
    return view_func(request, *args, **kwargs)
  File "/home/adrian/skyfolk/dash/views.py", line 585, in add_dashboard_entry
    workspace_slug = slugify_workspace(workspace)
  File "/home/adrian/skyfolk/dash/helpers.py", line 26, in slugify_workspace
    return slugify(val.lower()).lower()
AttributeError: 'DashboardWorkspace' object has no attribute 'lower'
2018-01-25 12:47:00,168 ERROR exception 24013 Internal Server Error: /dashboard/workspace/delete/1/
Traceback (most recent call last):
  File "/home/adrian/skyfolk/venv/lib/python3.6/site-packages/django/core/handlers/exception.py", line 41, in inner
    response = get_response(request)
  File "/home/adrian/skyfolk/venv/lib/python3.6/site-packages/django/core/handlers/base.py", line 249, in _legacy_get_response
    response = self._get_response(request)
  File "/home/adrian/skyfolk/venv/lib/python3.6/site-packages/django/core/handlers/base.py", line 187, in _get_response
    response = self.process_exception_by_middleware(e, request)
  File "/home/adrian/skyfolk/venv/lib/python3.6/site-packages/channels/handler.py", line 243, in process_exception_by_middleware
    return super(AsgiHandler, self).process_exception_by_middleware(exception, request)
  File "/home/adrian/skyfolk/venv/lib/python3.6/site-packages/django/core/handlers/base.py", line 185, in _get_response
    response = wrapped_callback(request, *callback_args, **callback_kwargs)
  File "/home/adrian/skyfolk/venv/lib/python3.6/site-packages/django/contrib/auth/decorators.py", line 23, in _wrapped_view
    return view_func(request, *args, **kwargs)
  File "/home/adrian/skyfolk/venv/lib/python3.6/site-packages/django/contrib/auth/decorators.py", line 23, in _wrapped_view
    return view_func(request, *args, **kwargs)
  File "/home/adrian/skyfolk/dash/views.py", line 1174, in delete_dashboard_workspace
    layout_uid=workspace.layout_uid, as_instance=True
NameError: name 'workspace' is not defined
2018-01-25 12:59:44,701 INFO publish 28724 adrian - ServiceTwitter - ServiceRss - lol - 0 new data
