2018-02-05 14:12:02,381 ERROR exception 1412 Internal Server Error: /dashboard/adrian/androids/
Traceback (most recent call last):
  File "/home/adrian/skyfolk/venv/lib/python3.6/site-packages/django/core/handlers/exception.py", line 41, in inner
    response = get_response(request)
  File "/home/adrian/skyfolk/venv/lib/python3.6/site-packages/django/core/handlers/base.py", line 249, in _legacy_get_response
    response = self._get_response(request)
  File "/home/adrian/skyfolk/venv/lib/python3.6/site-packages/django/core/handlers/base.py", line 187, in _get_response
    response = self.process_exception_by_middleware(e, request)
  File "/home/adrian/skyfolk/venv/lib/python3.6/site-packages/channels/handler.py", line 243, in process_exception_by_middleware
    return super(AsgiHandler, self).process_exception_by_middleware(exception, request)
  File "/home/adrian/skyfolk/venv/lib/python3.6/site-packages/django/core/handlers/base.py", line 185, in _get_response
    response = wrapped_callback(request, *callback_args, **callback_kwargs)
  File "/home/adrian/skyfolk/dash/views.py", line 1842, in public_dashboard
    return render(request, template_name, context)
  File "/home/adrian/skyfolk/venv/lib/python3.6/site-packages/django/shortcuts.py", line 30, in render
    content = loader.render_to_string(template_name, context, request, using=using)
  File "/home/adrian/skyfolk/venv/lib/python3.6/site-packages/django/template/loader.py", line 68, in render_to_string
    return template.render(context, request)
  File "/home/adrian/skyfolk/venv/lib/python3.6/site-packages/django/template/backends/django.py", line 66, in render
    return self.template.render(context)
  File "/home/adrian/skyfolk/venv/lib/python3.6/site-packages/django/template/base.py", line 207, in render
    return self._render(context)
  File "/home/adrian/skyfolk/venv/lib/python3.6/site-packages/django/test/utils.py", line 107, in instrumented_test_render
    return self.nodelist.render(context)
  File "/home/adrian/skyfolk/venv/lib/python3.6/site-packages/django/template/base.py", line 990, in render
    bit = node.render_annotated(context)
  File "/home/adrian/skyfolk/venv/lib/python3.6/site-packages/django/template/base.py", line 957, in render_annotated
    return self.render(context)
  File "/home/adrian/skyfolk/venv/lib/python3.6/site-packages/django/template/loader_tags.py", line 177, in render
    return compiled_parent._render(context)
  File "/home/adrian/skyfolk/venv/lib/python3.6/site-packages/django/test/utils.py", line 107, in instrumented_test_render
    return self.nodelist.render(context)
  File "/home/adrian/skyfolk/venv/lib/python3.6/site-packages/django/template/base.py", line 990, in render
    bit = node.render_annotated(context)
  File "/home/adrian/skyfolk/venv/lib/python3.6/site-packages/django/template/base.py", line 957, in render_annotated
    return self.render(context)
  File "/home/adrian/skyfolk/venv/lib/python3.6/site-packages/django/template/loader_tags.py", line 177, in render
    return compiled_parent._render(context)
  File "/home/adrian/skyfolk/venv/lib/python3.6/site-packages/django/test/utils.py", line 107, in instrumented_test_render
    return self.nodelist.render(context)
  File "/home/adrian/skyfolk/venv/lib/python3.6/site-packages/django/template/base.py", line 990, in render
    bit = node.render_annotated(context)
  File "/home/adrian/skyfolk/venv/lib/python3.6/site-packages/django/template/base.py", line 957, in render_annotated
    return self.render(context)
  File "/home/adrian/skyfolk/venv/lib/python3.6/site-packages/django/template/loader_tags.py", line 72, in render
    result = block.nodelist.render(context)
  File "/home/adrian/skyfolk/venv/lib/python3.6/site-packages/django/template/base.py", line 990, in render
    bit = node.render_annotated(context)
  File "/home/adrian/skyfolk/venv/lib/python3.6/site-packages/django/template/base.py", line 957, in render_annotated
    return self.render(context)
  File "/home/adrian/skyfolk/venv/lib/python3.6/site-packages/django/template/loader_tags.py", line 72, in render
    result = block.nodelist.render(context)
  File "/home/adrian/skyfolk/venv/lib/python3.6/site-packages/django/template/base.py", line 990, in render
    bit = node.render_annotated(context)
  File "/home/adrian/skyfolk/venv/lib/python3.6/site-packages/django/template/base.py", line 957, in render_annotated
    return self.render(context)
  File "/home/adrian/skyfolk/venv/lib/python3.6/site-packages/django/template/loader_tags.py", line 72, in render
    result = block.nodelist.render(context)
  File "/home/adrian/skyfolk/venv/lib/python3.6/site-packages/django/template/base.py", line 990, in render
    bit = node.render_annotated(context)
  File "/home/adrian/skyfolk/venv/lib/python3.6/site-packages/django/template/base.py", line 957, in render_annotated
    return self.render(context)
  File "/home/adrian/skyfolk/venv/lib/python3.6/site-packages/django/template/defaulttags.py", line 322, in render
    return nodelist.render(context)
  File "/home/adrian/skyfolk/venv/lib/python3.6/site-packages/django/template/base.py", line 990, in render
    bit = node.render_annotated(context)
  File "/home/adrian/skyfolk/venv/lib/python3.6/site-packages/django/template/base.py", line 957, in render_annotated
    return self.render(context)
  File "/home/adrian/skyfolk/venv/lib/python3.6/site-packages/django/template/defaulttags.py", line 458, in render
    url = reverse(view_name, args=args, kwargs=kwargs, current_app=current_app)
  File "/home/adrian/skyfolk/venv/lib/python3.6/site-packages/django/urls/base.py", line 91, in reverse
    return force_text(iri_to_uri(resolver._reverse_with_prefix(view, prefix, *args, **kwargs)))
  File "/home/adrian/skyfolk/venv/lib/python3.6/site-packages/django/urls/resolvers.py", line 497, in _reverse_with_prefix
    raise NoReverseMatch(msg)
django.urls.exceptions.NoReverseMatch: Reverse for 'dash.public_dashboard' with arguments '('adrian',)' not found. 1 pattern(s) tried: ['dashboard/(?P<username>[\\w-]+)/(?P<workspace>[\\w_\\-]+)/$']
2018-02-05 14:12:04,005 ERROR exception 1412 Internal Server Error: /dashboard/adrian/androids/
Traceback (most recent call last):
  File "/home/adrian/skyfolk/venv/lib/python3.6/site-packages/django/core/handlers/exception.py", line 41, in inner
    response = get_response(request)
  File "/home/adrian/skyfolk/venv/lib/python3.6/site-packages/django/core/handlers/base.py", line 249, in _legacy_get_response
    response = self._get_response(request)
  File "/home/adrian/skyfolk/venv/lib/python3.6/site-packages/django/core/handlers/base.py", line 187, in _get_response
    response = self.process_exception_by_middleware(e, request)
  File "/home/adrian/skyfolk/venv/lib/python3.6/site-packages/channels/handler.py", line 243, in process_exception_by_middleware
    return super(AsgiHandler, self).process_exception_by_middleware(exception, request)
  File "/home/adrian/skyfolk/venv/lib/python3.6/site-packages/django/core/handlers/base.py", line 185, in _get_response
    response = wrapped_callback(request, *callback_args, **callback_kwargs)
  File "/home/adrian/skyfolk/dash/views.py", line 1842, in public_dashboard
    return render(request, template_name, context)
  File "/home/adrian/skyfolk/venv/lib/python3.6/site-packages/django/shortcuts.py", line 30, in render
    content = loader.render_to_string(template_name, context, request, using=using)
  File "/home/adrian/skyfolk/venv/lib/python3.6/site-packages/django/template/loader.py", line 68, in render_to_string
    return template.render(context, request)
  File "/home/adrian/skyfolk/venv/lib/python3.6/site-packages/django/template/backends/django.py", line 66, in render
    return self.template.render(context)
  File "/home/adrian/skyfolk/venv/lib/python3.6/site-packages/django/template/base.py", line 207, in render
    return self._render(context)
  File "/home/adrian/skyfolk/venv/lib/python3.6/site-packages/django/test/utils.py", line 107, in instrumented_test_render
    return self.nodelist.render(context)
  File "/home/adrian/skyfolk/venv/lib/python3.6/site-packages/django/template/base.py", line 990, in render
    bit = node.render_annotated(context)
  File "/home/adrian/skyfolk/venv/lib/python3.6/site-packages/django/template/base.py", line 957, in render_annotated
    return self.render(context)
  File "/home/adrian/skyfolk/venv/lib/python3.6/site-packages/django/template/loader_tags.py", line 177, in render
    return compiled_parent._render(context)
  File "/home/adrian/skyfolk/venv/lib/python3.6/site-packages/django/test/utils.py", line 107, in instrumented_test_render
    return self.nodelist.render(context)
  File "/home/adrian/skyfolk/venv/lib/python3.6/site-packages/django/template/base.py", line 990, in render
    bit = node.render_annotated(context)
  File "/home/adrian/skyfolk/venv/lib/python3.6/site-packages/django/template/base.py", line 957, in render_annotated
    return self.render(context)
  File "/home/adrian/skyfolk/venv/lib/python3.6/site-packages/django/template/loader_tags.py", line 177, in render
    return compiled_parent._render(context)
  File "/home/adrian/skyfolk/venv/lib/python3.6/site-packages/django/test/utils.py", line 107, in instrumented_test_render
    return self.nodelist.render(context)
  File "/home/adrian/skyfolk/venv/lib/python3.6/site-packages/django/template/base.py", line 990, in render
    bit = node.render_annotated(context)
  File "/home/adrian/skyfolk/venv/lib/python3.6/site-packages/django/template/base.py", line 957, in render_annotated
    return self.render(context)
  File "/home/adrian/skyfolk/venv/lib/python3.6/site-packages/django/template/loader_tags.py", line 72, in render
    result = block.nodelist.render(context)
  File "/home/adrian/skyfolk/venv/lib/python3.6/site-packages/django/template/base.py", line 990, in render
    bit = node.render_annotated(context)
  File "/home/adrian/skyfolk/venv/lib/python3.6/site-packages/django/template/base.py", line 957, in render_annotated
    return self.render(context)
  File "/home/adrian/skyfolk/venv/lib/python3.6/site-packages/django/template/loader_tags.py", line 72, in render
    result = block.nodelist.render(context)
  File "/home/adrian/skyfolk/venv/lib/python3.6/site-packages/django/template/base.py", line 990, in render
    bit = node.render_annotated(context)
  File "/home/adrian/skyfolk/venv/lib/python3.6/site-packages/django/template/base.py", line 957, in render_annotated
    return self.render(context)
  File "/home/adrian/skyfolk/venv/lib/python3.6/site-packages/django/template/loader_tags.py", line 72, in render
    result = block.nodelist.render(context)
  File "/home/adrian/skyfolk/venv/lib/python3.6/site-packages/django/template/base.py", line 990, in render
    bit = node.render_annotated(context)
  File "/home/adrian/skyfolk/venv/lib/python3.6/site-packages/django/template/base.py", line 957, in render_annotated
    return self.render(context)
  File "/home/adrian/skyfolk/venv/lib/python3.6/site-packages/django/template/defaulttags.py", line 322, in render
    return nodelist.render(context)
  File "/home/adrian/skyfolk/venv/lib/python3.6/site-packages/django/template/base.py", line 990, in render
    bit = node.render_annotated(context)
  File "/home/adrian/skyfolk/venv/lib/python3.6/site-packages/django/template/base.py", line 957, in render_annotated
    return self.render(context)
  File "/home/adrian/skyfolk/venv/lib/python3.6/site-packages/django/template/defaulttags.py", line 458, in render
    url = reverse(view_name, args=args, kwargs=kwargs, current_app=current_app)
  File "/home/adrian/skyfolk/venv/lib/python3.6/site-packages/django/urls/base.py", line 91, in reverse
    return force_text(iri_to_uri(resolver._reverse_with_prefix(view, prefix, *args, **kwargs)))
  File "/home/adrian/skyfolk/venv/lib/python3.6/site-packages/django/urls/resolvers.py", line 497, in _reverse_with_prefix
    raise NoReverseMatch(msg)
django.urls.exceptions.NoReverseMatch: Reverse for 'dash.public_dashboard' with arguments '('adrian',)' not found. 1 pattern(s) tried: ['dashboard/(?P<username>[\\w-]+)/(?P<workspace>[\\w_\\-]+)/$']
2018-02-05 14:12:25,851 ERROR exception 1412 Internal Server Error: /dashboard/adrian/androids/
Traceback (most recent call last):
  File "/home/adrian/skyfolk/venv/lib/python3.6/site-packages/django/core/handlers/exception.py", line 41, in inner
    response = get_response(request)
  File "/home/adrian/skyfolk/venv/lib/python3.6/site-packages/django/core/handlers/base.py", line 249, in _legacy_get_response
    response = self._get_response(request)
  File "/home/adrian/skyfolk/venv/lib/python3.6/site-packages/django/core/handlers/base.py", line 187, in _get_response
    response = self.process_exception_by_middleware(e, request)
  File "/home/adrian/skyfolk/venv/lib/python3.6/site-packages/channels/handler.py", line 243, in process_exception_by_middleware
    return super(AsgiHandler, self).process_exception_by_middleware(exception, request)
  File "/home/adrian/skyfolk/venv/lib/python3.6/site-packages/django/core/handlers/base.py", line 185, in _get_response
    response = wrapped_callback(request, *callback_args, **callback_kwargs)
  File "/home/adrian/skyfolk/dash/views.py", line 1842, in public_dashboard
    return render(request, template_name, context)
  File "/home/adrian/skyfolk/venv/lib/python3.6/site-packages/django/shortcuts.py", line 30, in render
    content = loader.render_to_string(template_name, context, request, using=using)
  File "/home/adrian/skyfolk/venv/lib/python3.6/site-packages/django/template/loader.py", line 68, in render_to_string
    return template.render(context, request)
  File "/home/adrian/skyfolk/venv/lib/python3.6/site-packages/django/template/backends/django.py", line 66, in render
    return self.template.render(context)
  File "/home/adrian/skyfolk/venv/lib/python3.6/site-packages/django/template/base.py", line 207, in render
    return self._render(context)
  File "/home/adrian/skyfolk/venv/lib/python3.6/site-packages/django/test/utils.py", line 107, in instrumented_test_render
    return self.nodelist.render(context)
  File "/home/adrian/skyfolk/venv/lib/python3.6/site-packages/django/template/base.py", line 990, in render
    bit = node.render_annotated(context)
  File "/home/adrian/skyfolk/venv/lib/python3.6/site-packages/django/template/base.py", line 957, in render_annotated
    return self.render(context)
  File "/home/adrian/skyfolk/venv/lib/python3.6/site-packages/django/template/loader_tags.py", line 177, in render
    return compiled_parent._render(context)
  File "/home/adrian/skyfolk/venv/lib/python3.6/site-packages/django/test/utils.py", line 107, in instrumented_test_render
    return self.nodelist.render(context)
  File "/home/adrian/skyfolk/venv/lib/python3.6/site-packages/django/template/base.py", line 990, in render
    bit = node.render_annotated(context)
  File "/home/adrian/skyfolk/venv/lib/python3.6/site-packages/django/template/base.py", line 957, in render_annotated
    return self.render(context)
  File "/home/adrian/skyfolk/venv/lib/python3.6/site-packages/django/template/loader_tags.py", line 177, in render
    return compiled_parent._render(context)
  File "/home/adrian/skyfolk/venv/lib/python3.6/site-packages/django/test/utils.py", line 107, in instrumented_test_render
    return self.nodelist.render(context)
  File "/home/adrian/skyfolk/venv/lib/python3.6/site-packages/django/template/base.py", line 990, in render
    bit = node.render_annotated(context)
  File "/home/adrian/skyfolk/venv/lib/python3.6/site-packages/django/template/base.py", line 957, in render_annotated
    return self.render(context)
  File "/home/adrian/skyfolk/venv/lib/python3.6/site-packages/django/template/loader_tags.py", line 72, in render
    result = block.nodelist.render(context)
  File "/home/adrian/skyfolk/venv/lib/python3.6/site-packages/django/template/base.py", line 990, in render
    bit = node.render_annotated(context)
  File "/home/adrian/skyfolk/venv/lib/python3.6/site-packages/django/template/base.py", line 957, in render_annotated
    return self.render(context)
  File "/home/adrian/skyfolk/venv/lib/python3.6/site-packages/django/template/loader_tags.py", line 72, in render
    result = block.nodelist.render(context)
  File "/home/adrian/skyfolk/venv/lib/python3.6/site-packages/django/template/base.py", line 990, in render
    bit = node.render_annotated(context)
  File "/home/adrian/skyfolk/venv/lib/python3.6/site-packages/django/template/base.py", line 957, in render_annotated
    return self.render(context)
  File "/home/adrian/skyfolk/venv/lib/python3.6/site-packages/django/template/loader_tags.py", line 72, in render
    result = block.nodelist.render(context)
  File "/home/adrian/skyfolk/venv/lib/python3.6/site-packages/django/template/base.py", line 990, in render
    bit = node.render_annotated(context)
  File "/home/adrian/skyfolk/venv/lib/python3.6/site-packages/django/template/base.py", line 957, in render_annotated
    return self.render(context)
  File "/home/adrian/skyfolk/venv/lib/python3.6/site-packages/django/template/defaulttags.py", line 322, in render
    return nodelist.render(context)
  File "/home/adrian/skyfolk/venv/lib/python3.6/site-packages/django/template/base.py", line 990, in render
    bit = node.render_annotated(context)
  File "/home/adrian/skyfolk/venv/lib/python3.6/site-packages/django/template/base.py", line 957, in render_annotated
    return self.render(context)
  File "/home/adrian/skyfolk/venv/lib/python3.6/site-packages/django/template/defaulttags.py", line 458, in render
    url = reverse(view_name, args=args, kwargs=kwargs, current_app=current_app)
  File "/home/adrian/skyfolk/venv/lib/python3.6/site-packages/django/urls/base.py", line 91, in reverse
    return force_text(iri_to_uri(resolver._reverse_with_prefix(view, prefix, *args, **kwargs)))
  File "/home/adrian/skyfolk/venv/lib/python3.6/site-packages/django/urls/resolvers.py", line 497, in _reverse_with_prefix
    raise NoReverseMatch(msg)
django.urls.exceptions.NoReverseMatch: Reverse for 'dash.public_dashboard' with arguments '('adrian',)' not found. 1 pattern(s) tried: ['dashboard/(?P<username>[\\w-]+)/(?P<workspace>[\\w_\\-]+)/$']
2018-02-05 14:12:28,969 ERROR exception 1412 Internal Server Error: /dashboard/adrian/androids/
Traceback (most recent call last):
  File "/home/adrian/skyfolk/venv/lib/python3.6/site-packages/django/core/handlers/exception.py", line 41, in inner
    response = get_response(request)
  File "/home/adrian/skyfolk/venv/lib/python3.6/site-packages/django/core/handlers/base.py", line 249, in _legacy_get_response
    response = self._get_response(request)
  File "/home/adrian/skyfolk/venv/lib/python3.6/site-packages/django/core/handlers/base.py", line 187, in _get_response
    response = self.process_exception_by_middleware(e, request)
  File "/home/adrian/skyfolk/venv/lib/python3.6/site-packages/channels/handler.py", line 243, in process_exception_by_middleware
    return super(AsgiHandler, self).process_exception_by_middleware(exception, request)
  File "/home/adrian/skyfolk/venv/lib/python3.6/site-packages/django/core/handlers/base.py", line 185, in _get_response
    response = wrapped_callback(request, *callback_args, **callback_kwargs)
  File "/home/adrian/skyfolk/dash/views.py", line 1842, in public_dashboard
    return render(request, template_name, context)
  File "/home/adrian/skyfolk/venv/lib/python3.6/site-packages/django/shortcuts.py", line 30, in render
    content = loader.render_to_string(template_name, context, request, using=using)
  File "/home/adrian/skyfolk/venv/lib/python3.6/site-packages/django/template/loader.py", line 68, in render_to_string
    return template.render(context, request)
  File "/home/adrian/skyfolk/venv/lib/python3.6/site-packages/django/template/backends/django.py", line 66, in render
    return self.template.render(context)
  File "/home/adrian/skyfolk/venv/lib/python3.6/site-packages/django/template/base.py", line 207, in render
    return self._render(context)
  File "/home/adrian/skyfolk/venv/lib/python3.6/site-packages/django/test/utils.py", line 107, in instrumented_test_render
    return self.nodelist.render(context)
  File "/home/adrian/skyfolk/venv/lib/python3.6/site-packages/django/template/base.py", line 990, in render
    bit = node.render_annotated(context)
  File "/home/adrian/skyfolk/venv/lib/python3.6/site-packages/django/template/base.py", line 957, in render_annotated
    return self.render(context)
  File "/home/adrian/skyfolk/venv/lib/python3.6/site-packages/django/template/loader_tags.py", line 177, in render
    return compiled_parent._render(context)
  File "/home/adrian/skyfolk/venv/lib/python3.6/site-packages/django/test/utils.py", line 107, in instrumented_test_render
    return self.nodelist.render(context)
  File "/home/adrian/skyfolk/venv/lib/python3.6/site-packages/django/template/base.py", line 990, in render
    bit = node.render_annotated(context)
  File "/home/adrian/skyfolk/venv/lib/python3.6/site-packages/django/template/base.py", line 957, in render_annotated
    return self.render(context)
  File "/home/adrian/skyfolk/venv/lib/python3.6/site-packages/django/template/loader_tags.py", line 177, in render
    return compiled_parent._render(context)
  File "/home/adrian/skyfolk/venv/lib/python3.6/site-packages/django/test/utils.py", line 107, in instrumented_test_render
    return self.nodelist.render(context)
  File "/home/adrian/skyfolk/venv/lib/python3.6/site-packages/django/template/base.py", line 990, in render
    bit = node.render_annotated(context)
  File "/home/adrian/skyfolk/venv/lib/python3.6/site-packages/django/template/base.py", line 957, in render_annotated
    return self.render(context)
  File "/home/adrian/skyfolk/venv/lib/python3.6/site-packages/django/template/loader_tags.py", line 72, in render
    result = block.nodelist.render(context)
  File "/home/adrian/skyfolk/venv/lib/python3.6/site-packages/django/template/base.py", line 990, in render
    bit = node.render_annotated(context)
  File "/home/adrian/skyfolk/venv/lib/python3.6/site-packages/django/template/base.py", line 957, in render_annotated
    return self.render(context)
  File "/home/adrian/skyfolk/venv/lib/python3.6/site-packages/django/template/loader_tags.py", line 72, in render
    result = block.nodelist.render(context)
  File "/home/adrian/skyfolk/venv/lib/python3.6/site-packages/django/template/base.py", line 990, in render
    bit = node.render_annotated(context)
  File "/home/adrian/skyfolk/venv/lib/python3.6/site-packages/django/template/base.py", line 957, in render_annotated
    return self.render(context)
  File "/home/adrian/skyfolk/venv/lib/python3.6/site-packages/django/template/loader_tags.py", line 72, in render
    result = block.nodelist.render(context)
  File "/home/adrian/skyfolk/venv/lib/python3.6/site-packages/django/template/base.py", line 990, in render
    bit = node.render_annotated(context)
  File "/home/adrian/skyfolk/venv/lib/python3.6/site-packages/django/template/base.py", line 957, in render_annotated
    return self.render(context)
  File "/home/adrian/skyfolk/venv/lib/python3.6/site-packages/django/template/defaulttags.py", line 322, in render
    return nodelist.render(context)
  File "/home/adrian/skyfolk/venv/lib/python3.6/site-packages/django/template/base.py", line 990, in render
    bit = node.render_annotated(context)
  File "/home/adrian/skyfolk/venv/lib/python3.6/site-packages/django/template/base.py", line 957, in render_annotated
    return self.render(context)
  File "/home/adrian/skyfolk/venv/lib/python3.6/site-packages/django/template/defaulttags.py", line 458, in render
    url = reverse(view_name, args=args, kwargs=kwargs, current_app=current_app)
  File "/home/adrian/skyfolk/venv/lib/python3.6/site-packages/django/urls/base.py", line 91, in reverse
    return force_text(iri_to_uri(resolver._reverse_with_prefix(view, prefix, *args, **kwargs)))
  File "/home/adrian/skyfolk/venv/lib/python3.6/site-packages/django/urls/resolvers.py", line 497, in _reverse_with_prefix
    raise NoReverseMatch(msg)
django.urls.exceptions.NoReverseMatch: Reverse for 'dash.public_dashboard' with arguments '('adrian',)' not found. 1 pattern(s) tried: ['dashboard/(?P<username>[\\w-]+)/(?P<workspace>[\\w_\\-]+)/$']
2018-02-05 14:26:11,517 ERROR exception 8850 Internal Server Error: /dashboard/adrian/androids/
Traceback (most recent call last):
  File "/home/adrian/skyfolk/venv/lib/python3.6/site-packages/django/core/handlers/exception.py", line 41, in inner
    response = get_response(request)
  File "/home/adrian/skyfolk/venv/lib/python3.6/site-packages/django/core/handlers/base.py", line 249, in _legacy_get_response
    response = self._get_response(request)
  File "/home/adrian/skyfolk/venv/lib/python3.6/site-packages/django/core/handlers/base.py", line 187, in _get_response
    response = self.process_exception_by_middleware(e, request)
  File "/home/adrian/skyfolk/venv/lib/python3.6/site-packages/channels/handler.py", line 243, in process_exception_by_middleware
    return super(AsgiHandler, self).process_exception_by_middleware(exception, request)
  File "/home/adrian/skyfolk/venv/lib/python3.6/site-packages/django/core/handlers/base.py", line 185, in _get_response
    response = wrapped_callback(request, *callback_args, **callback_kwargs)
  File "/home/adrian/skyfolk/dash/views.py", line 1828, in public_dashboard
    print(p.plugin_uid)
AttributeError: 'AndroidMainPlaceholder' object has no attribute 'plugin_uid'
2018-02-05 16:55:15,021 ERROR exception 22115 Internal Server Error: /inicio/
Traceback (most recent call last):
  File "/home/adrian/skyfolk/venv/lib/python3.6/site-packages/django/template/base.py", line 507, in parse
    compile_func = self.tags[command]
KeyError: 'elif'

During handling of the above exception, another exception occurred:

Traceback (most recent call last):
  File "/home/adrian/skyfolk/venv/lib/python3.6/site-packages/django/core/handlers/exception.py", line 41, in inner
    response = get_response(request)
  File "/home/adrian/skyfolk/venv/lib/python3.6/site-packages/django/core/handlers/base.py", line 249, in _legacy_get_response
    response = self._get_response(request)
  File "/home/adrian/skyfolk/venv/lib/python3.6/site-packages/django/core/handlers/base.py", line 217, in _get_response
    response = self.process_exception_by_middleware(e, request)
  File "/home/adrian/skyfolk/venv/lib/python3.6/site-packages/channels/handler.py", line 243, in process_exception_by_middleware
    return super(AsgiHandler, self).process_exception_by_middleware(exception, request)
  File "/home/adrian/skyfolk/venv/lib/python3.6/site-packages/django/core/handlers/base.py", line 215, in _get_response
    response = response.render()
  File "/home/adrian/skyfolk/venv/lib/python3.6/site-packages/django/template/response.py", line 107, in render
    self.content = self.rendered_content
  File "/home/adrian/skyfolk/venv/lib/python3.6/site-packages/django/template/response.py", line 82, in rendered_content
    template = self.resolve_template(self.template_name)
  File "/home/adrian/skyfolk/venv/lib/python3.6/site-packages/django/template/response.py", line 64, in resolve_template
    return select_template(template, using=self.using)
  File "/home/adrian/skyfolk/venv/lib/python3.6/site-packages/django/template/loader.py", line 48, in select_template
    return engine.get_template(template_name)
  File "/home/adrian/skyfolk/venv/lib/python3.6/site-packages/django/template/backends/django.py", line 39, in get_template
    return Template(self.engine.get_template(template_name), self)
  File "/home/adrian/skyfolk/venv/lib/python3.6/site-packages/django/template/engine.py", line 162, in get_template
    template, origin = self.find_template(template_name)
  File "/home/adrian/skyfolk/venv/lib/python3.6/site-packages/django/template/engine.py", line 136, in find_template
    name, template_dirs=dirs, skip=skip,
  File "/home/adrian/skyfolk/venv/lib/python3.6/site-packages/django/template/loaders/base.py", line 44, in get_template
    contents, origin, origin.template_name, self.engine,
  File "/home/adrian/skyfolk/venv/lib/python3.6/site-packages/django/template/base.py", line 191, in __init__
    self.nodelist = self.compile_nodelist()
  File "/home/adrian/skyfolk/venv/lib/python3.6/site-packages/django/template/base.py", line 230, in compile_nodelist
    return parser.parse()
  File "/home/adrian/skyfolk/venv/lib/python3.6/site-packages/django/template/base.py", line 515, in parse
    raise self.error(token, e)
  File "/home/adrian/skyfolk/venv/lib/python3.6/site-packages/django/template/base.py", line 513, in parse
    compiled_result = compile_func(self, token)
  File "/home/adrian/skyfolk/venv/lib/python3.6/site-packages/django/template/loader_tags.py", line 312, in do_extends
    nodelist = parser.parse()
  File "/home/adrian/skyfolk/venv/lib/python3.6/site-packages/django/template/base.py", line 515, in parse
    raise self.error(token, e)
  File "/home/adrian/skyfolk/venv/lib/python3.6/site-packages/django/template/base.py", line 513, in parse
    compiled_result = compile_func(self, token)
  File "/home/adrian/skyfolk/venv/lib/python3.6/site-packages/django/template/loader_tags.py", line 255, in do_block
    nodelist = parser.parse(('endblock',))
  File "/home/adrian/skyfolk/venv/lib/python3.6/site-packages/django/template/base.py", line 515, in parse
    raise self.error(token, e)
  File "/home/adrian/skyfolk/venv/lib/python3.6/site-packages/django/template/base.py", line 513, in parse
    compiled_result = compile_func(self, token)
  File "/home/adrian/skyfolk/venv/lib/python3.6/site-packages/django/template/defaulttags.py", line 827, in do_for
    nodelist_loop = parser.parse(('empty', 'endfor',))
  File "/home/adrian/skyfolk/venv/lib/python3.6/site-packages/django/template/base.py", line 509, in parse
    self.invalid_block_tag(token, command, parse_until)
  File "/home/adrian/skyfolk/venv/lib/python3.6/site-packages/django/template/base.py", line 565, in invalid_block_tag
    get_text_list(["'%s'" % p for p in parse_until], 'or'),
django.template.exceptions.TemplateSyntaxError: Invalid block tag on line 305: 'elif', expected 'empty' or 'endfor'. Did you forget to register or load this tag?
2018-02-05 17:09:36,189 ERROR exception 28181 Internal Server Error: /inicio/
Traceback (most recent call last):
  File "/home/adrian/skyfolk/latest_news/views.py", line 129, in get_queryset
    placeholders = layout.get_placeholder_instances(dashboard_entries,
NameError: name 'layout' is not defined

During handling of the above exception, another exception occurred:

Traceback (most recent call last):
  File "/home/adrian/skyfolk/venv/lib/python3.6/site-packages/django/core/handlers/exception.py", line 41, in inner
    response = get_response(request)
  File "/home/adrian/skyfolk/venv/lib/python3.6/site-packages/django/core/handlers/base.py", line 249, in _legacy_get_response
    response = self._get_response(request)
  File "/home/adrian/skyfolk/venv/lib/python3.6/site-packages/django/core/handlers/base.py", line 187, in _get_response
    response = self.process_exception_by_middleware(e, request)
  File "/home/adrian/skyfolk/venv/lib/python3.6/site-packages/channels/handler.py", line 243, in process_exception_by_middleware
    return super(AsgiHandler, self).process_exception_by_middleware(exception, request)
  File "/home/adrian/skyfolk/venv/lib/python3.6/site-packages/django/core/handlers/base.py", line 185, in _get_response
    response = wrapped_callback(request, *callback_args, **callback_kwargs)
  File "/home/adrian/skyfolk/venv/lib/python3.6/site-packages/django/contrib/auth/decorators.py", line 23, in _wrapped_view
    return view_func(request, *args, **kwargs)
  File "/home/adrian/skyfolk/venv/lib/python3.6/site-packages/django/views/generic/base.py", line 68, in view
    return self.dispatch(request, *args, **kwargs)
  File "/home/adrian/skyfolk/venv/lib/python3.6/site-packages/django/views/generic/base.py", line 88, in dispatch
    return handler(request, *args, **kwargs)
  File "/home/adrian/skyfolk/venv/lib/python3.6/site-packages/django/views/generic/list.py", line 160, in get
    self.object_list = self.get_queryset()
  File "/home/adrian/skyfolk/latest_news/views.py", line 135, in get_queryset
    .filter(entries_q) \
  File "/home/adrian/skyfolk/venv/lib/python3.6/site-packages/django/db/models/manager.py", line 85, in manager_method
    return getattr(self.get_queryset(), name)(*args, **kwargs)
  File "/home/adrian/skyfolk/venv/lib/python3.6/site-packages/django/db/models/query.py", line 784, in filter
    return self._filter_or_exclude(False, *args, **kwargs)
  File "/home/adrian/skyfolk/venv/lib/python3.6/site-packages/django/db/models/query.py", line 802, in _filter_or_exclude
    clone.query.add_q(Q(*args, **kwargs))
  File "/home/adrian/skyfolk/venv/lib/python3.6/site-packages/django/db/models/sql/query.py", line 1250, in add_q
    clause, _ = self._add_q(q_object, self.used_aliases)
  File "/home/adrian/skyfolk/venv/lib/python3.6/site-packages/django/db/models/sql/query.py", line 1270, in _add_q
    current_negated, allow_joins, split_subq)
  File "/home/adrian/skyfolk/venv/lib/python3.6/site-packages/django/db/models/sql/query.py", line 1276, in _add_q
    allow_joins=allow_joins, split_subq=split_subq,
  File "/home/adrian/skyfolk/venv/lib/python3.6/site-packages/django/db/models/sql/query.py", line 1197, in build_filter
    raise FieldError('Related Field got invalid lookup: {}'.format(lookups[0]))
django.core.exceptions.FieldError: Related Field got invalid lookup: owner
2018-02-05 17:09:59,583 ERROR exception 28632 Internal Server Error: /inicio/
Traceback (most recent call last):
  File "/home/adrian/skyfolk/latest_news/views.py", line 129, in get_queryset
    placeholders = layout.get_placeholder_instances(dashboard_entries,
NameError: name 'layout' is not defined

During handling of the above exception, another exception occurred:

Traceback (most recent call last):
  File "/home/adrian/skyfolk/venv/lib/python3.6/site-packages/django/core/handlers/exception.py", line 41, in inner
    response = get_response(request)
  File "/home/adrian/skyfolk/venv/lib/python3.6/site-packages/django/core/handlers/base.py", line 249, in _legacy_get_response
    response = self._get_response(request)
  File "/home/adrian/skyfolk/venv/lib/python3.6/site-packages/django/core/handlers/base.py", line 187, in _get_response
    response = self.process_exception_by_middleware(e, request)
  File "/home/adrian/skyfolk/venv/lib/python3.6/site-packages/channels/handler.py", line 243, in process_exception_by_middleware
    return super(AsgiHandler, self).process_exception_by_middleware(exception, request)
  File "/home/adrian/skyfolk/venv/lib/python3.6/site-packages/django/core/handlers/base.py", line 185, in _get_response
    response = wrapped_callback(request, *callback_args, **callback_kwargs)
  File "/home/adrian/skyfolk/venv/lib/python3.6/site-packages/django/contrib/auth/decorators.py", line 23, in _wrapped_view
    return view_func(request, *args, **kwargs)
  File "/home/adrian/skyfolk/venv/lib/python3.6/site-packages/django/views/generic/base.py", line 68, in view
    return self.dispatch(request, *args, **kwargs)
  File "/home/adrian/skyfolk/venv/lib/python3.6/site-packages/django/views/generic/base.py", line 88, in dispatch
    return handler(request, *args, **kwargs)
  File "/home/adrian/skyfolk/venv/lib/python3.6/site-packages/django/views/generic/list.py", line 160, in get
    self.object_list = self.get_queryset()
  File "/home/adrian/skyfolk/latest_news/views.py", line 139, in get_queryset
    placeholders = layout.get_placeholder_instances(dashboard_entries,
NameError: name 'layout' is not defined
2018-02-05 17:17:57,610 ERROR exception 28632 Internal Server Error: /inicio/
Traceback (most recent call last):
  File "/home/adrian/skyfolk/latest_news/views.py", line 129, in get_queryset
    placeholders = layout.get_placeholder_instances(dashboard_entries,
NameError: name 'layout' is not defined

During handling of the above exception, another exception occurred:

Traceback (most recent call last):
  File "/home/adrian/skyfolk/venv/lib/python3.6/site-packages/django/core/handlers/exception.py", line 41, in inner
    response = get_response(request)
  File "/home/adrian/skyfolk/venv/lib/python3.6/site-packages/django/core/handlers/base.py", line 249, in _legacy_get_response
    response = self._get_response(request)
  File "/home/adrian/skyfolk/venv/lib/python3.6/site-packages/django/core/handlers/base.py", line 187, in _get_response
    response = self.process_exception_by_middleware(e, request)
  File "/home/adrian/skyfolk/venv/lib/python3.6/site-packages/channels/handler.py", line 243, in process_exception_by_middleware
    return super(AsgiHandler, self).process_exception_by_middleware(exception, request)
  File "/home/adrian/skyfolk/venv/lib/python3.6/site-packages/django/core/handlers/base.py", line 185, in _get_response
    response = wrapped_callback(request, *callback_args, **callback_kwargs)
  File "/home/adrian/skyfolk/venv/lib/python3.6/site-packages/django/contrib/auth/decorators.py", line 23, in _wrapped_view
    return view_func(request, *args, **kwargs)
  File "/home/adrian/skyfolk/venv/lib/python3.6/site-packages/django/views/generic/base.py", line 68, in view
    return self.dispatch(request, *args, **kwargs)
  File "/home/adrian/skyfolk/venv/lib/python3.6/site-packages/django/views/generic/base.py", line 88, in dispatch
    return handler(request, *args, **kwargs)
  File "/home/adrian/skyfolk/venv/lib/python3.6/site-packages/django/views/generic/list.py", line 160, in get
    self.object_list = self.get_queryset()
  File "/home/adrian/skyfolk/latest_news/views.py", line 139, in get_queryset
    placeholders = layout.get_placeholder_instances(dashboard_entries,
NameError: name 'layout' is not defined
2018-02-05 17:20:14,337 ERROR exception 30351 Internal Server Error: /inicio/
Traceback (most recent call last):
  File "/home/adrian/skyfolk/venv/lib/python3.6/site-packages/django/core/handlers/exception.py", line 41, in inner
    response = get_response(request)
  File "/home/adrian/skyfolk/venv/lib/python3.6/site-packages/django/core/handlers/base.py", line 249, in _legacy_get_response
    response = self._get_response(request)
  File "/home/adrian/skyfolk/venv/lib/python3.6/site-packages/django/core/handlers/base.py", line 187, in _get_response
    response = self.process_exception_by_middleware(e, request)
  File "/home/adrian/skyfolk/venv/lib/python3.6/site-packages/channels/handler.py", line 243, in process_exception_by_middleware
    return super(AsgiHandler, self).process_exception_by_middleware(exception, request)
  File "/home/adrian/skyfolk/venv/lib/python3.6/site-packages/django/core/handlers/base.py", line 185, in _get_response
    response = wrapped_callback(request, *callback_args, **callback_kwargs)
  File "/home/adrian/skyfolk/venv/lib/python3.6/site-packages/django/contrib/auth/decorators.py", line 23, in _wrapped_view
    return view_func(request, *args, **kwargs)
  File "/home/adrian/skyfolk/venv/lib/python3.6/site-packages/django/views/generic/base.py", line 68, in view
    return self.dispatch(request, *args, **kwargs)
  File "/home/adrian/skyfolk/venv/lib/python3.6/site-packages/django/views/generic/base.py", line 88, in dispatch
    return handler(request, *args, **kwargs)
  File "/home/adrian/skyfolk/venv/lib/python3.6/site-packages/django/views/generic/list.py", line 160, in get
    self.object_list = self.get_queryset()
  File "/home/adrian/skyfolk/latest_news/views.py", line 121, in get_queryset
    layout = get_layout(layout_uid='profile', as_instance=True)
NameError: name 'get_layout' is not defined
2018-02-05 17:20:40,858 ERROR exception 30941 Internal Server Error: /inicio/
Traceback (most recent call last):
  File "/home/adrian/skyfolk/latest_news/views.py", line 132, in get_queryset
    request=request)
NameError: name 'request' is not defined

During handling of the above exception, another exception occurred:

Traceback (most recent call last):
  File "/home/adrian/skyfolk/venv/lib/python3.6/site-packages/django/core/handlers/exception.py", line 41, in inner
    response = get_response(request)
  File "/home/adrian/skyfolk/venv/lib/python3.6/site-packages/django/core/handlers/base.py", line 249, in _legacy_get_response
    response = self._get_response(request)
  File "/home/adrian/skyfolk/venv/lib/python3.6/site-packages/django/core/handlers/base.py", line 187, in _get_response
    response = self.process_exception_by_middleware(e, request)
  File "/home/adrian/skyfolk/venv/lib/python3.6/site-packages/channels/handler.py", line 243, in process_exception_by_middleware
    return super(AsgiHandler, self).process_exception_by_middleware(exception, request)
  File "/home/adrian/skyfolk/venv/lib/python3.6/site-packages/django/core/handlers/base.py", line 185, in _get_response
    response = wrapped_callback(request, *callback_args, **callback_kwargs)
  File "/home/adrian/skyfolk/venv/lib/python3.6/site-packages/django/contrib/auth/decorators.py", line 23, in _wrapped_view
    return view_func(request, *args, **kwargs)
  File "/home/adrian/skyfolk/venv/lib/python3.6/site-packages/django/views/generic/base.py", line 68, in view
    return self.dispatch(request, *args, **kwargs)
  File "/home/adrian/skyfolk/venv/lib/python3.6/site-packages/django/views/generic/base.py", line 88, in dispatch
    return handler(request, *args, **kwargs)
  File "/home/adrian/skyfolk/venv/lib/python3.6/site-packages/django/views/generic/list.py", line 160, in get
    self.object_list = self.get_queryset()
  File "/home/adrian/skyfolk/latest_news/views.py", line 142, in get_queryset
    request=request)
NameError: name 'request' is not defined
2018-02-05 17:21:19,007 ERROR exception 31321 Internal Server Error: /inicio/
Traceback (most recent call last):
  File "/home/adrian/skyfolk/venv/lib/python3.6/site-packages/django/template/base.py", line 507, in parse
    compile_func = self.tags[command]
KeyError: 'else'

During handling of the above exception, another exception occurred:

Traceback (most recent call last):
  File "/home/adrian/skyfolk/venv/lib/python3.6/site-packages/django/core/handlers/exception.py", line 41, in inner
    response = get_response(request)
  File "/home/adrian/skyfolk/venv/lib/python3.6/site-packages/django/core/handlers/base.py", line 249, in _legacy_get_response
    response = self._get_response(request)
  File "/home/adrian/skyfolk/venv/lib/python3.6/site-packages/django/core/handlers/base.py", line 217, in _get_response
    response = self.process_exception_by_middleware(e, request)
  File "/home/adrian/skyfolk/venv/lib/python3.6/site-packages/channels/handler.py", line 243, in process_exception_by_middleware
    return super(AsgiHandler, self).process_exception_by_middleware(exception, request)
  File "/home/adrian/skyfolk/venv/lib/python3.6/site-packages/django/core/handlers/base.py", line 215, in _get_response
    response = response.render()
  File "/home/adrian/skyfolk/venv/lib/python3.6/site-packages/django/template/response.py", line 107, in render
    self.content = self.rendered_content
  File "/home/adrian/skyfolk/venv/lib/python3.6/site-packages/django/template/response.py", line 82, in rendered_content
    template = self.resolve_template(self.template_name)
  File "/home/adrian/skyfolk/venv/lib/python3.6/site-packages/django/template/response.py", line 64, in resolve_template
    return select_template(template, using=self.using)
  File "/home/adrian/skyfolk/venv/lib/python3.6/site-packages/django/template/loader.py", line 48, in select_template
    return engine.get_template(template_name)
  File "/home/adrian/skyfolk/venv/lib/python3.6/site-packages/django/template/backends/django.py", line 39, in get_template
    return Template(self.engine.get_template(template_name), self)
  File "/home/adrian/skyfolk/venv/lib/python3.6/site-packages/django/template/engine.py", line 162, in get_template
    template, origin = self.find_template(template_name)
  File "/home/adrian/skyfolk/venv/lib/python3.6/site-packages/django/template/engine.py", line 136, in find_template
    name, template_dirs=dirs, skip=skip,
  File "/home/adrian/skyfolk/venv/lib/python3.6/site-packages/django/template/loaders/base.py", line 44, in get_template
    contents, origin, origin.template_name, self.engine,
  File "/home/adrian/skyfolk/venv/lib/python3.6/site-packages/django/template/base.py", line 191, in __init__
    self.nodelist = self.compile_nodelist()
  File "/home/adrian/skyfolk/venv/lib/python3.6/site-packages/django/template/base.py", line 230, in compile_nodelist
    return parser.parse()
  File "/home/adrian/skyfolk/venv/lib/python3.6/site-packages/django/template/base.py", line 515, in parse
    raise self.error(token, e)
  File "/home/adrian/skyfolk/venv/lib/python3.6/site-packages/django/template/base.py", line 513, in parse
    compiled_result = compile_func(self, token)
  File "/home/adrian/skyfolk/venv/lib/python3.6/site-packages/django/template/loader_tags.py", line 312, in do_extends
    nodelist = parser.parse()
  File "/home/adrian/skyfolk/venv/lib/python3.6/site-packages/django/template/base.py", line 515, in parse
    raise self.error(token, e)
  File "/home/adrian/skyfolk/venv/lib/python3.6/site-packages/django/template/base.py", line 513, in parse
    compiled_result = compile_func(self, token)
  File "/home/adrian/skyfolk/venv/lib/python3.6/site-packages/django/template/loader_tags.py", line 255, in do_block
    nodelist = parser.parse(('endblock',))
  File "/home/adrian/skyfolk/venv/lib/python3.6/site-packages/django/template/base.py", line 515, in parse
    raise self.error(token, e)
  File "/home/adrian/skyfolk/venv/lib/python3.6/site-packages/django/template/base.py", line 513, in parse
    compiled_result = compile_func(self, token)
  File "/home/adrian/skyfolk/venv/lib/python3.6/site-packages/django/template/defaulttags.py", line 827, in do_for
    nodelist_loop = parser.parse(('empty', 'endfor',))
  File "/home/adrian/skyfolk/venv/lib/python3.6/site-packages/django/template/base.py", line 509, in parse
    self.invalid_block_tag(token, command, parse_until)
  File "/home/adrian/skyfolk/venv/lib/python3.6/site-packages/django/template/base.py", line 565, in invalid_block_tag
    get_text_list(["'%s'" % p for p in parse_until], 'or'),
django.template.exceptions.TemplateSyntaxError: Invalid block tag on line 340: 'else', expected 'empty' or 'endfor'. Did you forget to register or load this tag?
2018-02-05 17:21:21,914 ERROR exception 31321 Internal Server Error: /inicio/
Traceback (most recent call last):
  File "/home/adrian/skyfolk/venv/lib/python3.6/site-packages/django/template/base.py", line 507, in parse
    compile_func = self.tags[command]
KeyError: 'else'

During handling of the above exception, another exception occurred:

Traceback (most recent call last):
  File "/home/adrian/skyfolk/venv/lib/python3.6/site-packages/django/core/handlers/exception.py", line 41, in inner
    response = get_response(request)
  File "/home/adrian/skyfolk/venv/lib/python3.6/site-packages/django/core/handlers/base.py", line 249, in _legacy_get_response
    response = self._get_response(request)
  File "/home/adrian/skyfolk/venv/lib/python3.6/site-packages/django/core/handlers/base.py", line 217, in _get_response
    response = self.process_exception_by_middleware(e, request)
  File "/home/adrian/skyfolk/venv/lib/python3.6/site-packages/channels/handler.py", line 243, in process_exception_by_middleware
    return super(AsgiHandler, self).process_exception_by_middleware(exception, request)
  File "/home/adrian/skyfolk/venv/lib/python3.6/site-packages/django/core/handlers/base.py", line 215, in _get_response
    response = response.render()
  File "/home/adrian/skyfolk/venv/lib/python3.6/site-packages/django/template/response.py", line 107, in render
    self.content = self.rendered_content
  File "/home/adrian/skyfolk/venv/lib/python3.6/site-packages/django/template/response.py", line 82, in rendered_content
    template = self.resolve_template(self.template_name)
  File "/home/adrian/skyfolk/venv/lib/python3.6/site-packages/django/template/response.py", line 64, in resolve_template
    return select_template(template, using=self.using)
  File "/home/adrian/skyfolk/venv/lib/python3.6/site-packages/django/template/loader.py", line 48, in select_template
    return engine.get_template(template_name)
  File "/home/adrian/skyfolk/venv/lib/python3.6/site-packages/django/template/backends/django.py", line 39, in get_template
    return Template(self.engine.get_template(template_name), self)
  File "/home/adrian/skyfolk/venv/lib/python3.6/site-packages/django/template/engine.py", line 162, in get_template
    template, origin = self.find_template(template_name)
  File "/home/adrian/skyfolk/venv/lib/python3.6/site-packages/django/template/engine.py", line 136, in find_template
    name, template_dirs=dirs, skip=skip,
  File "/home/adrian/skyfolk/venv/lib/python3.6/site-packages/django/template/loaders/base.py", line 44, in get_template
    contents, origin, origin.template_name, self.engine,
  File "/home/adrian/skyfolk/venv/lib/python3.6/site-packages/django/template/base.py", line 191, in __init__
    self.nodelist = self.compile_nodelist()
  File "/home/adrian/skyfolk/venv/lib/python3.6/site-packages/django/template/base.py", line 230, in compile_nodelist
    return parser.parse()
  File "/home/adrian/skyfolk/venv/lib/python3.6/site-packages/django/template/base.py", line 515, in parse
    raise self.error(token, e)
  File "/home/adrian/skyfolk/venv/lib/python3.6/site-packages/django/template/base.py", line 513, in parse
    compiled_result = compile_func(self, token)
  File "/home/adrian/skyfolk/venv/lib/python3.6/site-packages/django/template/loader_tags.py", line 312, in do_extends
    nodelist = parser.parse()
  File "/home/adrian/skyfolk/venv/lib/python3.6/site-packages/django/template/base.py", line 515, in parse
    raise self.error(token, e)
  File "/home/adrian/skyfolk/venv/lib/python3.6/site-packages/django/template/base.py", line 513, in parse
    compiled_result = compile_func(self, token)
  File "/home/adrian/skyfolk/venv/lib/python3.6/site-packages/django/template/loader_tags.py", line 255, in do_block
    nodelist = parser.parse(('endblock',))
  File "/home/adrian/skyfolk/venv/lib/python3.6/site-packages/django/template/base.py", line 515, in parse
    raise self.error(token, e)
  File "/home/adrian/skyfolk/venv/lib/python3.6/site-packages/django/template/base.py", line 513, in parse
    compiled_result = compile_func(self, token)
  File "/home/adrian/skyfolk/venv/lib/python3.6/site-packages/django/template/defaulttags.py", line 827, in do_for
    nodelist_loop = parser.parse(('empty', 'endfor',))
  File "/home/adrian/skyfolk/venv/lib/python3.6/site-packages/django/template/base.py", line 509, in parse
    self.invalid_block_tag(token, command, parse_until)
  File "/home/adrian/skyfolk/venv/lib/python3.6/site-packages/django/template/base.py", line 565, in invalid_block_tag
    get_text_list(["'%s'" % p for p in parse_until], 'or'),
django.template.exceptions.TemplateSyntaxError: Invalid block tag on line 340: 'else', expected 'empty' or 'endfor'. Did you forget to register or load this tag?
2018-02-07 13:45:08,216 ERROR exception 21222 Internal Server Error: /inicio/
Traceback (most recent call last):
  File "/home/adrian/skyfolk/venv/lib/python3.6/site-packages/django/core/handlers/exception.py", line 41, in inner
    response = get_response(request)
  File "/home/adrian/skyfolk/venv/lib/python3.6/site-packages/django/core/handlers/base.py", line 249, in _legacy_get_response
    response = self._get_response(request)
  File "/home/adrian/skyfolk/venv/lib/python3.6/site-packages/django/core/handlers/base.py", line 187, in _get_response
    response = self.process_exception_by_middleware(e, request)
  File "/home/adrian/skyfolk/venv/lib/python3.6/site-packages/channels/handler.py", line 243, in process_exception_by_middleware
    return super(AsgiHandler, self).process_exception_by_middleware(exception, request)
  File "/home/adrian/skyfolk/venv/lib/python3.6/site-packages/django/core/handlers/base.py", line 185, in _get_response
    response = wrapped_callback(request, *callback_args, **callback_kwargs)
  File "/home/adrian/skyfolk/venv/lib/python3.6/site-packages/django/contrib/auth/decorators.py", line 23, in _wrapped_view
    return view_func(request, *args, **kwargs)
  File "/home/adrian/skyfolk/venv/lib/python3.6/site-packages/django/views/generic/base.py", line 68, in view
    return self.dispatch(request, *args, **kwargs)
  File "/home/adrian/skyfolk/venv/lib/python3.6/site-packages/django/views/generic/base.py", line 88, in dispatch
    return handler(request, *args, **kwargs)
  File "/home/adrian/skyfolk/venv/lib/python3.6/site-packages/django/views/generic/list.py", line 175, in get
    context = self.get_context_data()
  File "/home/adrian/skyfolk/latest_news/views.py", line 195, in get_context_data
    self.layout.collect_widget_media(dashboard_entries)
NameError: name 'dashboard_entries' is not defined
2018-02-07 13:55:53,011 ERROR exception 24066 Internal Server Error: /dashboard/adrian/public_workspace/
Traceback (most recent call last):
  File "/home/adrian/skyfolk/venv/lib/python3.6/site-packages/django/core/handlers/exception.py", line 41, in inner
    response = get_response(request)
  File "/home/adrian/skyfolk/venv/lib/python3.6/site-packages/django/core/handlers/base.py", line 249, in _legacy_get_response
    response = self._get_response(request)
  File "/home/adrian/skyfolk/venv/lib/python3.6/site-packages/django/core/handlers/base.py", line 187, in _get_response
    response = self.process_exception_by_middleware(e, request)
  File "/home/adrian/skyfolk/venv/lib/python3.6/site-packages/channels/handler.py", line 243, in process_exception_by_middleware
    return super(AsgiHandler, self).process_exception_by_middleware(exception, request)
  File "/home/adrian/skyfolk/venv/lib/python3.6/site-packages/django/core/handlers/base.py", line 185, in _get_response
    response = wrapped_callback(request, *callback_args, **callback_kwargs)
  File "/home/adrian/skyfolk/dash/views.py", line 1748, in public_dashboard
    m = Profile.objects.get(user_id=user.id)
UnboundLocalError: local variable 'user' referenced before assignment
2018-02-07 13:56:09,331 ERROR exception 24582 Internal Server Error: /dashboard/adrian/public_workspace/
Traceback (most recent call last):
  File "/home/adrian/skyfolk/venv/lib/python3.6/site-packages/django/core/handlers/exception.py", line 41, in inner
    response = get_response(request)
  File "/home/adrian/skyfolk/venv/lib/python3.6/site-packages/django/core/handlers/base.py", line 249, in _legacy_get_response
    response = self._get_response(request)
  File "/home/adrian/skyfolk/venv/lib/python3.6/site-packages/django/core/handlers/base.py", line 187, in _get_response
    response = self.process_exception_by_middleware(e, request)
  File "/home/adrian/skyfolk/venv/lib/python3.6/site-packages/channels/handler.py", line 243, in process_exception_by_middleware
    return super(AsgiHandler, self).process_exception_by_middleware(exception, request)
  File "/home/adrian/skyfolk/venv/lib/python3.6/site-packages/django/core/handlers/base.py", line 185, in _get_response
    response = wrapped_callback(request, *callback_args, **callback_kwargs)
  File "/home/adrian/skyfolk/dash/views.py", line 1756, in public_dashboard
    raise HttpResponseForbidden("No tienes permiso para visitar este workspace.")
TypeError: exceptions must derive from BaseException
