2018-01-26 13:18:27,240 ERROR exception 15607 Internal Server Error: /dashboard/entry/edit/4/
Traceback (most recent call last):
  File "/home/adrian/skyfolk/venv/lib/python3.6/site-packages/django/core/handlers/exception.py", line 41, in inner
    response = get_response(request)
  File "/home/adrian/skyfolk/venv/lib/python3.6/site-packages/django/core/handlers/base.py", line 249, in _legacy_get_response
    response = self._get_response(request)
  File "/home/adrian/skyfolk/venv/lib/python3.6/site-packages/django/core/handlers/base.py", line 217, in _get_response
    response = self.process_exception_by_middleware(e, request)
  File "/home/adrian/skyfolk/venv/lib/python3.6/site-packages/channels/handler.py", line 243, in process_exception_by_middleware
    return super(AsgiHandler, self).process_exception_by_middleware(exception, request)
  File "/home/adrian/skyfolk/venv/lib/python3.6/site-packages/django/core/handlers/base.py", line 215, in _get_response
    response = response.render()
  File "/home/adrian/skyfolk/venv/lib/python3.6/site-packages/django/template/response.py", line 107, in render
    self.content = self.rendered_content
  File "/home/adrian/skyfolk/venv/lib/python3.6/site-packages/django/template/response.py", line 84, in rendered_content
    content = template.render(context, self._request)
  File "/home/adrian/skyfolk/venv/lib/python3.6/site-packages/django/template/backends/django.py", line 66, in render
    return self.template.render(context)
  File "/home/adrian/skyfolk/venv/lib/python3.6/site-packages/django/template/base.py", line 207, in render
    return self._render(context)
  File "/home/adrian/skyfolk/venv/lib/python3.6/site-packages/django/test/utils.py", line 107, in instrumented_test_render
    return self.nodelist.render(context)
  File "/home/adrian/skyfolk/venv/lib/python3.6/site-packages/django/template/base.py", line 990, in render
    bit = node.render_annotated(context)
  File "/home/adrian/skyfolk/venv/lib/python3.6/site-packages/django/template/base.py", line 957, in render_annotated
    return self.render(context)
  File "/home/adrian/skyfolk/venv/lib/python3.6/site-packages/django/template/loader_tags.py", line 154, in render
    compiled_parent = self.get_parent(context)
  File "/home/adrian/skyfolk/venv/lib/python3.6/site-packages/django/template/loader_tags.py", line 144, in get_parent
    raise TemplateSyntaxError(error_msg)
django.template.exceptions.TemplateSyntaxError: Invalid template name in 'extends' tag: ''. Got this from the 'layout.get_edit_template_name' variable.
2018-01-26 13:19:42,239 ERROR exception 16007 Internal Server Error: /dashboard/entry/edit/4/
Traceback (most recent call last):
  File "/home/adrian/skyfolk/venv/lib/python3.6/site-packages/django/core/handlers/exception.py", line 41, in inner
    response = get_response(request)
  File "/home/adrian/skyfolk/venv/lib/python3.6/site-packages/django/core/handlers/base.py", line 249, in _legacy_get_response
    response = self._get_response(request)
  File "/home/adrian/skyfolk/venv/lib/python3.6/site-packages/django/core/handlers/base.py", line 217, in _get_response
    response = self.process_exception_by_middleware(e, request)
  File "/home/adrian/skyfolk/venv/lib/python3.6/site-packages/channels/handler.py", line 243, in process_exception_by_middleware
    return super(AsgiHandler, self).process_exception_by_middleware(exception, request)
  File "/home/adrian/skyfolk/venv/lib/python3.6/site-packages/django/core/handlers/base.py", line 215, in _get_response
    response = response.render()
  File "/home/adrian/skyfolk/venv/lib/python3.6/site-packages/django/template/response.py", line 107, in render
    self.content = self.rendered_content
  File "/home/adrian/skyfolk/venv/lib/python3.6/site-packages/django/template/response.py", line 84, in rendered_content
    content = template.render(context, self._request)
  File "/home/adrian/skyfolk/venv/lib/python3.6/site-packages/django/template/backends/django.py", line 66, in render
    return self.template.render(context)
  File "/home/adrian/skyfolk/venv/lib/python3.6/site-packages/django/template/base.py", line 207, in render
    return self._render(context)
  File "/home/adrian/skyfolk/venv/lib/python3.6/site-packages/django/test/utils.py", line 107, in instrumented_test_render
    return self.nodelist.render(context)
  File "/home/adrian/skyfolk/venv/lib/python3.6/site-packages/django/template/base.py", line 990, in render
    bit = node.render_annotated(context)
  File "/home/adrian/skyfolk/venv/lib/python3.6/site-packages/django/template/base.py", line 957, in render_annotated
    return self.render(context)
  File "/home/adrian/skyfolk/venv/lib/python3.6/site-packages/django/template/loader_tags.py", line 154, in render
    compiled_parent = self.get_parent(context)
  File "/home/adrian/skyfolk/venv/lib/python3.6/site-packages/django/template/loader_tags.py", line 144, in get_parent
    raise TemplateSyntaxError(error_msg)
django.template.exceptions.TemplateSyntaxError: Invalid template name in 'extends' tag: ''. Got this from the 'layout.get_edit_template_name' variable.
2018-01-26 13:21:00,624 ERROR exception 16557 Internal Server Error: /dashboard/entry/edit/4/
Traceback (most recent call last):
  File "/home/adrian/skyfolk/venv/lib/python3.6/site-packages/django/core/handlers/exception.py", line 41, in inner
    response = get_response(request)
  File "/home/adrian/skyfolk/venv/lib/python3.6/site-packages/django/core/handlers/base.py", line 249, in _legacy_get_response
    response = self._get_response(request)
  File "/home/adrian/skyfolk/venv/lib/python3.6/site-packages/django/core/handlers/base.py", line 187, in _get_response
    response = self.process_exception_by_middleware(e, request)
  File "/home/adrian/skyfolk/venv/lib/python3.6/site-packages/channels/handler.py", line 243, in process_exception_by_middleware
    return super(AsgiHandler, self).process_exception_by_middleware(exception, request)
  File "/home/adrian/skyfolk/venv/lib/python3.6/site-packages/django/core/handlers/base.py", line 185, in _get_response
    response = wrapped_callback(request, *callback_args, **callback_kwargs)
  File "/home/adrian/skyfolk/venv/lib/python3.6/site-packages/django/views/generic/base.py", line 68, in view
    return self.dispatch(request, *args, **kwargs)
  File "/home/adrian/skyfolk/venv/lib/python3.6/site-packages/django/utils/decorators.py", line 67, in _wrapper
    return bound_func(*args, **kwargs)
  File "/home/adrian/skyfolk/venv/lib/python3.6/site-packages/django/contrib/auth/decorators.py", line 23, in _wrapped_view
    return view_func(request, *args, **kwargs)
  File "/home/adrian/skyfolk/venv/lib/python3.6/site-packages/django/utils/decorators.py", line 63, in bound_func
    return func.__get__(self, type(self))(*args2, **kwargs2)
  File "/home/adrian/skyfolk/dash/views.py", line 771, in dispatch
    return super(EditDashboardEntry, self).dispatch(request, *args, **kwargs)
  File "/home/adrian/skyfolk/venv/lib/python3.6/site-packages/formtools/wizard/views.py", line 248, in dispatch
    response = super(WizardView, self).dispatch(request, *args, **kwargs)
  File "/home/adrian/skyfolk/venv/lib/python3.6/site-packages/django/views/generic/base.py", line 88, in dispatch
    return handler(request, *args, **kwargs)
  File "/home/adrian/skyfolk/venv/lib/python3.6/site-packages/formtools/wizard/views.py", line 266, in get
    return self.render(self.get_form())
  File "/home/adrian/skyfolk/venv/lib/python3.6/site-packages/formtools/wizard/views.py", line 585, in render
    context = self.get_context_data(form=form, **kwargs)
  File "/home/adrian/skyfolk/dash/views.py", line 811, in get_context_data
    {'edit_dashboard_entry_ajax_template_name': template_name_ajax}
UnboundLocalError: local variable 'template_name_ajax' referenced before assignment
2018-01-26 13:21:49,226 ERROR exception 16838 Internal Server Error: /dashboard/entry/edit/4/
Traceback (most recent call last):
  File "/home/adrian/skyfolk/venv/lib/python3.6/site-packages/django/core/handlers/exception.py", line 41, in inner
    response = get_response(request)
  File "/home/adrian/skyfolk/venv/lib/python3.6/site-packages/django/core/handlers/base.py", line 249, in _legacy_get_response
    response = self._get_response(request)
  File "/home/adrian/skyfolk/venv/lib/python3.6/site-packages/django/core/handlers/base.py", line 217, in _get_response
    response = self.process_exception_by_middleware(e, request)
  File "/home/adrian/skyfolk/venv/lib/python3.6/site-packages/channels/handler.py", line 243, in process_exception_by_middleware
    return super(AsgiHandler, self).process_exception_by_middleware(exception, request)
  File "/home/adrian/skyfolk/venv/lib/python3.6/site-packages/django/core/handlers/base.py", line 215, in _get_response
    response = response.render()
  File "/home/adrian/skyfolk/venv/lib/python3.6/site-packages/django/template/response.py", line 107, in render
    self.content = self.rendered_content
  File "/home/adrian/skyfolk/venv/lib/python3.6/site-packages/django/template/response.py", line 84, in rendered_content
    content = template.render(context, self._request)
  File "/home/adrian/skyfolk/venv/lib/python3.6/site-packages/django/template/backends/django.py", line 66, in render
    return self.template.render(context)
  File "/home/adrian/skyfolk/venv/lib/python3.6/site-packages/django/template/base.py", line 207, in render
    return self._render(context)
  File "/home/adrian/skyfolk/venv/lib/python3.6/site-packages/django/test/utils.py", line 107, in instrumented_test_render
    return self.nodelist.render(context)
  File "/home/adrian/skyfolk/venv/lib/python3.6/site-packages/django/template/base.py", line 990, in render
    bit = node.render_annotated(context)
  File "/home/adrian/skyfolk/venv/lib/python3.6/site-packages/django/template/base.py", line 957, in render_annotated
    return self.render(context)
  File "/home/adrian/skyfolk/venv/lib/python3.6/site-packages/django/template/loader_tags.py", line 154, in render
    compiled_parent = self.get_parent(context)
  File "/home/adrian/skyfolk/venv/lib/python3.6/site-packages/django/template/loader_tags.py", line 144, in get_parent
    raise TemplateSyntaxError(error_msg)
django.template.exceptions.TemplateSyntaxError: Invalid template name in 'extends' tag: ''. Got this from the 'layout.get_edit_template_name' variable.
2018-01-26 13:22:31,680 ERROR exception 16838 Internal Server Error: /dashboard/entry/edit/4/
Traceback (most recent call last):
  File "/home/adrian/skyfolk/venv/lib/python3.6/site-packages/django/core/handlers/exception.py", line 41, in inner
    response = get_response(request)
  File "/home/adrian/skyfolk/venv/lib/python3.6/site-packages/django/core/handlers/base.py", line 249, in _legacy_get_response
    response = self._get_response(request)
  File "/home/adrian/skyfolk/venv/lib/python3.6/site-packages/django/core/handlers/base.py", line 217, in _get_response
    response = self.process_exception_by_middleware(e, request)
  File "/home/adrian/skyfolk/venv/lib/python3.6/site-packages/channels/handler.py", line 243, in process_exception_by_middleware
    return super(AsgiHandler, self).process_exception_by_middleware(exception, request)
  File "/home/adrian/skyfolk/venv/lib/python3.6/site-packages/django/core/handlers/base.py", line 215, in _get_response
    response = response.render()
  File "/home/adrian/skyfolk/venv/lib/python3.6/site-packages/django/template/response.py", line 107, in render
    self.content = self.rendered_content
  File "/home/adrian/skyfolk/venv/lib/python3.6/site-packages/django/template/response.py", line 84, in rendered_content
    content = template.render(context, self._request)
  File "/home/adrian/skyfolk/venv/lib/python3.6/site-packages/django/template/backends/django.py", line 66, in render
    return self.template.render(context)
  File "/home/adrian/skyfolk/venv/lib/python3.6/site-packages/django/template/base.py", line 207, in render
    return self._render(context)
  File "/home/adrian/skyfolk/venv/lib/python3.6/site-packages/django/test/utils.py", line 107, in instrumented_test_render
    return self.nodelist.render(context)
  File "/home/adrian/skyfolk/venv/lib/python3.6/site-packages/django/template/base.py", line 990, in render
    bit = node.render_annotated(context)
  File "/home/adrian/skyfolk/venv/lib/python3.6/site-packages/django/template/base.py", line 957, in render_annotated
    return self.render(context)
  File "/home/adrian/skyfolk/venv/lib/python3.6/site-packages/django/template/loader_tags.py", line 154, in render
    compiled_parent = self.get_parent(context)
  File "/home/adrian/skyfolk/venv/lib/python3.6/site-packages/django/template/loader_tags.py", line 144, in get_parent
    raise TemplateSyntaxError(error_msg)
django.template.exceptions.TemplateSyntaxError: Invalid template name in 'extends' tag: ''. Got this from the 'layout.get_edit_template_name' variable.
2018-01-26 13:25:06,122 ERROR exception 17414 Internal Server Error: /dashboard/entry/edit/4/
Traceback (most recent call last):
  File "/home/adrian/skyfolk/venv/lib/python3.6/site-packages/django/core/handlers/exception.py", line 41, in inner
    response = get_response(request)
  File "/home/adrian/skyfolk/venv/lib/python3.6/site-packages/django/core/handlers/base.py", line 249, in _legacy_get_response
    response = self._get_response(request)
  File "/home/adrian/skyfolk/venv/lib/python3.6/site-packages/django/core/handlers/base.py", line 217, in _get_response
    response = self.process_exception_by_middleware(e, request)
  File "/home/adrian/skyfolk/venv/lib/python3.6/site-packages/channels/handler.py", line 243, in process_exception_by_middleware
    return super(AsgiHandler, self).process_exception_by_middleware(exception, request)
  File "/home/adrian/skyfolk/venv/lib/python3.6/site-packages/django/core/handlers/base.py", line 215, in _get_response
    response = response.render()
  File "/home/adrian/skyfolk/venv/lib/python3.6/site-packages/django/template/response.py", line 107, in render
    self.content = self.rendered_content
  File "/home/adrian/skyfolk/venv/lib/python3.6/site-packages/django/template/response.py", line 84, in rendered_content
    content = template.render(context, self._request)
  File "/home/adrian/skyfolk/venv/lib/python3.6/site-packages/django/template/backends/django.py", line 66, in render
    return self.template.render(context)
  File "/home/adrian/skyfolk/venv/lib/python3.6/site-packages/django/template/base.py", line 207, in render
    return self._render(context)
  File "/home/adrian/skyfolk/venv/lib/python3.6/site-packages/django/test/utils.py", line 107, in instrumented_test_render
    return self.nodelist.render(context)
  File "/home/adrian/skyfolk/venv/lib/python3.6/site-packages/django/template/base.py", line 990, in render
    bit = node.render_annotated(context)
  File "/home/adrian/skyfolk/venv/lib/python3.6/site-packages/django/template/base.py", line 957, in render_annotated
    return self.render(context)
  File "/home/adrian/skyfolk/venv/lib/python3.6/site-packages/django/template/loader_tags.py", line 154, in render
    compiled_parent = self.get_parent(context)
  File "/home/adrian/skyfolk/venv/lib/python3.6/site-packages/django/template/loader_tags.py", line 144, in get_parent
    raise TemplateSyntaxError(error_msg)
django.template.exceptions.TemplateSyntaxError: Invalid template name in 'extends' tag: ''. Got this from the 'layout.get_edit_template_name' variable.
2018-01-26 13:25:49,283 ERROR exception 17414 Internal Server Error: /dashboard/entry/edit/4/
Traceback (most recent call last):
  File "/home/adrian/skyfolk/venv/lib/python3.6/site-packages/django/core/handlers/exception.py", line 41, in inner
    response = get_response(request)
  File "/home/adrian/skyfolk/venv/lib/python3.6/site-packages/django/core/handlers/base.py", line 249, in _legacy_get_response
    response = self._get_response(request)
  File "/home/adrian/skyfolk/venv/lib/python3.6/site-packages/django/core/handlers/base.py", line 217, in _get_response
    response = self.process_exception_by_middleware(e, request)
  File "/home/adrian/skyfolk/venv/lib/python3.6/site-packages/channels/handler.py", line 243, in process_exception_by_middleware
    return super(AsgiHandler, self).process_exception_by_middleware(exception, request)
  File "/home/adrian/skyfolk/venv/lib/python3.6/site-packages/django/core/handlers/base.py", line 215, in _get_response
    response = response.render()
  File "/home/adrian/skyfolk/venv/lib/python3.6/site-packages/django/template/response.py", line 107, in render
    self.content = self.rendered_content
  File "/home/adrian/skyfolk/venv/lib/python3.6/site-packages/django/template/response.py", line 82, in rendered_content
    template = self.resolve_template(self.template_name)
  File "/home/adrian/skyfolk/venv/lib/python3.6/site-packages/django/template/response.py", line 66, in resolve_template
    return get_template(template, using=self.using)
  File "/home/adrian/skyfolk/venv/lib/python3.6/site-packages/django/template/loader.py", line 21, in get_template
    return engine.get_template(template_name)
  File "/home/adrian/skyfolk/venv/lib/python3.6/site-packages/django/template/backends/django.py", line 39, in get_template
    return Template(self.engine.get_template(template_name), self)
  File "/home/adrian/skyfolk/venv/lib/python3.6/site-packages/django/template/engine.py", line 162, in get_template
    template, origin = self.find_template(template_name)
  File "/home/adrian/skyfolk/venv/lib/python3.6/site-packages/django/template/engine.py", line 136, in find_template
    name, template_dirs=dirs, skip=skip,
  File "/home/adrian/skyfolk/venv/lib/python3.6/site-packages/django/template/loaders/base.py", line 44, in get_template
    contents, origin, origin.template_name, self.engine,
  File "/home/adrian/skyfolk/venv/lib/python3.6/site-packages/django/template/base.py", line 191, in __init__
    self.nodelist = self.compile_nodelist()
  File "/home/adrian/skyfolk/venv/lib/python3.6/site-packages/django/template/base.py", line 230, in compile_nodelist
    return parser.parse()
  File "/home/adrian/skyfolk/venv/lib/python3.6/site-packages/django/template/base.py", line 486, in parse
    raise self.error(token, e)
  File "/home/adrian/skyfolk/venv/lib/python3.6/site-packages/django/template/base.py", line 484, in parse
    filter_expression = self.compile_filter(token.contents)
  File "/home/adrian/skyfolk/venv/lib/python3.6/site-packages/django/template/base.py", line 600, in compile_filter
    return FilterExpression(token, self)
  File "/home/adrian/skyfolk/venv/lib/python3.6/site-packages/django/template/base.py", line 700, in __init__
    "from '%s'" % (token[upto:], token))
django.template.exceptions.TemplateSyntaxError: Could not parse the remainder: ' layout.get_edit_template_name' from 'extends layout.get_edit_template_name'
2018-01-26 13:25:51,787 ERROR exception 17414 Internal Server Error: /dashboard/entry/edit/4/
Traceback (most recent call last):
  File "/home/adrian/skyfolk/venv/lib/python3.6/site-packages/django/core/handlers/exception.py", line 41, in inner
    response = get_response(request)
  File "/home/adrian/skyfolk/venv/lib/python3.6/site-packages/django/core/handlers/base.py", line 249, in _legacy_get_response
    response = self._get_response(request)
  File "/home/adrian/skyfolk/venv/lib/python3.6/site-packages/django/core/handlers/base.py", line 217, in _get_response
    response = self.process_exception_by_middleware(e, request)
  File "/home/adrian/skyfolk/venv/lib/python3.6/site-packages/channels/handler.py", line 243, in process_exception_by_middleware
    return super(AsgiHandler, self).process_exception_by_middleware(exception, request)
  File "/home/adrian/skyfolk/venv/lib/python3.6/site-packages/django/core/handlers/base.py", line 215, in _get_response
    response = response.render()
  File "/home/adrian/skyfolk/venv/lib/python3.6/site-packages/django/template/response.py", line 107, in render
    self.content = self.rendered_content
  File "/home/adrian/skyfolk/venv/lib/python3.6/site-packages/django/template/response.py", line 82, in rendered_content
    template = self.resolve_template(self.template_name)
  File "/home/adrian/skyfolk/venv/lib/python3.6/site-packages/django/template/response.py", line 66, in resolve_template
    return get_template(template, using=self.using)
  File "/home/adrian/skyfolk/venv/lib/python3.6/site-packages/django/template/loader.py", line 21, in get_template
    return engine.get_template(template_name)
  File "/home/adrian/skyfolk/venv/lib/python3.6/site-packages/django/template/backends/django.py", line 39, in get_template
    return Template(self.engine.get_template(template_name), self)
  File "/home/adrian/skyfolk/venv/lib/python3.6/site-packages/django/template/engine.py", line 162, in get_template
    template, origin = self.find_template(template_name)
  File "/home/adrian/skyfolk/venv/lib/python3.6/site-packages/django/template/engine.py", line 136, in find_template
    name, template_dirs=dirs, skip=skip,
  File "/home/adrian/skyfolk/venv/lib/python3.6/site-packages/django/template/loaders/base.py", line 44, in get_template
    contents, origin, origin.template_name, self.engine,
  File "/home/adrian/skyfolk/venv/lib/python3.6/site-packages/django/template/base.py", line 191, in __init__
    self.nodelist = self.compile_nodelist()
  File "/home/adrian/skyfolk/venv/lib/python3.6/site-packages/django/template/base.py", line 230, in compile_nodelist
    return parser.parse()
  File "/home/adrian/skyfolk/venv/lib/python3.6/site-packages/django/template/base.py", line 486, in parse
    raise self.error(token, e)
  File "/home/adrian/skyfolk/venv/lib/python3.6/site-packages/django/template/base.py", line 484, in parse
    filter_expression = self.compile_filter(token.contents)
  File "/home/adrian/skyfolk/venv/lib/python3.6/site-packages/django/template/base.py", line 600, in compile_filter
    return FilterExpression(token, self)
  File "/home/adrian/skyfolk/venv/lib/python3.6/site-packages/django/template/base.py", line 700, in __init__
    "from '%s'" % (token[upto:], token))
django.template.exceptions.TemplateSyntaxError: Could not parse the remainder: ' layout.get_edit_template_name' from 'extends layout.get_edit_template_name'
2018-01-26 13:27:05,816 ERROR exception 17414 Internal Server Error: /dashboard/entry/edit/4/
Traceback (most recent call last):
  File "/home/adrian/skyfolk/venv/lib/python3.6/site-packages/django/core/handlers/exception.py", line 41, in inner
    response = get_response(request)
  File "/home/adrian/skyfolk/venv/lib/python3.6/site-packages/django/core/handlers/base.py", line 249, in _legacy_get_response
    response = self._get_response(request)
  File "/home/adrian/skyfolk/venv/lib/python3.6/site-packages/django/core/handlers/base.py", line 217, in _get_response
    response = self.process_exception_by_middleware(e, request)
  File "/home/adrian/skyfolk/venv/lib/python3.6/site-packages/channels/handler.py", line 243, in process_exception_by_middleware
    return super(AsgiHandler, self).process_exception_by_middleware(exception, request)
  File "/home/adrian/skyfolk/venv/lib/python3.6/site-packages/django/core/handlers/base.py", line 215, in _get_response
    response = response.render()
  File "/home/adrian/skyfolk/venv/lib/python3.6/site-packages/django/template/response.py", line 107, in render
    self.content = self.rendered_content
  File "/home/adrian/skyfolk/venv/lib/python3.6/site-packages/django/template/response.py", line 84, in rendered_content
    content = template.render(context, self._request)
  File "/home/adrian/skyfolk/venv/lib/python3.6/site-packages/django/template/backends/django.py", line 66, in render
    return self.template.render(context)
  File "/home/adrian/skyfolk/venv/lib/python3.6/site-packages/django/template/base.py", line 207, in render
    return self._render(context)
  File "/home/adrian/skyfolk/venv/lib/python3.6/site-packages/django/test/utils.py", line 107, in instrumented_test_render
    return self.nodelist.render(context)
  File "/home/adrian/skyfolk/venv/lib/python3.6/site-packages/django/template/base.py", line 990, in render
    bit = node.render_annotated(context)
  File "/home/adrian/skyfolk/venv/lib/python3.6/site-packages/django/template/base.py", line 957, in render_annotated
    return self.render(context)
  File "/home/adrian/skyfolk/venv/lib/python3.6/site-packages/django/template/loader_tags.py", line 154, in render
    compiled_parent = self.get_parent(context)
  File "/home/adrian/skyfolk/venv/lib/python3.6/site-packages/django/template/loader_tags.py", line 144, in get_parent
    raise TemplateSyntaxError(error_msg)
django.template.exceptions.TemplateSyntaxError: Invalid template name in 'extends' tag: ''. Got this from the 'layout.get_edit_template_name' variable.
2018-01-26 13:48:27,296 ERROR exception 24114 Internal Server Error: /dashboard/entry/edit/11/
Traceback (most recent call last):
  File "/home/adrian/skyfolk/venv/lib/python3.6/site-packages/django/core/handlers/exception.py", line 41, in inner
    response = get_response(request)
  File "/home/adrian/skyfolk/venv/lib/python3.6/site-packages/django/core/handlers/base.py", line 249, in _legacy_get_response
    response = self._get_response(request)
  File "/home/adrian/skyfolk/venv/lib/python3.6/site-packages/django/core/handlers/base.py", line 187, in _get_response
    response = self.process_exception_by_middleware(e, request)
  File "/home/adrian/skyfolk/venv/lib/python3.6/site-packages/channels/handler.py", line 243, in process_exception_by_middleware
    return super(AsgiHandler, self).process_exception_by_middleware(exception, request)
  File "/home/adrian/skyfolk/venv/lib/python3.6/site-packages/django/core/handlers/base.py", line 185, in _get_response
    response = wrapped_callback(request, *callback_args, **callback_kwargs)
  File "/home/adrian/skyfolk/venv/lib/python3.6/site-packages/django/views/generic/base.py", line 68, in view
    return self.dispatch(request, *args, **kwargs)
  File "/home/adrian/skyfolk/venv/lib/python3.6/site-packages/django/utils/decorators.py", line 67, in _wrapper
    return bound_func(*args, **kwargs)
  File "/home/adrian/skyfolk/venv/lib/python3.6/site-packages/django/contrib/auth/decorators.py", line 23, in _wrapped_view
    return view_func(request, *args, **kwargs)
  File "/home/adrian/skyfolk/venv/lib/python3.6/site-packages/django/utils/decorators.py", line 63, in bound_func
    return func.__get__(self, type(self))(*args2, **kwargs2)
  File "/home/adrian/skyfolk/dash/views.py", line 698, in dispatch
    return super(EditDashboardEntry, self).dispatch(request, *args, **kwargs)
  File "/home/adrian/skyfolk/venv/lib/python3.6/site-packages/formtools/wizard/views.py", line 248, in dispatch
    response = super(WizardView, self).dispatch(request, *args, **kwargs)
  File "/home/adrian/skyfolk/venv/lib/python3.6/site-packages/django/views/generic/base.py", line 88, in dispatch
    return handler(request, *args, **kwargs)
  File "/home/adrian/skyfolk/venv/lib/python3.6/site-packages/formtools/wizard/views.py", line 309, in post
    return self.render_done(form, **kwargs)
  File "/home/adrian/skyfolk/venv/lib/python3.6/site-packages/formtools/wizard/views.py", line 365, in render_done
    done_response = self.done(final_forms.values(), form_dict=final_forms, **kwargs)
  File "/home/adrian/skyfolk/dash/views.py", line 808, in done
    TriggerService.objects.filter(pk=self.obj.plugin_data.get('trigger')).delete()
AttributeError: 'str' object has no attribute 'get'
2018-01-26 13:51:33,259 ERROR exception 25892 Internal Server Error: /dashboard/entry/edit/11/
Traceback (most recent call last):
  File "/home/adrian/skyfolk/venv/lib/python3.6/site-packages/django/core/handlers/exception.py", line 41, in inner
    response = get_response(request)
  File "/home/adrian/skyfolk/venv/lib/python3.6/site-packages/django/core/handlers/base.py", line 249, in _legacy_get_response
    response = self._get_response(request)
  File "/home/adrian/skyfolk/venv/lib/python3.6/site-packages/django/core/handlers/base.py", line 198, in _get_response
    "returned None instead." % (callback.__module__, view_name)
ValueError: The view dash.views.EditDashboardEntry didn't return an HttpResponse object. It returned None instead.
2018-01-26 13:54:00,855 INFO publish 26604 adrian - ServiceTwitter - ServiceRss - Twitter WTF - 0 new data
2018-01-26 13:54:01,147 INFO publish 26604 adrian - ServiceTwitter - ServiceRss - wtf - 0 new data
2018-01-26 14:05:05,686 ERROR exception 28276 Internal Server Error: /submit_photo/
Traceback (most recent call last):
  File "/home/adrian/skyfolk/venv/lib/python3.6/site-packages/django/db/backends/utils.py", line 65, in execute
    return self.cursor.execute(sql, params)
  File "/home/adrian/skyfolk/venv/lib/python3.6/site-packages/django/db/backends/sqlite3/base.py", line 328, in execute
    return Database.Cursor.execute(self, query, params)
sqlite3.OperationalError: database is locked

The above exception was the direct cause of the following exception:

Traceback (most recent call last):
  File "/home/adrian/skyfolk/venv/lib/python3.6/site-packages/django/core/handlers/exception.py", line 41, in inner
    response = get_response(request)
  File "/home/adrian/skyfolk/venv/lib/python3.6/site-packages/django/core/handlers/base.py", line 249, in _legacy_get_response
    response = self._get_response(request)
  File "/home/adrian/skyfolk/venv/lib/python3.6/site-packages/django/core/handlers/base.py", line 187, in _get_response
    response = self.process_exception_by_middleware(e, request)
  File "/home/adrian/skyfolk/venv/lib/python3.6/site-packages/channels/handler.py", line 243, in process_exception_by_middleware
    return super(AsgiHandler, self).process_exception_by_middleware(exception, request)
  File "/home/adrian/skyfolk/venv/lib/python3.6/site-packages/django/core/handlers/base.py", line 185, in _get_response
    response = wrapped_callback(request, *callback_args, **callback_kwargs)
  File "/home/adrian/skyfolk/venv/lib/python3.6/site-packages/django/views/decorators/http.py", line 40, in inner
    return func(request, *args, **kwargs)
  File "/home/adrian/skyfolk/venv/lib/python3.6/site-packages/django/contrib/auth/decorators.py", line 23, in _wrapped_view
    return view_func(request, *args, **kwargs)
  File "/home/adrian/skyfolk/photologue/views.py", line 179, in upload_photo
    obj.save()
  File "/home/adrian/skyfolk/photologue/models.py", line 504, in save
    super(Photo, self).save(*args, **kwargs)
  File "/home/adrian/skyfolk/photologue/models.py", line 430, in save
    super(ImageModel, self).save(*args, **kwargs)
  File "/home/adrian/skyfolk/venv/lib/python3.6/site-packages/django/db/models/base.py", line 808, in save
    force_update=force_update, update_fields=update_fields)
  File "/home/adrian/skyfolk/venv/lib/python3.6/site-packages/django/db/models/base.py", line 838, in save_base
    updated = self._save_table(raw, cls, force_insert, force_update, using, update_fields)
  File "/home/adrian/skyfolk/venv/lib/python3.6/site-packages/django/db/models/base.py", line 924, in _save_table
    result = self._do_insert(cls._base_manager, using, fields, update_pk, raw)
  File "/home/adrian/skyfolk/venv/lib/python3.6/site-packages/django/db/models/base.py", line 963, in _do_insert
    using=using, raw=raw)
  File "/home/adrian/skyfolk/venv/lib/python3.6/site-packages/django/db/models/manager.py", line 85, in manager_method
    return getattr(self.get_queryset(), name)(*args, **kwargs)
  File "/home/adrian/skyfolk/venv/lib/python3.6/site-packages/django/db/models/query.py", line 1076, in _insert
    return query.get_compiler(using=using).execute_sql(return_id)
  File "/home/adrian/skyfolk/venv/lib/python3.6/site-packages/django/db/models/sql/compiler.py", line 1107, in execute_sql
    cursor.execute(sql, params)
  File "/home/adrian/skyfolk/venv/lib/python3.6/site-packages/django/db/backends/utils.py", line 80, in execute
    return super(CursorDebugWrapper, self).execute(sql, params)
  File "/home/adrian/skyfolk/venv/lib/python3.6/site-packages/django/db/backends/utils.py", line 65, in execute
    return self.cursor.execute(sql, params)
  File "/home/adrian/skyfolk/venv/lib/python3.6/site-packages/django/db/utils.py", line 94, in __exit__
    six.reraise(dj_exc_type, dj_exc_value, traceback)
  File "/home/adrian/skyfolk/venv/lib/python3.6/site-packages/django/utils/six.py", line 685, in reraise
    raise value.with_traceback(tb)
  File "/home/adrian/skyfolk/venv/lib/python3.6/site-packages/django/db/backends/utils.py", line 65, in execute
    return self.cursor.execute(sql, params)
  File "/home/adrian/skyfolk/venv/lib/python3.6/site-packages/django/db/backends/sqlite3/base.py", line 328, in execute
    return Database.Cursor.execute(self, query, params)
django.db.utils.OperationalError: database is locked
