2018-01-22 22:40:20,290 ERROR exception 23290 Internal Server Error: /th/
Traceback (most recent call last):
  File "/home/adrian/skyfolk/venv/lib/python3.5/site-packages/django/db/backends/utils.py", line 65, in execute
    return self.cursor.execute(sql, params)
  File "/home/adrian/skyfolk/venv/lib/python3.5/site-packages/django/db/backends/sqlite3/base.py", line 328, in execute
    return Database.Cursor.execute(self, query, params)
sqlite3.OperationalError: no such table: skyfolk_triggerservice

The above exception was the direct cause of the following exception:

Traceback (most recent call last):
  File "/home/adrian/skyfolk/venv/lib/python3.5/site-packages/django/core/handlers/exception.py", line 41, in inner
    response = get_response(request)
  File "/home/adrian/skyfolk/venv/lib/python3.5/site-packages/django/core/handlers/base.py", line 249, in _legacy_get_response
    response = self._get_response(request)
  File "/home/adrian/skyfolk/venv/lib/python3.5/site-packages/django/core/handlers/base.py", line 187, in _get_response
    response = self.process_exception_by_middleware(e, request)
  File "/home/adrian/skyfolk/venv/lib/python3.5/site-packages/channels/handler.py", line 243, in process_exception_by_middleware
    return super(AsgiHandler, self).process_exception_by_middleware(exception, request)
  File "/home/adrian/skyfolk/venv/lib/python3.5/site-packages/django/core/handlers/base.py", line 185, in _get_response
    response = wrapped_callback(request, *callback_args, **callback_kwargs)
  File "/home/adrian/skyfolk/venv/lib/python3.5/site-packages/django/views/generic/base.py", line 68, in view
    return self.dispatch(request, *args, **kwargs)
  File "/home/adrian/skyfolk/venv/lib/python3.5/site-packages/django/views/generic/base.py", line 88, in dispatch
    return handler(request, *args, **kwargs)
  File "/home/adrian/skyfolk/venv/lib/python3.5/site-packages/django/views/generic/list.py", line 175, in get
    context = self.get_context_data()
  File "/home/adrian/skyfolk/skyfolk/views.py", line 95, in get_context_data
    context = super(TriggerListView, self).get_context_data(**kwargs)
  File "/home/adrian/skyfolk/venv/lib/python3.5/site-packages/django/views/generic/list.py", line 135, in get_context_data
    paginator, page, queryset, is_paginated = self.paginate_queryset(queryset, page_size)
  File "/home/adrian/skyfolk/venv/lib/python3.5/site-packages/django/views/generic/list.py", line 79, in paginate_queryset
    page = paginator.page(page_number)
  File "/home/adrian/skyfolk/venv/lib/python3.5/site-packages/django/core/paginator.py", line 57, in page
    number = self.validate_number(number)
  File "/home/adrian/skyfolk/venv/lib/python3.5/site-packages/django/core/paginator.py", line 46, in validate_number
    if number > self.num_pages:
  File "/home/adrian/skyfolk/venv/lib/python3.5/site-packages/django/utils/functional.py", line 35, in __get__
    res = instance.__dict__[self.name] = self.func(instance)
  File "/home/adrian/skyfolk/venv/lib/python3.5/site-packages/django/core/paginator.py", line 91, in num_pages
    if self.count == 0 and not self.allow_empty_first_page:
  File "/home/adrian/skyfolk/venv/lib/python3.5/site-packages/django/utils/functional.py", line 35, in __get__
    res = instance.__dict__[self.name] = self.func(instance)
  File "/home/adrian/skyfolk/venv/lib/python3.5/site-packages/django/core/paginator.py", line 79, in count
    return self.object_list.count()
  File "/home/adrian/skyfolk/venv/lib/python3.5/site-packages/django/db/models/query.py", line 364, in count
    return self.query.get_count(using=self.db)
  File "/home/adrian/skyfolk/venv/lib/python3.5/site-packages/django/db/models/sql/query.py", line 499, in get_count
    number = obj.get_aggregation(using, ['__count'])['__count']
  File "/home/adrian/skyfolk/venv/lib/python3.5/site-packages/django/db/models/sql/query.py", line 480, in get_aggregation
    result = compiler.execute_sql(SINGLE)
  File "/home/adrian/skyfolk/venv/lib/python3.5/site-packages/django/db/models/sql/compiler.py", line 894, in execute_sql
    raise original_exception
  File "/home/adrian/skyfolk/venv/lib/python3.5/site-packages/django/db/models/sql/compiler.py", line 884, in execute_sql
    cursor.execute(sql, params)
  File "/home/adrian/skyfolk/venv/lib/python3.5/site-packages/debug_toolbar/panels/sql/tracking.py", line 164, in execute
    return self._record(self.cursor.execute, sql, params)
  File "/home/adrian/skyfolk/venv/lib/python3.5/site-packages/debug_toolbar/panels/sql/tracking.py", line 106, in _record
    return method(sql, params)
  File "/home/adrian/skyfolk/venv/lib/python3.5/site-packages/django/db/backends/utils.py", line 80, in execute
    return super(CursorDebugWrapper, self).execute(sql, params)
  File "/home/adrian/skyfolk/venv/lib/python3.5/site-packages/django/db/backends/utils.py", line 65, in execute
    return self.cursor.execute(sql, params)
  File "/home/adrian/skyfolk/venv/lib/python3.5/site-packages/django/db/utils.py", line 94, in __exit__
    six.reraise(dj_exc_type, dj_exc_value, traceback)
  File "/home/adrian/skyfolk/venv/lib/python3.5/site-packages/django/utils/six.py", line 685, in reraise
    raise value.with_traceback(tb)
  File "/home/adrian/skyfolk/venv/lib/python3.5/site-packages/django/db/backends/utils.py", line 65, in execute
    return self.cursor.execute(sql, params)
  File "/home/adrian/skyfolk/venv/lib/python3.5/site-packages/django/db/backends/sqlite3/base.py", line 328, in execute
    return Database.Cursor.execute(self, query, params)
django.db.utils.OperationalError: no such table: skyfolk_triggerservice
2018-01-22 22:51:44,273 ERROR exception 25970 Internal Server Error: /th/
Traceback (most recent call last):
  File "/home/adrian/skyfolk/venv/lib/python3.5/site-packages/django/db/backends/utils.py", line 65, in execute
    return self.cursor.execute(sql, params)
  File "/home/adrian/skyfolk/venv/lib/python3.5/site-packages/django/db/backends/sqlite3/base.py", line 328, in execute
    return Database.Cursor.execute(self, query, params)
sqlite3.OperationalError: no such table: skyfolk_triggerservice

The above exception was the direct cause of the following exception:

Traceback (most recent call last):
  File "/home/adrian/skyfolk/venv/lib/python3.5/site-packages/django/core/handlers/exception.py", line 41, in inner
    response = get_response(request)
  File "/home/adrian/skyfolk/venv/lib/python3.5/site-packages/django/core/handlers/base.py", line 249, in _legacy_get_response
    response = self._get_response(request)
  File "/home/adrian/skyfolk/venv/lib/python3.5/site-packages/django/core/handlers/base.py", line 187, in _get_response
    response = self.process_exception_by_middleware(e, request)
  File "/home/adrian/skyfolk/venv/lib/python3.5/site-packages/channels/handler.py", line 243, in process_exception_by_middleware
    return super(AsgiHandler, self).process_exception_by_middleware(exception, request)
  File "/home/adrian/skyfolk/venv/lib/python3.5/site-packages/django/core/handlers/base.py", line 185, in _get_response
    response = wrapped_callback(request, *callback_args, **callback_kwargs)
  File "/home/adrian/skyfolk/venv/lib/python3.5/site-packages/django/views/generic/base.py", line 68, in view
    return self.dispatch(request, *args, **kwargs)
  File "/home/adrian/skyfolk/venv/lib/python3.5/site-packages/django/views/generic/base.py", line 88, in dispatch
    return handler(request, *args, **kwargs)
  File "/home/adrian/skyfolk/venv/lib/python3.5/site-packages/django/views/generic/list.py", line 175, in get
    context = self.get_context_data()
  File "/home/adrian/skyfolk/skyfolk/views.py", line 95, in get_context_data
    context = super(TriggerListView, self).get_context_data(**kwargs)
  File "/home/adrian/skyfolk/venv/lib/python3.5/site-packages/django/views/generic/list.py", line 135, in get_context_data
    paginator, page, queryset, is_paginated = self.paginate_queryset(queryset, page_size)
  File "/home/adrian/skyfolk/venv/lib/python3.5/site-packages/django/views/generic/list.py", line 79, in paginate_queryset
    page = paginator.page(page_number)
  File "/home/adrian/skyfolk/venv/lib/python3.5/site-packages/django/core/paginator.py", line 57, in page
    number = self.validate_number(number)
  File "/home/adrian/skyfolk/venv/lib/python3.5/site-packages/django/core/paginator.py", line 46, in validate_number
    if number > self.num_pages:
  File "/home/adrian/skyfolk/venv/lib/python3.5/site-packages/django/utils/functional.py", line 35, in __get__
    res = instance.__dict__[self.name] = self.func(instance)
  File "/home/adrian/skyfolk/venv/lib/python3.5/site-packages/django/core/paginator.py", line 91, in num_pages
    if self.count == 0 and not self.allow_empty_first_page:
  File "/home/adrian/skyfolk/venv/lib/python3.5/site-packages/django/utils/functional.py", line 35, in __get__
    res = instance.__dict__[self.name] = self.func(instance)
  File "/home/adrian/skyfolk/venv/lib/python3.5/site-packages/django/core/paginator.py", line 79, in count
    return self.object_list.count()
  File "/home/adrian/skyfolk/venv/lib/python3.5/site-packages/django/db/models/query.py", line 364, in count
    return self.query.get_count(using=self.db)
  File "/home/adrian/skyfolk/venv/lib/python3.5/site-packages/django/db/models/sql/query.py", line 499, in get_count
    number = obj.get_aggregation(using, ['__count'])['__count']
  File "/home/adrian/skyfolk/venv/lib/python3.5/site-packages/django/db/models/sql/query.py", line 480, in get_aggregation
    result = compiler.execute_sql(SINGLE)
  File "/home/adrian/skyfolk/venv/lib/python3.5/site-packages/django/db/models/sql/compiler.py", line 894, in execute_sql
    raise original_exception
  File "/home/adrian/skyfolk/venv/lib/python3.5/site-packages/django/db/models/sql/compiler.py", line 884, in execute_sql
    cursor.execute(sql, params)
  File "/home/adrian/skyfolk/venv/lib/python3.5/site-packages/debug_toolbar/panels/sql/tracking.py", line 164, in execute
    return self._record(self.cursor.execute, sql, params)
  File "/home/adrian/skyfolk/venv/lib/python3.5/site-packages/debug_toolbar/panels/sql/tracking.py", line 106, in _record
    return method(sql, params)
  File "/home/adrian/skyfolk/venv/lib/python3.5/site-packages/django/db/backends/utils.py", line 80, in execute
    return super(CursorDebugWrapper, self).execute(sql, params)
  File "/home/adrian/skyfolk/venv/lib/python3.5/site-packages/django/db/backends/utils.py", line 65, in execute
    return self.cursor.execute(sql, params)
  File "/home/adrian/skyfolk/venv/lib/python3.5/site-packages/django/db/utils.py", line 94, in __exit__
    six.reraise(dj_exc_type, dj_exc_value, traceback)
  File "/home/adrian/skyfolk/venv/lib/python3.5/site-packages/django/utils/six.py", line 685, in reraise
    raise value.with_traceback(tb)
  File "/home/adrian/skyfolk/venv/lib/python3.5/site-packages/django/db/backends/utils.py", line 65, in execute
    return self.cursor.execute(sql, params)
  File "/home/adrian/skyfolk/venv/lib/python3.5/site-packages/django/db/backends/sqlite3/base.py", line 328, in execute
    return Database.Cursor.execute(self, query, params)
django.db.utils.OperationalError: no such table: skyfolk_triggerservice
2018-01-22 22:51:46,692 ERROR exception 25970 Internal Server Error: /th/
Traceback (most recent call last):
  File "/home/adrian/skyfolk/venv/lib/python3.5/site-packages/django/db/backends/utils.py", line 65, in execute
    return self.cursor.execute(sql, params)
  File "/home/adrian/skyfolk/venv/lib/python3.5/site-packages/django/db/backends/sqlite3/base.py", line 328, in execute
    return Database.Cursor.execute(self, query, params)
sqlite3.OperationalError: no such table: skyfolk_triggerservice

The above exception was the direct cause of the following exception:

Traceback (most recent call last):
  File "/home/adrian/skyfolk/venv/lib/python3.5/site-packages/django/core/handlers/exception.py", line 41, in inner
    response = get_response(request)
  File "/home/adrian/skyfolk/venv/lib/python3.5/site-packages/django/core/handlers/base.py", line 249, in _legacy_get_response
    response = self._get_response(request)
  File "/home/adrian/skyfolk/venv/lib/python3.5/site-packages/django/core/handlers/base.py", line 187, in _get_response
    response = self.process_exception_by_middleware(e, request)
  File "/home/adrian/skyfolk/venv/lib/python3.5/site-packages/channels/handler.py", line 243, in process_exception_by_middleware
    return super(AsgiHandler, self).process_exception_by_middleware(exception, request)
  File "/home/adrian/skyfolk/venv/lib/python3.5/site-packages/django/core/handlers/base.py", line 185, in _get_response
    response = wrapped_callback(request, *callback_args, **callback_kwargs)
  File "/home/adrian/skyfolk/venv/lib/python3.5/site-packages/django/views/generic/base.py", line 68, in view
    return self.dispatch(request, *args, **kwargs)
  File "/home/adrian/skyfolk/venv/lib/python3.5/site-packages/django/views/generic/base.py", line 88, in dispatch
    return handler(request, *args, **kwargs)
  File "/home/adrian/skyfolk/venv/lib/python3.5/site-packages/django/views/generic/list.py", line 175, in get
    context = self.get_context_data()
  File "/home/adrian/skyfolk/skyfolk/views.py", line 95, in get_context_data
    context = super(TriggerListView, self).get_context_data(**kwargs)
  File "/home/adrian/skyfolk/venv/lib/python3.5/site-packages/django/views/generic/list.py", line 135, in get_context_data
    paginator, page, queryset, is_paginated = self.paginate_queryset(queryset, page_size)
  File "/home/adrian/skyfolk/venv/lib/python3.5/site-packages/django/views/generic/list.py", line 79, in paginate_queryset
    page = paginator.page(page_number)
  File "/home/adrian/skyfolk/venv/lib/python3.5/site-packages/django/core/paginator.py", line 57, in page
    number = self.validate_number(number)
  File "/home/adrian/skyfolk/venv/lib/python3.5/site-packages/django/core/paginator.py", line 46, in validate_number
    if number > self.num_pages:
  File "/home/adrian/skyfolk/venv/lib/python3.5/site-packages/django/utils/functional.py", line 35, in __get__
    res = instance.__dict__[self.name] = self.func(instance)
  File "/home/adrian/skyfolk/venv/lib/python3.5/site-packages/django/core/paginator.py", line 91, in num_pages
    if self.count == 0 and not self.allow_empty_first_page:
  File "/home/adrian/skyfolk/venv/lib/python3.5/site-packages/django/utils/functional.py", line 35, in __get__
    res = instance.__dict__[self.name] = self.func(instance)
  File "/home/adrian/skyfolk/venv/lib/python3.5/site-packages/django/core/paginator.py", line 79, in count
    return self.object_list.count()
  File "/home/adrian/skyfolk/venv/lib/python3.5/site-packages/django/db/models/query.py", line 364, in count
    return self.query.get_count(using=self.db)
  File "/home/adrian/skyfolk/venv/lib/python3.5/site-packages/django/db/models/sql/query.py", line 499, in get_count
    number = obj.get_aggregation(using, ['__count'])['__count']
  File "/home/adrian/skyfolk/venv/lib/python3.5/site-packages/django/db/models/sql/query.py", line 480, in get_aggregation
    result = compiler.execute_sql(SINGLE)
  File "/home/adrian/skyfolk/venv/lib/python3.5/site-packages/django/db/models/sql/compiler.py", line 894, in execute_sql
    raise original_exception
  File "/home/adrian/skyfolk/venv/lib/python3.5/site-packages/django/db/models/sql/compiler.py", line 884, in execute_sql
    cursor.execute(sql, params)
  File "/home/adrian/skyfolk/venv/lib/python3.5/site-packages/debug_toolbar/panels/sql/tracking.py", line 164, in execute
    return self._record(self.cursor.execute, sql, params)
  File "/home/adrian/skyfolk/venv/lib/python3.5/site-packages/debug_toolbar/panels/sql/tracking.py", line 106, in _record
    return method(sql, params)
  File "/home/adrian/skyfolk/venv/lib/python3.5/site-packages/django/db/backends/utils.py", line 80, in execute
    return super(CursorDebugWrapper, self).execute(sql, params)
  File "/home/adrian/skyfolk/venv/lib/python3.5/site-packages/django/db/backends/utils.py", line 65, in execute
    return self.cursor.execute(sql, params)
  File "/home/adrian/skyfolk/venv/lib/python3.5/site-packages/django/db/utils.py", line 94, in __exit__
    six.reraise(dj_exc_type, dj_exc_value, traceback)
  File "/home/adrian/skyfolk/venv/lib/python3.5/site-packages/django/utils/six.py", line 685, in reraise
    raise value.with_traceback(tb)
  File "/home/adrian/skyfolk/venv/lib/python3.5/site-packages/django/db/backends/utils.py", line 65, in execute
    return self.cursor.execute(sql, params)
  File "/home/adrian/skyfolk/venv/lib/python3.5/site-packages/django/db/backends/sqlite3/base.py", line 328, in execute
    return Database.Cursor.execute(self, query, params)
django.db.utils.OperationalError: no such table: skyfolk_triggerservice
2018-01-22 22:58:43,395 ERROR exception 27424 Internal Server Error: /th/service/add/ServiceTwitter
Traceback (most recent call last):
  File "/home/adrian/skyfolk/venv/lib/python3.5/site-packages/django/core/handlers/exception.py", line 41, in inner
    response = get_response(request)
  File "/home/adrian/skyfolk/venv/lib/python3.5/site-packages/django/core/handlers/base.py", line 249, in _legacy_get_response
    response = self._get_response(request)
  File "/home/adrian/skyfolk/venv/lib/python3.5/site-packages/django/core/handlers/base.py", line 187, in _get_response
    response = self.process_exception_by_middleware(e, request)
  File "/home/adrian/skyfolk/venv/lib/python3.5/site-packages/channels/handler.py", line 243, in process_exception_by_middleware
    return super(AsgiHandler, self).process_exception_by_middleware(exception, request)
  File "/home/adrian/skyfolk/venv/lib/python3.5/site-packages/django/core/handlers/base.py", line 185, in _get_response
    response = wrapped_callback(request, *callback_args, **callback_kwargs)
  File "/home/adrian/skyfolk/venv/lib/python3.5/site-packages/django/views/generic/base.py", line 68, in view
    return self.dispatch(request, *args, **kwargs)
  File "/home/adrian/skyfolk/venv/lib/python3.5/site-packages/django/utils/decorators.py", line 67, in _wrapper
    return bound_func(*args, **kwargs)
  File "/home/adrian/skyfolk/venv/lib/python3.5/site-packages/django/contrib/auth/decorators.py", line 23, in _wrapped_view
    return view_func(request, *args, **kwargs)
  File "/home/adrian/skyfolk/venv/lib/python3.5/site-packages/django/utils/decorators.py", line 63, in bound_func
    return func.__get__(self, type(self))(*args2, **kwargs2)
  File "/home/adrian/skyfolk/skyfolk/views_userservices.py", line 110, in dispatch
    return super(UserServiceCreateView, self).dispatch(*args, **kwargs)
  File "/home/adrian/skyfolk/venv/lib/python3.5/site-packages/django/views/generic/base.py", line 88, in dispatch
    return handler(request, *args, **kwargs)
  File "/home/adrian/skyfolk/venv/lib/python3.5/site-packages/django/views/generic/edit.py", line 217, in post
    return super(BaseCreateView, self).post(request, *args, **kwargs)
  File "/home/adrian/skyfolk/venv/lib/python3.5/site-packages/django/views/generic/edit.py", line 183, in post
    return self.form_valid(form)
  File "/home/adrian/skyfolk/skyfolk/views_userservices.py", line 122, in form_valid
    default_provider.load_services()
  File "/home/adrian/skyfolk/skyfolk/service_provider.py", line 15, in load_services
    klass = import_from_path(class_path)
  File "/home/adrian/skyfolk/skyfolk/service_provider.py", line 39, in import_from_path
    return getattr(__import__(module_name, fromlist=[class_name]), class_name)
  File "/home/adrian/skyfolk/th_trello/my_trello.py", line 7, in <module>
    from skyfolk.apps import DjangoThConfig
ImportError: cannot import name 'DjangoThConfig'
2018-01-22 23:00:29,143 ERROR exception 27424 Internal Server Error: /th/service/create/
Traceback (most recent call last):
  File "/home/adrian/skyfolk/venv/lib/python3.5/site-packages/django/db/backends/utils.py", line 65, in execute
    return self.cursor.execute(sql, params)
  File "/home/adrian/skyfolk/venv/lib/python3.5/site-packages/django/db/backends/sqlite3/base.py", line 328, in execute
    return Database.Cursor.execute(self, query, params)
sqlite3.OperationalError: no such table: skyfolk_rss

The above exception was the direct cause of the following exception:

Traceback (most recent call last):
  File "/home/adrian/skyfolk/venv/lib/python3.5/site-packages/django/core/handlers/exception.py", line 41, in inner
    response = get_response(request)
  File "/home/adrian/skyfolk/venv/lib/python3.5/site-packages/django/core/handlers/base.py", line 249, in _legacy_get_response
    response = self._get_response(request)
  File "/home/adrian/skyfolk/venv/lib/python3.5/site-packages/django/core/handlers/base.py", line 187, in _get_response
    response = self.process_exception_by_middleware(e, request)
  File "/home/adrian/skyfolk/venv/lib/python3.5/site-packages/channels/handler.py", line 243, in process_exception_by_middleware
    return super(AsgiHandler, self).process_exception_by_middleware(exception, request)
  File "/home/adrian/skyfolk/venv/lib/python3.5/site-packages/django/core/handlers/base.py", line 185, in _get_response
    response = wrapped_callback(request, *callback_args, **callback_kwargs)
  File "/home/adrian/skyfolk/venv/lib/python3.5/site-packages/django/views/generic/base.py", line 68, in view
    return self.dispatch(request, *args, **kwargs)
  File "/home/adrian/skyfolk/venv/lib/python3.5/site-packages/django/utils/decorators.py", line 67, in _wrapper
    return bound_func(*args, **kwargs)
  File "/home/adrian/skyfolk/venv/lib/python3.5/site-packages/django/contrib/auth/decorators.py", line 23, in _wrapped_view
    return view_func(request, *args, **kwargs)
  File "/home/adrian/skyfolk/venv/lib/python3.5/site-packages/django/utils/decorators.py", line 63, in bound_func
    return func.__get__(self, type(self))(*args2, **kwargs2)
  File "/home/adrian/skyfolk/venv/lib/python3.5/site-packages/formtools/wizard/views.py", line 248, in dispatch
    response = super(WizardView, self).dispatch(request, *args, **kwargs)
  File "/home/adrian/skyfolk/venv/lib/python3.5/site-packages/django/views/generic/base.py", line 88, in dispatch
    return handler(request, *args, **kwargs)
  File "/home/adrian/skyfolk/venv/lib/python3.5/site-packages/formtools/wizard/views.py", line 309, in post
    return self.render_done(form, **kwargs)
  File "/home/adrian/skyfolk/venv/lib/python3.5/site-packages/formtools/wizard/views.py", line 365, in render_done
    done_response = self.done(final_forms.values(), form_dict=final_forms, **kwargs)
  File "/home/adrian/skyfolk/skyfolk/views_wizard.py", line 139, in done
    model_consumer.objects.create(**model_fields)
  File "/home/adrian/skyfolk/venv/lib/python3.5/site-packages/django/db/models/manager.py", line 85, in manager_method
    return getattr(self.get_queryset(), name)(*args, **kwargs)
  File "/home/adrian/skyfolk/venv/lib/python3.5/site-packages/django/db/models/query.py", line 394, in create
    obj.save(force_insert=True, using=self.db)
  File "/home/adrian/skyfolk/venv/lib/python3.5/site-packages/django/db/models/base.py", line 808, in save
    force_update=force_update, update_fields=update_fields)
  File "/home/adrian/skyfolk/venv/lib/python3.5/site-packages/django/db/models/base.py", line 838, in save_base
    updated = self._save_table(raw, cls, force_insert, force_update, using, update_fields)
  File "/home/adrian/skyfolk/venv/lib/python3.5/site-packages/django/db/models/base.py", line 924, in _save_table
    result = self._do_insert(cls._base_manager, using, fields, update_pk, raw)
  File "/home/adrian/skyfolk/venv/lib/python3.5/site-packages/django/db/models/base.py", line 963, in _do_insert
    using=using, raw=raw)
  File "/home/adrian/skyfolk/venv/lib/python3.5/site-packages/django/db/models/manager.py", line 85, in manager_method
    return getattr(self.get_queryset(), name)(*args, **kwargs)
  File "/home/adrian/skyfolk/venv/lib/python3.5/site-packages/django/db/models/query.py", line 1076, in _insert
    return query.get_compiler(using=using).execute_sql(return_id)
  File "/home/adrian/skyfolk/venv/lib/python3.5/site-packages/django/db/models/sql/compiler.py", line 1107, in execute_sql
    cursor.execute(sql, params)
  File "/home/adrian/skyfolk/venv/lib/python3.5/site-packages/debug_toolbar/panels/sql/tracking.py", line 164, in execute
    return self._record(self.cursor.execute, sql, params)
  File "/home/adrian/skyfolk/venv/lib/python3.5/site-packages/debug_toolbar/panels/sql/tracking.py", line 106, in _record
    return method(sql, params)
  File "/home/adrian/skyfolk/venv/lib/python3.5/site-packages/django/db/backends/utils.py", line 80, in execute
    return super(CursorDebugWrapper, self).execute(sql, params)
  File "/home/adrian/skyfolk/venv/lib/python3.5/site-packages/django/db/backends/utils.py", line 65, in execute
    return self.cursor.execute(sql, params)
  File "/home/adrian/skyfolk/venv/lib/python3.5/site-packages/django/db/utils.py", line 94, in __exit__
    six.reraise(dj_exc_type, dj_exc_value, traceback)
  File "/home/adrian/skyfolk/venv/lib/python3.5/site-packages/django/utils/six.py", line 685, in reraise
    raise value.with_traceback(tb)
  File "/home/adrian/skyfolk/venv/lib/python3.5/site-packages/django/db/backends/utils.py", line 65, in execute
    return self.cursor.execute(sql, params)
  File "/home/adrian/skyfolk/venv/lib/python3.5/site-packages/django/db/backends/sqlite3/base.py", line 328, in execute
    return Database.Cursor.execute(self, query, params)
django.db.utils.OperationalError: no such table: skyfolk_rss
2018-01-22 23:05:28,774 INFO publish 28775 adrian - ServiceTwitter - ServiceRss - rss - 0 new data
2018-01-22 23:06:24,344 ERROR exception 28440 Internal Server Error: /th/myfeeds/92a8a49a-b226-4930-949f-a0229afb35da/
Traceback (most recent call last):
  File "/home/adrian/skyfolk/venv/lib/python3.5/site-packages/django/core/handlers/exception.py", line 41, in inner
    response = get_response(request)
  File "/home/adrian/skyfolk/venv/lib/python3.5/site-packages/django/core/handlers/base.py", line 249, in _legacy_get_response
    response = self._get_response(request)
  File "/home/adrian/skyfolk/venv/lib/python3.5/site-packages/django/core/handlers/base.py", line 187, in _get_response
    response = self.process_exception_by_middleware(e, request)
  File "/home/adrian/skyfolk/venv/lib/python3.5/site-packages/channels/handler.py", line 243, in process_exception_by_middleware
    return super(AsgiHandler, self).process_exception_by_middleware(exception, request)
  File "/home/adrian/skyfolk/venv/lib/python3.5/site-packages/django/core/handlers/base.py", line 185, in _get_response
    response = wrapped_callback(request, *callback_args, **callback_kwargs)
  File "/home/adrian/skyfolk/venv/lib/python3.5/site-packages/django/views/generic/base.py", line 68, in view
    return self.dispatch(request, *args, **kwargs)
  File "/home/adrian/skyfolk/venv/lib/python3.5/site-packages/django/views/generic/base.py", line 88, in dispatch
    return handler(request, *args, **kwargs)
  File "/home/adrian/skyfolk/venv/lib/python3.5/site-packages/django/views/generic/base.py", line 155, in get
    context = self.get_context_data(**kwargs)
  File "/home/adrian/skyfolk/th_rss/views.py", line 35, in get_context_data
    context['version'] = skyfolk.__version__
AttributeError: module 'skyfolk' has no attribute '__version__'
2018-01-22 23:18:14,348 INFO publish 32363 adrian - ServiceTwitter - ServiceRss - TWITTER => RSS - 0 new data
2018-01-22 23:21:18,457 ERROR exception 31757 Internal Server Error: /dashboard/edit/
Traceback (most recent call last):
  File "/home/adrian/skyfolk/venv/lib/python3.5/site-packages/django/template/defaulttags.py", line 1038, in find_library
    return parser.libraries[name]
KeyError: 'thumbnail'

During handling of the above exception, another exception occurred:

Traceback (most recent call last):
  File "/home/adrian/skyfolk/venv/lib/python3.5/site-packages/django/core/handlers/exception.py", line 41, in inner
    response = get_response(request)
  File "/home/adrian/skyfolk/venv/lib/python3.5/site-packages/django/core/handlers/base.py", line 249, in _legacy_get_response
    response = self._get_response(request)
  File "/home/adrian/skyfolk/venv/lib/python3.5/site-packages/django/core/handlers/base.py", line 187, in _get_response
    response = self.process_exception_by_middleware(e, request)
  File "/home/adrian/skyfolk/venv/lib/python3.5/site-packages/channels/handler.py", line 243, in process_exception_by_middleware
    return super(AsgiHandler, self).process_exception_by_middleware(exception, request)
  File "/home/adrian/skyfolk/venv/lib/python3.5/site-packages/django/core/handlers/base.py", line 185, in _get_response
    response = wrapped_callback(request, *callback_args, **callback_kwargs)
  File "/home/adrian/skyfolk/venv/lib/python3.5/site-packages/django/contrib/auth/decorators.py", line 23, in _wrapped_view
    return view_func(request, *args, **kwargs)
  File "/home/adrian/skyfolk/venv/lib/python3.5/site-packages/django/contrib/auth/decorators.py", line 23, in _wrapped_view
    return view_func(request, *args, **kwargs)
  File "/home/adrian/skyfolk/dash/views.py", line 251, in edit_dashboard
    return render(request, template_name, context)
  File "/home/adrian/skyfolk/venv/lib/python3.5/site-packages/django/shortcuts.py", line 30, in render
    content = loader.render_to_string(template_name, context, request, using=using)
  File "/home/adrian/skyfolk/venv/lib/python3.5/site-packages/django/template/loader.py", line 68, in render_to_string
    return template.render(context, request)
  File "/home/adrian/skyfolk/venv/lib/python3.5/site-packages/django/template/backends/django.py", line 66, in render
    return self.template.render(context)
  File "/home/adrian/skyfolk/venv/lib/python3.5/site-packages/django/template/base.py", line 207, in render
    return self._render(context)
  File "/home/adrian/skyfolk/venv/lib/python3.5/site-packages/django/test/utils.py", line 107, in instrumented_test_render
    return self.nodelist.render(context)
  File "/home/adrian/skyfolk/venv/lib/python3.5/site-packages/django/template/base.py", line 990, in render
    bit = node.render_annotated(context)
  File "/home/adrian/skyfolk/venv/lib/python3.5/site-packages/django/template/base.py", line 957, in render_annotated
    return self.render(context)
  File "/home/adrian/skyfolk/venv/lib/python3.5/site-packages/django/template/loader_tags.py", line 177, in render
    return compiled_parent._render(context)
  File "/home/adrian/skyfolk/venv/lib/python3.5/site-packages/django/test/utils.py", line 107, in instrumented_test_render
    return self.nodelist.render(context)
  File "/home/adrian/skyfolk/venv/lib/python3.5/site-packages/django/template/base.py", line 990, in render
    bit = node.render_annotated(context)
  File "/home/adrian/skyfolk/venv/lib/python3.5/site-packages/django/template/base.py", line 957, in render_annotated
    return self.render(context)
  File "/home/adrian/skyfolk/venv/lib/python3.5/site-packages/django/template/loader_tags.py", line 177, in render
    return compiled_parent._render(context)
  File "/home/adrian/skyfolk/venv/lib/python3.5/site-packages/django/test/utils.py", line 107, in instrumented_test_render
    return self.nodelist.render(context)
  File "/home/adrian/skyfolk/venv/lib/python3.5/site-packages/django/template/base.py", line 990, in render
    bit = node.render_annotated(context)
  File "/home/adrian/skyfolk/venv/lib/python3.5/site-packages/django/template/base.py", line 957, in render_annotated
    return self.render(context)
  File "/home/adrian/skyfolk/venv/lib/python3.5/site-packages/django/template/loader_tags.py", line 177, in render
    return compiled_parent._render(context)
  File "/home/adrian/skyfolk/venv/lib/python3.5/site-packages/django/test/utils.py", line 107, in instrumented_test_render
    return self.nodelist.render(context)
  File "/home/adrian/skyfolk/venv/lib/python3.5/site-packages/django/template/base.py", line 990, in render
    bit = node.render_annotated(context)
  File "/home/adrian/skyfolk/venv/lib/python3.5/site-packages/django/template/base.py", line 957, in render_annotated
    return self.render(context)
  File "/home/adrian/skyfolk/venv/lib/python3.5/site-packages/django/template/loader_tags.py", line 177, in render
    return compiled_parent._render(context)
  File "/home/adrian/skyfolk/venv/lib/python3.5/site-packages/django/test/utils.py", line 107, in instrumented_test_render
    return self.nodelist.render(context)
  File "/home/adrian/skyfolk/venv/lib/python3.5/site-packages/django/template/base.py", line 990, in render
    bit = node.render_annotated(context)
  File "/home/adrian/skyfolk/venv/lib/python3.5/site-packages/django/template/base.py", line 957, in render_annotated
    return self.render(context)
  File "/home/adrian/skyfolk/venv/lib/python3.5/site-packages/django/template/loader_tags.py", line 72, in render
    result = block.nodelist.render(context)
  File "/home/adrian/skyfolk/venv/lib/python3.5/site-packages/django/template/base.py", line 990, in render
    bit = node.render_annotated(context)
  File "/home/adrian/skyfolk/venv/lib/python3.5/site-packages/django/template/base.py", line 957, in render_annotated
    return self.render(context)
  File "/home/adrian/skyfolk/venv/lib/python3.5/site-packages/django/template/loader_tags.py", line 72, in render
    result = block.nodelist.render(context)
  File "/home/adrian/skyfolk/venv/lib/python3.5/site-packages/django/template/base.py", line 990, in render
    bit = node.render_annotated(context)
  File "/home/adrian/skyfolk/venv/lib/python3.5/site-packages/django/template/base.py", line 957, in render_annotated
    return self.render(context)
  File "/home/adrian/skyfolk/venv/lib/python3.5/site-packages/django/template/defaulttags.py", line 216, in render
    nodelist.append(node.render_annotated(context))
  File "/home/adrian/skyfolk/venv/lib/python3.5/site-packages/django/template/base.py", line 957, in render_annotated
    return self.render(context)
  File "/home/adrian/skyfolk/venv/lib/python3.5/site-packages/django/template/base.py", line 1040, in render
    output = self.filter_expression.resolve(context)
  File "/home/adrian/skyfolk/venv/lib/python3.5/site-packages/django/template/base.py", line 708, in resolve
    obj = self.var.resolve(context)
  File "/home/adrian/skyfolk/venv/lib/python3.5/site-packages/django/template/base.py", line 849, in resolve
    value = self._resolve_lookup(context)
  File "/home/adrian/skyfolk/venv/lib/python3.5/site-packages/django/template/base.py", line 911, in _resolve_lookup
    current = current()
  File "/home/adrian/skyfolk/dash/base.py", line 551, in render_for_edit
    return render_to_string(self.get_edit_template_name(), context)
  File "/home/adrian/skyfolk/venv/lib/python3.5/site-packages/django/template/loader.py", line 68, in render_to_string
    return template.render(context, request)
  File "/home/adrian/skyfolk/venv/lib/python3.5/site-packages/django/template/backends/django.py", line 66, in render
    return self.template.render(context)
  File "/home/adrian/skyfolk/venv/lib/python3.5/site-packages/django/template/base.py", line 207, in render
    return self._render(context)
  File "/home/adrian/skyfolk/venv/lib/python3.5/site-packages/django/test/utils.py", line 107, in instrumented_test_render
    return self.nodelist.render(context)
  File "/home/adrian/skyfolk/venv/lib/python3.5/site-packages/django/template/base.py", line 990, in render
    bit = node.render_annotated(context)
  File "/home/adrian/skyfolk/venv/lib/python3.5/site-packages/django/template/base.py", line 957, in render_annotated
    return self.render(context)
  File "/home/adrian/skyfolk/venv/lib/python3.5/site-packages/django/template/defaulttags.py", line 216, in render
    nodelist.append(node.render_annotated(context))
  File "/home/adrian/skyfolk/venv/lib/python3.5/site-packages/django/template/base.py", line 957, in render_annotated
    return self.render(context)
  File "/home/adrian/skyfolk/venv/lib/python3.5/site-packages/django/template/base.py", line 1040, in render
    output = self.filter_expression.resolve(context)
  File "/home/adrian/skyfolk/venv/lib/python3.5/site-packages/django/template/base.py", line 708, in resolve
    obj = self.var.resolve(context)
  File "/home/adrian/skyfolk/venv/lib/python3.5/site-packages/django/template/base.py", line 849, in resolve
    value = self._resolve_lookup(context)
  File "/home/adrian/skyfolk/venv/lib/python3.5/site-packages/django/template/base.py", line 911, in _resolve_lookup
    current = current()
  File "/home/adrian/skyfolk/dash/base.py", line 1146, in render
    render = widget.render(request=request)
  File "/home/adrian/skyfolk/dash/contrib/plugins/image/dash_widgets.py", line 62, in render
    return render_to_string('image/render.html', context)
  File "/home/adrian/skyfolk/venv/lib/python3.5/site-packages/django/template/loader.py", line 67, in render_to_string
    template = get_template(template_name, using=using)
  File "/home/adrian/skyfolk/venv/lib/python3.5/site-packages/django/template/loader.py", line 21, in get_template
    return engine.get_template(template_name)
  File "/home/adrian/skyfolk/venv/lib/python3.5/site-packages/django/template/backends/django.py", line 39, in get_template
    return Template(self.engine.get_template(template_name), self)
  File "/home/adrian/skyfolk/venv/lib/python3.5/site-packages/django/template/engine.py", line 162, in get_template
    template, origin = self.find_template(template_name)
  File "/home/adrian/skyfolk/venv/lib/python3.5/site-packages/django/template/engine.py", line 136, in find_template
    name, template_dirs=dirs, skip=skip,
  File "/home/adrian/skyfolk/venv/lib/python3.5/site-packages/django/template/loaders/base.py", line 44, in get_template
    contents, origin, origin.template_name, self.engine,
  File "/home/adrian/skyfolk/venv/lib/python3.5/site-packages/django/template/base.py", line 191, in __init__
    self.nodelist = self.compile_nodelist()
  File "/home/adrian/skyfolk/venv/lib/python3.5/site-packages/django/template/base.py", line 230, in compile_nodelist
    return parser.parse()
  File "/home/adrian/skyfolk/venv/lib/python3.5/site-packages/django/template/base.py", line 515, in parse
    raise self.error(token, e)
  File "/home/adrian/skyfolk/venv/lib/python3.5/site-packages/django/template/base.py", line 513, in parse
    compiled_result = compile_func(self, token)
  File "/home/adrian/skyfolk/venv/lib/python3.5/site-packages/django/template/defaulttags.py", line 1095, in load
    lib = find_library(parser, name)
  File "/home/adrian/skyfolk/venv/lib/python3.5/site-packages/django/template/defaulttags.py", line 1042, in find_library
    name, "\n".join(sorted(parser.libraries.keys())),
django.template.exceptions.TemplateSyntaxError: 'thumbnail' is not a registered tag library. Must be one of:
account
admin_list
admin_modify
admin_static
admin_urls
app_filters
avatar_tags
badgify_tags
cache
compress
dash_tags
decorators
django_th_extras
el_pagination_tags
embed_video_tags
emoji_tags
group_utils
guardian_tags
highlight
highlighting
humanize
i18n
indent_text
js_reverse
l10n
log
more_like_this
mptt_admin
mptt_tags
notification_tags
pagination_tags
photo_publications_tags
photologue_tags
postman_admin_modify
postman_tags
rest_framework
rss_feed_tags
socialaccount
static
staticfiles
syntax_color
truncate_letters
tz
webpack_loader
widont
2018-01-22 23:27:16,379 ERROR exception 1979 Internal Server Error: /dashboard/
Traceback (most recent call last):
  File "/home/adrian/skyfolk/venv/lib/python3.5/site-packages/django/core/handlers/exception.py", line 41, in inner
    response = get_response(request)
  File "/home/adrian/skyfolk/venv/lib/python3.5/site-packages/django/core/handlers/base.py", line 249, in _legacy_get_response
    response = self._get_response(request)
  File "/home/adrian/skyfolk/venv/lib/python3.5/site-packages/django/core/handlers/base.py", line 187, in _get_response
    response = self.process_exception_by_middleware(e, request)
  File "/home/adrian/skyfolk/venv/lib/python3.5/site-packages/channels/handler.py", line 243, in process_exception_by_middleware
    return super(AsgiHandler, self).process_exception_by_middleware(exception, request)
  File "/home/adrian/skyfolk/venv/lib/python3.5/site-packages/django/core/handlers/base.py", line 185, in _get_response
    response = wrapped_callback(request, *callback_args, **callback_kwargs)
  File "/home/adrian/skyfolk/venv/lib/python3.5/site-packages/django/contrib/auth/decorators.py", line 23, in _wrapped_view
    return view_func(request, *args, **kwargs)
  File "/home/adrian/skyfolk/dash/views.py", line 166, in dashboard
    return render(request, template_name, context)
  File "/home/adrian/skyfolk/venv/lib/python3.5/site-packages/django/shortcuts.py", line 30, in render
    content = loader.render_to_string(template_name, context, request, using=using)
  File "/home/adrian/skyfolk/venv/lib/python3.5/site-packages/django/template/loader.py", line 67, in render_to_string
    template = get_template(template_name, using=using)
  File "/home/adrian/skyfolk/venv/lib/python3.5/site-packages/django/template/loader.py", line 25, in get_template
    raise TemplateDoesNotExist(template_name, chain=chain)
django.template.exceptions.TemplateDoesNotExist: accounts/profile.html
