2018-02-05 12:42:17,836 ERROR exception 29269 Internal Server Error: /dashboard/plugin-widgets/main/androids/pos/3/
Traceback (most recent call last):
  File "/home/adrian/skyfolk/venv/lib/python3.6/site-packages/django/core/handlers/exception.py", line 41, in inner
    response = get_response(request)
  File "/home/adrian/skyfolk/venv/lib/python3.6/site-packages/django/core/handlers/base.py", line 249, in _legacy_get_response
    response = self._get_response(request)
  File "/home/adrian/skyfolk/venv/lib/python3.6/site-packages/django/core/handlers/base.py", line 187, in _get_response
    response = self.process_exception_by_middleware(e, request)
  File "/home/adrian/skyfolk/venv/lib/python3.6/site-packages/channels/handler.py", line 243, in process_exception_by_middleware
    return super(AsgiHandler, self).process_exception_by_middleware(exception, request)
  File "/home/adrian/skyfolk/venv/lib/python3.6/site-packages/django/core/handlers/base.py", line 185, in _get_response
    response = wrapped_callback(request, *callback_args, **callback_kwargs)
  File "/home/adrian/skyfolk/venv/lib/python3.6/site-packages/django/contrib/auth/decorators.py", line 23, in _wrapped_view
    return view_func(request, *args, **kwargs)
  File "/home/adrian/skyfolk/dash/views.py", line 1146, in plugin_widgets
    occupied_cells=occupied_cells
  File "/home/adrian/skyfolk/dash/utils.py", line 210, in get_widgets
    reverse('dash.add_dashboard_entry', kwargs=kwargs)
  File "/home/adrian/skyfolk/venv/lib/python3.6/site-packages/django/urls/base.py", line 91, in reverse
    return force_text(iri_to_uri(resolver._reverse_with_prefix(view, prefix, *args, **kwargs)))
  File "/home/adrian/skyfolk/venv/lib/python3.6/site-packages/django/urls/resolvers.py", line 497, in _reverse_with_prefix
    raise NoReverseMatch(msg)
django.urls.exceptions.NoReverseMatch: Reverse for 'dash.add_dashboard_entry' with keyword arguments '{'placeholder_uid': 'main', 'plugin_uid': 'trigger_1x1', 'workspace': <DashboardWorkspace: Android's>, 'position': '3'}' not found. 4 pattern(s) tried: ['dashboard/entry/add/(?P<placeholder_uid>[\\w_]+)/(?P<plugin_uid>[\\w_\\-]+)/$', 'dashboard/entry/add/(?P<placeholder_uid>[\\w_]+)/(?P<plugin_uid>[\\w_\\-]+)/pos/(?P<position>\\d+)/$', 'dashboard/entry/add/(?P<placeholder_uid>[\\w_]+)/(?P<plugin_uid>[\\w_\\-]+)/ws/(?P<workspace>[\\w_\\-]+)/$', 'dashboard/entry/add/(?P<placeholder_uid>[\\w_]+)/(?P<plugin_uid>[\\w_\\-]+)/ws/(?P<workspace>[\\w_\\-]+)/pos/(?P<position>\\d+)/$']
2018-02-05 12:45:22,833 ERROR exception 30812 Internal Server Error: /dashboard/plugin-widgets/main/androids/pos/1/
Traceback (most recent call last):
  File "/home/adrian/skyfolk/venv/lib/python3.6/site-packages/django/core/handlers/exception.py", line 41, in inner
    response = get_response(request)
  File "/home/adrian/skyfolk/venv/lib/python3.6/site-packages/django/core/handlers/base.py", line 249, in _legacy_get_response
    response = self._get_response(request)
  File "/home/adrian/skyfolk/venv/lib/python3.6/site-packages/django/core/handlers/base.py", line 187, in _get_response
    response = self.process_exception_by_middleware(e, request)
  File "/home/adrian/skyfolk/venv/lib/python3.6/site-packages/channels/handler.py", line 243, in process_exception_by_middleware
    return super(AsgiHandler, self).process_exception_by_middleware(exception, request)
  File "/home/adrian/skyfolk/venv/lib/python3.6/site-packages/django/core/handlers/base.py", line 185, in _get_response
    response = wrapped_callback(request, *callback_args, **callback_kwargs)
  File "/home/adrian/skyfolk/venv/lib/python3.6/site-packages/django/contrib/auth/decorators.py", line 23, in _wrapped_view
    return view_func(request, *args, **kwargs)
  File "/home/adrian/skyfolk/dash/views.py", line 1147, in plugin_widgets
    occupied_cells=occupied_cells
  File "/home/adrian/skyfolk/dash/utils.py", line 210, in get_widgets
    reverse('dash.add_dashboard_entry', kwargs=kwargs)
  File "/home/adrian/skyfolk/venv/lib/python3.6/site-packages/django/urls/base.py", line 91, in reverse
    return force_text(iri_to_uri(resolver._reverse_with_prefix(view, prefix, *args, **kwargs)))
  File "/home/adrian/skyfolk/venv/lib/python3.6/site-packages/django/urls/resolvers.py", line 497, in _reverse_with_prefix
    raise NoReverseMatch(msg)
django.urls.exceptions.NoReverseMatch: Reverse for 'dash.add_dashboard_entry' with keyword arguments '{'placeholder_uid': 'main', 'plugin_uid': 'trigger_1x1', 'workspace': <DashboardWorkspace: Android's>, 'position': '1'}' not found. 4 pattern(s) tried: ['dashboard/entry/add/(?P<placeholder_uid>[\\w_]+)/(?P<plugin_uid>[\\w_\\-]+)/$', 'dashboard/entry/add/(?P<placeholder_uid>[\\w_]+)/(?P<plugin_uid>[\\w_\\-]+)/pos/(?P<position>\\d+)/$', 'dashboard/entry/add/(?P<placeholder_uid>[\\w_]+)/(?P<plugin_uid>[\\w_\\-]+)/ws/(?P<workspace>[\\w_\\-]+)/$', 'dashboard/entry/add/(?P<placeholder_uid>[\\w_]+)/(?P<plugin_uid>[\\w_\\-]+)/ws/(?P<workspace>[\\w_\\-]+)/pos/(?P<position>\\d+)/$']
2018-02-05 12:46:05,039 ERROR exception 31066 Internal Server Error: /dashboard/plugin-widgets/main/androids/pos/2/
Traceback (most recent call last):
  File "/home/adrian/skyfolk/venv/lib/python3.6/site-packages/django/core/handlers/exception.py", line 41, in inner
    response = get_response(request)
  File "/home/adrian/skyfolk/venv/lib/python3.6/site-packages/django/core/handlers/base.py", line 249, in _legacy_get_response
    response = self._get_response(request)
  File "/home/adrian/skyfolk/venv/lib/python3.6/site-packages/django/core/handlers/base.py", line 187, in _get_response
    response = self.process_exception_by_middleware(e, request)
  File "/home/adrian/skyfolk/venv/lib/python3.6/site-packages/channels/handler.py", line 243, in process_exception_by_middleware
    return super(AsgiHandler, self).process_exception_by_middleware(exception, request)
  File "/home/adrian/skyfolk/venv/lib/python3.6/site-packages/django/core/handlers/base.py", line 185, in _get_response
    response = wrapped_callback(request, *callback_args, **callback_kwargs)
  File "/home/adrian/skyfolk/venv/lib/python3.6/site-packages/django/contrib/auth/decorators.py", line 23, in _wrapped_view
    return view_func(request, *args, **kwargs)
  File "/home/adrian/skyfolk/dash/views.py", line 1148, in plugin_widgets
    occupied_cells=occupied_cells
  File "/home/adrian/skyfolk/dash/utils.py", line 210, in get_widgets
    reverse('dash.add_dashboard_entry', kwargs=kwargs)
  File "/home/adrian/skyfolk/venv/lib/python3.6/site-packages/django/urls/base.py", line 91, in reverse
    return force_text(iri_to_uri(resolver._reverse_with_prefix(view, prefix, *args, **kwargs)))
  File "/home/adrian/skyfolk/venv/lib/python3.6/site-packages/django/urls/resolvers.py", line 497, in _reverse_with_prefix
    raise NoReverseMatch(msg)
django.urls.exceptions.NoReverseMatch: Reverse for 'dash.add_dashboard_entry' with keyword arguments '{'placeholder_uid': 'main', 'plugin_uid': 'trigger_1x1', 'workspace': <DashboardWorkspace: Android's>, 'position': '2'}' not found. 4 pattern(s) tried: ['dashboard/entry/add/(?P<placeholder_uid>[\\w_]+)/(?P<plugin_uid>[\\w_\\-]+)/$', 'dashboard/entry/add/(?P<placeholder_uid>[\\w_]+)/(?P<plugin_uid>[\\w_\\-]+)/pos/(?P<position>\\d+)/$', 'dashboard/entry/add/(?P<placeholder_uid>[\\w_]+)/(?P<plugin_uid>[\\w_\\-]+)/ws/(?P<workspace>[\\w_\\-]+)/$', 'dashboard/entry/add/(?P<placeholder_uid>[\\w_]+)/(?P<plugin_uid>[\\w_\\-]+)/ws/(?P<workspace>[\\w_\\-]+)/pos/(?P<position>\\d+)/$']
2018-02-05 12:46:35,587 ERROR exception 31379 Internal Server Error: /dashboard/plugin-widgets/main/androids/pos/2/
Traceback (most recent call last):
  File "/home/adrian/skyfolk/venv/lib/python3.6/site-packages/django/core/handlers/exception.py", line 41, in inner
    response = get_response(request)
  File "/home/adrian/skyfolk/venv/lib/python3.6/site-packages/django/core/handlers/base.py", line 249, in _legacy_get_response
    response = self._get_response(request)
  File "/home/adrian/skyfolk/venv/lib/python3.6/site-packages/django/core/handlers/base.py", line 187, in _get_response
    response = self.process_exception_by_middleware(e, request)
  File "/home/adrian/skyfolk/venv/lib/python3.6/site-packages/channels/handler.py", line 243, in process_exception_by_middleware
    return super(AsgiHandler, self).process_exception_by_middleware(exception, request)
  File "/home/adrian/skyfolk/venv/lib/python3.6/site-packages/django/core/handlers/base.py", line 185, in _get_response
    response = wrapped_callback(request, *callback_args, **callback_kwargs)
  File "/home/adrian/skyfolk/venv/lib/python3.6/site-packages/django/contrib/auth/decorators.py", line 23, in _wrapped_view
    return view_func(request, *args, **kwargs)
  File "/home/adrian/skyfolk/dash/views.py", line 1145, in plugin_widgets
    occupied_cells=occupied_cells
  File "/home/adrian/skyfolk/dash/utils.py", line 210, in get_widgets
    reverse('dash.add_dashboard_entry', kwargs=kwargs)
  File "/home/adrian/skyfolk/venv/lib/python3.6/site-packages/django/urls/base.py", line 91, in reverse
    return force_text(iri_to_uri(resolver._reverse_with_prefix(view, prefix, *args, **kwargs)))
  File "/home/adrian/skyfolk/venv/lib/python3.6/site-packages/django/urls/resolvers.py", line 497, in _reverse_with_prefix
    raise NoReverseMatch(msg)
django.urls.exceptions.NoReverseMatch: Reverse for 'dash.add_dashboard_entry' with keyword arguments '{'placeholder_uid': 'main', 'plugin_uid': 'trigger_1x1', 'workspace': <DashboardWorkspace: Android's>, 'position': '2'}' not found. 4 pattern(s) tried: ['dashboard/entry/add/(?P<placeholder_uid>[\\w_]+)/(?P<plugin_uid>[\\w_\\-]+)/$', 'dashboard/entry/add/(?P<placeholder_uid>[\\w_]+)/(?P<plugin_uid>[\\w_\\-]+)/pos/(?P<position>\\d+)/$', 'dashboard/entry/add/(?P<placeholder_uid>[\\w_]+)/(?P<plugin_uid>[\\w_\\-]+)/ws/(?P<workspace>[\\w_\\-]+)/$', 'dashboard/entry/add/(?P<placeholder_uid>[\\w_]+)/(?P<plugin_uid>[\\w_\\-]+)/ws/(?P<workspace>[\\w_\\-]+)/pos/(?P<position>\\d+)/$']
2018-02-05 12:48:00,186 ERROR exception 32134 Internal Server Error: /dashboard/plugin-widgets/main/androids/pos/1/
Traceback (most recent call last):
  File "/home/adrian/skyfolk/venv/lib/python3.6/site-packages/django/core/handlers/exception.py", line 41, in inner
    response = get_response(request)
  File "/home/adrian/skyfolk/venv/lib/python3.6/site-packages/django/core/handlers/base.py", line 249, in _legacy_get_response
    response = self._get_response(request)
  File "/home/adrian/skyfolk/venv/lib/python3.6/site-packages/django/core/handlers/base.py", line 187, in _get_response
    response = self.process_exception_by_middleware(e, request)
  File "/home/adrian/skyfolk/venv/lib/python3.6/site-packages/channels/handler.py", line 243, in process_exception_by_middleware
    return super(AsgiHandler, self).process_exception_by_middleware(exception, request)
  File "/home/adrian/skyfolk/venv/lib/python3.6/site-packages/django/core/handlers/base.py", line 185, in _get_response
    response = wrapped_callback(request, *callback_args, **callback_kwargs)
  File "/home/adrian/skyfolk/venv/lib/python3.6/site-packages/django/contrib/auth/decorators.py", line 23, in _wrapped_view
    return view_func(request, *args, **kwargs)
  File "/home/adrian/skyfolk/dash/views.py", line 1146, in plugin_widgets
    occupied_cells=occupied_cells
  File "/home/adrian/skyfolk/dash/utils.py", line 210, in get_widgets
    reverse('dash.add_dashboard_entry', kwargs=kwargs)
  File "/home/adrian/skyfolk/venv/lib/python3.6/site-packages/django/urls/base.py", line 91, in reverse
    return force_text(iri_to_uri(resolver._reverse_with_prefix(view, prefix, *args, **kwargs)))
  File "/home/adrian/skyfolk/venv/lib/python3.6/site-packages/django/urls/resolvers.py", line 497, in _reverse_with_prefix
    raise NoReverseMatch(msg)
django.urls.exceptions.NoReverseMatch: Reverse for 'dash.add_dashboard_entry' with keyword arguments '{'placeholder_uid': 'main', 'plugin_uid': 'trigger_1x1', 'workspace': <DashboardWorkspace: Android's>, 'position': '1'}' not found. 4 pattern(s) tried: ['dashboard/entry/add/(?P<placeholder_uid>[\\w_]+)/(?P<plugin_uid>[\\w_\\-]+)/$', 'dashboard/entry/add/(?P<placeholder_uid>[\\w_]+)/(?P<plugin_uid>[\\w_\\-]+)/pos/(?P<position>\\d+)/$', 'dashboard/entry/add/(?P<placeholder_uid>[\\w_]+)/(?P<plugin_uid>[\\w_\\-]+)/ws/(?P<workspace>[\\w_\\-]+)/$', 'dashboard/entry/add/(?P<placeholder_uid>[\\w_]+)/(?P<plugin_uid>[\\w_\\-]+)/ws/(?P<workspace>[\\w_\\-]+)/pos/(?P<position>\\d+)/$']
2018-02-05 12:49:08,072 ERROR exception 32439 Internal Server Error: /dashboard/plugin-widgets/main/androids/pos/1/
Traceback (most recent call last):
  File "/home/adrian/skyfolk/venv/lib/python3.6/site-packages/django/core/handlers/exception.py", line 41, in inner
    response = get_response(request)
  File "/home/adrian/skyfolk/venv/lib/python3.6/site-packages/django/core/handlers/base.py", line 249, in _legacy_get_response
    response = self._get_response(request)
  File "/home/adrian/skyfolk/venv/lib/python3.6/site-packages/django/core/handlers/base.py", line 187, in _get_response
    response = self.process_exception_by_middleware(e, request)
  File "/home/adrian/skyfolk/venv/lib/python3.6/site-packages/channels/handler.py", line 243, in process_exception_by_middleware
    return super(AsgiHandler, self).process_exception_by_middleware(exception, request)
  File "/home/adrian/skyfolk/venv/lib/python3.6/site-packages/django/core/handlers/base.py", line 185, in _get_response
    response = wrapped_callback(request, *callback_args, **callback_kwargs)
  File "/home/adrian/skyfolk/venv/lib/python3.6/site-packages/django/contrib/auth/decorators.py", line 23, in _wrapped_view
    return view_func(request, *args, **kwargs)
  File "/home/adrian/skyfolk/dash/views.py", line 1147, in plugin_widgets
    occupied_cells=occupied_cells
  File "/home/adrian/skyfolk/dash/utils.py", line 210, in get_widgets
    reverse('dash.add_dashboard_entry', kwargs=kwargs)
  File "/home/adrian/skyfolk/venv/lib/python3.6/site-packages/django/urls/base.py", line 91, in reverse
    return force_text(iri_to_uri(resolver._reverse_with_prefix(view, prefix, *args, **kwargs)))
  File "/home/adrian/skyfolk/venv/lib/python3.6/site-packages/django/urls/resolvers.py", line 497, in _reverse_with_prefix
    raise NoReverseMatch(msg)
django.urls.exceptions.NoReverseMatch: Reverse for 'dash.add_dashboard_entry' with keyword arguments '{'placeholder_uid': 'main', 'plugin_uid': 'trigger_1x1', 'workspace': <DashboardWorkspace: Android's>, 'position': '1'}' not found. 4 pattern(s) tried: ['dashboard/entry/add/(?P<placeholder_uid>[\\w_]+)/(?P<plugin_uid>[\\w_\\-]+)/$', 'dashboard/entry/add/(?P<placeholder_uid>[\\w_]+)/(?P<plugin_uid>[\\w_\\-]+)/pos/(?P<position>\\d+)/$', 'dashboard/entry/add/(?P<placeholder_uid>[\\w_]+)/(?P<plugin_uid>[\\w_\\-]+)/ws/(?P<workspace>[\\w_\\-]+)/$', 'dashboard/entry/add/(?P<placeholder_uid>[\\w_]+)/(?P<plugin_uid>[\\w_\\-]+)/ws/(?P<workspace>[\\w_\\-]+)/pos/(?P<position>\\d+)/$']
2018-02-05 12:49:53,600 ERROR exception 475 Internal Server Error: /dashboard/plugin-widgets/main/androids/pos/1/
Traceback (most recent call last):
  File "/home/adrian/skyfolk/venv/lib/python3.6/site-packages/django/core/handlers/exception.py", line 41, in inner
    response = get_response(request)
  File "/home/adrian/skyfolk/venv/lib/python3.6/site-packages/django/core/handlers/base.py", line 249, in _legacy_get_response
    response = self._get_response(request)
  File "/home/adrian/skyfolk/venv/lib/python3.6/site-packages/django/core/handlers/base.py", line 187, in _get_response
    response = self.process_exception_by_middleware(e, request)
  File "/home/adrian/skyfolk/venv/lib/python3.6/site-packages/channels/handler.py", line 243, in process_exception_by_middleware
    return super(AsgiHandler, self).process_exception_by_middleware(exception, request)
  File "/home/adrian/skyfolk/venv/lib/python3.6/site-packages/django/core/handlers/base.py", line 185, in _get_response
    response = wrapped_callback(request, *callback_args, **callback_kwargs)
  File "/home/adrian/skyfolk/venv/lib/python3.6/site-packages/django/contrib/auth/decorators.py", line 23, in _wrapped_view
    return view_func(request, *args, **kwargs)
  File "/home/adrian/skyfolk/dash/views.py", line 1103, in plugin_widgets
    workspace__slug=workspace.slug
TypeError: build_cells_matrix() got an unexpected keyword argument 'workspace__slug'
2018-02-05 12:49:55,394 ERROR exception 475 Internal Server Error: /dashboard/plugin-widgets/main/androids/pos/2/
Traceback (most recent call last):
  File "/home/adrian/skyfolk/venv/lib/python3.6/site-packages/django/core/handlers/exception.py", line 41, in inner
    response = get_response(request)
  File "/home/adrian/skyfolk/venv/lib/python3.6/site-packages/django/core/handlers/base.py", line 249, in _legacy_get_response
    response = self._get_response(request)
  File "/home/adrian/skyfolk/venv/lib/python3.6/site-packages/django/core/handlers/base.py", line 187, in _get_response
    response = self.process_exception_by_middleware(e, request)
  File "/home/adrian/skyfolk/venv/lib/python3.6/site-packages/channels/handler.py", line 243, in process_exception_by_middleware
    return super(AsgiHandler, self).process_exception_by_middleware(exception, request)
  File "/home/adrian/skyfolk/venv/lib/python3.6/site-packages/django/core/handlers/base.py", line 185, in _get_response
    response = wrapped_callback(request, *callback_args, **callback_kwargs)
  File "/home/adrian/skyfolk/venv/lib/python3.6/site-packages/django/contrib/auth/decorators.py", line 23, in _wrapped_view
    return view_func(request, *args, **kwargs)
  File "/home/adrian/skyfolk/dash/views.py", line 1103, in plugin_widgets
    workspace__slug=workspace.slug
TypeError: build_cells_matrix() got an unexpected keyword argument 'workspace__slug'
2018-02-05 12:55:02,176 ERROR exception 2812 Internal Server Error: /dashboard/plugin-widgets/main/androids/pos/2/
Traceback (most recent call last):
  File "/home/adrian/skyfolk/venv/lib/python3.6/site-packages/django/core/handlers/exception.py", line 41, in inner
    response = get_response(request)
  File "/home/adrian/skyfolk/venv/lib/python3.6/site-packages/django/core/handlers/base.py", line 249, in _legacy_get_response
    response = self._get_response(request)
  File "/home/adrian/skyfolk/venv/lib/python3.6/site-packages/django/core/handlers/base.py", line 187, in _get_response
    response = self.process_exception_by_middleware(e, request)
  File "/home/adrian/skyfolk/venv/lib/python3.6/site-packages/channels/handler.py", line 243, in process_exception_by_middleware
    return super(AsgiHandler, self).process_exception_by_middleware(exception, request)
  File "/home/adrian/skyfolk/venv/lib/python3.6/site-packages/django/core/handlers/base.py", line 185, in _get_response
    response = wrapped_callback(request, *callback_args, **callback_kwargs)
  File "/home/adrian/skyfolk/venv/lib/python3.6/site-packages/django/contrib/auth/decorators.py", line 23, in _wrapped_view
    return view_func(request, *args, **kwargs)
  File "/home/adrian/skyfolk/dash/views.py", line 1146, in plugin_widgets
    occupied_cells=occupied_cells
  File "/home/adrian/skyfolk/dash/utils.py", line 210, in get_widgets
    reverse('dash.add_dashboard_entry', kwargs=kwargs)
  File "/home/adrian/skyfolk/venv/lib/python3.6/site-packages/django/urls/base.py", line 91, in reverse
    return force_text(iri_to_uri(resolver._reverse_with_prefix(view, prefix, *args, **kwargs)))
  File "/home/adrian/skyfolk/venv/lib/python3.6/site-packages/django/urls/resolvers.py", line 497, in _reverse_with_prefix
    raise NoReverseMatch(msg)
django.urls.exceptions.NoReverseMatch: Reverse for 'dash.add_dashboard_entry' with keyword arguments '{'placeholder_uid': 'main', 'plugin_uid': 'trigger_1x1', 'workspace': <DashboardWorkspace: Android's>, 'position': '2'}' not found. 4 pattern(s) tried: ['dashboard/entry/add/(?P<placeholder_uid>[\\w_]+)/(?P<plugin_uid>[\\w_\\-]+)/$', 'dashboard/entry/add/(?P<placeholder_uid>[\\w_]+)/(?P<plugin_uid>[\\w_\\-]+)/pos/(?P<position>\\d+)/$', 'dashboard/entry/add/(?P<placeholder_uid>[\\w_]+)/(?P<plugin_uid>[\\w_\\-]+)/ws/(?P<workspace>[\\w_\\-]+)/$', 'dashboard/entry/add/(?P<placeholder_uid>[\\w_]+)/(?P<plugin_uid>[\\w_\\-]+)/ws/(?P<workspace>[\\w_\\-]+)/pos/(?P<position>\\d+)/$']
2018-02-05 12:56:39,686 ERROR exception 3520 Internal Server Error: /dashboard/plugin-widgets/main/androids/pos/1/
Traceback (most recent call last):
  File "/home/adrian/skyfolk/venv/lib/python3.6/site-packages/django/core/handlers/exception.py", line 41, in inner
    response = get_response(request)
  File "/home/adrian/skyfolk/venv/lib/python3.6/site-packages/django/core/handlers/base.py", line 249, in _legacy_get_response
    response = self._get_response(request)
  File "/home/adrian/skyfolk/venv/lib/python3.6/site-packages/django/core/handlers/base.py", line 187, in _get_response
    response = self.process_exception_by_middleware(e, request)
  File "/home/adrian/skyfolk/venv/lib/python3.6/site-packages/channels/handler.py", line 243, in process_exception_by_middleware
    return super(AsgiHandler, self).process_exception_by_middleware(exception, request)
  File "/home/adrian/skyfolk/venv/lib/python3.6/site-packages/django/core/handlers/base.py", line 185, in _get_response
    response = wrapped_callback(request, *callback_args, **callback_kwargs)
  File "/home/adrian/skyfolk/venv/lib/python3.6/site-packages/django/contrib/auth/decorators.py", line 23, in _wrapped_view
    return view_func(request, *args, **kwargs)
  File "/home/adrian/skyfolk/dash/views.py", line 1146, in plugin_widgets
    occupied_cells=occupied_cells
  File "/home/adrian/skyfolk/dash/utils.py", line 211, in get_widgets
    reverse('dash.add_dashboard_entry', kwargs=kwargs)
  File "/home/adrian/skyfolk/venv/lib/python3.6/site-packages/django/urls/base.py", line 91, in reverse
    return force_text(iri_to_uri(resolver._reverse_with_prefix(view, prefix, *args, **kwargs)))
  File "/home/adrian/skyfolk/venv/lib/python3.6/site-packages/django/urls/resolvers.py", line 497, in _reverse_with_prefix
    raise NoReverseMatch(msg)
django.urls.exceptions.NoReverseMatch: Reverse for 'dash.add_dashboard_entry' with keyword arguments '{'placeholder_uid': 'main', 'plugin_uid': 'trigger_1x1', 'workspace': <DashboardWorkspace: Android's>, 'position': '1'}' not found. 4 pattern(s) tried: ['dashboard/entry/add/(?P<placeholder_uid>[\\w_]+)/(?P<plugin_uid>[\\w_\\-]+)/$', 'dashboard/entry/add/(?P<placeholder_uid>[\\w_]+)/(?P<plugin_uid>[\\w_\\-]+)/pos/(?P<position>\\d+)/$', 'dashboard/entry/add/(?P<placeholder_uid>[\\w_]+)/(?P<plugin_uid>[\\w_\\-]+)/ws/(?P<workspace>[\\w_\\-]+)/$', 'dashboard/entry/add/(?P<placeholder_uid>[\\w_]+)/(?P<plugin_uid>[\\w_\\-]+)/ws/(?P<workspace>[\\w_\\-]+)/pos/(?P<position>\\d+)/$']
2018-02-05 12:57:22,186 ERROR exception 3912 Internal Server Error: /dashboard/plugin-widgets/main/androids/pos/1/
Traceback (most recent call last):
  File "/home/adrian/skyfolk/venv/lib/python3.6/site-packages/django/core/handlers/exception.py", line 41, in inner
    response = get_response(request)
  File "/home/adrian/skyfolk/venv/lib/python3.6/site-packages/django/core/handlers/base.py", line 249, in _legacy_get_response
    response = self._get_response(request)
  File "/home/adrian/skyfolk/venv/lib/python3.6/site-packages/django/core/handlers/base.py", line 187, in _get_response
    response = self.process_exception_by_middleware(e, request)
  File "/home/adrian/skyfolk/venv/lib/python3.6/site-packages/channels/handler.py", line 243, in process_exception_by_middleware
    return super(AsgiHandler, self).process_exception_by_middleware(exception, request)
  File "/home/adrian/skyfolk/venv/lib/python3.6/site-packages/django/core/handlers/base.py", line 185, in _get_response
    response = wrapped_callback(request, *callback_args, **callback_kwargs)
  File "/home/adrian/skyfolk/venv/lib/python3.6/site-packages/django/contrib/auth/decorators.py", line 23, in _wrapped_view
    return view_func(request, *args, **kwargs)
  File "/home/adrian/skyfolk/dash/views.py", line 1146, in plugin_widgets
    occupied_cells=occupied_cells
  File "/home/adrian/skyfolk/dash/utils.py", line 212, in get_widgets
    reverse('dash.add_dashboard_entry', kwargs=kwargs)
  File "/home/adrian/skyfolk/venv/lib/python3.6/site-packages/django/urls/base.py", line 91, in reverse
    return force_text(iri_to_uri(resolver._reverse_with_prefix(view, prefix, *args, **kwargs)))
  File "/home/adrian/skyfolk/venv/lib/python3.6/site-packages/django/urls/resolvers.py", line 497, in _reverse_with_prefix
    raise NoReverseMatch(msg)
django.urls.exceptions.NoReverseMatch: Reverse for 'dash.add_dashboard_entry' with keyword arguments '{'placeholder_uid': 'main', 'plugin_uid': 'trigger_1x1', 'workspace': <DashboardWorkspace: Android's>, 'position': '1'}' not found. 4 pattern(s) tried: ['dashboard/entry/add/(?P<placeholder_uid>[\\w_]+)/(?P<plugin_uid>[\\w_\\-]+)/$', 'dashboard/entry/add/(?P<placeholder_uid>[\\w_]+)/(?P<plugin_uid>[\\w_\\-]+)/pos/(?P<position>\\d+)/$', 'dashboard/entry/add/(?P<placeholder_uid>[\\w_]+)/(?P<plugin_uid>[\\w_\\-]+)/ws/(?P<workspace>[\\w_\\-]+)/$', 'dashboard/entry/add/(?P<placeholder_uid>[\\w_]+)/(?P<plugin_uid>[\\w_\\-]+)/ws/(?P<workspace>[\\w_\\-]+)/pos/(?P<position>\\d+)/$']
2018-02-05 12:59:01,344 ERROR exception 4695 Internal Server Error: /dashboard/plugin-widgets/main/androids/pos/2/
Traceback (most recent call last):
  File "/home/adrian/skyfolk/venv/lib/python3.6/site-packages/django/core/handlers/exception.py", line 41, in inner
    response = get_response(request)
  File "/home/adrian/skyfolk/venv/lib/python3.6/site-packages/django/core/handlers/base.py", line 249, in _legacy_get_response
    response = self._get_response(request)
  File "/home/adrian/skyfolk/venv/lib/python3.6/site-packages/django/core/handlers/base.py", line 187, in _get_response
    response = self.process_exception_by_middleware(e, request)
  File "/home/adrian/skyfolk/venv/lib/python3.6/site-packages/channels/handler.py", line 243, in process_exception_by_middleware
    return super(AsgiHandler, self).process_exception_by_middleware(exception, request)
  File "/home/adrian/skyfolk/venv/lib/python3.6/site-packages/django/core/handlers/base.py", line 185, in _get_response
    response = wrapped_callback(request, *callback_args, **callback_kwargs)
  File "/home/adrian/skyfolk/venv/lib/python3.6/site-packages/django/contrib/auth/decorators.py", line 23, in _wrapped_view
    return view_func(request, *args, **kwargs)
  File "/home/adrian/skyfolk/dash/views.py", line 1146, in plugin_widgets
    occupied_cells=occupied_cells
  File "/home/adrian/skyfolk/dash/utils.py", line 212, in get_widgets
    reverse('dash.add_dashboard_entry', kwargs=kwargs)
  File "/home/adrian/skyfolk/venv/lib/python3.6/site-packages/django/urls/base.py", line 91, in reverse
    return force_text(iri_to_uri(resolver._reverse_with_prefix(view, prefix, *args, **kwargs)))
  File "/home/adrian/skyfolk/venv/lib/python3.6/site-packages/django/urls/resolvers.py", line 497, in _reverse_with_prefix
    raise NoReverseMatch(msg)
django.urls.exceptions.NoReverseMatch: Reverse for 'dash.add_dashboard_entry' with keyword arguments '{'placeholder_uid': 'main', 'plugin_uid': 'trigger_1x1', 'workspace': "Android's", 'position': '2'}' not found. 4 pattern(s) tried: ['dashboard/entry/add/(?P<placeholder_uid>[\\w_]+)/(?P<plugin_uid>[\\w_\\-]+)/$', 'dashboard/entry/add/(?P<placeholder_uid>[\\w_]+)/(?P<plugin_uid>[\\w_\\-]+)/pos/(?P<position>\\d+)/$', 'dashboard/entry/add/(?P<placeholder_uid>[\\w_]+)/(?P<plugin_uid>[\\w_\\-]+)/ws/(?P<workspace>[\\w_\\-]+)/$', 'dashboard/entry/add/(?P<placeholder_uid>[\\w_]+)/(?P<plugin_uid>[\\w_\\-]+)/ws/(?P<workspace>[\\w_\\-]+)/pos/(?P<position>\\d+)/$']
2018-02-05 12:59:03,010 ERROR exception 4695 Internal Server Error: /dashboard/plugin-widgets/main/androids/pos/1/
Traceback (most recent call last):
  File "/home/adrian/skyfolk/venv/lib/python3.6/site-packages/django/core/handlers/exception.py", line 41, in inner
    response = get_response(request)
  File "/home/adrian/skyfolk/venv/lib/python3.6/site-packages/django/core/handlers/base.py", line 249, in _legacy_get_response
    response = self._get_response(request)
  File "/home/adrian/skyfolk/venv/lib/python3.6/site-packages/django/core/handlers/base.py", line 187, in _get_response
    response = self.process_exception_by_middleware(e, request)
  File "/home/adrian/skyfolk/venv/lib/python3.6/site-packages/channels/handler.py", line 243, in process_exception_by_middleware
    return super(AsgiHandler, self).process_exception_by_middleware(exception, request)
  File "/home/adrian/skyfolk/venv/lib/python3.6/site-packages/django/core/handlers/base.py", line 185, in _get_response
    response = wrapped_callback(request, *callback_args, **callback_kwargs)
  File "/home/adrian/skyfolk/venv/lib/python3.6/site-packages/django/contrib/auth/decorators.py", line 23, in _wrapped_view
    return view_func(request, *args, **kwargs)
  File "/home/adrian/skyfolk/dash/views.py", line 1146, in plugin_widgets
    occupied_cells=occupied_cells
  File "/home/adrian/skyfolk/dash/utils.py", line 212, in get_widgets
    reverse('dash.add_dashboard_entry', kwargs=kwargs)
  File "/home/adrian/skyfolk/venv/lib/python3.6/site-packages/django/urls/base.py", line 91, in reverse
    return force_text(iri_to_uri(resolver._reverse_with_prefix(view, prefix, *args, **kwargs)))
  File "/home/adrian/skyfolk/venv/lib/python3.6/site-packages/django/urls/resolvers.py", line 497, in _reverse_with_prefix
    raise NoReverseMatch(msg)
django.urls.exceptions.NoReverseMatch: Reverse for 'dash.add_dashboard_entry' with keyword arguments '{'placeholder_uid': 'main', 'plugin_uid': 'trigger_1x1', 'workspace': "Android's", 'position': '1'}' not found. 4 pattern(s) tried: ['dashboard/entry/add/(?P<placeholder_uid>[\\w_]+)/(?P<plugin_uid>[\\w_\\-]+)/$', 'dashboard/entry/add/(?P<placeholder_uid>[\\w_]+)/(?P<plugin_uid>[\\w_\\-]+)/pos/(?P<position>\\d+)/$', 'dashboard/entry/add/(?P<placeholder_uid>[\\w_]+)/(?P<plugin_uid>[\\w_\\-]+)/ws/(?P<workspace>[\\w_\\-]+)/$', 'dashboard/entry/add/(?P<placeholder_uid>[\\w_]+)/(?P<plugin_uid>[\\w_\\-]+)/ws/(?P<workspace>[\\w_\\-]+)/pos/(?P<position>\\d+)/$']
2018-02-05 13:05:25,890 ERROR exception 7187 Internal Server Error: /dashboard/entry/add/main/video_1x1/ws/androids/pos/2/
Traceback (most recent call last):
  File "/home/adrian/skyfolk/venv/lib/python3.6/site-packages/django/core/handlers/exception.py", line 41, in inner
    response = get_response(request)
  File "/home/adrian/skyfolk/venv/lib/python3.6/site-packages/django/core/handlers/base.py", line 249, in _legacy_get_response
    response = self._get_response(request)
  File "/home/adrian/skyfolk/venv/lib/python3.6/site-packages/django/core/handlers/base.py", line 187, in _get_response
    response = self.process_exception_by_middleware(e, request)
  File "/home/adrian/skyfolk/venv/lib/python3.6/site-packages/channels/handler.py", line 243, in process_exception_by_middleware
    return super(AsgiHandler, self).process_exception_by_middleware(exception, request)
  File "/home/adrian/skyfolk/venv/lib/python3.6/site-packages/django/core/handlers/base.py", line 185, in _get_response
    response = wrapped_callback(request, *callback_args, **callback_kwargs)
  File "/home/adrian/skyfolk/venv/lib/python3.6/site-packages/django/views/generic/base.py", line 68, in view
    return self.dispatch(request, *args, **kwargs)
  File "/home/adrian/skyfolk/venv/lib/python3.6/site-packages/django/utils/decorators.py", line 67, in _wrapper
    return bound_func(*args, **kwargs)
  File "/home/adrian/skyfolk/venv/lib/python3.6/site-packages/django/contrib/auth/decorators.py", line 23, in _wrapped_view
    return view_func(request, *args, **kwargs)
  File "/home/adrian/skyfolk/venv/lib/python3.6/site-packages/django/utils/decorators.py", line 63, in bound_func
    return func.__get__(self, type(self))(*args2, **kwargs2)
  File "/home/adrian/skyfolk/dash/views.py", line 313, in dispatch
    workspace=self.workspace.slug,
AttributeError: 'str' object has no attribute 'slug'
2018-02-05 13:06:05,900 ERROR exception 7396 Internal Server Error: /dashboard/plugin-widgets/main/androids/pos/3/
Traceback (most recent call last):
  File "/home/adrian/skyfolk/venv/lib/python3.6/site-packages/django/core/handlers/exception.py", line 41, in inner
    response = get_response(request)
  File "/home/adrian/skyfolk/venv/lib/python3.6/site-packages/django/core/handlers/base.py", line 249, in _legacy_get_response
    response = self._get_response(request)
  File "/home/adrian/skyfolk/venv/lib/python3.6/site-packages/django/core/handlers/base.py", line 187, in _get_response
    response = self.process_exception_by_middleware(e, request)
  File "/home/adrian/skyfolk/venv/lib/python3.6/site-packages/channels/handler.py", line 243, in process_exception_by_middleware
    return super(AsgiHandler, self).process_exception_by_middleware(exception, request)
  File "/home/adrian/skyfolk/venv/lib/python3.6/site-packages/django/core/handlers/base.py", line 185, in _get_response
    response = wrapped_callback(request, *callback_args, **callback_kwargs)
  File "/home/adrian/skyfolk/venv/lib/python3.6/site-packages/django/contrib/auth/decorators.py", line 23, in _wrapped_view
    return view_func(request, *args, **kwargs)
  File "/home/adrian/skyfolk/dash/views.py", line 1135, in plugin_widgets
    kwargs=kwargs
  File "/home/adrian/skyfolk/venv/lib/python3.6/site-packages/django/urls/base.py", line 91, in reverse
    return force_text(iri_to_uri(resolver._reverse_with_prefix(view, prefix, *args, **kwargs)))
  File "/home/adrian/skyfolk/venv/lib/python3.6/site-packages/django/urls/resolvers.py", line 497, in _reverse_with_prefix
    raise NoReverseMatch(msg)
django.urls.exceptions.NoReverseMatch: Reverse for 'dash.paste_dashboard_entry' with keyword arguments '{'placeholder_uid': 'main', 'position': '3', 'workspace': <DashboardWorkspace: Android's>}' not found. 2 pattern(s) tried: ['dashboard/entry/paste/(?P<placeholder_uid>[\\w_]+)/pos/(?P<position>\\d+)/$', 'dashboard/entry/paste/(?P<placeholder_uid>[\\w_]+)/(?P<workspace>[\\w_\\-]+)/pos/(?P<position>\\d+)/$']
2018-02-05 13:06:11,669 ERROR exception 7396 Internal Server Error: /dashboard/plugin-widgets/main/androids/pos/2/
Traceback (most recent call last):
  File "/home/adrian/skyfolk/venv/lib/python3.6/site-packages/django/core/handlers/exception.py", line 41, in inner
    response = get_response(request)
  File "/home/adrian/skyfolk/venv/lib/python3.6/site-packages/django/core/handlers/base.py", line 249, in _legacy_get_response
    response = self._get_response(request)
  File "/home/adrian/skyfolk/venv/lib/python3.6/site-packages/django/core/handlers/base.py", line 187, in _get_response
    response = self.process_exception_by_middleware(e, request)
  File "/home/adrian/skyfolk/venv/lib/python3.6/site-packages/channels/handler.py", line 243, in process_exception_by_middleware
    return super(AsgiHandler, self).process_exception_by_middleware(exception, request)
  File "/home/adrian/skyfolk/venv/lib/python3.6/site-packages/django/core/handlers/base.py", line 185, in _get_response
    response = wrapped_callback(request, *callback_args, **callback_kwargs)
  File "/home/adrian/skyfolk/venv/lib/python3.6/site-packages/django/contrib/auth/decorators.py", line 23, in _wrapped_view
    return view_func(request, *args, **kwargs)
  File "/home/adrian/skyfolk/dash/views.py", line 1135, in plugin_widgets
    kwargs=kwargs
  File "/home/adrian/skyfolk/venv/lib/python3.6/site-packages/django/urls/base.py", line 91, in reverse
    return force_text(iri_to_uri(resolver._reverse_with_prefix(view, prefix, *args, **kwargs)))
  File "/home/adrian/skyfolk/venv/lib/python3.6/site-packages/django/urls/resolvers.py", line 497, in _reverse_with_prefix
    raise NoReverseMatch(msg)
django.urls.exceptions.NoReverseMatch: Reverse for 'dash.paste_dashboard_entry' with keyword arguments '{'placeholder_uid': 'main', 'position': '2', 'workspace': <DashboardWorkspace: Android's>}' not found. 2 pattern(s) tried: ['dashboard/entry/paste/(?P<placeholder_uid>[\\w_]+)/pos/(?P<position>\\d+)/$', 'dashboard/entry/paste/(?P<placeholder_uid>[\\w_]+)/(?P<workspace>[\\w_\\-]+)/pos/(?P<position>\\d+)/$']
2018-02-05 13:06:21,272 ERROR exception 7666 Internal Server Error: /dashboard/plugin-widgets/main/androids/pos/2/
Traceback (most recent call last):
  File "/home/adrian/skyfolk/venv/lib/python3.6/site-packages/django/core/handlers/exception.py", line 41, in inner
    response = get_response(request)
  File "/home/adrian/skyfolk/venv/lib/python3.6/site-packages/django/core/handlers/base.py", line 249, in _legacy_get_response
    response = self._get_response(request)
  File "/home/adrian/skyfolk/venv/lib/python3.6/site-packages/django/core/handlers/base.py", line 187, in _get_response
    response = self.process_exception_by_middleware(e, request)
  File "/home/adrian/skyfolk/venv/lib/python3.6/site-packages/channels/handler.py", line 243, in process_exception_by_middleware
    return super(AsgiHandler, self).process_exception_by_middleware(exception, request)
  File "/home/adrian/skyfolk/venv/lib/python3.6/site-packages/django/core/handlers/base.py", line 185, in _get_response
    response = wrapped_callback(request, *callback_args, **callback_kwargs)
  File "/home/adrian/skyfolk/venv/lib/python3.6/site-packages/django/contrib/auth/decorators.py", line 23, in _wrapped_view
    return view_func(request, *args, **kwargs)
  File "/home/adrian/skyfolk/dash/views.py", line 1135, in plugin_widgets
    kwargs=kwargs
  File "/home/adrian/skyfolk/venv/lib/python3.6/site-packages/django/urls/base.py", line 91, in reverse
    return force_text(iri_to_uri(resolver._reverse_with_prefix(view, prefix, *args, **kwargs)))
  File "/home/adrian/skyfolk/venv/lib/python3.6/site-packages/django/urls/resolvers.py", line 497, in _reverse_with_prefix
    raise NoReverseMatch(msg)
django.urls.exceptions.NoReverseMatch: Reverse for 'dash.paste_dashboard_entry' with keyword arguments '{'placeholder_uid': 'main', 'position': '2', 'workspace': <DashboardWorkspace: Android's>}' not found. 2 pattern(s) tried: ['dashboard/entry/paste/(?P<placeholder_uid>[\\w_]+)/pos/(?P<position>\\d+)/$', 'dashboard/entry/paste/(?P<placeholder_uid>[\\w_]+)/(?P<workspace>[\\w_\\-]+)/pos/(?P<position>\\d+)/$']
2018-02-05 13:06:22,906 ERROR exception 7666 Internal Server Error: /dashboard/plugin-widgets/main/androids/pos/2/
Traceback (most recent call last):
  File "/home/adrian/skyfolk/venv/lib/python3.6/site-packages/django/core/handlers/exception.py", line 41, in inner
    response = get_response(request)
  File "/home/adrian/skyfolk/venv/lib/python3.6/site-packages/django/core/handlers/base.py", line 249, in _legacy_get_response
    response = self._get_response(request)
  File "/home/adrian/skyfolk/venv/lib/python3.6/site-packages/django/core/handlers/base.py", line 187, in _get_response
    response = self.process_exception_by_middleware(e, request)
  File "/home/adrian/skyfolk/venv/lib/python3.6/site-packages/channels/handler.py", line 243, in process_exception_by_middleware
    return super(AsgiHandler, self).process_exception_by_middleware(exception, request)
  File "/home/adrian/skyfolk/venv/lib/python3.6/site-packages/django/core/handlers/base.py", line 185, in _get_response
    response = wrapped_callback(request, *callback_args, **callback_kwargs)
  File "/home/adrian/skyfolk/venv/lib/python3.6/site-packages/django/contrib/auth/decorators.py", line 23, in _wrapped_view
    return view_func(request, *args, **kwargs)
  File "/home/adrian/skyfolk/dash/views.py", line 1135, in plugin_widgets
    kwargs=kwargs
  File "/home/adrian/skyfolk/venv/lib/python3.6/site-packages/django/urls/base.py", line 91, in reverse
    return force_text(iri_to_uri(resolver._reverse_with_prefix(view, prefix, *args, **kwargs)))
  File "/home/adrian/skyfolk/venv/lib/python3.6/site-packages/django/urls/resolvers.py", line 497, in _reverse_with_prefix
    raise NoReverseMatch(msg)
django.urls.exceptions.NoReverseMatch: Reverse for 'dash.paste_dashboard_entry' with keyword arguments '{'placeholder_uid': 'main', 'position': '2', 'workspace': <DashboardWorkspace: Android's>}' not found. 2 pattern(s) tried: ['dashboard/entry/paste/(?P<placeholder_uid>[\\w_]+)/pos/(?P<position>\\d+)/$', 'dashboard/entry/paste/(?P<placeholder_uid>[\\w_]+)/(?P<workspace>[\\w_\\-]+)/pos/(?P<position>\\d+)/$']
2018-02-05 13:07:29,706 ERROR exception 8135 Internal Server Error: /dashboard/plugin-widgets/main/androids/pos/2/
Traceback (most recent call last):
  File "/home/adrian/skyfolk/venv/lib/python3.6/site-packages/django/core/handlers/exception.py", line 41, in inner
    response = get_response(request)
  File "/home/adrian/skyfolk/venv/lib/python3.6/site-packages/django/core/handlers/base.py", line 249, in _legacy_get_response
    response = self._get_response(request)
  File "/home/adrian/skyfolk/venv/lib/python3.6/site-packages/django/core/handlers/base.py", line 187, in _get_response
    response = self.process_exception_by_middleware(e, request)
  File "/home/adrian/skyfolk/venv/lib/python3.6/site-packages/channels/handler.py", line 243, in process_exception_by_middleware
    return super(AsgiHandler, self).process_exception_by_middleware(exception, request)
  File "/home/adrian/skyfolk/venv/lib/python3.6/site-packages/django/core/handlers/base.py", line 185, in _get_response
    response = wrapped_callback(request, *callback_args, **callback_kwargs)
  File "/home/adrian/skyfolk/venv/lib/python3.6/site-packages/django/contrib/auth/decorators.py", line 23, in _wrapped_view
    return view_func(request, *args, **kwargs)
  File "/home/adrian/skyfolk/dash/views.py", line 1135, in plugin_widgets
    kwargs=kwargs
  File "/home/adrian/skyfolk/venv/lib/python3.6/site-packages/django/urls/base.py", line 91, in reverse
    return force_text(iri_to_uri(resolver._reverse_with_prefix(view, prefix, *args, **kwargs)))
  File "/home/adrian/skyfolk/venv/lib/python3.6/site-packages/django/urls/resolvers.py", line 497, in _reverse_with_prefix
    raise NoReverseMatch(msg)
django.urls.exceptions.NoReverseMatch: Reverse for 'dash.paste_dashboard_entry' with keyword arguments '{'placeholder_uid': 'main', 'position': '2', 'workspace': <DashboardWorkspace: Android's>}' not found. 2 pattern(s) tried: ['dashboard/entry/paste/(?P<placeholder_uid>[\\w_]+)/pos/(?P<position>\\d+)/$', 'dashboard/entry/paste/(?P<placeholder_uid>[\\w_]+)/(?P<workspace>[\\w_\\-]+)/pos/(?P<position>\\d+)/$']
2018-02-05 13:07:40,482 ERROR exception 8271 Internal Server Error: /dashboard/plugin-widgets/main/androids/pos/3/
Traceback (most recent call last):
  File "/home/adrian/skyfolk/venv/lib/python3.6/site-packages/django/core/handlers/exception.py", line 41, in inner
    response = get_response(request)
  File "/home/adrian/skyfolk/venv/lib/python3.6/site-packages/django/core/handlers/base.py", line 249, in _legacy_get_response
    response = self._get_response(request)
  File "/home/adrian/skyfolk/venv/lib/python3.6/site-packages/django/core/handlers/base.py", line 187, in _get_response
    response = self.process_exception_by_middleware(e, request)
  File "/home/adrian/skyfolk/venv/lib/python3.6/site-packages/channels/handler.py", line 243, in process_exception_by_middleware
    return super(AsgiHandler, self).process_exception_by_middleware(exception, request)
  File "/home/adrian/skyfolk/venv/lib/python3.6/site-packages/django/core/handlers/base.py", line 185, in _get_response
    response = wrapped_callback(request, *callback_args, **callback_kwargs)
  File "/home/adrian/skyfolk/venv/lib/python3.6/site-packages/django/contrib/auth/decorators.py", line 23, in _wrapped_view
    return view_func(request, *args, **kwargs)
  File "/home/adrian/skyfolk/dash/views.py", line 1146, in plugin_widgets
    occupied_cells=occupied_cells
  File "/home/adrian/skyfolk/dash/utils.py", line 212, in get_widgets
    reverse('dash.add_dashboard_entry', kwargs=kwargs)
  File "/home/adrian/skyfolk/venv/lib/python3.6/site-packages/django/urls/base.py", line 91, in reverse
    return force_text(iri_to_uri(resolver._reverse_with_prefix(view, prefix, *args, **kwargs)))
  File "/home/adrian/skyfolk/venv/lib/python3.6/site-packages/django/urls/resolvers.py", line 497, in _reverse_with_prefix
    raise NoReverseMatch(msg)
django.urls.exceptions.NoReverseMatch: Reverse for 'dash.add_dashboard_entry' with keyword arguments '{'placeholder_uid': 'main', 'plugin_uid': 'trigger_1x1', 'workspace': <DashboardWorkspace: Android's>, 'position': '3'}' not found. 4 pattern(s) tried: ['dashboard/entry/add/(?P<placeholder_uid>[\\w_]+)/(?P<plugin_uid>[\\w_\\-]+)/$', 'dashboard/entry/add/(?P<placeholder_uid>[\\w_]+)/(?P<plugin_uid>[\\w_\\-]+)/pos/(?P<position>\\d+)/$', 'dashboard/entry/add/(?P<placeholder_uid>[\\w_]+)/(?P<plugin_uid>[\\w_\\-]+)/ws/(?P<workspace>[\\w_\\-]+)/$', 'dashboard/entry/add/(?P<placeholder_uid>[\\w_]+)/(?P<plugin_uid>[\\w_\\-]+)/ws/(?P<workspace>[\\w_\\-]+)/pos/(?P<position>\\d+)/$']
2018-02-05 13:07:56,042 ERROR exception 8406 Internal Server Error: /dashboard/plugin-widgets/main/androids/pos/3/
Traceback (most recent call last):
  File "/home/adrian/skyfolk/venv/lib/python3.6/site-packages/django/core/handlers/exception.py", line 41, in inner
    response = get_response(request)
  File "/home/adrian/skyfolk/venv/lib/python3.6/site-packages/django/core/handlers/base.py", line 249, in _legacy_get_response
    response = self._get_response(request)
  File "/home/adrian/skyfolk/venv/lib/python3.6/site-packages/django/core/handlers/base.py", line 187, in _get_response
    response = self.process_exception_by_middleware(e, request)
  File "/home/adrian/skyfolk/venv/lib/python3.6/site-packages/channels/handler.py", line 243, in process_exception_by_middleware
    return super(AsgiHandler, self).process_exception_by_middleware(exception, request)
  File "/home/adrian/skyfolk/venv/lib/python3.6/site-packages/django/core/handlers/base.py", line 185, in _get_response
    response = wrapped_callback(request, *callback_args, **callback_kwargs)
  File "/home/adrian/skyfolk/venv/lib/python3.6/site-packages/django/contrib/auth/decorators.py", line 23, in _wrapped_view
    return view_func(request, *args, **kwargs)
  File "/home/adrian/skyfolk/dash/views.py", line 1144, in plugin_widgets
    occupied_cells=occupied_cells
  File "/home/adrian/skyfolk/dash/utils.py", line 212, in get_widgets
    reverse('dash.add_dashboard_entry', kwargs=kwargs)
  File "/home/adrian/skyfolk/venv/lib/python3.6/site-packages/django/urls/base.py", line 91, in reverse
    return force_text(iri_to_uri(resolver._reverse_with_prefix(view, prefix, *args, **kwargs)))
  File "/home/adrian/skyfolk/venv/lib/python3.6/site-packages/django/urls/resolvers.py", line 497, in _reverse_with_prefix
    raise NoReverseMatch(msg)
django.urls.exceptions.NoReverseMatch: Reverse for 'dash.add_dashboard_entry' with keyword arguments '{'placeholder_uid': 'main', 'plugin_uid': 'trigger_1x1', 'workspace': <DashboardWorkspace: Android's>, 'position': '3'}' not found. 4 pattern(s) tried: ['dashboard/entry/add/(?P<placeholder_uid>[\\w_]+)/(?P<plugin_uid>[\\w_\\-]+)/$', 'dashboard/entry/add/(?P<placeholder_uid>[\\w_]+)/(?P<plugin_uid>[\\w_\\-]+)/pos/(?P<position>\\d+)/$', 'dashboard/entry/add/(?P<placeholder_uid>[\\w_]+)/(?P<plugin_uid>[\\w_\\-]+)/ws/(?P<workspace>[\\w_\\-]+)/$', 'dashboard/entry/add/(?P<placeholder_uid>[\\w_]+)/(?P<plugin_uid>[\\w_\\-]+)/ws/(?P<workspace>[\\w_\\-]+)/pos/(?P<position>\\d+)/$']
2018-02-05 13:08:37,432 ERROR exception 8764 Internal Server Error: /dashboard/plugin-widgets/main/androids/pos/3/
Traceback (most recent call last):
  File "/home/adrian/skyfolk/venv/lib/python3.6/site-packages/django/core/handlers/exception.py", line 41, in inner
    response = get_response(request)
  File "/home/adrian/skyfolk/venv/lib/python3.6/site-packages/django/core/handlers/base.py", line 249, in _legacy_get_response
    response = self._get_response(request)
  File "/home/adrian/skyfolk/venv/lib/python3.6/site-packages/django/core/handlers/base.py", line 187, in _get_response
    response = self.process_exception_by_middleware(e, request)
  File "/home/adrian/skyfolk/venv/lib/python3.6/site-packages/channels/handler.py", line 243, in process_exception_by_middleware
    return super(AsgiHandler, self).process_exception_by_middleware(exception, request)
  File "/home/adrian/skyfolk/venv/lib/python3.6/site-packages/django/core/handlers/base.py", line 185, in _get_response
    response = wrapped_callback(request, *callback_args, **callback_kwargs)
  File "/home/adrian/skyfolk/venv/lib/python3.6/site-packages/django/contrib/auth/decorators.py", line 23, in _wrapped_view
    return view_func(request, *args, **kwargs)
  File "/home/adrian/skyfolk/dash/views.py", line 1146, in plugin_widgets
    occupied_cells=occupied_cells
  File "/home/adrian/skyfolk/dash/utils.py", line 212, in get_widgets
    reverse('dash.add_dashboard_entry', kwargs=kwargs)
  File "/home/adrian/skyfolk/venv/lib/python3.6/site-packages/django/urls/base.py", line 91, in reverse
    return force_text(iri_to_uri(resolver._reverse_with_prefix(view, prefix, *args, **kwargs)))
  File "/home/adrian/skyfolk/venv/lib/python3.6/site-packages/django/urls/resolvers.py", line 497, in _reverse_with_prefix
    raise NoReverseMatch(msg)
django.urls.exceptions.NoReverseMatch: Reverse for 'dash.add_dashboard_entry' with keyword arguments '{'placeholder_uid': 'main', 'plugin_uid': 'trigger_1x1', 'workspace': <DashboardWorkspace: Android's>, 'position': '3'}' not found. 4 pattern(s) tried: ['dashboard/entry/add/(?P<placeholder_uid>[\\w_]+)/(?P<plugin_uid>[\\w_\\-]+)/$', 'dashboard/entry/add/(?P<placeholder_uid>[\\w_]+)/(?P<plugin_uid>[\\w_\\-]+)/pos/(?P<position>\\d+)/$', 'dashboard/entry/add/(?P<placeholder_uid>[\\w_]+)/(?P<plugin_uid>[\\w_\\-]+)/ws/(?P<workspace>[\\w_\\-]+)/$', 'dashboard/entry/add/(?P<placeholder_uid>[\\w_]+)/(?P<plugin_uid>[\\w_\\-]+)/ws/(?P<workspace>[\\w_\\-]+)/pos/(?P<position>\\d+)/$']
2018-02-05 13:09:14,825 ERROR exception 9203 Internal Server Error: /dashboard/plugin-widgets/main/androids/pos/5/
Traceback (most recent call last):
  File "/home/adrian/skyfolk/venv/lib/python3.6/site-packages/django/core/handlers/exception.py", line 41, in inner
    response = get_response(request)
  File "/home/adrian/skyfolk/venv/lib/python3.6/site-packages/django/core/handlers/base.py", line 249, in _legacy_get_response
    response = self._get_response(request)
  File "/home/adrian/skyfolk/venv/lib/python3.6/site-packages/django/core/handlers/base.py", line 187, in _get_response
    response = self.process_exception_by_middleware(e, request)
  File "/home/adrian/skyfolk/venv/lib/python3.6/site-packages/channels/handler.py", line 243, in process_exception_by_middleware
    return super(AsgiHandler, self).process_exception_by_middleware(exception, request)
  File "/home/adrian/skyfolk/venv/lib/python3.6/site-packages/django/core/handlers/base.py", line 185, in _get_response
    response = wrapped_callback(request, *callback_args, **callback_kwargs)
  File "/home/adrian/skyfolk/venv/lib/python3.6/site-packages/django/contrib/auth/decorators.py", line 23, in _wrapped_view
    return view_func(request, *args, **kwargs)
  File "/home/adrian/skyfolk/dash/views.py", line 1146, in plugin_widgets
    occupied_cells=occupied_cells
  File "/home/adrian/skyfolk/dash/utils.py", line 210, in get_widgets
    reverse('dash.add_dashboard_entry', kwargs=kwargs)
  File "/home/adrian/skyfolk/venv/lib/python3.6/site-packages/django/urls/base.py", line 91, in reverse
    return force_text(iri_to_uri(resolver._reverse_with_prefix(view, prefix, *args, **kwargs)))
  File "/home/adrian/skyfolk/venv/lib/python3.6/site-packages/django/urls/resolvers.py", line 497, in _reverse_with_prefix
    raise NoReverseMatch(msg)
django.urls.exceptions.NoReverseMatch: Reverse for 'dash.add_dashboard_entry' with keyword arguments '{'placeholder_uid': 'main', 'plugin_uid': 'trigger_1x1', 'workspace': <DashboardWorkspace: Android's>, 'position': '5'}' not found. 4 pattern(s) tried: ['dashboard/entry/add/(?P<placeholder_uid>[\\w_]+)/(?P<plugin_uid>[\\w_\\-]+)/$', 'dashboard/entry/add/(?P<placeholder_uid>[\\w_]+)/(?P<plugin_uid>[\\w_\\-]+)/pos/(?P<position>\\d+)/$', 'dashboard/entry/add/(?P<placeholder_uid>[\\w_]+)/(?P<plugin_uid>[\\w_\\-]+)/ws/(?P<workspace>[\\w_\\-]+)/$', 'dashboard/entry/add/(?P<placeholder_uid>[\\w_]+)/(?P<plugin_uid>[\\w_\\-]+)/ws/(?P<workspace>[\\w_\\-]+)/pos/(?P<position>\\d+)/$']
2018-02-05 13:09:34,505 ERROR exception 9465 Internal Server Error: /dashboard/entry/paste/main/androids/pos/5/
Traceback (most recent call last):
  File "/home/adrian/skyfolk/venv/lib/python3.6/site-packages/django/core/handlers/exception.py", line 41, in inner
    response = get_response(request)
  File "/home/adrian/skyfolk/venv/lib/python3.6/site-packages/django/core/handlers/base.py", line 249, in _legacy_get_response
    response = self._get_response(request)
  File "/home/adrian/skyfolk/venv/lib/python3.6/site-packages/django/core/handlers/base.py", line 187, in _get_response
    response = self.process_exception_by_middleware(e, request)
  File "/home/adrian/skyfolk/venv/lib/python3.6/site-packages/channels/handler.py", line 243, in process_exception_by_middleware
    return super(AsgiHandler, self).process_exception_by_middleware(exception, request)
  File "/home/adrian/skyfolk/venv/lib/python3.6/site-packages/django/core/handlers/base.py", line 185, in _get_response
    response = wrapped_callback(request, *callback_args, **callback_kwargs)
  File "/home/adrian/skyfolk/venv/lib/python3.6/site-packages/django/contrib/auth/decorators.py", line 23, in _wrapped_view
    return view_func(request, *args, **kwargs)
  File "/home/adrian/skyfolk/dash/views.py", line 1682, in paste_dashboard_entry
    return redirect('dash.edit_dashboard', workspace=workspace.slug)
AttributeError: 'str' object has no attribute 'slug'
2018-02-05 13:09:48,034 ERROR exception 9607 Internal Server Error: /dashboard/entry/paste/main/androids/pos/5/
Traceback (most recent call last):
  File "/home/adrian/skyfolk/venv/lib/python3.6/site-packages/django/core/handlers/exception.py", line 41, in inner
    response = get_response(request)
  File "/home/adrian/skyfolk/venv/lib/python3.6/site-packages/django/core/handlers/base.py", line 249, in _legacy_get_response
    response = self._get_response(request)
  File "/home/adrian/skyfolk/venv/lib/python3.6/site-packages/django/core/handlers/base.py", line 187, in _get_response
    response = self.process_exception_by_middleware(e, request)
  File "/home/adrian/skyfolk/venv/lib/python3.6/site-packages/channels/handler.py", line 243, in process_exception_by_middleware
    return super(AsgiHandler, self).process_exception_by_middleware(exception, request)
  File "/home/adrian/skyfolk/venv/lib/python3.6/site-packages/django/core/handlers/base.py", line 185, in _get_response
    response = wrapped_callback(request, *callback_args, **callback_kwargs)
  File "/home/adrian/skyfolk/venv/lib/python3.6/site-packages/django/contrib/auth/decorators.py", line 23, in _wrapped_view
    return view_func(request, *args, **kwargs)
  File "/home/adrian/skyfolk/dash/views.py", line 1682, in paste_dashboard_entry
    return redirect('dash.edit_dashboard', workspace=workspace.slug)
AttributeError: 'str' object has no attribute 'slug'
2018-02-05 13:09:53,015 ERROR exception 9607 Internal Server Error: /dashboard/plugin-widgets/main/androids/pos/3/
Traceback (most recent call last):
  File "/home/adrian/skyfolk/venv/lib/python3.6/site-packages/django/core/handlers/exception.py", line 41, in inner
    response = get_response(request)
  File "/home/adrian/skyfolk/venv/lib/python3.6/site-packages/django/core/handlers/base.py", line 249, in _legacy_get_response
    response = self._get_response(request)
  File "/home/adrian/skyfolk/venv/lib/python3.6/site-packages/django/core/handlers/base.py", line 187, in _get_response
    response = self.process_exception_by_middleware(e, request)
  File "/home/adrian/skyfolk/venv/lib/python3.6/site-packages/channels/handler.py", line 243, in process_exception_by_middleware
    return super(AsgiHandler, self).process_exception_by_middleware(exception, request)
  File "/home/adrian/skyfolk/venv/lib/python3.6/site-packages/django/core/handlers/base.py", line 185, in _get_response
    response = wrapped_callback(request, *callback_args, **callback_kwargs)
  File "/home/adrian/skyfolk/venv/lib/python3.6/site-packages/django/contrib/auth/decorators.py", line 23, in _wrapped_view
    return view_func(request, *args, **kwargs)
  File "/home/adrian/skyfolk/dash/views.py", line 1135, in plugin_widgets
    kwargs=kwargs
  File "/home/adrian/skyfolk/venv/lib/python3.6/site-packages/django/urls/base.py", line 91, in reverse
    return force_text(iri_to_uri(resolver._reverse_with_prefix(view, prefix, *args, **kwargs)))
  File "/home/adrian/skyfolk/venv/lib/python3.6/site-packages/django/urls/resolvers.py", line 497, in _reverse_with_prefix
    raise NoReverseMatch(msg)
django.urls.exceptions.NoReverseMatch: Reverse for 'dash.paste_dashboard_entry' with keyword arguments '{'placeholder_uid': 'main', 'position': '3', 'workspace': <DashboardWorkspace: Android's>}' not found. 2 pattern(s) tried: ['dashboard/entry/paste/(?P<placeholder_uid>[\\w_]+)/pos/(?P<position>\\d+)/$', 'dashboard/entry/paste/(?P<placeholder_uid>[\\w_]+)/(?P<workspace>[\\w_\\-]+)/pos/(?P<position>\\d+)/$']
2018-02-05 13:11:26,195 ERROR exception 9854 Internal Server Error: /dashboard/entry/paste/main/androids/pos/4/
Traceback (most recent call last):
  File "/home/adrian/skyfolk/venv/lib/python3.6/site-packages/django/core/handlers/exception.py", line 41, in inner
    response = get_response(request)
  File "/home/adrian/skyfolk/venv/lib/python3.6/site-packages/django/core/handlers/base.py", line 249, in _legacy_get_response
    response = self._get_response(request)
  File "/home/adrian/skyfolk/venv/lib/python3.6/site-packages/django/core/handlers/base.py", line 187, in _get_response
    response = self.process_exception_by_middleware(e, request)
  File "/home/adrian/skyfolk/venv/lib/python3.6/site-packages/channels/handler.py", line 243, in process_exception_by_middleware
    return super(AsgiHandler, self).process_exception_by_middleware(exception, request)
  File "/home/adrian/skyfolk/venv/lib/python3.6/site-packages/django/core/handlers/base.py", line 185, in _get_response
    response = wrapped_callback(request, *callback_args, **callback_kwargs)
  File "/home/adrian/skyfolk/venv/lib/python3.6/site-packages/django/contrib/auth/decorators.py", line 23, in _wrapped_view
    return view_func(request, *args, **kwargs)
  File "/home/adrian/skyfolk/dash/views.py", line 1682, in paste_dashboard_entry
    return redirect('dash.edit_dashboard', workspace=workspace.slug)
AttributeError: 'str' object has no attribute 'slug'
2018-02-05 13:26:35,436 ERROR exception 13202 Internal Server Error: /dashboard/plugin-widgets/main/pos/1/
Traceback (most recent call last):
  File "/home/adrian/skyfolk/venv/lib/python3.6/site-packages/django/core/handlers/exception.py", line 41, in inner
    response = get_response(request)
  File "/home/adrian/skyfolk/venv/lib/python3.6/site-packages/django/core/handlers/base.py", line 249, in _legacy_get_response
    response = self._get_response(request)
  File "/home/adrian/skyfolk/venv/lib/python3.6/site-packages/django/core/handlers/base.py", line 187, in _get_response
    response = self.process_exception_by_middleware(e, request)
  File "/home/adrian/skyfolk/venv/lib/python3.6/site-packages/channels/handler.py", line 243, in process_exception_by_middleware
    return super(AsgiHandler, self).process_exception_by_middleware(exception, request)
  File "/home/adrian/skyfolk/venv/lib/python3.6/site-packages/django/core/handlers/base.py", line 185, in _get_response
    response = wrapped_callback(request, *callback_args, **callback_kwargs)
  File "/home/adrian/skyfolk/venv/lib/python3.6/site-packages/django/contrib/auth/decorators.py", line 23, in _wrapped_view
    return view_func(request, *args, **kwargs)
  File "/home/adrian/skyfolk/dash/views.py", line 1144, in plugin_widgets
    workspace=workspace.slug,
AttributeError: 'NoneType' object has no attribute 'slug'
